Workbook

Sheet 👥 Daftar Nama Pasien
B1: =IFERROR(__xludf.DUMMYFUNCTION("IMPORTRANGE(""https://docs.google.com/spreadsheets/d/1q5irXBuyRkQM_goHlRjPTSwHk1on6thK70p8lljqLrs/edit?gid=1342096879#gid=1342096879"",""🙎‍♂️ Pasien!$G$2:$I"")"),"Nama Pasien") -> Nama Pasien | C1: =IFERROR(__xludf.DUMMYFUNCTION("""COMPUTED_VALUE"""),"No. RM") -> No. RM | D1: =IFERROR(__xludf.DUMMYFUNCTION("""COMPUTED_VALUE"""),"Usia") -> Usia
B2: =IFERROR(__xludf.DUMMYFUNCTION("""COMPUTED_VALUE"""),"OFF") -> OFF | C2: =IFERROR(__xludf.DUMMYFUNCTION("""COMPUTED_VALUE"""),"OFF") -> OFF
B3: =IFERROR(__xludf.DUMMYFUNCTION("""COMPUTED_VALUE"""),"LIBUR") -> LIBUR | C3: =IFERROR(__xludf.DUMMYFUNCTION("""COMPUTED_VALUE"""),"LIBUR") -> LIBUR
B4: =IFERROR(__xludf.DUMMYFUNCTION("""COMPUTED_VALUE"""),"TA") -> TA | C4: =IFERROR(__xludf.DUMMYFUNCTION("""COMPUTED_VALUE"""),"TA") -> TA
B5: =IFERROR(__xludf.DUMMYFUNCTION("""COMPUTED_VALUE"""),"MANAJEMEN") -> MANAJEMEN | C5: =IFERROR(__xludf.DUMMYFUNCTION("""COMPUTED_VALUE"""),"MANAJEMEN") -> MANAJEMEN
B6: =IFERROR(__xludf.DUMMYFUNCTION("""COMPUTED_VALUE"""),"KHUSUS") -> KHUSUS | C6: =IFERROR(__xludf.DUMMYFUNCTION("""COMPUTED_VALUE"""),"KHUSUS") -> KHUSUS
B7: =IFERROR(__xludf.DUMMYFUNCTION("""COMPUTED_VALUE"""),"BELUM ISI DATA") -> BELUM ISI DATA | C7: =IFERROR(__xludf.DUMMYFUNCTION("""COMPUTED_VALUE"""),"BELUM ISI DATA") -> BELUM ISI DATA
C8: =IFERROR(__xludf.DUMMYFUNCTION("""COMPUTED_VALUE"""),"") | D8: =IFERROR(__xludf.DUMMYFUNCTION("""COMPUTED_VALUE"""),"")
B9: =IFERROR(__xludf.DUMMYFUNCTION("""COMPUTED_VALUE"""),"ZHOFRAN FARRAS ATAYA") -> ZHOFRAN FARRAS ATAYA | C9: =IFERROR(__xludf.DUMMYFUNCTION("""COMPUTED_VALUE"""),"Z0922105765") -> Z0922105765 | D9: =IFERROR(__xludf.DUMMYFUNCTION("""COMPUTED_VALUE"""),17.0) -> 17
B10: =IFERROR(__xludf.DUMMYFUNCTION("""COMPUTED_VALUE"""),"DIAH SUCI RINI") -> DIAH SUCI RINI | C10: =IFERROR(__xludf.DUMMYFUNCTION("""COMPUTED_VALUE"""),"D5722102445") -> D5722102445 | D10: =IFERROR(__xludf.DUMMYFUNCTION("""COMPUTED_VALUE"""),68.0) -> 68
B11: =IFERROR(__xludf.DUMMYFUNCTION("""COMPUTED_VALUE"""),"MEIZARANI HELJA") -> MEIZARANI HELJA | C11: =IFERROR(__xludf.DUMMYFUNCTION("""COMPUTED_VALUE"""),"M9322128010") -> M9322128010 | D11: =IFERROR(__xludf.DUMMYFUNCTION("""COMPUTED_VALUE"""),33.0) -> 33
B12: =IFERROR(__xludf.DUMMYFUNCTION("""COMPUTED_VALUE"""),"HUWAIDAH THIFAL NAURAH") -> HUWAIDAH THIFAL NAURAH | C12: =IFERROR(__xludf.DUMMYFUNCTION("""COMPUTED_VALUE"""),"H0123016085") -> H0123016085 | D12: =IFERROR(__xludf.DUMMYFUNCTION("""COMPUTED_VALUE"""),25.0) -> 25
B13: =IFERROR(__xludf.DUMMYFUNCTION("""COMPUTED_VALUE"""),"SUFIRNA") -> SUFIRNA | C13: =IFERROR(__xludf.DUMMYFUNCTION("""COMPUTED_VALUE"""),"S7823018882") -> S7823018882 | D13: =IFERROR(__xludf.DUMMYFUNCTION("""COMPUTED_VALUE"""),48.0) -> 48
B14: =IFERROR(__xludf.DUMMYFUNCTION("""COMPUTED_VALUE"""),"ALVIN DIYANDRA") -> ALVIN DIYANDRA | C14: =IFERROR(__xludf.DUMMYFUNCTION("""COMPUTED_VALUE"""),"A9723017817") -> A9723017817 | D14: =IFERROR(__xludf.DUMMYFUNCTION("""COMPUTED_VALUE"""),29.0) -> 29
B15: =IFERROR(__xludf.DUMMYFUNCTION("""COMPUTED_VALUE"""),"ANDI ICHWANUL AZWAR") -> ANDI ICHWANUL AZWAR | C15: =IFERROR(__xludf.DUMMYFUNCTION("""COMPUTED_VALUE"""),"A8823011011") -> A8823011011 | D15: =IFERROR(__xludf.DUMMYFUNCTION("""COMPUTED_VALUE"""),37.0) -> 37
B16: =IFERROR(__xludf.DUMMYFUNCTION("""COMPUTED_VALUE"""),"AREEFAQEEL DIEN HAQQ") -> AREEFAQEEL DIEN HAQQ | C16: =IFERROR(__xludf.DUMMYFUNCTION("""COMPUTED_VALUE"""),"A1023015335") -> A1023015335 | D16: =IFERROR(__xludf.DUMMYFUNCTION("""COMPUTED_VALUE"""),15.0) -> 15
B17: =IFERROR(__xludf.DUMMYFUNCTION("""COMPUTED_VALUE"""),"NURLINA") -> NURLINA | C17: =IFERROR(__xludf.DUMMYFUNCTION("""COMPUTED_VALUE"""),"N8523017483") -> N8523017483 | D17: =IFERROR(__xludf.DUMMYFUNCTION("""COMPUTED_VALUE"""),40.0) -> 40
B18: =IFERROR(__xludf.DUMMYFUNCTION("""COMPUTED_VALUE"""),"A. THENU") -> A. THENU | C18: =IFERROR(__xludf.DUMMYFUNCTION("""COMPUTED_VALUE"""),"A7023018857") -> A7023018857 | D18: =IFERROR(__xludf.DUMMYFUNCTION("""COMPUTED_VALUE"""),55.0) -> 55
B19: =IFERROR(__xludf.DUMMYFUNCTION("""COMPUTED_VALUE"""),"ATIKA ALIFIA F. TOBING") -> ATIKA ALIFIA F. TOBING | C19: =IFERROR(__xludf.DUMMYFUNCTION("""COMPUTED_VALUE"""),"A9023018425") -> A9023018425 | D19: =IFERROR(__xludf.DUMMYFUNCTION("""COMPUTED_VALUE"""),36.0) -> 36
B20: =IFERROR(__xludf.DUMMYFUNCTION("""COMPUTED_VALUE"""),"JAKA SEPTIADI") -> JAKA SEPTIADI | C20: =IFERROR(__xludf.DUMMYFUNCTION("""COMPUTED_VALUE"""),"J8823016633") -> J8823016633 | D20: =IFERROR(__xludf.DUMMYFUNCTION("""COMPUTED_VALUE"""),38.0) -> 38
B21: =IFERROR(__xludf.DUMMYFUNCTION("""COMPUTED_VALUE"""),"MARIYO") -> MARIYO | C21: =IFERROR(__xludf.DUMMYFUNCTION("""COMPUTED_VALUE"""),"M6523010470") -> M6523010470 | D21: =IFERROR(__xludf.DUMMYFUNCTION("""COMPUTED_VALUE"""),60.0) -> 60
B22: =IFERROR(__xludf.DUMMYFUNCTION("""COMPUTED_VALUE"""),"ADIEL PRATAMA PUTRA K.") -> ADIEL PRATAMA PUTRA K. | C22: =IFERROR(__xludf.DUMMYFUNCTION("""COMPUTED_VALUE"""),"A0623015163") -> A0623015163 | D22: =IFERROR(__xludf.DUMMYFUNCTION("""COMPUTED_VALUE"""),20.0) -> 20
B23: =IFERROR(__xludf.DUMMYFUNCTION("""COMPUTED_VALUE"""),"DAVID BURUI") -> DAVID BURUI | C23: =IFERROR(__xludf.DUMMYFUNCTION("""COMPUTED_VALUE"""),"D6123013327") -> D6123013327 | D23: =IFERROR(__xludf.DUMMYFUNCTION("""COMPUTED_VALUE"""),64.0) -> 64
B24: =IFERROR(__xludf.DUMMYFUNCTION("""COMPUTED_VALUE"""),"DEDI SUNARDI") -> DEDI SUNARDI | C24: =IFERROR(__xludf.DUMMYFUNCTION("""COMPUTED_VALUE"""),"D8223017622") -> D8223017622 | D24: =IFERROR(__xludf.DUMMYFUNCTION("""COMPUTED_VALUE"""),43.0) -> 43
B25: =IFERROR(__xludf.DUMMYFUNCTION("""COMPUTED_VALUE"""),"MIGUEL TJONDRO") -> MIGUEL TJONDRO | C25: =IFERROR(__xludf.DUMMYFUNCTION("""COMPUTED_VALUE"""),"M9823010741") -> M9823010741 | D25: =IFERROR(__xludf.DUMMYFUNCTION("""COMPUTED_VALUE"""),28.0) -> 28
B26: =IFERROR(__xludf.DUMMYFUNCTION("""COMPUTED_VALUE"""),"TRI WAHYUNI") -> TRI WAHYUNI | C26: =IFERROR(__xludf.DUMMYFUNCTION("""COMPUTED_VALUE"""),"T7623010391") -> T7623010391 | D26: =IFERROR(__xludf.DUMMYFUNCTION("""COMPUTED_VALUE"""),50.0) -> 50
B27: =IFERROR(__xludf.DUMMYFUNCTION("""COMPUTED_VALUE"""),"ANANTA UTAMI") -> ANANTA UTAMI | C27: =IFERROR(__xludf.DUMMYFUNCTION("""COMPUTED_VALUE"""),"A9123011070") -> A9123011070 | D27: =IFERROR(__xludf.DUMMYFUNCTION("""COMPUTED_VALUE"""),34.0) -> 34
B28: =IFERROR(__xludf.DUMMYFUNCTION("""COMPUTED_VALUE"""),"EMMI") -> EMMI | C28: =IFERROR(__xludf.DUMMYFUNCTION("""COMPUTED_VALUE"""),"E6223013059") -> E6223013059 | D28: =IFERROR(__xludf.DUMMYFUNCTION("""COMPUTED_VALUE"""),63.0) -> 63
B29: =IFERROR(__xludf.DUMMYFUNCTION("""COMPUTED_VALUE"""),"ZIQRIL HAKIM R") -> ZIQRIL HAKIM R | C29: =IFERROR(__xludf.DUMMYFUNCTION("""COMPUTED_VALUE"""),"Z0423010391") -> Z0423010391 | D29: =IFERROR(__xludf.DUMMYFUNCTION("""COMPUTED_VALUE"""),21.0) -> 21
B30: =IFERROR(__xludf.DUMMYFUNCTION("""COMPUTED_VALUE"""),"ERNA SETIAWATY") -> ERNA SETIAWATY | C30: =IFERROR(__xludf.DUMMYFUNCTION("""COMPUTED_VALUE"""),"E5423019005") -> E5423019005 | D30: =IFERROR(__xludf.DUMMYFUNCTION("""COMPUTED_VALUE"""),71.0) -> 71
B31: =IFERROR(__xludf.DUMMYFUNCTION("""COMPUTED_VALUE"""),"EVA DOLOROSA") -> EVA DOLOROSA | C31: =IFERROR(__xludf.DUMMYFUNCTION("""COMPUTED_VALUE"""),"E6723010889") -> E6723010889 | D31: =IFERROR(__xludf.DUMMYFUNCTION("""COMPUTED_VALUE"""),59.0) -> 59
B32: =IFERROR(__xludf.DUMMYFUNCTION("""COMPUTED_VALUE"""),"ANTO PRAYUGO") -> ANTO PRAYUGO | C32: =IFERROR(__xludf.DUMMYFUNCTION("""COMPUTED_VALUE"""),"A9523012989") -> A9523012989 | D32: =IFERROR(__xludf.DUMMYFUNCTION("""COMPUTED_VALUE"""),31.0) -> 31
B33: =IFERROR(__xludf.DUMMYFUNCTION("""COMPUTED_VALUE"""),"FAHMI") -> FAHMI | C33: =IFERROR(__xludf.DUMMYFUNCTION("""COMPUTED_VALUE"""),"F8623010888") -> F8623010888 | D33: =IFERROR(__xludf.DUMMYFUNCTION("""COMPUTED_VALUE"""),40.0) -> 40
B34: =IFERROR(__xludf.DUMMYFUNCTION("""COMPUTED_VALUE"""),"RYANDI ARDIENDA P.") -> RYANDI ARDIENDA P. | C34: =IFERROR(__xludf.DUMMYFUNCTION("""COMPUTED_VALUE"""),"R9323012323") -> R9323012323 | D34: =IFERROR(__xludf.DUMMYFUNCTION("""COMPUTED_VALUE"""),32.0) -> 32
B35: =IFERROR(__xludf.DUMMYFUNCTION("""COMPUTED_VALUE"""),"NURYANTO") -> NURYANTO | C35: =IFERROR(__xludf.DUMMYFUNCTION("""COMPUTED_VALUE"""),"N5423010002") -> N5423010002 | D35: =IFERROR(__xludf.DUMMYFUNCTION("""COMPUTED_VALUE"""),71.0) -> 71
B36: =IFERROR(__xludf.DUMMYFUNCTION("""COMPUTED_VALUE"""),"DIMAS PANDU HIDAYATULLAH") -> DIMAS PANDU HIDAYATULLAH | C36: =IFERROR(__xludf.DUMMYFUNCTION("""COMPUTED_VALUE"""),"D0023011314") -> D0023011314 | D36: =IFERROR(__xludf.DUMMYFUNCTION("""COMPUTED_VALUE"""),26.0) -> 26
B37: =IFERROR(__xludf.DUMMYFUNCTION("""COMPUTED_VALUE"""),"EIVA RADE SIHO") -> EIVA RADE SIHO | C37: =IFERROR(__xludf.DUMMYFUNCTION("""COMPUTED_VALUE"""),"E7623015810") -> E7623015810 | D37: =IFERROR(__xludf.DUMMYFUNCTION("""COMPUTED_VALUE"""),49.0) -> 49
B38: =IFERROR(__xludf.DUMMYFUNCTION("""COMPUTED_VALUE"""),"ERICK TRIENARDO") -> ERICK TRIENARDO | C38: =IFERROR(__xludf.DUMMYFUNCTION("""COMPUTED_VALUE"""),"E9723014638") -> E9723014638 | D38: =IFERROR(__xludf.DUMMYFUNCTION("""COMPUTED_VALUE"""),29.0) -> 29
B39: =IFERROR(__xludf.DUMMYFUNCTION("""COMPUTED_VALUE"""),"FLAVIUS PANGAREGO") -> FLAVIUS PANGAREGO | C39: =IFERROR(__xludf.DUMMYFUNCTION("""COMPUTED_VALUE"""),"F9623012859") -> F9623012859 | D39: =IFERROR(__xludf.DUMMYFUNCTION("""COMPUTED_VALUE"""),30.0) -> 30
B40: =IFERROR(__xludf.DUMMYFUNCTION("""COMPUTED_VALUE"""),"HERI RAHMANTO") -> HERI RAHMANTO | C40: =IFERROR(__xludf.DUMMYFUNCTION("""COMPUTED_VALUE"""),"H6123011926") -> H6123011926 | D40: =IFERROR(__xludf.DUMMYFUNCTION("""COMPUTED_VALUE"""),65.0) -> 65
...

Sheet ⬇️ PEMASUKAN
B1: CATATAN PEMASUKAN LAYANAN FISIOTERAPI GANG SEHAT PONTIANAK 2026
B4: NO | C4: ADMIN | D4: TANGGAL | E4: TAHUN | F4: BULAN | G4: JAM | H4: FISIO | I4: NAMA PASIEN | J4: PEMBELIAN | K4: KATEGORI PEMBELIAN | L4: STATUS PEMBELIAN | M4: KETERANGAN BAYAR | N4: JUMLAH BAYAR | O4: DISKON | P4: HARGA | Q4: KEKURANGAN | R4: METODE BAYAR | S4: PENJAMIN | T4: ✅ | U4: CATATAN
B5: 60 | C5: NOPI | D5: 45844 | E5: =if(D5="","",text(D5,"YYY")) -> 2025 | F5: =if(D5="","",text(D5,"MM")&" "&text(D5,"MMM")) -> 07 Jul | I5: HARYA PAMUNGKAS | J5: K.PT - PAKET 1 | K5: {=IF(J5="","", XLOOKUP(J5,'⚙️ Pengaturan'!$E$2:$E3237,'⚙️ Pengaturan'!$G$2:$G3237))} -> KLINIK FT PAKET | L5: =if(I5="","",if(countifs($J$5:J5,J5,$I$5:I5,I5)=1,"BARU","LANJUTAN")) -> BARU | M5: DP | N5: 200000 | O5: 0 | P5: {=IFNA(XLOOKUP(J5,'⚙️ Pengaturan'!$E$2:$E3237,'⚙️ Pengaturan'!$F$2:$F3237),"")} -> 650000 | Q5: =IF(I5="","",(N5+O5)-P5) -> -450000 | R5: TRANSFER BCA | S5: HARYA PAMUNGKAS | T5: TRUE
B6: 84 | C6: LAINNYA | D6: 45846 | E6: =if(D6="","",text(D6,"YYY")) -> 2025 | F6: =if(D6="","",text(D6,"MM")&" "&text(D6,"MMM")) -> 07 Jul | I6: SUKARDI. SH MM | J6: K.PT - PAKET 1 | K6: {=IF(J6="","", XLOOKUP(J6,'⚙️ Pengaturan'!$E$2:$E3237,'⚙️ Pengaturan'!$G$2:$G3237))} -> KLINIK FT PAKET | L6: =if(I6="","",if(countifs($J$5:J6,J6,$I$5:I6,I6)=1,"BARU","LANJUTAN")) -> BARU | M6: DP | N6: 200000 | O6: 0 | P6: {=IFNA(XLOOKUP(J6,'⚙️ Pengaturan'!$E$2:$E3237,'⚙️ Pengaturan'!$F$2:$F3237),"")} -> 650000 | Q6: =IF(I6="","",(N6+O6)-P6) -> -450000 | R6: TUNAI | S6: - | T6: TRUE
B7: 247 | C7: LAINNYA | D7: 45858 | E7: =if(D7="","",text(D7,"YYY")) -> 2025 | F7: =if(D7="","",text(D7,"MM")&" "&text(D7,"MMM")) -> 07 Jul | I7: MURTI JULIANDARI | J7: K.PT - PAKET 1 | K7: {=IF(J7="","", XLOOKUP(J7,'⚙️ Pengaturan'!$E$2:$E3237,'⚙️ Pengaturan'!$G$2:$G3237))} -> KLINIK FT PAKET | L7: =if(I7="","",if(countifs($J$5:J7,J7,$I$5:I7,I7)=1,"BARU","LANJUTAN")) -> BARU | M7: DP | N7: 250000 | O7: 0 | P7: {=IFNA(XLOOKUP(J7,'⚙️ Pengaturan'!$E$2:$E3237,'⚙️ Pengaturan'!$F$2:$F3237),"")} -> 650000 | Q7: =IF(I7="","",(N7+O7)-P7) -> -400000 | R7: TRANSFER BCA | S7: MURTI JULIANDARI | T7: TRUE
B8: 317 | C8: NOPI | D8: 45864 | E8: =if(D8="","",text(D8,"YYY")) -> 2025 | F8: =if(D8="","",text(D8,"MM")&" "&text(D8,"MMM")) -> 07 Jul | I8: MURTI JULIANDARI | J8: K.PT - PAKET 1 | K8: {=IF(J8="","", XLOOKUP(J8,'⚙️ Pengaturan'!$E$2:$E3237,'⚙️ Pengaturan'!$G$2:$G3237))} -> KLINIK FT PAKET | L8: =if(I8="","",if(countifs($J$5:J8,J8,$I$5:I8,I8)=1,"BARU","LANJUTAN")) -> LANJUTAN | M8: CICILAN | N8: 200000 | O8: 250000 | P8: {=IFNA(XLOOKUP(J8,'⚙️ Pengaturan'!$E$2:$E3237,'⚙️ Pengaturan'!$F$2:$F3237),"")} -> 650000 | Q8: =IF(I8="","",(N8+O8)-P8) -> -200000 | R8: TUNAI | S8: - | T8: TRUE
B9: 696 | C9: NOPI | D9: 45897 | E9: =if(D9="","",text(D9,"YYY")) -> 2025 | F9: =if(D9="","",text(D9,"MM")&" "&text(D9,"MMM")) -> 08 Agu | I9: MUNAGI | J9: K.PT - PAKET 1 | K9: {=IF(J9="","", XLOOKUP(J9,'⚙️ Pengaturan'!$E$2:$E3237,'⚙️ Pengaturan'!$G$2:$G3237))} -> KLINIK FT PAKET | L9: =if(I9="","",if(countifs($J$5:J9,J9,$I$5:I9,I9)=1,"BARU","LANJUTAN")) -> BARU | M9: DP | N9: 200000 | O9: 0 | P9: {=IFNA(XLOOKUP(J9,'⚙️ Pengaturan'!$E$2:$E3237,'⚙️ Pengaturan'!$F$2:$F3237),"")} -> 650000 | Q9: =IF(I9="","",(N9+O9)-P9) -> -450000 | R9: TUNAI | S9: - | T9: TRUE
B10: 738 | C10: SUCI | D10: 45901 | E10: =if(D10="","",text(D10,"YYY")) -> 2025 | F10: =if(D10="","",text(D10,"MM")&" "&text(D10,"MMM")) -> 09 Sep | I10: MUNAGI | J10: K.PT - PAKET 1 | K10: {=IF(J10="","", XLOOKUP(J10,'⚙️ Pengaturan'!$E$2:$E3237,'⚙️ Pengaturan'!$G$2:$G3237))} -> KLINIK FT PAKET | L10: =if(I10="","",if(countifs($J$5:J10,J10,$I$5:I10,I10)=1,"BARU","LANJUTAN")) -> LANJUTAN | M10: CICILAN | N10: 200000 | O10: 200000 | P10: {=IFNA(XLOOKUP(J10,'⚙️ Pengaturan'!$E$2:$E3237,'⚙️ Pengaturan'!$F$2:$F3237),"")} -> 650000 | Q10: =IF(I10="","",(N10+O10)-P10) -> -250000 | R10: TUNAI | S10: - | T10: TRUE
B11: 1013 | C11: NOPI | D11: 45925 | E11: =if(D11="","",text(D11,"YYY")) -> 2025 | F11: =if(D11="","",text(D11,"MM")&" "&text(D11,"MMM")) -> 09 Sep | I11: SYAHRIL AKBARI | J11: K.PT - PAKET 1 | K11: {=IF(J11="","", XLOOKUP(J11,'⚙️ Pengaturan'!$E$2:$E3237,'⚙️ Pengaturan'!$G$2:$G3237))} -> KLINIK FT PAKET | L11: =if(I11="","",if(countifs($J$5:J11,J11,$I$5:I11,I11)=1,"BARU","LANJUTAN")) -> BARU | M11: DP | N11: 200000 | O11: 0 | P11: {=IFNA(XLOOKUP(J11,'⚙️ Pengaturan'!$E$2:$E3237,'⚙️ Pengaturan'!$F$2:$F3237),"")} -> 650000 | Q11: =IF(I11="","",(N11+O11)-P11) -> -450000 | R11: TUNAI | S11: - | T11: TRUE
B12: 1085 | C12: SUCI | D12: 45931 | E12: =if(D12="","",text(D12,"YYY")) -> 2025 | F12: =if(D12="","",text(D12,"MM")&" "&text(D12,"MMM")) -> 10 Okt | I12: RUDI HARTONO | J12: K.PT - PAKET 2 | K12: {=IF(J12="","", XLOOKUP(J12,'⚙️ Pengaturan'!$E$2:$E3237,'⚙️ Pengaturan'!$G$2:$G3237))} -> KLINIK FT PAKET | L12: =if(I12="","",if(countifs($J$5:J12,J12,$I$5:I12,I12)=1,"BARU","LANJUTAN")) -> BARU | M12: DP | N12: 500000 | O12: 0 | P12: {=IFNA(XLOOKUP(J12,'⚙️ Pengaturan'!$E$2:$E3237,'⚙️ Pengaturan'!$F$2:$F3237),"")} -> 1200000 | Q12: =IF(I12="","",(N12+O12)-P12) -> -700000 | R12: EDC BCA | S12: RUDI HARTONO | T12: TRUE
B13: 1153 | C13: SUCI | D13: 45937 | E13: =if(D13="","",text(D13,"YYY")) -> 2025 | F13: =if(D13="","",text(D13,"MM")&" "&text(D13,"MMM")) -> 10 Okt | I13: ARIFIN NUR ROCHMAD | J13: K.PT - PAKET 1 | K13: {=IF(J13="","", XLOOKUP(J13,'⚙️ Pengaturan'!$E$2:$E3237,'⚙️ Pengaturan'!$G$2:$G3237))} -> KLINIK FT PAKET | L13: =if(I13="","",if(countifs($J$5:J13,J13,$I$5:I13,I13)=1,"BARU","LANJUTAN")) -> BARU | M13: DP | N13: 200000 | O13: 0 | P13: {=IFNA(XLOOKUP(J13,'⚙️ Pengaturan'!$E$2:$E3237,'⚙️ Pengaturan'!$F$2:$F3237),"")} -> 650000 | Q13: =IF(I13="","",(N13+O13)-P13) -> -450000 | R13: TUNAI | S13: - | T13: TRUE
B14: 1159 | C14: SUCI | D14: 45938 | E14: =if(D14="","",text(D14,"YYY")) -> 2025 | F14: =if(D14="","",text(D14,"MM")&" "&text(D14,"MMM")) -> 10 Okt | I14: CINTHYA MEILIZA | J14: K.PT - PAKET 1 | K14: {=IF(J14="","", XLOOKUP(J14,'⚙️ Pengaturan'!$E$2:$E3237,'⚙️ Pengaturan'!$G$2:$G3237))} -> KLINIK FT PAKET | L14: =if(I14="","",if(countifs($J$5:J14,J14,$I$5:I14,I14)=1,"BARU","LANJUTAN")) -> BARU | M14: DP | N14: 200000 | O14: 0 | P14: {=IFNA(XLOOKUP(J14,'⚙️ Pengaturan'!$E$2:$E3237,'⚙️ Pengaturan'!$F$2:$F3237),"")} -> 650000 | Q14: =IF(I14="","",(N14+O14)-P14) -> -450000 | R14: TRANSFER BCA | S14: CINTHYA MEILIZA | T14: TRUE
B15: 1172 | C15: NOPI | D15: 45939 | E15: =if(D15="","",text(D15,"YYY")) -> 2025 | F15: =if(D15="","",text(D15,"MM")&" "&text(D15,"MMM")) -> 10 Okt | I15: SULAIMAN 9601 | J15: K.PT - PAKET 2 | K15: {=IF(J15="","", XLOOKUP(J15,'⚙️ Pengaturan'!$E$2:$E3237,'⚙️ Pengaturan'!$G$2:$G3237))} -> KLINIK FT PAKET | L15: =if(I15="","",if(countifs($J$5:J15,J15,$I$5:I15,I15)=1,"BARU","LANJUTAN")) -> BARU | M15: DP | N15: 500000 | O15: 0 | P15: {=IFNA(XLOOKUP(J15,'⚙️ Pengaturan'!$E$2:$E3237,'⚙️ Pengaturan'!$F$2:$F3237),"")} -> 1200000 | Q15: =IF(I15="","",(N15+O15)-P15) -> -700000 | R15: TUNAI | S15: - | T15: TRUE
B16: 1313 | C16: SUCI | D16: 45951 | E16: =if(D16="","",text(D16,"YYY")) -> 2025 | F16: =if(D16="","",text(D16,"MM")&" "&text(D16,"MMM")) -> 10 Okt | I16: DIKI FIRMANSYAH | J16: K.PT - PAKET 1 | K16: {=IF(J16="","", XLOOKUP(J16,'⚙️ Pengaturan'!$E$2:$E3237,'⚙️ Pengaturan'!$G$2:$G3237))} -> KLINIK FT PAKET | L16: =if(I16="","",if(countifs($J$5:J16,J16,$I$5:I16,I16)=1,"BARU","LANJUTAN")) -> BARU | M16: DP | N16: 300000 | O16: 0 | P16: {=IFNA(XLOOKUP(J16,'⚙️ Pengaturan'!$E$2:$E3237,'⚙️ Pengaturan'!$F$2:$F3237),"")} -> 650000 | Q16: =IF(I16="","",(N16+O16)-P16) -> -350000 | R16: TRANSFER BCA | S16: DIKI FIRNANDA | T16: TRUE
B17: 1324 | C17: NOPI | D17: 45952 | E17: =if(D17="","",text(D17,"YYY")) -> 2025 | F17: =if(D17="","",text(D17,"MM")&" "&text(D17,"MMM")) -> 10 Okt | I17: ALY AL DASTAN | J17: K.PT - PAKET 1 | K17: {=IF(J17="","", XLOOKUP(J17,'⚙️ Pengaturan'!$E$2:$E3237,'⚙️ Pengaturan'!$G$2:$G3237))} -> KLINIK FT PAKET | L17: =if(I17="","",if(countifs($J$5:J17,J17,$I$5:I17,I17)=1,"BARU","LANJUTAN")) -> BARU | M17: DP | N17: 200000 | O17: 0 | P17: {=IFNA(XLOOKUP(J17,'⚙️ Pengaturan'!$E$2:$E3237,'⚙️ Pengaturan'!$F$2:$F3237),"")} -> 650000 | Q17: =IF(I17="","",(N17+O17)-P17) -> -450000 | R17: TUNAI | S17: - | T17: TRUE
B18: 1354 | C18: NOPI | D18: 45955 | E18: =if(D18="","",text(D18,"YYY")) -> 2025 | F18: =if(D18="","",text(D18,"MM")&" "&text(D18,"MMM")) -> 10 Okt | I18: TUTI TRISNAWATI | J18: K.PT - PAKET 1 | K18: {=IF(J18="","", XLOOKUP(J18,'⚙️ Pengaturan'!$E$2:$E3237,'⚙️ Pengaturan'!$G$2:$G3237))} -> KLINIK FT PAKET | L18: =if(I18="","",if(countifs($J$5:J18,J18,$I$5:I18,I18)=1,"BARU","LANJUTAN")) -> BARU | M18: DP | N18: 200000 | O18: 0 | P18: {=IFNA(XLOOKUP(J18,'⚙️ Pengaturan'!$E$2:$E3237,'⚙️ Pengaturan'!$F$2:$F3237),"")} -> 650000 | Q18: =IF(I18="","",(N18+O18)-P18) -> -450000 | R18: TUNAI | S18: - | T18: TRUE
B19: 1569 | C19: SUCI | D19: 45972 | E19: =if(D19="","",text(D19,"YYY")) -> 2025 | F19: =if(D19="","",text(D19,"MM")&" "&text(D19,"MMM")) -> 11 Nov | I19: ARIFIN NUR ROCHMAD | J19: K.PT - PAKET 1 | K19: {=IF(J19="","", XLOOKUP(J19,'⚙️ Pengaturan'!$E$2:$E3237,'⚙️ Pengaturan'!$G$2:$G3237))} -> KLINIK FT PAKET | L19: =if(I19="","",if(countifs($J$5:J19,J19,$I$5:I19,I19)=1,"BARU","LANJUTAN")) -> LANJUTAN | M19: DP | N19: 200000 | O19: 0 | P19: {=IFNA(XLOOKUP(J19,'⚙️ Pengaturan'!$E$2:$E3237,'⚙️ Pengaturan'!$F$2:$F3237),"")} -> 650000 | Q19: =IF(I19="","",(N19+O19)-P19) -> -450000 | R19: TUNAI | S19: - | T19: TRUE
B20: 1577 | C20: NOPI | D20: 45973 | E20: =if(D20="","",text(D20,"YYY")) -> 2025 | F20: =if(D20="","",text(D20,"MM")&" "&text(D20,"MMM")) -> 11 Nov | I20: ZULKIFLI HASANUDDIN | J20: K.PT - PAKET 1 | K20: {=IF(J20="","", XLOOKUP(J20,'⚙️ Pengaturan'!$E$2:$E3237,'⚙️ Pengaturan'!$G$2:$G3237))} -> KLINIK FT PAKET | L20: =if(I20="","",if(countifs($J$5:J20,J20,$I$5:I20,I20)=1,"BARU","LANJUTAN")) -> BARU | M20: DP | N20: 200000 | O20: 0 | P20: {=IFNA(XLOOKUP(J20,'⚙️ Pengaturan'!$E$2:$E3237,'⚙️ Pengaturan'!$F$2:$F3237),"")} -> 650000 | Q20: =IF(I20="","",(N20+O20)-P20) -> -450000 | R20: TRANSFER BCA | S20: ZULKIFLI HASANUDDIN | T20: TRUE
B21: 1593 | C21: SUCI | D21: 45976 | E21: =if(D21="","",text(D21,"YYY")) -> 2025 | F21: =if(D21="","",text(D21,"MM")&" "&text(D21,"MMM")) -> 11 Nov | I21: DHAIFULLAH IRFAN HAFIZH | J21: K.PT - PAKET 2 | K21: {=IF(J21="","", XLOOKUP(J21,'⚙️ Pengaturan'!$E$2:$E3237,'⚙️ Pengaturan'!$G$2:$G3237))} -> KLINIK FT PAKET | L21: =if(I21="","",if(countifs($J$5:J21,J21,$I$5:I21,I21)=1,"BARU","LANJUTAN")) -> BARU | M21: DP | N21: 600000 | O21: 0 | P21: {=IFNA(XLOOKUP(J21,'⚙️ Pengaturan'!$E$2:$E3237,'⚙️ Pengaturan'!$F$2:$F3237),"")} -> 1200000 | Q21: =IF(I21="","",(N21+O21)-P21) -> -600000 | R21: TUNAI | S21: - | T21: TRUE
B22: 1637 | C22: NOPI | D22: 45979 | E22: =if(D22="","",text(D22,"YYY")) -> 2025 | F22: =if(D22="","",text(D22,"MM")&" "&text(D22,"MMM")) -> 11 Nov | I22: RUDI HARTONO | J22: K.PT - PAKET 2 | K22: {=IF(J22="","", XLOOKUP(J22,'⚙️ Pengaturan'!$E$2:$E3237,'⚙️ Pengaturan'!$G$2:$G3237))} -> KLINIK FT PAKET | L22: =if(I22="","",if(countifs($J$5:J22,J22,$I$5:I22,I22)=1,"BARU","LANJUTAN")) -> LANJUTAN | M22: DP | N22: 500000 | O22: 0 | P22: {=IFNA(XLOOKUP(J22,'⚙️ Pengaturan'!$E$2:$E3237,'⚙️ Pengaturan'!$F$2:$F3237),"")} -> 1200000 | Q22: =IF(I22="","",(N22+O22)-P22) -> -700000 | R22: EDC BCA | S22: RUDI HARTONO | T22: TRUE
B23: 1762 | C23: NOPI | D23: 45990 | E23: =if(D23="","",text(D23,"YYY")) -> 2025 | F23: =if(D23="","",text(D23,"MM")&" "&text(D23,"MMM")) -> 11 Nov | I23: TUTI TRISNAWATI | J23: K.PT - PAKET 1 | K23: {=IF(J23="","", XLOOKUP(J23,'⚙️ Pengaturan'!$E$2:$E3237,'⚙️ Pengaturan'!$G$2:$G3237))} -> KLINIK FT PAKET | L23: =if(I23="","",if(countifs($J$5:J23,J23,$I$5:I23,I23)=1,"BARU","LANJUTAN")) -> LANJUTAN | M23: DP | N23: 200000 | O23: 0 | P23: {=IFNA(XLOOKUP(J23,'⚙️ Pengaturan'!$E$2:$E3237,'⚙️ Pengaturan'!$F$2:$F3237),"")} -> 650000 | Q23: =IF(I23="","",(N23+O23)-P23) -> -450000 | R23: TUNAI | S23: - | T23: TRUE
B24: 1896 | C24: SUCI | D24: 46001 | E24: =if(D24="","",text(D24,"YYY")) -> 2025 | F24: =if(D24="","",text(D24,"MM")&" "&text(D24,"MMM")) -> 12 Des | I24: KRIS YOGI DWI PUTRA SIBARANI | J24: K.PT - PAKET 1 | K24: {=IF(J24="","", XLOOKUP(J24,'⚙️ Pengaturan'!$E$2:$E3237,'⚙️ Pengaturan'!$G$2:$G3237))} -> KLINIK FT PAKET | L24: =if(I24="","",if(countifs($J$5:J24,J24,$I$5:I24,I24)=1,"BARU","LANJUTAN")) -> BARU | M24: DP | N24: 200000 | O24: 0 | P24: {=IFNA(XLOOKUP(J24,'⚙️ Pengaturan'!$E$2:$E3237,'⚙️ Pengaturan'!$F$2:$F3237),"")} -> 650000 | Q24: =IF(I24="","",(N24+O24)-P24) -> -450000 | R24: TRANSFER BCA | S24: KRIS YOGI DWI PUTRA SIBARANI | T24: TRUE
B25: 1904 | C25: SUCI | D25: 46001 | E25: =if(D25="","",text(D25,"YYY")) -> 2025 | F25: =if(D25="","",text(D25,"MM")&" "&text(D25,"MMM")) -> 12 Des | I25: ANDRIANI | J25: K.PT - PAKET 1 | K25: {=IF(J25="","", XLOOKUP(J25,'⚙️ Pengaturan'!$E$2:$E3237,'⚙️ Pengaturan'!$G$2:$G3237))} -> KLINIK FT PAKET | L25: =if(I25="","",if(countifs($J$5:J25,J25,$I$5:I25,I25)=1,"BARU","LANJUTAN")) -> BARU | M25: DP | N25: 200000 | O25: 0 | P25: {=IFNA(XLOOKUP(J25,'⚙️ Pengaturan'!$E$2:$E3237,'⚙️ Pengaturan'!$F$2:$F3237),"")} -> 650000 | Q25: =IF(I25="","",(N25+O25)-P25) -> -450000 | R25: TRANSFER BCA | S25: ANDRIANI | T25: TRUE
B26: 1923 | C26: NOPI | D26: 46004 | E26: =if(D26="","",text(D26,"YYY")) -> 2025 | F26: =if(D26="","",text(D26,"MM")&" "&text(D26,"MMM")) -> 12 Des | I26: ANGELICA BUNARDI | J26: K.PT - PAKET 1 | K26: {=IF(J26="","", XLOOKUP(J26,'⚙️ Pengaturan'!$E$2:$E3237,'⚙️ Pengaturan'!$G$2:$G3237))} -> KLINIK FT PAKET | L26: =if(I26="","",if(countifs($J$5:J26,J26,$I$5:I26,I26)=1,"BARU","LANJUTAN")) -> BARU | M26: DP | N26: 200000 | O26: 0 | P26: {=IFNA(XLOOKUP(J26,'⚙️ Pengaturan'!$E$2:$E3237,'⚙️ Pengaturan'!$F$2:$F3237),"")} -> 650000 | Q26: =IF(I26="","",(N26+O26)-P26) -> -450000 | R26: TRANSFER BCA | S26: ANGELICA BUNARDI | T26: TRUE
B27: 1974 | C27: SUCI | D27: 46007 | E27: =if(D27="","",text(D27,"YYY")) -> 2025 | F27: =if(D27="","",text(D27,"MM")&" "&text(D27,"MMM")) -> 12 Des | I27: RUSDI SULAIMAN | J27: V.PT - PAKET VISIT | K27: {=IF(J27="","", XLOOKUP(J27,'⚙️ Pengaturan'!$E$2:$E3237,'⚙️ Pengaturan'!$G$2:$G3237))} -> VISIT FT PAKET | L27: =if(I27="","",if(countifs($J$5:J27,J27,$I$5:I27,I27)=1,"BARU","LANJUTAN")) -> BARU | M27: DP | N27: 1000000 | O27: 0 | P27: {=IFNA(XLOOKUP(J27,'⚙️ Pengaturan'!$E$2:$E3237,'⚙️ Pengaturan'!$F$2:$F3237),"")} -> 1800000 | Q27: =IF(I27="","",(N27+O27)-P27) -> -800000 | R27: TRANSFER BCA | S27: RUSDI SULAIMAN | T27: TRUE
B28: 1982 | C28: NOPI | D28: 46008 | E28: =if(D28="","",text(D28,"YYY")) -> 2025 | F28: =if(D28="","",text(D28,"MM")&" "&text(D28,"MMM")) -> 12 Des | I28: ALPAWI | J28: K.PT - PAKET 2 | K28: {=IF(J28="","", XLOOKUP(J28,'⚙️ Pengaturan'!$E$2:$E3237,'⚙️ Pengaturan'!$G$2:$G3237))} -> KLINIK FT PAKET | L28: =if(I28="","",if(countifs($J$5:J28,J28,$I$5:I28,I28)=1,"BARU","LANJUTAN")) -> BARU | M28: DP | N28: 500000 | O28: 0 | P28: {=IFNA(XLOOKUP(J28,'⚙️ Pengaturan'!$E$2:$E3237,'⚙️ Pengaturan'!$F$2:$F3237),"")} -> 1200000 | Q28: =IF(I28="","",(N28+O28)-P28) -> -700000 | R28: TRANSFER BCA | S28: SITI ROHANI | T28: TRUE
B29: 2040 | C29: NOPI | D29: 46014 | E29: =if(D29="","",text(D29,"YYY")) -> 2025 | F29: =if(D29="","",text(D29,"MM")&" "&text(D29,"MMM")) -> 12 Des | I29: ANDRIANI | J29: K.PT - PAKET 1 | K29: {=IF(J29="","", XLOOKUP(J29,'⚙️ Pengaturan'!$E$2:$E3237,'⚙️ Pengaturan'!$G$2:$G3237))} -> KLINIK FT PAKET | L29: =if(I29="","",if(countifs($J$5:J29,J29,$I$5:I29,I29)=1,"BARU","LANJUTAN")) -> LANJUTAN | M29: CICILAN | N29: 200000 | O29: 200000 | P29: {=IFNA(XLOOKUP(J29,'⚙️ Pengaturan'!$E$2:$E3237,'⚙️ Pengaturan'!$F$2:$F3237),"")} -> 650000 | Q29: =IF(I29="","",(N29+O29)-P29) -> -250000 | R29: TRANSFER BCA | S29: ANDRIANI | T29: TRUE
B30: 2043 | C30: NOPI | D30: 46014 | E30: =if(D30="","",text(D30,"YYY")) -> 2025 | F30: =if(D30="","",text(D30,"MM")&" "&text(D30,"MMM")) -> 12 Des | I30: ANGELICA | J30: K.PT - PAKET 1 | K30: {=IF(J30="","", XLOOKUP(J30,'⚙️ Pengaturan'!$E$2:$E3237,'⚙️ Pengaturan'!$G$2:$G3237))} -> KLINIK FT PAKET | L30: =if(I30="","",if(countifs($J$5:J30,J30,$I$5:I30,I30)=1,"BARU","LANJUTAN")) -> BARU | M30: DP | N30: 200000 | O30: 0 | P30: {=IFNA(XLOOKUP(J30,'⚙️ Pengaturan'!$E$2:$E3237,'⚙️ Pengaturan'!$F$2:$F3237),"")} -> 650000 | Q30: =IF(I30="","",(N30+O30)-P30) -> -450000 | R30: TUNAI | S30: - | T30: TRUE
B31: 2056 | C31: NOPI | D31: 46015 | E31: =if(D31="","",text(D31,"YYY")) -> 2025 | F31: =if(D31="","",text(D31,"MM")&" "&text(D31,"MMM")) -> 12 Des | I31: BEDJO RAHARDJO | J31: K.PT - PAKET 2 | K31: {=IF(J31="","", XLOOKUP(J31,'⚙️ Pengaturan'!$E$2:$E3237,'⚙️ Pengaturan'!$G$2:$G3237))} -> KLINIK FT PAKET | L31: =if(I31="","",if(countifs($J$5:J31,J31,$I$5:I31,I31)=1,"BARU","LANJUTAN")) -> BARU | M31: DP | N31: 500000 | O31: 0 | P31: {=IFNA(XLOOKUP(J31,'⚙️ Pengaturan'!$E$2:$E3237,'⚙️ Pengaturan'!$F$2:$F3237),"")} -> 1200000 | Q31: =IF(I31="","",(N31+O31)-P31) -> -700000 | R31: TUNAI | S31: - | T31: TRUE
B32: 2063 | C32: LAINNYA | D32: 46017 | E32: =if(D32="","",text(D32,"YYY")) -> 2025 | F32: =if(D32="","",text(D32,"MM")&" "&text(D32,"MMM")) -> 12 Des | G32: 16.00 | H32: DESTY | I32: ENDAH SEPTIANINGSIH | J32: K.TA - TERAPI AWAL | K32: {=IF(J32="","", XLOOKUP(J32,'⚙️ Pengaturan'!$E$2:$E3237,'⚙️ Pengaturan'!$G$2:$G3237))} -> KLINIK FT TA | L32: =if(I32="","",if(countifs($J$5:J32,J32,$I$5:I32,I32)=1,"BARU","LANJUTAN")) -> BARU | M32: LUNAS | N32: 250000 | O32: 0 | P32: {=IFNA(XLOOKUP(J32,'⚙️ Pengaturan'!$E$2:$E3237,'⚙️ Pengaturan'!$F$2:$F3237),"")} -> 250000 | Q32: =IF(I32="","",(N32+O32)-P32) -> 0 | R32: TRANSFER BCA | S32: ENDAH SEPTIANINGSIH | T32: TRUE
B33: 2064 | C33: LAINNYA | D33: 46017 | E33: =if(D33="","",text(D33,"YYY")) -> 2025 | F33: =if(D33="","",text(D33,"MM")&" "&text(D33,"MMM")) -> 12 Des | G33: 16.00 | H33: DESTY | I33: ENDAH SEPTIANINGSIH | J33: K.PT - PAKET 1 | K33: {=IF(J33="","", XLOOKUP(J33,'⚙️ Pengaturan'!$E$2:$E3237,'⚙️ Pengaturan'!$G$2:$G3237))} -> KLINIK FT PAKET | L33: =if(I33="","",if(countifs($J$5:J33,J33,$I$5:I33,I33)=1,"BARU","LANJUTAN")) -> BARU | M33: LUNAS | N33: 650000 | O33: 0 | P33: {=IFNA(XLOOKUP(J33,'⚙️ Pengaturan'!$E$2:$E3237,'⚙️ Pengaturan'!$F$2:$F3237),"")} -> 650000 | Q33: =IF(I33="","",(N33+O33)-P33) -> 0 | R33: TRANSFER BCA | S33: ENDAH SEPTIANINGSIH | T33: TRUE
B34: 2065 | C34: LAINNYA | D34: 46017 | E34: =if(D34="","",text(D34,"YYY")) -> 2025 | F34: =if(D34="","",text(D34,"MM")&" "&text(D34,"MMM")) -> 12 Des | G34: 20.00 | H34: DANI | I34: DONNY TRI PUJIANTO | J34: K.TA - TERAPI AWAL | K34: {=IF(J34="","", XLOOKUP(J34,'⚙️ Pengaturan'!$E$2:$E3237,'⚙️ Pengaturan'!$G$2:$G3237))} -> KLINIK FT TA | L34: =if(I34="","",if(countifs($J$5:J34,J34,$I$5:I34,I34)=1,"BARU","LANJUTAN")) -> BARU | M34: LUNAS | N34: 250000 | O34: 0 | P34: {=IFNA(XLOOKUP(J34,'⚙️ Pengaturan'!$E$2:$E3237,'⚙️ Pengaturan'!$F$2:$F3237),"")} -> 250000 | Q34: =IF(I34="","",(N34+O34)-P34) -> 0 | R34: TRANSFER BCA | S34: MARGARETA CHANDRADINATA | T34: TRUE
B35: 2066 | C35: SUCI | D35: 46018 | E35: =if(D35="","",text(D35,"YYY")) -> 2025 | F35: =if(D35="","",text(D35,"MM")&" "&text(D35,"MMM")) -> 12 Des | G35: 14.00 | H35: ORY | I35: TJONG LIE TJHIUN ALS SUKIMAN | J35: K.PT - PAKET 1 | K35: {=IF(J35="","", XLOOKUP(J35,'⚙️ Pengaturan'!$E$2:$E3237,'⚙️ Pengaturan'!$G$2:$G3237))} -> KLINIK FT PAKET | L35: =if(I35="","",if(countifs($J$5:J35,J35,$I$5:I35,I35)=1,"BARU","LANJUTAN")) -> BARU | M35: PELUNASAN | N35: 450000 | O35: 200000 | P35: {=IFNA(XLOOKUP(J35,'⚙️ Pengaturan'!$E$2:$E3237,'⚙️ Pengaturan'!$F$2:$F3237),"")} -> 650000 | Q35: =IF(I35="","",(N35+O35)-P35) -> 0 | R35: TUNAI | S35: - | T35: TRUE
B36: 2067 | C36: SUCI | D36: 46018 | E36: =if(D36="","",text(D36,"YYY")) -> 2025 | F36: =if(D36="","",text(D36,"MM")&" "&text(D36,"MMM")) -> 12 Des | G36: 14.00 | H36: AUL | I36: DRSHENDRA SALIM | J36: K.TA - TERAPI AWAL | K36: {=IF(J36="","", XLOOKUP(J36,'⚙️ Pengaturan'!$E$2:$E3237,'⚙️ Pengaturan'!$G$2:$G3237))} -> KLINIK FT TA | L36: =if(I36="","",if(countifs($J$5:J36,J36,$I$5:I36,I36)=1,"BARU","LANJUTAN")) -> BARU | M36: LUNAS | N36: 250000 | O36: 0 | P36: {=IFNA(XLOOKUP(J36,'⚙️ Pengaturan'!$E$2:$E3237,'⚙️ Pengaturan'!$F$2:$F3237),"")} -> 250000 | Q36: =IF(I36="","",(N36+O36)-P36) -> 0 | R36: EDC BCA | S36: LINA TJENDERA | T36: TRUE
B37: 2068 | C37: SUCI | D37: 46018 | E37: =if(D37="","",text(D37,"YYY")) -> 2025 | F37: =if(D37="","",text(D37,"MM")&" "&text(D37,"MMM")) -> 12 Des | G37: 11.00 | H37: WAHYU | I37: WAHONO | J37: K.PT - PAKET 1 | K37: {=IF(J37="","", XLOOKUP(J37,'⚙️ Pengaturan'!$E$2:$E3237,'⚙️ Pengaturan'!$G$2:$G3237))} -> KLINIK FT PAKET | L37: =if(I37="","",if(countifs($J$5:J37,J37,$I$5:I37,I37)=1,"BARU","LANJUTAN")) -> BARU | M37: LUNAS | N37: 650000 | O37: 0 | P37: {=IFNA(XLOOKUP(J37,'⚙️ Pengaturan'!$E$2:$E3237,'⚙️ Pengaturan'!$F$2:$F3237),"")} -> 650000 | Q37: =IF(I37="","",(N37+O37)-P37) -> 0 | R37: EDC BCA | S37: BINTARI | T37: TRUE
B38: 2069 | C38: NOPI | D38: 46018 | E38: =if(D38="","",text(D38,"YYY")) -> 2025 | F38: =if(D38="","",text(D38,"MM")&" "&text(D38,"MMM")) -> 12 Des | G38: 18.00 | H38: HESTI | I38: YUNITA | J38: K.PT - PAKET 1 | K38: {=IF(J38="","", XLOOKUP(J38,'⚙️ Pengaturan'!$E$2:$E3237,'⚙️ Pengaturan'!$G$2:$G3237))} -> KLINIK FT PAKET | L38: =if(I38="","",if(countifs($J$5:J38,J38,$I$5:I38,I38)=1,"BARU","LANJUTAN")) -> BARU | M38: LUNAS | N38: 650000 | O38: 0 | P38: {=IFNA(XLOOKUP(J38,'⚙️ Pengaturan'!$E$2:$E3237,'⚙️ Pengaturan'!$F$2:$F3237),"")} -> 650000 | Q38: =IF(I38="","",(N38+O38)-P38) -> 0 | R38: TRANSFER BCA | S38: YUNITA | T38: TRUE
B39: 2070 | C39: NOPI | D39: 46018 | E39: =if(D39="","",text(D39,"YYY")) -> 2025 | F39: =if(D39="","",text(D39,"MM")&" "&text(D39,"MMM")) -> 12 Des | G39: 15.00 | H39: AUL | I39: RIZKI RAMADHANI | J39: K.TA - TERAPI AWAL | K39: {=IF(J39="","", XLOOKUP(J39,'⚙️ Pengaturan'!$E$2:$E3237,'⚙️ Pengaturan'!$G$2:$G3237))} -> KLINIK FT TA | L39: =if(I39="","",if(countifs($J$5:J39,J39,$I$5:I39,I39)=1,"BARU","LANJUTAN")) -> BARU | M39: LUNAS | N39: 250000 | O39: 0 | P39: {=IFNA(XLOOKUP(J39,'⚙️ Pengaturan'!$E$2:$E3237,'⚙️ Pengaturan'!$F$2:$F3237),"")} -> 250000 | Q39: =IF(I39="","",(N39+O39)-P39) -> 0 | R39: TRANSFER BCA | S39: HARRY FURQON | T39: TRUE
B40: 2071 | C40: NOPI | D40: 46018 | E40: =if(D40="","",text(D40,"YYY")) -> 2025 | F40: =if(D40="","",text(D40,"MM")&" "&text(D40,"MMM")) -> 12 Des | G40: 17.00 | H40: ORY | I40: HAMDAN IDRIS | J40: K.ST - SESI TERAPI | K40: {=IF(J40="","", XLOOKUP(J40,'⚙️ Pengaturan'!$E$2:$E3237,'⚙️ Pengaturan'!$G$2:$G3237))} -> KLINIK FT SESI | L40: =if(I40="","",if(countifs($J$5:J40,J40,$I$5:I40,I40)=1,"BARU","LANJUTAN")) -> BARU | M40: LUNAS | N40: 150000 | O40: 0 | P40: {=IFNA(XLOOKUP(J40,'⚙️ Pengaturan'!$E$2:$E3237,'⚙️ Pengaturan'!$F$2:$F3237),"")} -> 150000 | Q40: =IF(I40="","",(N40+O40)-P40) -> 0 | R40: TUNAI | S40: - | T40: TRUE
B41: 2072 | C41: NOPI | D41: 46018 | E41: =if(D41="","",text(D41,"YYY")) -> 2025 | F41: =if(D41="","",text(D41,"MM")&" "&text(D41,"MMM")) -> 12 Des | G41: 16.00 | H41: OKTA | I41: LIMINA DJUITA LIMAS | J41: K.ST - SESI TERAPI | K41: {=IF(J41="","", XLOOKUP(J41,'⚙️ Pengaturan'!$E$2:$E3237,'⚙️ Pengaturan'!$G$2:$G3237))} -> KLINIK FT SESI | L41: =if(I41="","",if(countifs($J$5:J41,J41,$I$5:I41,I41)=1,"BARU","LANJUTAN")) -> BARU | M41: LUNAS | N41: 150000 | O41: 0 | P41: {=IFNA(XLOOKUP(J41,'⚙️ Pengaturan'!$E$2:$E3237,'⚙️ Pengaturan'!$F$2:$F3237),"")} -> 150000 | Q41: =IF(I41="","",(N41+O41)-P41) -> 0 | R41: TRANSFER BCA | S41: LIMINA DJUITA LIMAS | T41: TRUE
B42: 2073 | C42: NOPI | D42: 46018 | E42: =if(D42="","",text(D42,"YYY")) -> 2025 | F42: =if(D42="","",text(D42,"MM")&" "&text(D42,"MMM")) -> 12 Des | G42: 18.00 | H42: WAHYU | I42: YOSTRYAN CHENATA | J42: K.PT - PAKET 1 | K42: {=IF(J42="","", XLOOKUP(J42,'⚙️ Pengaturan'!$E$2:$E3237,'⚙️ Pengaturan'!$G$2:$G3237))} -> KLINIK FT PAKET | L42: =if(I42="","",if(countifs($J$5:J42,J42,$I$5:I42,I42)=1,"BARU","LANJUTAN")) -> BARU | M42: LUNAS | N42: 650000 | O42: 0 | P42: {=IFNA(XLOOKUP(J42,'⚙️ Pengaturan'!$E$2:$E3237,'⚙️ Pengaturan'!$F$2:$F3237),"")} -> 650000 | Q42: =IF(I42="","",(N42+O42)-P42) -> 0 | R42: TRANSFER BCA | S42: YOSTRYAN CHENATA | T42: TRUE
...

Sheet TARGET

Sheet Detail431-KLINIK FT TA-02 Jul 2
A1: NO | B1: ADMIN | C1: TANGGAL | D1: TAHUN | E1: BULAN | F1: JAM | G1: FISIO | H1: NAMA PASIEN | I1: PEMBELIAN | J1: KATEGORI PEMBELIAN | K1: STATUS PEMBELIAN | L1: KETERANGAN BAYAR | M1: JUMLAH BAYAR | N1: DISKON | O1: HARGA | P1: KEKURANGAN | Q1: METODE BAYAR | R1: PENJAMIN | S1: ✅ | T1: CATATAN
A2: 4298 | B2: ICA | C2: 46205 | D2: 2026 | E2: 07 Jul | F2: 11.00 | G2: PRITY | H2: SYIFA NABILA RUFINA | I2: K.TA - TERAPI AWAL | J2: KLINIK FT TA | K2: BARU | L2: LUNAS | M2: 250000 | N2: 0 | O2: 250000 | P2: 0 | Q2: TUNAI | R2: - | S2: TRUE
A3: 4300 | B3: ICA | C3: 46205 | D3: 2026 | E3: 07 Jul | F3: 15.00 | G3: PRITY | H3: LIM LIE SIAM | I3: K.TA - TERAPI AWAL | J3: KLINIK FT TA | K3: BARU | L3: LUNAS | M3: 250000 | N3: 0 | O3: 250000 | P3: 0 | Q3: TRANSFER BCA | R3: valencia | S3: TRUE
A4: 4302 | B4: DHEA | C4: 46205 | D4: 2026 | E4: 07 Jul | F4: 16.00 | G4: PUTRI | H4: FADIL AKBAR | I4: K.TA - TERAPI AWAL | J4: KLINIK FT TA | K4: BARU | L4: LUNAS | M4: 250000 | N4: 0 | O4: 250000 | P4: 0 | Q4: TUNAI | R4: - | S4: TRUE
A5: 4306 | B5: DHEA | C5: 46205 | D5: 2026 | E5: 07 Jul | F5: 17.00 | G5: PUTRI | H5: ASTISZA SYAHLA LUDMILLA PARABI | I5: K.TA - TERAPI AWAL | J5: KLINIK FT TA | K5: BARU | L5: LUNAS | M5: 250000 | N5: 0 | O5: 250000 | P5: 0 | Q5: TRANSFER BCA | R5: ASTISZA SYAHLA LUDMILLA PARABI | S5: TRUE
A6: 4308 | B6: DHEA | C6: 46205 | D6: 2026 | E6: 07 Jul | F6: 19.00 | G6: OKTA | H6: SUCI NANDA LESTARI | I6: K.TA - TERAPI AWAL | J6: KLINIK FT TA | K6: BARU | L6: LUNAS | M6: 250000 | N6: 0 | O6: 250000 | P6: 0 | Q6: TUNAI | R6: - | S6: TRUE

Sheet ⬆️ PENGELUARAN
B1: CATATAN PENGELUARAN FISIOTERAPI GANG SEHAT PONTIANAK 2026
B4: Z | C4: ADMIN | D4: TANGGAL | E4: TAHUN | F4: BULAN | G4: NOMINAL | H4: JENIS PENGELUARAN | I4: KETERANGAN | J4: KATEGORI | K4: ✅ | L4: CATATAN | M4: Column 12
B5: 324 | C5: NOPI | D5: 46018 | E5: =if(D5="","",text(D5,"yyyy")) -> 2025 | F5: =if(D5="","",text(D5,"mm")&" "&text(D5,"mmm")) -> 12 Des | G5: 500000 | H5: TUNAI | I5: BONUS BG MADI | J5: BEBAN GAJI | K5: TRUE
B6: 325 | C6: NOPI | D6: 46018 | E6: =if(D6="","",text(D6,"yyyy")) -> 2025 | F6: =if(D6="","",text(D6,"mm")&" "&text(D6,"mmm")) -> 12 Des | G6: 48000 | H6: TUNAI | I6: WAHYU DAN HESTI | J6: TUKAR TUNAI | K6: TRUE
B7: 326 | C7: NOPI | D7: 46018 | E7: =if(D7="","",text(D7,"yyyy")) -> 2025 | F7: =if(D7="","",text(D7,"mm")&" "&text(D7,"mmm")) -> 12 Des | G7: 200000 | H7: TUNAI | I7: WAHYU | J7: TUKAR TUNAI | K7: TRUE
B8: 327 | C8: NOPI | D8: 46019 | E8: =if(D8="","",text(D8,"yyyy")) -> 2025 | F8: =if(D8="","",text(D8,"mm")&" "&text(D8,"mmm")) -> 12 Des | G8: 20000 | H8: TUNAI | I8: BELI NOTA | J8: BEBAN PELAYANAN FGS | K8: TRUE
B9: 328 | C9: SUCI | D9: 46019 | E9: =if(D9="","",text(D9,"yyyy")) -> 2025 | F9: =if(D9="","",text(D9,"mm")&" "&text(D9,"mmm")) -> 12 Des | G9: 21000 | H9: TUNAI | I9: PISPOT | J9: BEBAN PELAYANAN FGS | K9: TRUE
B10: 329 | C10: SUCI | D10: 46019 | E10: =if(D10="","",text(D10,"yyyy")) -> 2025 | F10: =if(D10="","",text(D10,"mm")&" "&text(D10,"mmm")) -> 12 Des | G10: 19000 | H10: TUNAI | I10: ICEGEL | J10: BEBAN PELAYANAN FGS | K10: TRUE
B11: 330 | C11: SUCI | D11: 46019 | E11: =if(D11="","",text(D11,"yyyy")) -> 2025 | F11: =if(D11="","",text(D11,"mm")&" "&text(D11,"mmm")) -> 12 Des | G11: 29000 | H11: TUNAI | I11: TT BELI MAKAN | J11: TUKAR TUNAI | K11: TRUE
B12: 331 | C12: SUCI | D12: 46019 | E12: =if(D12="","",text(D12,"yyyy")) -> 2025 | F12: =if(D12="","",text(D12,"mm")&" "&text(D12,"mmm")) -> 12 Des | G12: 50000 | H12: TUNAI | I12: SUCI | J12: TUKAR TUNAI | K12: TRUE
B13: 332 | C13: NOPI | D13: 46020 | E13: =if(D13="","",text(D13,"yyyy")) -> 2025 | F13: =if(D13="","",text(D13,"mm")&" "&text(D13,"mmm")) -> 12 Des | G13: 200000 | H13: TUNAI | I13: TIA | J13: TUKAR TUNAI | K13: TRUE
B14: 333 | C14: NOPI | D14: 46020 | E14: =if(D14="","",text(D14,"yyyy")) -> 2025 | F14: =if(D14="","",text(D14,"mm")&" "&text(D14,"mmm")) -> 12 Des | G14: 50000 | H14: TUNAI | I14: KEKURANGAN GAJI HENA | J14: BEBAN GAJI | K14: TRUE
B15: 334 | C15: NOPI | D15: 46020 | E15: =if(D15="","",text(D15,"yyyy")) -> 2025 | F15: =if(D15="","",text(D15,"mm")&" "&text(D15,"mmm")) -> 12 Des | G15: 120000 | H15: TUNAI | I15: BAYAR BAJU AUL | J15: BEBAN PELAYANAN FGS | K15: TRUE
B16: 335 | C16: NOPI | D16: 46025 | E16: =if(D16="","",text(D16,"yyyy")) -> 2026 | F16: =if(D16="","",text(D16,"mm")&" "&text(D16,"mmm")) -> 01 Jan | G16: 148000 | H16: TUNAI | I16: BELI MAP | J16: BEBAN PELAYANAN FGS | K16: TRUE
... B41: 360 | C41: SUCI | D41: 46035 | E41: =if(D41="","",text(D41,"yyyy")) -> 2026 | F41: =if(D41="","",text(D41,"mm")&" "&text(D41,"mmm")) -> 01 Jan | G41: 100000 | H41: TUNAI | I41: HENA TT | J41: TUKAR TUNAI | K41: TRUE
B42: 361 | C42: SUCI | D42: 46035 | E42: 2026 | F42: 01 Jan | G42: 200000 | H42: TUNAI | I42: TIA TT | J42: TUKAR TUNAI | K42: TRUE
B43: 362 | C43: SUCI | D43: 46036 | E43: =if(D43="","",text(D43,"yyyy")) -> 2026 | F43: =if(D43="","",text(D43,"mm")&" "&text(D43,"mmm")) -> 01 Jan | G43: 50000 | H43: TUNAI | I43: KONSUMSI RETURN TO SPORT PIPO | J43: BEBAN PELAYANAN FGS | K43: TRUE
B44: 363 | C44: NOPI | D44: 46036 | E44: =if(D44="","",text(D44,"yyyy")) -> 2026 | F44: =if(D44="","",text(D44,"mm")&" "&text(D44,"mmm")) -> 01 Jan | G44: 50000 | H44: TUNAI | I44: NOPI | J44: TUKAR TUNAI | K44: TRUE
B45: 364 | C45: NOPI | D45: 46036 | E45: =if(D45="","",text(D45,"yyyy")) -> 2026 | F45: =if(D45="","",text(D45,"mm")&" "&text(D45,"mmm")) -> 01 Jan | G45: 200000 | H45: TUNAI | I45: TIA | J45: TUKAR TUNAI | K45: TRUE
B46: 365 | C46: NOPI | D46: 46037 | E46: =if(D46="","",text(D46,"yyyy")) -> 2026 | F46: =if(D46="","",text(D46,"mm")&" "&text(D46,"mmm")) -> 01 Jan | G46: 50000 | H46: TUNAI | I46: HENA AMBIL UANG JARAK TA CE FEBE | J46: JARAK VISIT | K46: TRUE
B47: 366 | C47: NOPI | D47: 46037 | E47: =if(D47="","",text(D47,"yyyy")) -> 2026 | F47: =if(D47="","",text(D47,"mm")&" "&text(D47,"mmm")) -> 01 Jan | G47: 100000 | H47: TUNAI | I47: DESTY AMBIL JARAK KAK NOVI 2X SESI | J47: JARAK VISIT | K47: TRUE
B48: 367 | C48: NOPI | D48: 46037 | E48: =if(D48="","",text(D48,"yyyy")) -> 2026 | F48: =if(D48="","",text(D48,"mm")&" "&text(D48,"mmm")) -> 01 Jan | G48: 100000 | H48: TUNAI | I48: NOPI | J48: TUKAR TUNAI | K48: TRUE
B49: 368 | C49: NOPI | D49: 46039 | E49: =if(D49="","",text(D49,"yyyy")) -> 2026 | F49: =if(D49="","",text(D49,"mm")&" "&text(D49,"mmm")) -> 01 Jan | G49: 15000 | H49: TUNAI | I49: BELI ES BATU | J49: BEBAN PELAYANAN FGS | K49: TRUE
B50: 369 | C50: NOPI | D50: 46039 | E50: =if(D50="","",text(D50,"yyyy")) -> 2026 | F50: =if(D50="","",text(D50,"mm")&" "&text(D50,"mmm")) -> 01 Jan | G50: 100000 | H50: TUNAI | I50: SUCI | J50: TUKAR TUNAI | K50: TRUE
B51: 370 | C51: NOPI | D51: 46039 | E51: =if(D51="","",text(D51,"yyyy")) -> 2026 | F51: =if(D51="","",text(D51,"mm")&" "&text(D51,"mmm")) -> 01 Jan | G51: 300000 | H51: TUNAI | I51: EDO | J51: TUKAR TUNAI | K51: TRUE
B52: 371 | C52: NOPI | D52: 46039 | E52: =if(D52="","",text(D52,"yyyy")) -> 2026 | F52: =if(D52="","",text(D52,"mm")&" "&text(D52,"mmm")) -> 01 Jan | G52: 50000 | H52: TUNAI | I52: JARAK HENA (AN. ASNAH) | J52: BEBAN GAJI | K52: TRUE
B53: 372 | C53: SUCI | D53: 46040 | E53: =if(D53="","",text(D53,"yyyy")) -> 2026 | F53: =if(D53="","",text(D53,"mm")&" "&text(D53,"mmm")) -> 01 Jan | G53: 80000 | H53: TUNAI | I53: BELI LAMPU | J53: BEBAN PELAYANAN FGS | K53: TRUE
B54: 373 | C54: SUCI | D54: 46040 | E54: =if(D54="","",text(D54,"yyyy")) -> 2026 | F54: =if(D54="","",text(D54,"mm")&" "&text(D54,"mmm")) -> 01 Jan | G54: 50000 | H54: TUNAI | I54: KOPI PELANGI DANI | J54: BEBAN PELAYANAN FGS | K54: TRUE
... B62: 381 | C62: SUCI | D62: 46042 | E62: =if(D62="","",text(D62,"yyyy")) -> 2026 | F62: =if(D62="","",text(D62,"mm")&" "&text(D62,"mmm")) -> 01 Jan | G62: 100000 | H62: TUNAI | I62: TT NOPI | J62: TUKAR TUNAI | K62: TRUE
B63: 382 | C63: SUCI | D63: 46042 | E63: 2026 | F63: 01 Jan | G63: 50000 | H63: TUNAI | I63: TT HESTI | J63: TUKAR TUNAI | K63: TRUE
B64: 383 | C64: SUCI | D64: 46042 | E64: 2026 | F64: 01 Jan | G64: 100000 | H64: TUNAI | I64: TT HEN | J64: TUKAR TUNAI | K64: TRUE
B65: 384 | C65: SUCI | D65: 46042 | E65: =if(D65="","",text(D65,"yyyy")) -> 2026 | F65: =if(D65="","",text(D65,"mm")&" "&text(D65,"mmm")) -> 01 Jan | G65: 400000 | H65: TUNAI | I65: DESTY AMBIL JARAK KAK NOVI SISANYA | J65: TUKAR TUNAI | K65: TRUE
B66: 385 | C66: SUCI | D66: 46042 | E66: 2026 | F66: 01 Jan | G66: 86000 | H66: TUNAI | I66: PAKET BASEP | J66: TUKAR TUNAI | K66: TRUE
B67: 386 | C67: NOPI | D67: 46043 | G67: 100000 | H67: TUNAI | I67: HENA | J67: TUKAR TUNAI | K67: TRUE
B68: 387 | C68: NOPI | D68: 46043 | E68: =if(D68="","",text(D68,"yyyy")) -> 2026 | F68: =if(D68="","",text(D68,"mm")&" "&text(D68,"mmm")) -> 01 Jan | G68: 200000 | H68: TUNAI | I68: TIA | J68: TUKAR TUNAI | K68: TRUE
B69: 388 | C69: NOPI | D69: 46043 | E69: =if(D69="","",text(D69,"yyyy")) -> 2026 | F69: =if(D69="","",text(D69,"mm")&" "&text(D69,"mmm")) -> 01 Jan | G69: 400000 | H69: TUNAI | I69: BAYAR SEDOT WC GRIYA ANAK | J69: BEBAN PELAYANAN FGS | K69: TRUE
B70: 389 | C70: NOPI | D70: 46044 | E70: =if(D70="","",text(D70,"yyyy")) -> 2026 | F70: =if(D70="","",text(D70,"mm")&" "&text(D70,"mmm")) -> 01 Jan | G70: 50000 | H70: TUNAI | I70: BETULKAN LAMPU DPN ASESSMENT | J70: BEBAN PELAYANAN FGS | K70: TRUE
B71: 390 | C71: NOPI | D71: 46044 | E71: =if(D71="","",text(D71,"yyyy")) -> 2026 | F71: =if(D71="","",text(D71,"mm")&" "&text(D71,"mmm")) -> 01 Jan | G71: 100000 | H71: TUNAI | I71: NOPI | J71: TUKAR TUNAI | K71: TRUE
B72: 391 | C72: NOPI | D72: 46044 | E72: =if(D72="","",text(D72,"yyyy")) -> 2026 | F72: =if(D72="","",text(D72,"mm")&" "&text(D72,"mmm")) -> 01 Jan | G72: 50000 | H72: TUNAI | I72: HENA | J72: TUKAR TUNAI | K72: TRUE
B73: 392 | C73: NOPI | D73: 46044 | E73: =if(D73="","",text(D73,"yyyy")) -> 2026 | F73: =if(D73="","",text(D73,"mm")&" "&text(D73,"mmm")) -> 01 Jan | G73: 38000 | H73: TUNAI | I73: HENA DAN OKTA | J73: TUKAR TUNAI | K73: TRUE
...

Sheet 📝 REKAP HARIAN
B1: Rekap Harian Admin
O2: Cash Hari Ini
N3: =K6-O6 -> 1000000
B5: Jumlah Kwitansi Pemasukan | F5: Jumlah Layanan Masuk | J5: Jumlah Pemasukan | N5: Jumlah Pengeluaran
K6: {=XLOOKUP("TUNAI",$J$7:$J1006,$K$7:$K1006,"0")} -> 1000000 | O6: {=XLOOKUP("TUNAI",$N$7:$N1006,$O$7:OK1006,"0")} -> 0

Sheet FORM
B1: REKAP HARIAN TRANSAKSI FISIOTERAPI GANG SEHAT PONTIANAK
B2: =text(today(),"mmmm")&" "&text(today(),"yyyy") -> Juli 2026
B5: KOMPONEN | C5: 1 | D5: 2 | E5: 3 | F5: 4 | G5: 5 | H5: 6 | I5: 7 | J5: 8 | K5: 9 | L5: 10 | M5: 11 | N5: 12 | O5: 13 | P5: 14 | Q5: 15 | R5: 16 | S5: 17 | T5: 18 | U5: 19 | V5: 20 | W5: 21 | X5: 22 | Y5: 23 | Z5: 24 | AA5: 25 | AB5: 26 | AC5: 27 | AD5: 28 | AE5: 29 | AF5: 30 | AG5: 31 | AH5: Hasil | AI5: Target | AJ5: Capaian
B6: Jumlah Kwitansi / Bukti Transfer
B7: Jumlah Layanan & Target
B8: Nominal Pemasukan
B9: Jumlah Data Error
B12: Catatan:

Sheet ⚙️ Pengaturan
B1: ADMIN | E1: PEMBELIAN | F1: HARGA | G1: KATEGORI | J1: KETERANGAN | M1: METODE BAYAR | P1: JAM | S1: FISIO
B2: DHEA | E2: K.PT - PAKET 1 | F2: 650000 | G2: KLINIK FT PAKET | J2: LUNAS | M2: TUNAI | P2: 10.00 | S2: AUL
B3: HESTY | E3: K.PT - PAKET 2 | F3: 1200000 | G3: KLINIK FT PAKET | J3: DP | M3: TRANSFER BCA | P3: 11.00 | S3: DANI
B4: ICA | E4: K.PT - PAKET GOLD | F4: 1300000 | G4: KLINIK FT PAKET | J4: CICILAN | M4: TRANSFER BANK KALBAR | P4: 12.00 | S4: DANRU
B5: SUCI | E5: K.PT - PAKET PLATINUM | F5: 2400000 | G5: KLINIK FT PAKET | J5: PELUNASAN | M5: EDC BCA | P5: 13.00 | S5: DESTY
B6: LAINNYA | E6: K.PT - PAKET SILVER | F6: 750000 | G6: KLINIK FT PAKET | P6: 14.00 | S6: EDO
E7: K.ST - SESI TERAPI | F7: 150000 | G7: KLINIK FT SESI | P7: 15.00 | S7: HENA
E8: K.ST - SESI TERAPI NEW | F8: 180000 | G8: KLINIK FT SESI | P8: 16.00 | S8: HESTI
E9: K.TA - TERAPI AWAL | F9: 250000 | G9: KLINIK FT TA | P9: 17.00 | S9: NADA
E10: S.TR - BANDAGE 15 CM | F10: 0 | G10: STORE | P10: 18.00 | S10: OKTA
E11: S.TR - BANDAGE 7,5 CM | F11: 25000 | G11: STORE | P11: 19.00 | S11: ORY
E12: S.TR - FINGER TAPE | F12: 20000 | G12: STORE | P12: 20.00 | S12: PRITY
E13: S.TR - ICE BAG | F13: 50000 | G13: STORE | P13: 21.00 | S13: PUTRI
E14: S.TR - KINESIO TAPE | F14: 45000 | G14: STORE | P14: LAINNYA | S14: WAHYU
E15: S.TR - MINI BAND HITAM | F15: 40000 | G15: STORE | S15: ALAM
E16: S.TR - MINI BAND KUNING | F16: 25000 | G16: STORE | S16: LAINNYA
E17: S.TR - MINI BAND MERAH | F17: 35000 | G17: STORE
E18: S.TR - RIGID TAPE (STRAPPAL) | F18: 50000 | G18: STORE
E19: V.PT - PAKET VISIT | F19: 1800000 | G19: VISIT FT PAKET
E20: V.PT - PAKET VISIT + JARAK | F20: 2300000 | G20: VISIT FT PAKET
E21: V.ST - SESI VISIT | F21: 200000 | G21: VISIT FT SESI
E22: V.ST - SESI VISIT + JARAK | F22: 250000 | G22: VISIT FT SESI
E23: V.TA - TERAPI AWAL VISIT | F23: 300000 | G23: VISIT FT TA
E24: V.TA - TERAPI AWAL VISIT + JARAK | F24: 350000 | G24: VISIT FT TA
E25: S.KL - SESI TERAPI | F25: 110000 | G25: KELAS LANSIA SESI
E26: S.KL - PAKET GOLD | F26: 400000 | G26: KELAS LANSIA PAKET
E27: S.KL - PAKET SILVER | F27: 720000 | G27: KELAS LANSIA PAKET
E28: S.KL - PAKET PLATINUM | F28: 960000 | G28: KELAS LANSIA PAKET
... E42: V.PM - PAKET FULL BODY VISIT | F42: 570000 | G42: VISIT SM PAKET
