Workbook

Sheet 👥 Daftar Nama Pasien
B1: =IFERROR(__xludf.DUMMYFUNCTION("IMPORTRANGE(""https://docs.google.com/spreadsheets/d/1q5irXBuyRkQM_goHlRjPTSwHk1on6thK70p8lljqLrs/edit?gid=1342096879#gid=1342096879"",""🙎‍♂️ Pasien!$G$2:$I"")"),"Nama Pasien") -> Nama Pasien | C1: =IFERROR(__xludf.DUMMYFUNCTION("""COMPUTED_VALUE"""),"No. RM") -> No. RM | D1: =IFERROR(__xludf.DUMMYFUNCTION("""COMPUTED_VALUE"""),"Usia") -> Usia
B2: =IFERROR(__xludf.DUMMYFUNCTION("""COMPUTED_VALUE"""),"OFF") -> OFF | C2: =IFERROR(__xludf.DUMMYFUNCTION("""COMPUTED_VALUE"""),"OFF") -> OFF
B3: =IFERROR(__xludf.DUMMYFUNCTION("""COMPUTED_VALUE"""),"LIBUR") -> LIBUR | C3: =IFERROR(__xludf.DUMMYFUNCTION("""COMPUTED_VALUE"""),"LIBUR") -> LIBUR
B4: =IFERROR(__xludf.DUMMYFUNCTION("""COMPUTED_VALUE"""),"TA") -> TA
B5: =IFERROR(__xludf.DUMMYFUNCTION("""COMPUTED_VALUE"""),"MANAJEMEN") -> MANAJEMEN | C5: =IFERROR(__xludf.DUMMYFUNCTION("""COMPUTED_VALUE"""),"MANAJEMEN") -> MANAJEMEN
B6: =IFERROR(__xludf.DUMMYFUNCTION("""COMPUTED_VALUE"""),"KHUSUS") -> KHUSUS | C6: =IFERROR(__xludf.DUMMYFUNCTION("""COMPUTED_VALUE"""),"KHUSUS") -> KHUSUS
B7: =IFERROR(__xludf.DUMMYFUNCTION("""COMPUTED_VALUE"""),"PIPO") -> PIPO | C7: =IFERROR(__xludf.DUMMYFUNCTION("""COMPUTED_VALUE"""),"PANGSUMA FC") -> PANGSUMA FC
C8: =IFERROR(__xludf.DUMMYFUNCTION("""COMPUTED_VALUE"""),"") | D8: =IFERROR(__xludf.DUMMYFUNCTION("""COMPUTED_VALUE"""),"")
B9: =IFERROR(__xludf.DUMMYFUNCTION("""COMPUTED_VALUE"""),"ZHOFRAN FARRAS ATAYA") -> ZHOFRAN FARRAS ATAYA | C9: =IFERROR(__xludf.DUMMYFUNCTION("""COMPUTED_VALUE"""),"Z0922105765") -> Z0922105765 | D9: =IFERROR(__xludf.DUMMYFUNCTION("""COMPUTED_VALUE"""),17.0) -> 17
B10: =IFERROR(__xludf.DUMMYFUNCTION("""COMPUTED_VALUE"""),"DIAH SUCI RINI") -> DIAH SUCI RINI | C10: =IFERROR(__xludf.DUMMYFUNCTION("""COMPUTED_VALUE"""),"D5722102445") -> D5722102445 | D10: =IFERROR(__xludf.DUMMYFUNCTION("""COMPUTED_VALUE"""),68.0) -> 68
B11: =IFERROR(__xludf.DUMMYFUNCTION("""COMPUTED_VALUE"""),"MEIZARANI HELJA") -> MEIZARANI HELJA | C11: =IFERROR(__xludf.DUMMYFUNCTION("""COMPUTED_VALUE"""),"M9322128010") -> M9322128010 | D11: =IFERROR(__xludf.DUMMYFUNCTION("""COMPUTED_VALUE"""),33.0) -> 33
B12: =IFERROR(__xludf.DUMMYFUNCTION("""COMPUTED_VALUE"""),"HUWAIDAH THIFAL NAURAH") -> HUWAIDAH THIFAL NAURAH | C12: =IFERROR(__xludf.DUMMYFUNCTION("""COMPUTED_VALUE"""),"H0123016085") -> H0123016085 | D12: =IFERROR(__xludf.DUMMYFUNCTION("""COMPUTED_VALUE"""),25.0) -> 25
B13: =IFERROR(__xludf.DUMMYFUNCTION("""COMPUTED_VALUE"""),"SUFIRNA") -> SUFIRNA | C13: =IFERROR(__xludf.DUMMYFUNCTION("""COMPUTED_VALUE"""),"S7823018882") -> S7823018882 | D13: =IFERROR(__xludf.DUMMYFUNCTION("""COMPUTED_VALUE"""),48.0) -> 48
B14: =IFERROR(__xludf.DUMMYFUNCTION("""COMPUTED_VALUE"""),"ALVIN DIYANDRA") -> ALVIN DIYANDRA | C14: =IFERROR(__xludf.DUMMYFUNCTION("""COMPUTED_VALUE"""),"A9723017817") -> A9723017817 | D14: =IFERROR(__xludf.DUMMYFUNCTION("""COMPUTED_VALUE"""),29.0) -> 29
B15: =IFERROR(__xludf.DUMMYFUNCTION("""COMPUTED_VALUE"""),"ANDI ICHWANUL AZWAR") -> ANDI ICHWANUL AZWAR | C15: =IFERROR(__xludf.DUMMYFUNCTION("""COMPUTED_VALUE"""),"A8823011011") -> A8823011011 | D15: =IFERROR(__xludf.DUMMYFUNCTION("""COMPUTED_VALUE"""),37.0) -> 37
B16: =IFERROR(__xludf.DUMMYFUNCTION("""COMPUTED_VALUE"""),"AREEFAQEEL DIEN HAQQ") -> AREEFAQEEL DIEN HAQQ | C16: =IFERROR(__xludf.DUMMYFUNCTION("""COMPUTED_VALUE"""),"A1023015335") -> A1023015335 | D16: =IFERROR(__xludf.DUMMYFUNCTION("""COMPUTED_VALUE"""),15.0) -> 15
B17: =IFERROR(__xludf.DUMMYFUNCTION("""COMPUTED_VALUE"""),"NURLINA") -> NURLINA | C17: =IFERROR(__xludf.DUMMYFUNCTION("""COMPUTED_VALUE"""),"N8523017483") -> N8523017483 | D17: =IFERROR(__xludf.DUMMYFUNCTION("""COMPUTED_VALUE"""),40.0) -> 40
B18: =IFERROR(__xludf.DUMMYFUNCTION("""COMPUTED_VALUE"""),"A. THENU") -> A. THENU | C18: =IFERROR(__xludf.DUMMYFUNCTION("""COMPUTED_VALUE"""),"A7023018857") -> A7023018857 | D18: =IFERROR(__xludf.DUMMYFUNCTION("""COMPUTED_VALUE"""),55.0) -> 55
B19: =IFERROR(__xludf.DUMMYFUNCTION("""COMPUTED_VALUE"""),"ATIKA ALIFIA F. TOBING") -> ATIKA ALIFIA F. TOBING | C19: =IFERROR(__xludf.DUMMYFUNCTION("""COMPUTED_VALUE"""),"A9023018425") -> A9023018425 | D19: =IFERROR(__xludf.DUMMYFUNCTION("""COMPUTED_VALUE"""),36.0) -> 36
B20: =IFERROR(__xludf.DUMMYFUNCTION("""COMPUTED_VALUE"""),"JAKA SEPTIADI") -> JAKA SEPTIADI | C20: =IFERROR(__xludf.DUMMYFUNCTION("""COMPUTED_VALUE"""),"J8823016633") -> J8823016633 | D20: =IFERROR(__xludf.DUMMYFUNCTION("""COMPUTED_VALUE"""),38.0) -> 38
B21: =IFERROR(__xludf.DUMMYFUNCTION("""COMPUTED_VALUE"""),"MARIYO") -> MARIYO | C21: =IFERROR(__xludf.DUMMYFUNCTION("""COMPUTED_VALUE"""),"M6523010470") -> M6523010470 | D21: =IFERROR(__xludf.DUMMYFUNCTION("""COMPUTED_VALUE"""),60.0) -> 60
B22: =IFERROR(__xludf.DUMMYFUNCTION("""COMPUTED_VALUE"""),"ADIEL PRATAMA PUTRA K.") -> ADIEL PRATAMA PUTRA K. | C22: =IFERROR(__xludf.DUMMYFUNCTION("""COMPUTED_VALUE"""),"A0623015163") -> A0623015163 | D22: =IFERROR(__xludf.DUMMYFUNCTION("""COMPUTED_VALUE"""),20.0) -> 20
B23: =IFERROR(__xludf.DUMMYFUNCTION("""COMPUTED_VALUE"""),"DAVID BURUI") -> DAVID BURUI | C23: =IFERROR(__xludf.DUMMYFUNCTION("""COMPUTED_VALUE"""),"D6123013327") -> D6123013327 | D23: =IFERROR(__xludf.DUMMYFUNCTION("""COMPUTED_VALUE"""),64.0) -> 64
B24: =IFERROR(__xludf.DUMMYFUNCTION("""COMPUTED_VALUE"""),"DEDI SUNARDI") -> DEDI SUNARDI | C24: =IFERROR(__xludf.DUMMYFUNCTION("""COMPUTED_VALUE"""),"D8223017622") -> D8223017622 | D24: =IFERROR(__xludf.DUMMYFUNCTION("""COMPUTED_VALUE"""),43.0) -> 43
B25: =IFERROR(__xludf.DUMMYFUNCTION("""COMPUTED_VALUE"""),"MIGUEL TJONDRO") -> MIGUEL TJONDRO | C25: =IFERROR(__xludf.DUMMYFUNCTION("""COMPUTED_VALUE"""),"M9823010741") -> M9823010741 | D25: =IFERROR(__xludf.DUMMYFUNCTION("""COMPUTED_VALUE"""),28.0) -> 28
B26: =IFERROR(__xludf.DUMMYFUNCTION("""COMPUTED_VALUE"""),"TRI WAHYUNI") -> TRI WAHYUNI | C26: =IFERROR(__xludf.DUMMYFUNCTION("""COMPUTED_VALUE"""),"T7623010391") -> T7623010391 | D26: =IFERROR(__xludf.DUMMYFUNCTION("""COMPUTED_VALUE"""),50.0) -> 50
B27: =IFERROR(__xludf.DUMMYFUNCTION("""COMPUTED_VALUE"""),"ANANTA UTAMI") -> ANANTA UTAMI | C27: =IFERROR(__xludf.DUMMYFUNCTION("""COMPUTED_VALUE"""),"A9123011070") -> A9123011070 | D27: =IFERROR(__xludf.DUMMYFUNCTION("""COMPUTED_VALUE"""),34.0) -> 34
B28: =IFERROR(__xludf.DUMMYFUNCTION("""COMPUTED_VALUE"""),"EMMI") -> EMMI | C28: =IFERROR(__xludf.DUMMYFUNCTION("""COMPUTED_VALUE"""),"E6223013059") -> E6223013059 | D28: =IFERROR(__xludf.DUMMYFUNCTION("""COMPUTED_VALUE"""),63.0) -> 63
B29: =IFERROR(__xludf.DUMMYFUNCTION("""COMPUTED_VALUE"""),"ZIQRIL HAKIM R") -> ZIQRIL HAKIM R | C29: =IFERROR(__xludf.DUMMYFUNCTION("""COMPUTED_VALUE"""),"Z0423010391") -> Z0423010391 | D29: =IFERROR(__xludf.DUMMYFUNCTION("""COMPUTED_VALUE"""),21.0) -> 21
B30: =IFERROR(__xludf.DUMMYFUNCTION("""COMPUTED_VALUE"""),"ERNA SETIAWATY") -> ERNA SETIAWATY | C30: =IFERROR(__xludf.DUMMYFUNCTION("""COMPUTED_VALUE"""),"E5423019005") -> E5423019005 | D30: =IFERROR(__xludf.DUMMYFUNCTION("""COMPUTED_VALUE"""),71.0) -> 71
B31: =IFERROR(__xludf.DUMMYFUNCTION("""COMPUTED_VALUE"""),"EVA DOLOROSA") -> EVA DOLOROSA | C31: =IFERROR(__xludf.DUMMYFUNCTION("""COMPUTED_VALUE"""),"E6723010889") -> E6723010889 | D31: =IFERROR(__xludf.DUMMYFUNCTION("""COMPUTED_VALUE"""),58.0) -> 58
B32: =IFERROR(__xludf.DUMMYFUNCTION("""COMPUTED_VALUE"""),"ANTO PRAYUGO") -> ANTO PRAYUGO | C32: =IFERROR(__xludf.DUMMYFUNCTION("""COMPUTED_VALUE"""),"A9523012989") -> A9523012989 | D32: =IFERROR(__xludf.DUMMYFUNCTION("""COMPUTED_VALUE"""),31.0) -> 31
B33: =IFERROR(__xludf.DUMMYFUNCTION("""COMPUTED_VALUE"""),"FAHMI") -> FAHMI | C33: =IFERROR(__xludf.DUMMYFUNCTION("""COMPUTED_VALUE"""),"F8623010888") -> F8623010888 | D33: =IFERROR(__xludf.DUMMYFUNCTION("""COMPUTED_VALUE"""),40.0) -> 40
B34: =IFERROR(__xludf.DUMMYFUNCTION("""COMPUTED_VALUE"""),"RYANDI ARDIENDA P.") -> RYANDI ARDIENDA P. | C34: =IFERROR(__xludf.DUMMYFUNCTION("""COMPUTED_VALUE"""),"R9323012323") -> R9323012323 | D34: =IFERROR(__xludf.DUMMYFUNCTION("""COMPUTED_VALUE"""),32.0) -> 32
B35: =IFERROR(__xludf.DUMMYFUNCTION("""COMPUTED_VALUE"""),"NURYANTO") -> NURYANTO | C35: =IFERROR(__xludf.DUMMYFUNCTION("""COMPUTED_VALUE"""),"N5423010002") -> N5423010002 | D35: =IFERROR(__xludf.DUMMYFUNCTION("""COMPUTED_VALUE"""),71.0) -> 71
B36: =IFERROR(__xludf.DUMMYFUNCTION("""COMPUTED_VALUE"""),"DIMAS PANDU HIDAYATULLAH") -> DIMAS PANDU HIDAYATULLAH | C36: =IFERROR(__xludf.DUMMYFUNCTION("""COMPUTED_VALUE"""),"D0023011314") -> D0023011314 | D36: =IFERROR(__xludf.DUMMYFUNCTION("""COMPUTED_VALUE"""),26.0) -> 26
B37: =IFERROR(__xludf.DUMMYFUNCTION("""COMPUTED_VALUE"""),"EIVA RADE SIHO") -> EIVA RADE SIHO | C37: =IFERROR(__xludf.DUMMYFUNCTION("""COMPUTED_VALUE"""),"E7623015810") -> E7623015810 | D37: =IFERROR(__xludf.DUMMYFUNCTION("""COMPUTED_VALUE"""),49.0) -> 49
B38: =IFERROR(__xludf.DUMMYFUNCTION("""COMPUTED_VALUE"""),"ERICK TRIENARDO") -> ERICK TRIENARDO | C38: =IFERROR(__xludf.DUMMYFUNCTION("""COMPUTED_VALUE"""),"E9723014638") -> E9723014638 | D38: =IFERROR(__xludf.DUMMYFUNCTION("""COMPUTED_VALUE"""),29.0) -> 29
B39: =IFERROR(__xludf.DUMMYFUNCTION("""COMPUTED_VALUE"""),"FLAVIUS PANGAREGO") -> FLAVIUS PANGAREGO | C39: =IFERROR(__xludf.DUMMYFUNCTION("""COMPUTED_VALUE"""),"F9623012859") -> F9623012859 | D39: =IFERROR(__xludf.DUMMYFUNCTION("""COMPUTED_VALUE"""),30.0) -> 30
B40: =IFERROR(__xludf.DUMMYFUNCTION("""COMPUTED_VALUE"""),"HERI RAHMANTO") -> HERI RAHMANTO | C40: =IFERROR(__xludf.DUMMYFUNCTION("""COMPUTED_VALUE"""),"H6123011926") -> H6123011926 | D40: =IFERROR(__xludf.DUMMYFUNCTION("""COMPUTED_VALUE"""),65.0) -> 65
...

Sheet ⬇️ PEMASUKAN
B1: CATATAN PEMASUKAN LAYANAN FISIOTERAPI GANG SEHAT PONTIANAK 2026
B4: NO | C4: ADMIN | D4: TANGGAL | E4: TAHUN | F4: BULAN | G4: JAM | H4: FISIO | I4: NAMA PASIEN | J4: JENIS | K4: PEMBELIAN | L4: KATEGORI PEMBELIAN | M4: KETERANGAN BAYAR | N4: JUMLAH BAYAR | O4: DISKON | P4: HARGA | Q4: KEKURANGAN | R4: METODE BAYAR | S4: PENJAMIN | T4: ✅ | U4: CATATAN
B5: 2109 | C5: SUCI | D5: 46025 | E5: =if(D5="","",text(D5,"YYY")) -> 2026 | F5: =if(D5="","",text(D5,"MM")&" "&text(D5,"MMM")) -> 01 Jan | G5: 11.00 | H5: OKTA | I5: ANDIANA MARJAYANTI | J5: BARU | K5: K.TA - TERAPI AWAL | L5: =IF(ISNUMBER(SEARCH("*K.TA*",K5)),"TA KLINIK",IF(ISNUMBER(SEARCH("*K.PT*",K5)),"PAKET KLINIK",IF(ISNUMBER(SEARCH("*K.ST*",K5)),"SESI KLINIK",IF(ISNUMBER(SEARCH("*V.TA*",K5)),"TA VISIT",IF(ISNUMBER(SEARCH("*V.ST*",K5)),"SESI VISIT",IF(ISNUMBER(SEARCH("*V.PT*",K5)),"PAKET VISIT","LAINNYA")))))) -> TA KLINIK | M5: LUNAS | N5: 250000 | O5: 0 | P5: {=IFNA(XLOOKUP(K5,'⚙️ Pengaturan'!$E$2:$E800,'⚙️ Pengaturan'!$F$2:$F800),"")} -> 250000 | Q5: =IF(I5="","",(N5+O5)-P5) -> 0 | R5: TRANSFER BCA | S5: ANDIANA MARJAYANTI | T5: TRUE
B6: 2110 | C6: SUCI | D6: 46025 | E6: =if(D6="","",text(D6,"YYY")) -> 2026 | F6: =if(D6="","",text(D6,"MM")&" "&text(D6,"MMM")) -> 01 Jan | G6: 12.00 | H6: WAHYU | I6: SETIO BONO SAPUTRO | K6: K.ST - SESI TERAPI | L6: =IF(ISNUMBER(SEARCH("*K.TA*",K6)),"TA KLINIK",IF(ISNUMBER(SEARCH("*K.PT*",K6)),"PAKET KLINIK",IF(ISNUMBER(SEARCH("*K.ST*",K6)),"SESI KLINIK",IF(ISNUMBER(SEARCH("*V.TA*",K6)),"TA VISIT",IF(ISNUMBER(SEARCH("*V.ST*",K6)),"SESI VISIT",IF(ISNUMBER(SEARCH("*V.PT*",K6)),"PAKET VISIT","LAINNYA")))))) -> SESI KLINIK | M6: LUNAS | N6: 150000 | O6: 0 | P6: {=IFNA(XLOOKUP(K6,'⚙️ Pengaturan'!$E$2:$E800,'⚙️ Pengaturan'!$F$2:$F800),"")} -> 150000 | Q6: =IF(I6="","",(N6+O6)-P6) -> 0 | R6: TUNAI | S6: - | T6: TRUE
B7: 2111 | C7: SUCI | D7: 46025 | E7: =if(D7="","",text(D7,"YYY")) -> 2026 | F7: =if(D7="","",text(D7,"MM")&" "&text(D7,"MMM")) -> 01 Jan | G7: 12.00 | H7: DANI | I7: IVONNY | J7: BARU | K7: K.TA - TERAPI AWAL | L7: =IF(ISNUMBER(SEARCH("*K.TA*",K7)),"TA KLINIK",IF(ISNUMBER(SEARCH("*K.PT*",K7)),"PAKET KLINIK",IF(ISNUMBER(SEARCH("*K.ST*",K7)),"SESI KLINIK",IF(ISNUMBER(SEARCH("*V.TA*",K7)),"TA VISIT",IF(ISNUMBER(SEARCH("*V.ST*",K7)),"SESI VISIT",IF(ISNUMBER(SEARCH("*V.PT*",K7)),"PAKET VISIT","LAINNYA")))))) -> TA KLINIK | M7: LUNAS | N7: 250000 | O7: 0 | P7: {=IFNA(XLOOKUP(K7,'⚙️ Pengaturan'!$E$2:$E800,'⚙️ Pengaturan'!$F$2:$F800),"")} -> 250000 | Q7: =IF(I7="","",(N7+O7)-P7) -> 0 | R7: TUNAI | S7: - | T7: TRUE
B8: 2112 | C8: SUCI | D8: 46025 | E8: =if(D8="","",text(D8,"YYY")) -> 2026 | F8: =if(D8="","",text(D8,"MM")&" "&text(D8,"MMM")) -> 01 Jan | G8: 15.00 | H8: WAHYU | I8: YUBANADI | K8: K.PT - PAKET 1 | L8: =IF(ISNUMBER(SEARCH("*K.TA*",K8)),"TA KLINIK",IF(ISNUMBER(SEARCH("*K.PT*",K8)),"PAKET KLINIK",IF(ISNUMBER(SEARCH("*K.ST*",K8)),"SESI KLINIK",IF(ISNUMBER(SEARCH("*V.TA*",K8)),"TA VISIT",IF(ISNUMBER(SEARCH("*V.ST*",K8)),"SESI VISIT",IF(ISNUMBER(SEARCH("*V.PT*",K8)),"PAKET VISIT","LAINNYA")))))) -> PAKET KLINIK | M8: LUNAS | N8: 650000 | O8: 0 | P8: {=IFNA(XLOOKUP(K8,'⚙️ Pengaturan'!$E$2:$E800,'⚙️ Pengaturan'!$F$2:$F800),"")} -> 650000 | Q8: =IF(I8="","",(N8+O8)-P8) -> 0 | R8: TUNAI | S8: - | T8: TRUE
B9: 2113 | C9: NOPI | D9: 46025 | E9: =if(D9="","",text(D9,"YYY")) -> 2026 | F9: =if(D9="","",text(D9,"MM")&" "&text(D9,"MMM")) -> 01 Jan | G9: 17.00 | H9: PRITY | I9: SRI ESRI | K9: K.PT - PAKET 2 | L9: =IF(ISNUMBER(SEARCH("*K.TA*",K9)),"TA KLINIK",IF(ISNUMBER(SEARCH("*K.PT*",K9)),"PAKET KLINIK",IF(ISNUMBER(SEARCH("*K.ST*",K9)),"SESI KLINIK",IF(ISNUMBER(SEARCH("*V.TA*",K9)),"TA VISIT",IF(ISNUMBER(SEARCH("*V.ST*",K9)),"SESI VISIT",IF(ISNUMBER(SEARCH("*V.PT*",K9)),"PAKET VISIT","LAINNYA")))))) -> PAKET KLINIK | M9: LUNAS | N9: 1200000 | O9: 0 | P9: {=IFNA(XLOOKUP(K9,'⚙️ Pengaturan'!$E$2:$E800,'⚙️ Pengaturan'!$F$2:$F800),"")} -> 1200000 | Q9: =IF(I9="","",(N9+O9)-P9) -> 0 | R9: EDC BCA | S9: SRI ESRI | T9: TRUE
B10: 2114 | C10: NOPI | D10: 46025 | E10: =if(D10="","",text(D10,"YYY")) -> 2026 | F10: =if(D10="","",text(D10,"MM")&" "&text(D10,"MMM")) -> 01 Jan | G10: 16.00 | H10: PRITY | I10: PUTERA ANUGRAH PRATAMA | J10: BARU | K10: K.TA - TERAPI AWAL | L10: =IF(ISNUMBER(SEARCH("*K.TA*",K10)),"TA KLINIK",IF(ISNUMBER(SEARCH("*K.PT*",K10)),"PAKET KLINIK",IF(ISNUMBER(SEARCH("*K.ST*",K10)),"SESI KLINIK",IF(ISNUMBER(SEARCH("*V.TA*",K10)),"TA VISIT",IF(ISNUMBER(SEARCH("*V.ST*",K10)),"SESI VISIT",IF(ISNUMBER(SEARCH("*V.PT*",K10)),"PAKET VISIT","LAINNYA")))))) -> TA KLINIK | M10: LUNAS | N10: 250000 | O10: 0 | P10: {=IFNA(XLOOKUP(K10,'⚙️ Pengaturan'!$E$2:$E800,'⚙️ Pengaturan'!$F$2:$F800),"")} -> 250000 | Q10: =IF(I10="","",(N10+O10)-P10) -> 0 | R10: TRANSFER BCA | S10: PUTERA ANUGRAH PRATAMA | T10: TRUE
B11: 2115 | C11: NOPI | D11: 46025 | E11: =if(D11="","",text(D11,"YYY")) -> 2026 | F11: =if(D11="","",text(D11,"MM")&" "&text(D11,"MMM")) -> 01 Jan | G11: 16.00 | H11: DESTY | I11: SUGIH WIRAMANTRI | J11: BARU | K11: K.TA - TERAPI AWAL | L11: =IF(ISNUMBER(SEARCH("*K.TA*",K11)),"TA KLINIK",IF(ISNUMBER(SEARCH("*K.PT*",K11)),"PAKET KLINIK",IF(ISNUMBER(SEARCH("*K.ST*",K11)),"SESI KLINIK",IF(ISNUMBER(SEARCH("*V.TA*",K11)),"TA VISIT",IF(ISNUMBER(SEARCH("*V.ST*",K11)),"SESI VISIT",IF(ISNUMBER(SEARCH("*V.PT*",K11)),"PAKET VISIT","LAINNYA")))))) -> TA KLINIK | M11: LUNAS | N11: 250000 | O11: 0 | P11: {=IFNA(XLOOKUP(K11,'⚙️ Pengaturan'!$E$2:$E800,'⚙️ Pengaturan'!$F$2:$F800),"")} -> 250000 | Q11: =IF(I11="","",(N11+O11)-P11) -> 0 | R11: TRANSFER BCA | S11: SUGIH WIRAMANTRI | T11: TRUE
B12: 2116 | C12: NOPI | D12: 46025 | E12: =if(D12="","",text(D12,"YYY")) -> 2026 | F12: =if(D12="","",text(D12,"MM")&" "&text(D12,"MMM")) -> 01 Jan | G12: 17.00 | H12: DESTY | I12: K. E. ANANTA UTAMI | J12: BARU | K12: K.TA - TERAPI AWAL | L12: =IF(ISNUMBER(SEARCH("*K.TA*",K12)),"TA KLINIK",IF(ISNUMBER(SEARCH("*K.PT*",K12)),"PAKET KLINIK",IF(ISNUMBER(SEARCH("*K.ST*",K12)),"SESI KLINIK",IF(ISNUMBER(SEARCH("*V.TA*",K12)),"TA VISIT",IF(ISNUMBER(SEARCH("*V.ST*",K12)),"SESI VISIT",IF(ISNUMBER(SEARCH("*V.PT*",K12)),"PAKET VISIT","LAINNYA")))))) -> TA KLINIK | M12: LUNAS | N12: 250000 | O12: 0 | P12: {=IFNA(XLOOKUP(K12,'⚙️ Pengaturan'!$E$2:$E800,'⚙️ Pengaturan'!$F$2:$F800),"")} -> 250000 | Q12: =IF(I12="","",(N12+O12)-P12) -> 0 | R12: TUNAI | S12: - | T12: TRUE
B13: 2117 | C13: NOPI | D13: 46025 | E13: =if(D13="","",text(D13,"YYY")) -> 2026 | F13: =if(D13="","",text(D13,"MM")&" "&text(D13,"MMM")) -> 01 Jan | G13: 17.00 | H13: ORY | I13: HAMDAN IDRIS | K13: K.ST - SESI TERAPI | L13: =IF(ISNUMBER(SEARCH("*K.TA*",K13)),"TA KLINIK",IF(ISNUMBER(SEARCH("*K.PT*",K13)),"PAKET KLINIK",IF(ISNUMBER(SEARCH("*K.ST*",K13)),"SESI KLINIK",IF(ISNUMBER(SEARCH("*V.TA*",K13)),"TA VISIT",IF(ISNUMBER(SEARCH("*V.ST*",K13)),"SESI VISIT",IF(ISNUMBER(SEARCH("*V.PT*",K13)),"PAKET VISIT","LAINNYA")))))) -> SESI KLINIK | M13: LUNAS | N13: 150000 | O13: 0 | P13: {=IFNA(XLOOKUP(K13,'⚙️ Pengaturan'!$E$2:$E800,'⚙️ Pengaturan'!$F$2:$F800),"")} -> 150000 | Q13: =IF(I13="","",(N13+O13)-P13) -> 0 | R13: TUNAI | S13: - | T13: TRUE
B14: 2118 | C14: NOPI | D14: 46025 | E14: =if(D14="","",text(D14,"YYY")) -> 2026 | F14: =if(D14="","",text(D14,"MM")&" "&text(D14,"MMM")) -> 01 Jan | G14: 18.00 | H14: DESTY | I14: KOLENIUS KOLAI | J14: BARU | K14: K.TA - TERAPI AWAL | L14: =IF(ISNUMBER(SEARCH("*K.TA*",K14)),"TA KLINIK",IF(ISNUMBER(SEARCH("*K.PT*",K14)),"PAKET KLINIK",IF(ISNUMBER(SEARCH("*K.ST*",K14)),"SESI KLINIK",IF(ISNUMBER(SEARCH("*V.TA*",K14)),"TA VISIT",IF(ISNUMBER(SEARCH("*V.ST*",K14)),"SESI VISIT",IF(ISNUMBER(SEARCH("*V.PT*",K14)),"PAKET VISIT","LAINNYA")))))) -> TA KLINIK | M14: LUNAS | N14: 250000 | O14: 0 | P14: {=IFNA(XLOOKUP(K14,'⚙️ Pengaturan'!$E$2:$E800,'⚙️ Pengaturan'!$F$2:$F800),"")} -> 250000 | Q14: =IF(I14="","",(N14+O14)-P14) -> 0 | R14: TUNAI | S14: - | T14: TRUE
B15: 2119 | C15: NOPI | D15: 46025 | E15: =if(D15="","",text(D15,"YYY")) -> 2026 | F15: =if(D15="","",text(D15,"MM")&" "&text(D15,"MMM")) -> 01 Jan | G15: 18.00 | H15: PRITY | I15: EMMA | J15: BARU | K15: K.TA - TERAPI AWAL | L15: =IF(ISNUMBER(SEARCH("*K.TA*",K15)),"TA KLINIK",IF(ISNUMBER(SEARCH("*K.PT*",K15)),"PAKET KLINIK",IF(ISNUMBER(SEARCH("*K.ST*",K15)),"SESI KLINIK",IF(ISNUMBER(SEARCH("*V.TA*",K15)),"TA VISIT",IF(ISNUMBER(SEARCH("*V.ST*",K15)),"SESI VISIT",IF(ISNUMBER(SEARCH("*V.PT*",K15)),"PAKET VISIT","LAINNYA")))))) -> TA KLINIK | M15: LUNAS | N15: 250000 | O15: 0 | P15: {=IFNA(XLOOKUP(K15,'⚙️ Pengaturan'!$E$2:$E800,'⚙️ Pengaturan'!$F$2:$F800),"")} -> 250000 | Q15: =IF(I15="","",(N15+O15)-P15) -> 0 | R15: TUNAI | S15: - | T15: TRUE
B16: 2120 | C16: NOPI | D16: 46025 | E16: =if(D16="","",text(D16,"YYY")) -> 2026 | F16: =if(D16="","",text(D16,"MM")&" "&text(D16,"MMM")) -> 01 Jan | G16: 20.00 | H16: DESTY | I16: YA MUHAMMAD IKHSANDI | J16: BARU | K16: K.TA - TERAPI AWAL | L16: =IF(ISNUMBER(SEARCH("*K.TA*",K16)),"TA KLINIK",IF(ISNUMBER(SEARCH("*K.PT*",K16)),"PAKET KLINIK",IF(ISNUMBER(SEARCH("*K.ST*",K16)),"SESI KLINIK",IF(ISNUMBER(SEARCH("*V.TA*",K16)),"TA VISIT",IF(ISNUMBER(SEARCH("*V.ST*",K16)),"SESI VISIT",IF(ISNUMBER(SEARCH("*V.PT*",K16)),"PAKET VISIT","LAINNYA")))))) -> TA KLINIK | M16: LUNAS | N16: 250000 | O16: 0 | P16: {=IFNA(XLOOKUP(K16,'⚙️ Pengaturan'!$E$2:$E800,'⚙️ Pengaturan'!$F$2:$F800),"")} -> 250000 | Q16: =IF(I16="","",(N16+O16)-P16) -> 0 | R16: TUNAI | S16: - | T16: TRUE
B17: 2121 | C17: NOPI | D17: 46025 | E17: =if(D17="","",text(D17,"YYY")) -> 2026 | F17: =if(D17="","",text(D17,"MM")&" "&text(D17,"MMM")) -> 01 Jan | G17: 20.00 | H17: AUL | I17: TAUFIK | J17: BARU | K17: K.TA - TERAPI AWAL | L17: =IF(ISNUMBER(SEARCH("*K.TA*",K17)),"TA KLINIK",IF(ISNUMBER(SEARCH("*K.PT*",K17)),"PAKET KLINIK",IF(ISNUMBER(SEARCH("*K.ST*",K17)),"SESI KLINIK",IF(ISNUMBER(SEARCH("*V.TA*",K17)),"TA VISIT",IF(ISNUMBER(SEARCH("*V.ST*",K17)),"SESI VISIT",IF(ISNUMBER(SEARCH("*V.PT*",K17)),"PAKET VISIT","LAINNYA")))))) -> TA KLINIK | M17: LUNAS | N17: 250000 | O17: 0 | P17: {=IFNA(XLOOKUP(K17,'⚙️ Pengaturan'!$E$2:$E800,'⚙️ Pengaturan'!$F$2:$F800),"")} -> 250000 | Q17: =IF(I17="","",(N17+O17)-P17) -> 0 | R17: TUNAI | S17: - | T17: TRUE
B18: 2122 | C18: NOPI | D18: 46025 | E18: =if(D18="","",text(D18,"YYY")) -> 2026 | F18: =if(D18="","",text(D18,"MM")&" "&text(D18,"MMM")) -> 01 Jan | G18: 20.00 | H18: PRITY | I18: SHELSY MELANY | J18: BARU | K18: K.TA - TERAPI AWAL | L18: =IF(ISNUMBER(SEARCH("*K.TA*",K18)),"TA KLINIK",IF(ISNUMBER(SEARCH("*K.PT*",K18)),"PAKET KLINIK",IF(ISNUMBER(SEARCH("*K.ST*",K18)),"SESI KLINIK",IF(ISNUMBER(SEARCH("*V.TA*",K18)),"TA VISIT",IF(ISNUMBER(SEARCH("*V.ST*",K18)),"SESI VISIT",IF(ISNUMBER(SEARCH("*V.PT*",K18)),"PAKET VISIT","LAINNYA")))))) -> TA KLINIK | M18: LUNAS | N18: 250000 | O18: 0 | P18: {=IFNA(XLOOKUP(K18,'⚙️ Pengaturan'!$E$2:$E800,'⚙️ Pengaturan'!$F$2:$F800),"")} -> 250000 | Q18: =IF(I18="","",(N18+O18)-P18) -> 0 | R18: TUNAI | S18: - | T18: TRUE
B19: 2123 | C19: NOPI | D19: 46025 | E19: =if(D19="","",text(D19,"YYY")) -> 2026 | F19: =if(D19="","",text(D19,"MM")&" "&text(D19,"MMM")) -> 01 Jan | G19: 21.00 | H19: DESTY | I19: RANDA ARZA SAPUTRA | K19: K.PT - PAKET 1 | L19: =IF(ISNUMBER(SEARCH("*K.TA*",K19)),"TA KLINIK",IF(ISNUMBER(SEARCH("*K.PT*",K19)),"PAKET KLINIK",IF(ISNUMBER(SEARCH("*K.ST*",K19)),"SESI KLINIK",IF(ISNUMBER(SEARCH("*V.TA*",K19)),"TA VISIT",IF(ISNUMBER(SEARCH("*V.ST*",K19)),"SESI VISIT",IF(ISNUMBER(SEARCH("*V.PT*",K19)),"PAKET VISIT","LAINNYA")))))) -> PAKET KLINIK | M19: PELUNASAN | N19: 450000 | O19: 200000 | P19: {=IFNA(XLOOKUP(K19,'⚙️ Pengaturan'!$E$2:$E800,'⚙️ Pengaturan'!$F$2:$F800),"")} -> 650000 | Q19: =IF(I19="","",(N19+O19)-P19) -> 0 | R19: TRANSFER BCA | S19: RANDA ARZA SAPUTRA | T19: TRUE
B20: 2124 | C20: NOPI | D20: 46025 | E20: =if(D20="","",text(D20,"YYY")) -> 2026 | F20: =if(D20="","",text(D20,"MM")&" "&text(D20,"MMM")) -> 01 Jan | G20: 21.00 | H20: PRITY | I20: PUTRI ATIKAH | J20: BARU | K20: K.TA - TERAPI AWAL | L20: =IF(ISNUMBER(SEARCH("*K.TA*",K20)),"TA KLINIK",IF(ISNUMBER(SEARCH("*K.PT*",K20)),"PAKET KLINIK",IF(ISNUMBER(SEARCH("*K.ST*",K20)),"SESI KLINIK",IF(ISNUMBER(SEARCH("*V.TA*",K20)),"TA VISIT",IF(ISNUMBER(SEARCH("*V.ST*",K20)),"SESI VISIT",IF(ISNUMBER(SEARCH("*V.PT*",K20)),"PAKET VISIT","LAINNYA")))))) -> TA KLINIK | M20: LUNAS | N20: 250000 | O20: 0 | P20: {=IFNA(XLOOKUP(K20,'⚙️ Pengaturan'!$E$2:$E800,'⚙️ Pengaturan'!$F$2:$F800),"")} -> 250000 | Q20: =IF(I20="","",(N20+O20)-P20) -> 0 | R20: TRANSFER BCA | S20: RACHMAT RIYANTO | T20: TRUE
B21: 2125 | C21: NOPI | D21: 46025 | E21: =if(D21="","",text(D21,"YYY")) -> 2026 | F21: =if(D21="","",text(D21,"MM")&" "&text(D21,"MMM")) -> 01 Jan | G21: 21.00 | H21: ORY | I21: WISNU WARDANA | K21: K.PT - PAKET 2 | L21: =IF(ISNUMBER(SEARCH("*K.TA*",K21)),"TA KLINIK",IF(ISNUMBER(SEARCH("*K.PT*",K21)),"PAKET KLINIK",IF(ISNUMBER(SEARCH("*K.ST*",K21)),"SESI KLINIK",IF(ISNUMBER(SEARCH("*V.TA*",K21)),"TA VISIT",IF(ISNUMBER(SEARCH("*V.ST*",K21)),"SESI VISIT",IF(ISNUMBER(SEARCH("*V.PT*",K21)),"PAKET VISIT","LAINNYA")))))) -> PAKET KLINIK | M21: LUNAS | N21: 1200000 | O21: 0 | P21: {=IFNA(XLOOKUP(K21,'⚙️ Pengaturan'!$E$2:$E800,'⚙️ Pengaturan'!$F$2:$F800),"")} -> 1200000 | Q21: =IF(I21="","",(N21+O21)-P21) -> 0 | R21: TRANSFER BCA | S21: WISNU WARDANA | T21: TRUE
B22: 2126 | C22: NOPI | D22: 46025 | E22: =if(D22="","",text(D22,"YYY")) -> 2026 | F22: =if(D22="","",text(D22,"MM")&" "&text(D22,"MMM")) -> 01 Jan | G22: 10.00 | H22: HESTI | I22: ISNINDAR | K22: K.ST - SESI TERAPI | L22: =IF(ISNUMBER(SEARCH("*K.TA*",K22)),"TA KLINIK",IF(ISNUMBER(SEARCH("*K.PT*",K22)),"PAKET KLINIK",IF(ISNUMBER(SEARCH("*K.ST*",K22)),"SESI KLINIK",IF(ISNUMBER(SEARCH("*V.TA*",K22)),"TA VISIT",IF(ISNUMBER(SEARCH("*V.ST*",K22)),"SESI VISIT",IF(ISNUMBER(SEARCH("*V.PT*",K22)),"PAKET VISIT","LAINNYA")))))) -> SESI KLINIK | M22: LUNAS | N22: 150000 | O22: 0 | P22: {=IFNA(XLOOKUP(K22,'⚙️ Pengaturan'!$E$2:$E800,'⚙️ Pengaturan'!$F$2:$F800),"")} -> 150000 | Q22: =IF(I22="","",(N22+O22)-P22) -> 0 | R22: TRANSFER BCA | S22: ISNINDAR | T22: TRUE
B23: 2127 | C23: NOPI | D23: 46025 | E23: =if(D23="","",text(D23,"YYY")) -> 2026 | F23: =if(D23="","",text(D23,"MM")&" "&text(D23,"MMM")) -> 01 Jan | G23: 15.00 | H23: HENA | I23: ATHA HANIF PRADIPTA | J23: BARU | K23: K.TA - TERAPI AWAL | L23: =IF(ISNUMBER(SEARCH("*K.TA*",K23)),"TA KLINIK",IF(ISNUMBER(SEARCH("*K.PT*",K23)),"PAKET KLINIK",IF(ISNUMBER(SEARCH("*K.ST*",K23)),"SESI KLINIK",IF(ISNUMBER(SEARCH("*V.TA*",K23)),"TA VISIT",IF(ISNUMBER(SEARCH("*V.ST*",K23)),"SESI VISIT",IF(ISNUMBER(SEARCH("*V.PT*",K23)),"PAKET VISIT","LAINNYA")))))) -> TA KLINIK | M23: LUNAS | N23: 250000 | O23: 0 | P23: {=IFNA(XLOOKUP(K23,'⚙️ Pengaturan'!$E$2:$E800,'⚙️ Pengaturan'!$F$2:$F800),"")} -> 250000 | Q23: =IF(I23="","",(N23+O23)-P23) -> 0 | R23: TRANSFER BCA | S23: ATHA HANIF PRADIPTA | T23: TRUE
B24: 2128 | C24: NOPI | D24: 46025 | E24: =if(D24="","",text(D24,"YYY")) -> 2026 | F24: =if(D24="","",text(D24,"MM")&" "&text(D24,"MMM")) -> 01 Jan | G24: 17.00 | H24: OKTA | I24: GALIH PITA LOKA | J24: BARU | K24: V.TA - TERAPI AWAL VISIT + JARAK | L24: =IF(ISNUMBER(SEARCH("*K.TA*",K24)),"TA KLINIK",IF(ISNUMBER(SEARCH("*K.PT*",K24)),"PAKET KLINIK",IF(ISNUMBER(SEARCH("*K.ST*",K24)),"SESI KLINIK",IF(ISNUMBER(SEARCH("*V.TA*",K24)),"TA VISIT",IF(ISNUMBER(SEARCH("*V.ST*",K24)),"SESI VISIT",IF(ISNUMBER(SEARCH("*V.PT*",K24)),"PAKET VISIT","LAINNYA")))))) -> TA VISIT | M24: LUNAS | N24: 350000 | O24: 0 | P24: {=IFNA(XLOOKUP(K24,'⚙️ Pengaturan'!$E$2:$E800,'⚙️ Pengaturan'!$F$2:$F800),"")} -> 350000 | Q24: =IF(I24="","",(N24+O24)-P24) -> 0 | R24: TRANSFER BCA | S24: GALIH PITA LOKA | T24: TRUE
B25: 2129 | C25: SUCI | D25: 46026 | E25: =if(D25="","",text(D25,"YYY")) -> 2026 | F25: =if(D25="","",text(D25,"MM")&" "&text(D25,"MMM")) -> 01 Jan | G25: 11.00 | H25: WAHYU | I25: WACHYU WIDAYAT | K25: K.PT - PAKET 1 | L25: =IF(ISNUMBER(SEARCH("*K.TA*",K25)),"TA KLINIK",IF(ISNUMBER(SEARCH("*K.PT*",K25)),"PAKET KLINIK",IF(ISNUMBER(SEARCH("*K.ST*",K25)),"SESI KLINIK",IF(ISNUMBER(SEARCH("*V.TA*",K25)),"TA VISIT",IF(ISNUMBER(SEARCH("*V.ST*",K25)),"SESI VISIT",IF(ISNUMBER(SEARCH("*V.PT*",K25)),"PAKET VISIT","LAINNYA")))))) -> PAKET KLINIK | M25: LUNAS | N25: 650000 | O25: 0 | P25: {=IFNA(XLOOKUP(K25,'⚙️ Pengaturan'!$E$2:$E800,'⚙️ Pengaturan'!$F$2:$F800),"")} -> 650000 | Q25: =IF(I25="","",(N25+O25)-P25) -> 0 | R25: TUNAI | S25: - | T25: TRUE
B26: 2130 | C26: SUCI | D26: 46026 | E26: =if(D26="","",text(D26,"YYY")) -> 2026 | F26: =if(D26="","",text(D26,"MM")&" "&text(D26,"MMM")) -> 01 Jan | G26: 12.00 | H26: DANI | I26: BELLY | J26: LANJUT | K26: K.PT - PAKET 1 | L26: =IF(ISNUMBER(SEARCH("*K.TA*",K26)),"TA KLINIK",IF(ISNUMBER(SEARCH("*K.PT*",K26)),"PAKET KLINIK",IF(ISNUMBER(SEARCH("*K.ST*",K26)),"SESI KLINIK",IF(ISNUMBER(SEARCH("*V.TA*",K26)),"TA VISIT",IF(ISNUMBER(SEARCH("*V.ST*",K26)),"SESI VISIT",IF(ISNUMBER(SEARCH("*V.PT*",K26)),"PAKET VISIT","LAINNYA")))))) -> PAKET KLINIK | M26: LUNAS | N26: 650000 | O26: 0 | P26: {=IFNA(XLOOKUP(K26,'⚙️ Pengaturan'!$E$2:$E800,'⚙️ Pengaturan'!$F$2:$F800),"")} -> 650000 | Q26: =IF(I26="","",(N26+O26)-P26) -> 0 | R26: TUNAI | S26: - | T26: TRUE
B27: 2131 | C27: SUCI | D27: 46026 | E27: =if(D27="","",text(D27,"YYY")) -> 2026 | F27: =if(D27="","",text(D27,"MM")&" "&text(D27,"MMM")) -> 01 Jan | G27: 12.00 | H27: HESTI | I27: WIWIK HARTATI | J27: BARU | K27: K.TA - TERAPI AWAL | L27: =IF(ISNUMBER(SEARCH("*K.TA*",K27)),"TA KLINIK",IF(ISNUMBER(SEARCH("*K.PT*",K27)),"PAKET KLINIK",IF(ISNUMBER(SEARCH("*K.ST*",K27)),"SESI KLINIK",IF(ISNUMBER(SEARCH("*V.TA*",K27)),"TA VISIT",IF(ISNUMBER(SEARCH("*V.ST*",K27)),"SESI VISIT",IF(ISNUMBER(SEARCH("*V.PT*",K27)),"PAKET VISIT","LAINNYA")))))) -> TA KLINIK | M27: LUNAS | N27: 250000 | O27: 0 | P27: {=IFNA(XLOOKUP(K27,'⚙️ Pengaturan'!$E$2:$E800,'⚙️ Pengaturan'!$F$2:$F800),"")} -> 250000 | Q27: =IF(I27="","",(N27+O27)-P27) -> 0 | R27: TRANSFER BCA | S27: WIWIK HARTATI | T27: TRUE
B28: 2133 | C28: NOPI | D28: 46026 | E28: =if(D28="","",text(D28,"YYY")) -> 2026 | F28: =if(D28="","",text(D28,"MM")&" "&text(D28,"MMM")) -> 01 Jan | G28: 18.00 | H28: AUL | I28: CHOTIBUL UMAMI | J28: BARU | K28: K.TA - TERAPI AWAL | L28: =IF(ISNUMBER(SEARCH("*K.TA*",K28)),"TA KLINIK",IF(ISNUMBER(SEARCH("*K.PT*",K28)),"PAKET KLINIK",IF(ISNUMBER(SEARCH("*K.ST*",K28)),"SESI KLINIK",IF(ISNUMBER(SEARCH("*V.TA*",K28)),"TA VISIT",IF(ISNUMBER(SEARCH("*V.ST*",K28)),"SESI VISIT",IF(ISNUMBER(SEARCH("*V.PT*",K28)),"PAKET VISIT","LAINNYA")))))) -> TA KLINIK | M28: LUNAS | N28: 250000 | O28: 0 | P28: {=IFNA(XLOOKUP(K28,'⚙️ Pengaturan'!$E$2:$E800,'⚙️ Pengaturan'!$F$2:$F800),"")} -> 250000 | Q28: =IF(I28="","",(N28+O28)-P28) -> 0 | R28: TRANSFER BCA | S28: NIDYA RISWANDA TRISMA W | T28: TRUE
B29: 2134 | C29: NOPI | D29: 46026 | E29: =if(D29="","",text(D29,"YYY")) -> 2026 | F29: =if(D29="","",text(D29,"MM")&" "&text(D29,"MMM")) -> 01 Jan | G29: 20.00 | H29: PRITY | I29: EMMA | K29: K.ST - SESI TERAPI | L29: =IF(ISNUMBER(SEARCH("*K.TA*",K29)),"TA KLINIK",IF(ISNUMBER(SEARCH("*K.PT*",K29)),"PAKET KLINIK",IF(ISNUMBER(SEARCH("*K.ST*",K29)),"SESI KLINIK",IF(ISNUMBER(SEARCH("*V.TA*",K29)),"TA VISIT",IF(ISNUMBER(SEARCH("*V.ST*",K29)),"SESI VISIT",IF(ISNUMBER(SEARCH("*V.PT*",K29)),"PAKET VISIT","LAINNYA")))))) -> SESI KLINIK | M29: LUNAS | N29: 150000 | O29: 0 | P29: {=IFNA(XLOOKUP(K29,'⚙️ Pengaturan'!$E$2:$E800,'⚙️ Pengaturan'!$F$2:$F800),"")} -> 150000 | Q29: =IF(I29="","",(N29+O29)-P29) -> 0 | R29: TUNAI | S29: - | T29: TRUE
B30: 2135 | C30: NOPI | D30: 46026 | E30: =if(D30="","",text(D30,"YYY")) -> 2026 | F30: =if(D30="","",text(D30,"MM")&" "&text(D30,"MMM")) -> 01 Jan | G30: 20.00 | H30: PRITY | I30: EMMA | K30: K.ST - SESI TERAPI | L30: =IF(ISNUMBER(SEARCH("*K.TA*",K30)),"TA KLINIK",IF(ISNUMBER(SEARCH("*K.PT*",K30)),"PAKET KLINIK",IF(ISNUMBER(SEARCH("*K.ST*",K30)),"SESI KLINIK",IF(ISNUMBER(SEARCH("*V.TA*",K30)),"TA VISIT",IF(ISNUMBER(SEARCH("*V.ST*",K30)),"SESI VISIT",IF(ISNUMBER(SEARCH("*V.PT*",K30)),"PAKET VISIT","LAINNYA")))))) -> SESI KLINIK | M30: LUNAS | N30: 150000 | O30: 0 | P30: {=IFNA(XLOOKUP(K30,'⚙️ Pengaturan'!$E$2:$E800,'⚙️ Pengaturan'!$F$2:$F800),"")} -> 150000 | Q30: =IF(I30="","",(N30+O30)-P30) -> 0 | R30: TUNAI | S30: - | T30: TRUE
B31: 2136 | C31: NOPI | D31: 46026 | E31: =if(D31="","",text(D31,"YYY")) -> 2026 | F31: =if(D31="","",text(D31,"MM")&" "&text(D31,"MMM")) -> 01 Jan | G31: 20.00 | H31: DESTY | I31: KOLENIUS KOLAI | K31: K.ST - SESI TERAPI | L31: =IF(ISNUMBER(SEARCH("*K.TA*",K31)),"TA KLINIK",IF(ISNUMBER(SEARCH("*K.PT*",K31)),"PAKET KLINIK",IF(ISNUMBER(SEARCH("*K.ST*",K31)),"SESI KLINIK",IF(ISNUMBER(SEARCH("*V.TA*",K31)),"TA VISIT",IF(ISNUMBER(SEARCH("*V.ST*",K31)),"SESI VISIT",IF(ISNUMBER(SEARCH("*V.PT*",K31)),"PAKET VISIT","LAINNYA")))))) -> SESI KLINIK | M31: LUNAS | N31: 150000 | O31: 0 | P31: {=IFNA(XLOOKUP(K31,'⚙️ Pengaturan'!$E$2:$E800,'⚙️ Pengaturan'!$F$2:$F800),"")} -> 150000 | Q31: =IF(I31="","",(N31+O31)-P31) -> 0 | R31: TUNAI | S31: - | T31: TRUE
B32: 2137 | C32: NOPI | D32: 46026 | E32: =if(D32="","",text(D32,"YYY")) -> 2026 | F32: =if(D32="","",text(D32,"MM")&" "&text(D32,"MMM")) -> 01 Jan | G32: 20.00 | H32: DESTY | I32: KOLENIUS KOLAI | K32: K.ST - SESI TERAPI | L32: =IF(ISNUMBER(SEARCH("*K.TA*",K32)),"TA KLINIK",IF(ISNUMBER(SEARCH("*K.PT*",K32)),"PAKET KLINIK",IF(ISNUMBER(SEARCH("*K.ST*",K32)),"SESI KLINIK",IF(ISNUMBER(SEARCH("*V.TA*",K32)),"TA VISIT",IF(ISNUMBER(SEARCH("*V.ST*",K32)),"SESI VISIT",IF(ISNUMBER(SEARCH("*V.PT*",K32)),"PAKET VISIT","LAINNYA")))))) -> SESI KLINIK | M32: LUNAS | N32: 150000 | O32: 0 | P32: {=IFNA(XLOOKUP(K32,'⚙️ Pengaturan'!$E$2:$E800,'⚙️ Pengaturan'!$F$2:$F800),"")} -> 150000 | Q32: =IF(I32="","",(N32+O32)-P32) -> 0 | R32: TUNAI | S32: - | T32: TRUE
B33: 2138 | C33: NOPI | D33: 46026 | E33: =if(D33="","",text(D33,"YYY")) -> 2026 | F33: =if(D33="","",text(D33,"MM")&" "&text(D33,"MMM")) -> 01 Jan | G33: 20.00 | H33: ORY | I33: MUHAMMAD FADHIL RAMADHANI | J33: BARU | K33: K.TA - TERAPI AWAL | L33: =IF(ISNUMBER(SEARCH("*K.TA*",K33)),"TA KLINIK",IF(ISNUMBER(SEARCH("*K.PT*",K33)),"PAKET KLINIK",IF(ISNUMBER(SEARCH("*K.ST*",K33)),"SESI KLINIK",IF(ISNUMBER(SEARCH("*V.TA*",K33)),"TA VISIT",IF(ISNUMBER(SEARCH("*V.ST*",K33)),"SESI VISIT",IF(ISNUMBER(SEARCH("*V.PT*",K33)),"PAKET VISIT","LAINNYA")))))) -> TA KLINIK | M33: LUNAS | N33: 250000 | O33: 0 | P33: {=IFNA(XLOOKUP(K33,'⚙️ Pengaturan'!$E$2:$E800,'⚙️ Pengaturan'!$F$2:$F800),"")} -> 250000 | Q33: =IF(I33="","",(N33+O33)-P33) -> 0 | R33: TRANSFER BCA | S33: MUHAMMAD FADHIL RAMADHANI | T33: TRUE
B34: 2139 | C34: NOPI | D34: 46026 | E34: =if(D34="","",text(D34,"YYY")) -> 2026 | F34: =if(D34="","",text(D34,"MM")&" "&text(D34,"MMM")) -> 01 Jan | G34: 20.00 | H34: AUL | I34: ANDRI DOS SANTOS | K34: K.ST - SESI TERAPI | L34: =IF(ISNUMBER(SEARCH("*K.TA*",K34)),"TA KLINIK",IF(ISNUMBER(SEARCH("*K.PT*",K34)),"PAKET KLINIK",IF(ISNUMBER(SEARCH("*K.ST*",K34)),"SESI KLINIK",IF(ISNUMBER(SEARCH("*V.TA*",K34)),"TA VISIT",IF(ISNUMBER(SEARCH("*V.ST*",K34)),"SESI VISIT",IF(ISNUMBER(SEARCH("*V.PT*",K34)),"PAKET VISIT","LAINNYA")))))) -> SESI KLINIK | M34: LUNAS | N34: 150000 | O34: 0 | P34: {=IFNA(XLOOKUP(K34,'⚙️ Pengaturan'!$E$2:$E800,'⚙️ Pengaturan'!$F$2:$F800),"")} -> 150000 | Q34: =IF(I34="","",(N34+O34)-P34) -> 0 | R34: TRANSFER BCA | S34: ANDRI DOS SANTOS | T34: TRUE
B35: 2140 | C35: SUCI | D35: 46026 | E35: =if(D35="","",text(D35,"YYY")) -> 2026 | F35: =if(D35="","",text(D35,"MM")&" "&text(D35,"MMM")) -> 01 Jan | G35: 14.00 | H35: HENA | I35: ELISABETH SUTINI | J35: BARU | K35: K.TA - TERAPI AWAL | L35: =IF(ISNUMBER(SEARCH("*K.TA*",K35)),"TA KLINIK",IF(ISNUMBER(SEARCH("*K.PT*",K35)),"PAKET KLINIK",IF(ISNUMBER(SEARCH("*K.ST*",K35)),"SESI KLINIK",IF(ISNUMBER(SEARCH("*V.TA*",K35)),"TA VISIT",IF(ISNUMBER(SEARCH("*V.ST*",K35)),"SESI VISIT",IF(ISNUMBER(SEARCH("*V.PT*",K35)),"PAKET VISIT","LAINNYA")))))) -> TA KLINIK | M35: LUNAS | N35: 250000 | O35: 0 | P35: {=IFNA(XLOOKUP(K35,'⚙️ Pengaturan'!$E$2:$E800,'⚙️ Pengaturan'!$F$2:$F800),"")} -> 250000 | Q35: =IF(I35="","",(N35+O35)-P35) -> 0 | R35: TRANSFER BCA | S35: YASINTA | T35: TRUE
B36: 2141 | C36: SUCI | D36: 46027 | E36: =if(D36="","",text(D36,"YYY")) -> 2026 | F36: =if(D36="","",text(D36,"MM")&" "&text(D36,"MMM")) -> 01 Jan | G36: 10.00 | H36: ORY | I36: DARMANSYAH | J36: BARU | K36: K.TA - TERAPI AWAL | L36: =IF(ISNUMBER(SEARCH("*K.TA*",K36)),"TA KLINIK",IF(ISNUMBER(SEARCH("*K.PT*",K36)),"PAKET KLINIK",IF(ISNUMBER(SEARCH("*K.ST*",K36)),"SESI KLINIK",IF(ISNUMBER(SEARCH("*V.TA*",K36)),"TA VISIT",IF(ISNUMBER(SEARCH("*V.ST*",K36)),"SESI VISIT",IF(ISNUMBER(SEARCH("*V.PT*",K36)),"PAKET VISIT","LAINNYA")))))) -> TA KLINIK | M36: LUNAS | N36: 250000 | O36: 0 | P36: {=IFNA(XLOOKUP(K36,'⚙️ Pengaturan'!$E$2:$E800,'⚙️ Pengaturan'!$F$2:$F800),"")} -> 250000 | Q36: =IF(I36="","",(N36+O36)-P36) -> 0 | R36: TUNAI | S36: - | T36: TRUE
B37: 2142 | C37: SUCI | D37: 46027 | E37: =if(D37="","",text(D37,"YYY")) -> 2026 | F37: =if(D37="","",text(D37,"MM")&" "&text(D37,"MMM")) -> 01 Jan | G37: 10.00 | H37: DESTY | I37: K. E. ANANTA UTAMI | K37: K.PT - PAKET 1 | L37: =IF(ISNUMBER(SEARCH("*K.TA*",K37)),"TA KLINIK",IF(ISNUMBER(SEARCH("*K.PT*",K37)),"PAKET KLINIK",IF(ISNUMBER(SEARCH("*K.ST*",K37)),"SESI KLINIK",IF(ISNUMBER(SEARCH("*V.TA*",K37)),"TA VISIT",IF(ISNUMBER(SEARCH("*V.ST*",K37)),"SESI VISIT",IF(ISNUMBER(SEARCH("*V.PT*",K37)),"PAKET VISIT","LAINNYA")))))) -> PAKET KLINIK | M37: DP | N37: 200000 | O37: 0 | P37: {=IFNA(XLOOKUP(K37,'⚙️ Pengaturan'!$E$2:$E800,'⚙️ Pengaturan'!$F$2:$F800),"")} -> 650000 | Q37: =IF(I37="","",(N37+O37)-P37) -> -450000 | R37: EDC BCA | S37: ANANTA UTAMI | T37: TRUE
B38: 2143 | C38: SUCI | D38: 46027 | E38: =if(D38="","",text(D38,"YYY")) -> 2026 | F38: =if(D38="","",text(D38,"MM")&" "&text(D38,"MMM")) -> 01 Jan | G38: 10.00 | H38: PRITY | I38: SHELSY MELANY | K38: K.PT - PAKET 2 | L38: =IF(ISNUMBER(SEARCH("*K.TA*",K38)),"TA KLINIK",IF(ISNUMBER(SEARCH("*K.PT*",K38)),"PAKET KLINIK",IF(ISNUMBER(SEARCH("*K.ST*",K38)),"SESI KLINIK",IF(ISNUMBER(SEARCH("*V.TA*",K38)),"TA VISIT",IF(ISNUMBER(SEARCH("*V.ST*",K38)),"SESI VISIT",IF(ISNUMBER(SEARCH("*V.PT*",K38)),"PAKET VISIT","LAINNYA")))))) -> PAKET KLINIK | M38: DP | N38: 500000 | O38: 0 | P38: {=IFNA(XLOOKUP(K38,'⚙️ Pengaturan'!$E$2:$E800,'⚙️ Pengaturan'!$F$2:$F800),"")} -> 1200000 | Q38: =IF(I38="","",(N38+O38)-P38) -> -700000 | R38: TUNAI | S38: - | T38: TRUE
B39: 2144 | C39: SUCI | D39: 46027 | E39: =if(D39="","",text(D39,"YYY")) -> 2026 | F39: =if(D39="","",text(D39,"MM")&" "&text(D39,"MMM")) -> 01 Jan | G39: 11.00 | H39: DANI | I39: JUVENTYA | J39: BARU | K39: K.TA - TERAPI AWAL | L39: =IF(ISNUMBER(SEARCH("*K.TA*",K39)),"TA KLINIK",IF(ISNUMBER(SEARCH("*K.PT*",K39)),"PAKET KLINIK",IF(ISNUMBER(SEARCH("*K.ST*",K39)),"SESI KLINIK",IF(ISNUMBER(SEARCH("*V.TA*",K39)),"TA VISIT",IF(ISNUMBER(SEARCH("*V.ST*",K39)),"SESI VISIT",IF(ISNUMBER(SEARCH("*V.PT*",K39)),"PAKET VISIT","LAINNYA")))))) -> TA KLINIK | M39: LUNAS | N39: 250000 | O39: 0 | P39: {=IFNA(XLOOKUP(K39,'⚙️ Pengaturan'!$E$2:$E800,'⚙️ Pengaturan'!$F$2:$F800),"")} -> 250000 | Q39: =IF(I39="","",(N39+O39)-P39) -> 0 | R39: TUNAI | S39: - | T39: TRUE
B40: 2145 | C40: SUCI | D40: 46027 | E40: =if(D40="","",text(D40,"YYY")) -> 2026 | F40: =if(D40="","",text(D40,"MM")&" "&text(D40,"MMM")) -> 01 Jan | G40: 13.00 | H40: ORY | I40: TJONG LIE TJHIUN ALS SUKIMAN | K40: K.PT - PAKET 1 | L40: =IF(ISNUMBER(SEARCH("*K.TA*",K40)),"TA KLINIK",IF(ISNUMBER(SEARCH("*K.PT*",K40)),"PAKET KLINIK",IF(ISNUMBER(SEARCH("*K.ST*",K40)),"SESI KLINIK",IF(ISNUMBER(SEARCH("*V.TA*",K40)),"TA VISIT",IF(ISNUMBER(SEARCH("*V.ST*",K40)),"SESI VISIT",IF(ISNUMBER(SEARCH("*V.PT*",K40)),"PAKET VISIT","LAINNYA")))))) -> PAKET KLINIK | M40: DP | N40: 200000 | O40: 0 | P40: {=IFNA(XLOOKUP(K40,'⚙️ Pengaturan'!$E$2:$E800,'⚙️ Pengaturan'!$F$2:$F800),"")} -> 650000 | Q40: =IF(I40="","",(N40+O40)-P40) -> -450000 | R40: TUNAI | S40: - | T40: TRUE
B41: 2146 | C41: NOPI | D41: 46027 | E41: =if(D41="","",text(D41,"YYY")) -> 2026 | F41: =if(D41="","",text(D41,"MM")&" "&text(D41,"MMM")) -> 01 Jan | G41: 15.00 | H41: HENA | I41: ATHA HANIF PRADIPTA | K41: K.PT - PAKET 1 | L41: =IF(ISNUMBER(SEARCH("*K.TA*",K41)),"TA KLINIK",IF(ISNUMBER(SEARCH("*K.PT*",K41)),"PAKET KLINIK",IF(ISNUMBER(SEARCH("*K.ST*",K41)),"SESI KLINIK",IF(ISNUMBER(SEARCH("*V.TA*",K41)),"TA VISIT",IF(ISNUMBER(SEARCH("*V.ST*",K41)),"SESI VISIT",IF(ISNUMBER(SEARCH("*V.PT*",K41)),"PAKET VISIT","LAINNYA")))))) -> PAKET KLINIK | M41: LUNAS | N41: 650000 | O41: 0 | P41: {=IFNA(XLOOKUP(K41,'⚙️ Pengaturan'!$E$2:$E800,'⚙️ Pengaturan'!$F$2:$F800),"")} -> 650000 | Q41: =IF(I41="","",(N41+O41)-P41) -> 0 | R41: TRANSFER BCA | S41: DWI RACHMAWAN | T41: TRUE
B42: 2147 | C42: NOPI | D42: 46027 | E42: =if(D42="","",text(D42,"YYY")) -> 2026 | F42: =if(D42="","",text(D42,"MM")&" "&text(D42,"MMM")) -> 01 Jan | G42: 16.00 | H42: DESTY | I42: PUTRI ATIKAH | K42: V.ST - SESI VISIT | L42: =IF(ISNUMBER(SEARCH("*K.TA*",K42)),"TA KLINIK",IF(ISNUMBER(SEARCH("*K.PT*",K42)),"PAKET KLINIK",IF(ISNUMBER(SEARCH("*K.ST*",K42)),"SESI KLINIK",IF(ISNUMBER(SEARCH("*V.TA*",K42)),"TA VISIT",IF(ISNUMBER(SEARCH("*V.ST*",K42)),"SESI VISIT",IF(ISNUMBER(SEARCH("*V.PT*",K42)),"PAKET VISIT","LAINNYA")))))) -> SESI VISIT | M42: LUNAS | N42: 200000 | O42: 0 | P42: {=IFNA(XLOOKUP(K42,'⚙️ Pengaturan'!$E$2:$E800,'⚙️ Pengaturan'!$F$2:$F800),"")} -> 200000 | Q42: =IF(I42="","",(N42+O42)-P42) -> 0 | R42: TRANSFER BCA | S42: PUTRI ATIKAH | T42: TRUE
...

Sheet ⬆️ PENGELUARAN
B1: CATATAN PENGELUARAN FISIOTERAPI GANG SEHAT PONTIANAK 2026
B4: Z | C4: ADMIN | D4: TANGGAL | E4: TAHUN | F4: BULAN | G4: NOMINAL | H4: JENIS PENGELUARAN | I4: KETERANGAN | J4: KATEGORI | K4: ✅ | L4: CATATAN | M4: Column 12
B5: 335 | C5: NOPI | D5: 46025 | E5: =if(D5="","",text(D5,"yyyy")) -> 2026 | F5: =if(D5="","",text(D5,"mm")&" "&text(D5,"mmm")) -> 01 Jan | G5: 148000 | H5: TUNAI | I5: BELI MAP | J5: BEBAN PELAYANAN FGS | K5: TRUE
B6: 336 | C6: NOPI | D6: 46026 | E6: =if(D6="","",text(D6,"yyyy")) -> 2026 | F6: =if(D6="","",text(D6,"mm")&" "&text(D6,"mmm")) -> 01 Jan | G6: 400000 | H6: TUNAI | I6: TIA | J6: TUKAR TUNAI | K6: TRUE
B7: 337 | C7: NOPI | D7: 46026 | E7: =if(D7="","",text(D7,"yyyy")) -> 2026 | F7: =if(D7="","",text(D7,"mm")&" "&text(D7,"mmm")) -> 01 Jan | G7: 15000 | H7: TUNAI | I7: BELI ES BATU | J7: BEBAN PELAYANAN FGS | K7: TRUE
B8: 338 | C8: NOPI | D8: 46027 | E8: =if(D8="","",text(D8,"yyyy")) -> 2026 | F8: =if(D8="","",text(D8,"mm")&" "&text(D8,"mmm")) -> 01 Jan | G8: 100000 | H8: TUNAI | I8: SUCI | J8: TUKAR TUNAI | K8: TRUE
B9: 339 | C9: NOPI | D9: 46027 | E9: =if(D9="","",text(D9,"yyyy")) -> 2026 | F9: =if(D9="","",text(D9,"mm")&" "&text(D9,"mmm")) -> 01 Jan | G9: 150000 | H9: TUNAI | I9: NOPI | J9: TUKAR TUNAI | K9: TRUE
B10: 340 | C10: NOPI | D10: 46027 | E10: =if(D10="","",text(D10,"yyyy")) -> 2026 | F10: =if(D10="","",text(D10,"mm")&" "&text(D10,"mmm")) -> 01 Jan | G10: 150000 | H10: TUNAI | I10: BYR SMPAH | J10: BEBAN PELAYANAN FGS | K10: TRUE
B11: 341 | C11: NOPI | D11: 46027 | E11: =if(D11="","",text(D11,"yyyy")) -> 2026 | F11: =if(D11="","",text(D11,"mm")&" "&text(D11,"mmm")) -> 01 Jan | G11: 50000 | H11: TUNAI | I11: HENA | J11: TUKAR TUNAI | K11: TRUE
B12: 342 | C12: NOPI | D12: 46028 | E12: =if(D12="","",text(D12,"yyyy")) -> 2026 | F12: =if(D12="","",text(D12,"mm")&" "&text(D12,"mmm")) -> 01 Jan | G12: 150000 | H12: TUNAI | I12: BELI AIR BLUE, DOUBLE TIP, MAP DAN PENGHARUM AC | J12: BEBAN PELAYANAN FGS | K12: TRUE
B13: 343 | C13: NOPI | D13: 46029 | E13: =if(D13="","",text(D13,"yyyy")) -> 2026 | F13: =if(D13="","",text(D13,"mm")&" "&text(D13,"mmm")) -> 01 Jan | G13: 200000 | H13: TUNAI | I13: NOPI | J13: TUKAR TUNAI | K13: TRUE
B14: 344 | C14: NOPI | D14: 46030 | E14: =if(D14="","",text(D14,"yyyy")) -> 2026 | F14: =if(D14="","",text(D14,"mm")&" "&text(D14,"mmm")) -> 01 Jan | G14: 150000 | H14: TUNAI | I14: EDO | J14: TUKAR TUNAI | K14: TRUE
B15: 345 | C15: NOPI | D15: 46030 | E15: =if(D15="","",text(D15,"yyyy")) -> 2026 | F15: =if(D15="","",text(D15,"mm")&" "&text(D15,"mmm")) -> 01 Jan | G15: 100000 | H15: TUNAI | I15: SUCI | J15: TUKAR TUNAI | K15: TRUE
B16: 346 | C16: NOPI | D16: 46030 | E16: =if(D16="","",text(D16,"yyyy")) -> 2026 | F16: =if(D16="","",text(D16,"mm")&" "&text(D16,"mmm")) -> 01 Jan | G16: 50000 | H16: TUNAI | I16: NOPI | J16: TUKAR TUNAI | K16: TRUE
... B30: 360 | C30: SUCI | D30: 46035 | E30: =if(D30="","",text(D30,"yyyy")) -> 2026 | F30: =if(D30="","",text(D30,"mm")&" "&text(D30,"mmm")) -> 01 Jan | G30: 100000 | H30: TUNAI | I30: HENA TT | J30: TUKAR TUNAI | K30: TRUE
B31: 361 | C31: SUCI | D31: 46035 | E31: 2026 | F31: 01 Jan | G31: 200000 | H31: TUNAI | I31: TIA TT | J31: TUKAR TUNAI | K31: TRUE
B32: 362 | C32: SUCI | D32: 46036 | E32: =if(D32="","",text(D32,"yyyy")) -> 2026 | F32: =if(D32="","",text(D32,"mm")&" "&text(D32,"mmm")) -> 01 Jan | G32: 50000 | H32: TUNAI | I32: KONSUMSI RETURN TO SPORT PIPO | J32: BEBAN PELAYANAN FGS | K32: TRUE
B33: 363 | C33: NOPI | D33: 46036 | E33: =if(D33="","",text(D33,"yyyy")) -> 2026 | F33: =if(D33="","",text(D33,"mm")&" "&text(D33,"mmm")) -> 01 Jan | G33: 50000 | H33: TUNAI | I33: NOPI | J33: TUKAR TUNAI | K33: TRUE
B34: 364 | C34: NOPI | D34: 46036 | E34: =if(D34="","",text(D34,"yyyy")) -> 2026 | F34: =if(D34="","",text(D34,"mm")&" "&text(D34,"mmm")) -> 01 Jan | G34: 200000 | H34: TUNAI | I34: TIA | J34: TUKAR TUNAI | K34: TRUE
B35: 365 | C35: NOPI | D35: 46037 | E35: =if(D35="","",text(D35,"yyyy")) -> 2026 | F35: =if(D35="","",text(D35,"mm")&" "&text(D35,"mmm")) -> 01 Jan | G35: 50000 | H35: TUNAI | I35: HENA AMBIL UANG JARAK TA CE FEBE | J35: JARAK VISIT | K35: TRUE
B36: 366 | C36: NOPI | D36: 46037 | E36: =if(D36="","",text(D36,"yyyy")) -> 2026 | F36: =if(D36="","",text(D36,"mm")&" "&text(D36,"mmm")) -> 01 Jan | G36: 100000 | H36: TUNAI | I36: DESTY AMBIL JARAK KAK NOVI 2X SESI | J36: JARAK VISIT | K36: TRUE
B37: 367 | C37: NOPI | D37: 46037 | E37: =if(D37="","",text(D37,"yyyy")) -> 2026 | F37: =if(D37="","",text(D37,"mm")&" "&text(D37,"mmm")) -> 01 Jan | G37: 100000 | H37: TUNAI | I37: NOPI | J37: TUKAR TUNAI | K37: TRUE
B38: 368 | C38: NOPI | D38: 46039 | E38: =if(D38="","",text(D38,"yyyy")) -> 2026 | F38: =if(D38="","",text(D38,"mm")&" "&text(D38,"mmm")) -> 01 Jan | G38: 15000 | H38: TUNAI | I38: BELI ES BATU | J38: BEBAN PELAYANAN FGS | K38: TRUE
B39: 369 | C39: NOPI | D39: 46039 | E39: =if(D39="","",text(D39,"yyyy")) -> 2026 | F39: =if(D39="","",text(D39,"mm")&" "&text(D39,"mmm")) -> 01 Jan | G39: 100000 | H39: TUNAI | I39: SUCI | J39: TUKAR TUNAI | K39: TRUE
B40: 370 | C40: NOPI | D40: 46039 | E40: =if(D40="","",text(D40,"yyyy")) -> 2026 | F40: =if(D40="","",text(D40,"mm")&" "&text(D40,"mmm")) -> 01 Jan | G40: 300000 | H40: TUNAI | I40: EDO | J40: TUKAR TUNAI | K40: TRUE
B41: 371 | C41: NOPI | D41: 46039 | E41: =if(D41="","",text(D41,"yyyy")) -> 2026 | F41: =if(D41="","",text(D41,"mm")&" "&text(D41,"mmm")) -> 01 Jan | G41: 50000 | H41: TUNAI | I41: JARAK HENA (AN. ASNAH) | J41: BEBAN GAJI | K41: TRUE
B42: 372 | C42: SUCI | D42: 46040 | E42: =if(D42="","",text(D42,"yyyy")) -> 2026 | F42: =if(D42="","",text(D42,"mm")&" "&text(D42,"mmm")) -> 01 Jan | G42: 80000 | H42: TUNAI | I42: BELI LAMPU | J42: BEBAN PELAYANAN FGS | K42: TRUE
B43: 373 | C43: SUCI | D43: 46040 | E43: =if(D43="","",text(D43,"yyyy")) -> 2026 | F43: =if(D43="","",text(D43,"mm")&" "&text(D43,"mmm")) -> 01 Jan | G43: 50000 | H43: TUNAI | I43: KOPI PELANGI DANI | J43: BEBAN PELAYANAN FGS | K43: TRUE
... B51: 381 | C51: SUCI | D51: 46042 | E51: =if(D51="","",text(D51,"yyyy")) -> 2026 | F51: =if(D51="","",text(D51,"mm")&" "&text(D51,"mmm")) -> 01 Jan | G51: 100000 | H51: TUNAI | I51: TT NOPI | J51: TUKAR TUNAI | K51: TRUE
B52: 382 | C52: SUCI | D52: 46042 | E52: 2026 | F52: 01 Jan | G52: 50000 | H52: TUNAI | I52: TT HESTI | J52: TUKAR TUNAI | K52: TRUE
B53: 383 | C53: SUCI | D53: 46042 | E53: 2026 | F53: 01 Jan | G53: 100000 | H53: TUNAI | I53: TT HEN | J53: TUKAR TUNAI | K53: TRUE
B54: 384 | C54: SUCI | D54: 46042 | E54: =if(D54="","",text(D54,"yyyy")) -> 2026 | F54: =if(D54="","",text(D54,"mm")&" "&text(D54,"mmm")) -> 01 Jan | G54: 400000 | H54: TUNAI | I54: DESTY AMBIL JARAK KAK NOVI SISANYA | J54: TUKAR TUNAI | K54: TRUE
B55: 385 | C55: SUCI | D55: 46042 | E55: 2026 | F55: 01 Jan | G55: 86000 | H55: TUNAI | I55: PAKET BASEP | J55: TUKAR TUNAI | K55: TRUE
B56: 386 | C56: NOPI | D56: 46043 | G56: 100000 | H56: TUNAI | I56: HENA | J56: TUKAR TUNAI | K56: TRUE
B57: 387 | C57: NOPI | D57: 46043 | E57: =if(D57="","",text(D57,"yyyy")) -> 2026 | F57: =if(D57="","",text(D57,"mm")&" "&text(D57,"mmm")) -> 01 Jan | G57: 200000 | H57: TUNAI | I57: TIA | J57: TUKAR TUNAI | K57: TRUE
B58: 388 | C58: NOPI | D58: 46043 | E58: =if(D58="","",text(D58,"yyyy")) -> 2026 | F58: =if(D58="","",text(D58,"mm")&" "&text(D58,"mmm")) -> 01 Jan | G58: 400000 | H58: TUNAI | I58: BAYAR SEDOT WC GRIYA ANAK | J58: BEBAN PELAYANAN FGS | K58: TRUE
B59: 389 | C59: NOPI | D59: 46044 | E59: =if(D59="","",text(D59,"yyyy")) -> 2026 | F59: =if(D59="","",text(D59,"mm")&" "&text(D59,"mmm")) -> 01 Jan | G59: 50000 | H59: TUNAI | I59: BETULKAN LAMPU DPN ASESSMENT | J59: BEBAN PELAYANAN FGS | K59: TRUE
B60: 390 | C60: NOPI | D60: 46044 | E60: =if(D60="","",text(D60,"yyyy")) -> 2026 | F60: =if(D60="","",text(D60,"mm")&" "&text(D60,"mmm")) -> 01 Jan | G60: 100000 | H60: TUNAI | I60: NOPI | J60: TUKAR TUNAI | K60: TRUE
B61: 391 | C61: NOPI | D61: 46044 | E61: =if(D61="","",text(D61,"yyyy")) -> 2026 | F61: =if(D61="","",text(D61,"mm")&" "&text(D61,"mmm")) -> 01 Jan | G61: 50000 | H61: TUNAI | I61: HENA | J61: TUKAR TUNAI | K61: TRUE
B62: 392 | C62: NOPI | D62: 46044 | E62: =if(D62="","",text(D62,"yyyy")) -> 2026 | F62: =if(D62="","",text(D62,"mm")&" "&text(D62,"mmm")) -> 01 Jan | G62: 38000 | H62: TUNAI | I62: HENA DAN OKTA | J62: TUKAR TUNAI | K62: TRUE
...

Sheet 📝 REKAP HARIAN
B1: Rekap Harian Admin
O2: Cash Hari Ini
N3: =K6-O6 -> 0
B5: Jumlah Kwitansi Pemasukan | F5: Jumlah Layanan Masuk | J5: Jumlah Pemasukan | N5: Jumlah Pengeluaran
K6: {=XLOOKUP("TUNAI",$J$7:$J1006,$K$7:$K1006,"0")} -> 0 | O6: {=XLOOKUP("TUNAI",$N$7:$N1006,$O$7:OK1006,"0")} -> 0

Sheet 📈 ANALISIS BULANAN
B1: VALIDASI JUMLAH TRANSAKSI BULANAN
B2: Dari | C2: 46023
B3: Sampai | C3: 46053
B5: JUMLAH LAYANAN PER TANGGAL | W5: JUMLAH LAYANAN PER FISIO

Sheet 🎯 ANALISIS CLOSING
A2: TANGGAL | B2: Bulan | C2: NAMA PASIEN | D2: USIA | E2: LAYANAN TERAKHIR | F2: STATUS | G2: KATEGORI | H2: TERAPIS | I2: ADMIN | J2: KETERANGAN | M2: TERAPIS | N2: JUMLAH TA | O2: CLOSING PAKET | P2: CLOSING SESI | Q2: TIDAK CLOSING | R2: TOTAL CLOSING | U2: TERAPIS | V2: CLOSING PAKET | W2: CLOSING SESI | X2: TIDAK CLOSING | Y2: TOTAL CLOSING
A3: =IFERROR(__xludf.DUMMYFUNCTION("FILTER('⬇️ PEMASUKAN'!$D$5:$D1181,'⬇️ PEMASUKAN'!$K$5:$K1181=""K.TA - TERAPI AWAL"")"),46025.0) -> 46025 | B3: =if(A3="","", text(A3,"mm")&text(A3,"mmm")) -> 01Jan | C3: =IFERROR(__xludf.DUMMYFUNCTION("FILTER('⬇️ PEMASUKAN'!$I$5:$I1181,'⬇️ PEMASUKAN'!$K$5:$K1181=""K.TA - TERAPI AWAL"")"),"ANDIANA MARJAYANTI") -> ANDIANA MARJAYANTI | D3: {=IFNA(XLOOKUP(C3,'👥 Daftar Nama Pasien'!$B$6:$B1181,'👥 Daftar Nama Pasien'!$D$6:$D1181),"")} -> 29 | E3: {=XLOOKUP(C3,'⬇️ PEMASUKAN'!$I$5:$I1181,'⬇️ PEMASUKAN'!$K$5:$K1181,,0,-1)} -> K.ST - SESI TERAPI | F3: =IF(E3="K.TA - TERAPI AWAL","TIDAK CLOSING",E3) -> K.ST - SESI TERAPI | G3: =IF(C3="","",IF(ISNUMBER(SEARCH("*K.PT*",F3)),"CLOSING PAKET",IF(ISNUMBER(SEARCH("*K.ST*",F3)),"CLOSING SESI","TIDAK CLOSING"))) -> CLOSING SESI | H3: =IFERROR(__xludf.DUMMYFUNCTION("FILTER('⬇️ PEMASUKAN'!$H$5:$H1181,'⬇️ PEMASUKAN'!$K$5:$K1181=""K.TA - TERAPI AWAL"")"),"OKTA") -> OKTA | I3: =IFERROR(__xludf.DUMMYFUNCTION("FILTER('⬇️ PEMASUKAN'!$C$5:$C1181,'⬇️ PEMASUKAN'!$K$5:$K1181=""K.TA - TERAPI AWAL"")"),"SUCI") -> SUCI | M3: HESTI | N3: =COUNTIF($H$2:$H1181,M3) -> 28 | O3: =COUNTIFS($H$2:$H1181,M3,$G$2:$G1181,"*PAKET*") -> 11 | P3: =COUNTIFS($H$2:$H1181,M3,$G$2:$G1181,"*SESI*") -> 9 | Q3: =COUNTIFS($H$2:$H1181,M3,$G$2:$G1181,"*TIDAK*") -> 8 | R3: =SUM(O3:P3) -> 20 | U3: HESTI | V3: =IFERROR(O3/N3,0) -> 0.39285714 | W3: =IFERROR(P3/N3,0) -> 0.32142857 | X3: =IFERROR(Q3/N3,0) -> 0.28571429 | Y3: =IFERROR(R3/N3,0) -> 0.71428571
A4: =IFERROR(__xludf.DUMMYFUNCTION("""COMPUTED_VALUE"""),46025.0) -> 46025 | B4: =if(A4="","", text(A4,"mm")&text(A4,"mmm")) -> 01Jan | C4: =IFERROR(__xludf.DUMMYFUNCTION("""COMPUTED_VALUE"""),"IVONNY") -> IVONNY | D4: {=IFNA(XLOOKUP(C4,'👥 Daftar Nama Pasien'!$B$6:$B1181,'👥 Daftar Nama Pasien'!$D$6:$D1181),"")} -> 37 | E4: {=XLOOKUP(C4,'⬇️ PEMASUKAN'!$I$5:$I1181,'⬇️ PEMASUKAN'!$K$5:$K1181,,0,-1)} -> K.TA - TERAPI AWAL | F4: =IF(E4="K.TA - TERAPI AWAL","TIDAK CLOSING",E4) -> TIDAK CLOSING | G4: =IF(C4="","",IF(ISNUMBER(SEARCH("*K.PT*",F4)),"CLOSING PAKET",IF(ISNUMBER(SEARCH("*K.ST*",F4)),"CLOSING SESI","TIDAK CLOSING"))) -> TIDAK CLOSING | H4: =IFERROR(__xludf.DUMMYFUNCTION("""COMPUTED_VALUE"""),"DANI") -> DANI | I4: =IFERROR(__xludf.DUMMYFUNCTION("""COMPUTED_VALUE"""),"SUCI") -> SUCI | M4: DANRU | N4: =COUNTIF($H$2:$H1182,M4) -> 0 | O4: =COUNTIFS($H$2:$H1182,M4,$G$2:$G1182,"*PAKET*") -> 0 | P4: =COUNTIFS($H$2:$H1182,M4,$G$2:$G1182,"*SESI*") -> 0 | Q4: =COUNTIFS($H$2:$H1182,M4,$G$2:$G1182,"*TIDAK*") -> 0 | R4: =SUM(O4:P4) -> 0 | U4: DANRU | V4: =IFERROR(O4/N4,0) -> 0 | W4: =IFERROR(P4/N4,0) -> 0 | X4: =IFERROR(Q4/N4,0) -> 0 | Y4: =IFERROR(R4/N4,0) -> 0
A5: =IFERROR(__xludf.DUMMYFUNCTION("""COMPUTED_VALUE"""),46025.0) -> 46025 | B5: =if(A5="","", text(A5,"mm")&text(A5,"mmm")) -> 01Jan | C5: =IFERROR(__xludf.DUMMYFUNCTION("""COMPUTED_VALUE"""),"PUTERA ANUGRAH PRATAMA") -> PUTERA ANUGRAH PRATAMA | D5: {=IFNA(XLOOKUP(C5,'👥 Daftar Nama Pasien'!$B$6:$B1181,'👥 Daftar Nama Pasien'!$D$6:$D1181),"")} -> 25 | E5: {=XLOOKUP(C5,'⬇️ PEMASUKAN'!$I$5:$I1181,'⬇️ PEMASUKAN'!$K$5:$K1181,,0,-1)} -> K.TA - TERAPI AWAL | F5: =IF(E5="K.TA - TERAPI AWAL","TIDAK CLOSING",E5) -> TIDAK CLOSING | G5: =IF(C5="","",IF(ISNUMBER(SEARCH("*K.PT*",F5)),"CLOSING PAKET",IF(ISNUMBER(SEARCH("*K.ST*",F5)),"CLOSING SESI","TIDAK CLOSING"))) -> TIDAK CLOSING | H5: =IFERROR(__xludf.DUMMYFUNCTION("""COMPUTED_VALUE"""),"PRITY") -> PRITY | I5: =IFERROR(__xludf.DUMMYFUNCTION("""COMPUTED_VALUE"""),"NOPI") -> NOPI | M5: NADA | N5: =COUNTIF($H$2:$H1183,M5) -> 0 | O5: =COUNTIFS($H$2:$H1183,M5,$G$2:$G1183,"*PAKET*") -> 0 | P5: =COUNTIFS($H$2:$H1183,M5,$G$2:$G1183,"*SESI*") -> 0 | Q5: =COUNTIFS($H$2:$H1183,M5,$G$2:$G1183,"*TIDAK*") -> 0 | R5: =SUM(O5:P5) -> 0 | U5: NADA | V5: =IFERROR(O5/N5,0) -> 0 | W5: =IFERROR(P5/N5,0) -> 0 | X5: =IFERROR(Q5/N5,0) -> 0 | Y5: =IFERROR(R5/N5,0) -> 0
A6: =IFERROR(__xludf.DUMMYFUNCTION("""COMPUTED_VALUE"""),46025.0) -> 46025 | B6: =if(A6="","", text(A6,"mm")&text(A6,"mmm")) -> 01Jan | C6: =IFERROR(__xludf.DUMMYFUNCTION("""COMPUTED_VALUE"""),"SUGIH WIRAMANTRI") -> SUGIH WIRAMANTRI | D6: {=IFNA(XLOOKUP(C6,'👥 Daftar Nama Pasien'!$B$6:$B1181,'👥 Daftar Nama Pasien'!$D$6:$D1181),"")} | E6: {=XLOOKUP(C6,'⬇️ PEMASUKAN'!$I$5:$I1181,'⬇️ PEMASUKAN'!$K$5:$K1181,,0,-1)} -> K.ST - SESI TERAPI | F6: =IF(E6="K.TA - TERAPI AWAL","TIDAK CLOSING",E6) -> K.ST - SESI TERAPI | G6: =IF(C6="","",IF(ISNUMBER(SEARCH("*K.PT*",F6)),"CLOSING PAKET",IF(ISNUMBER(SEARCH("*K.ST*",F6)),"CLOSING SESI","TIDAK CLOSING"))) -> CLOSING SESI | H6: =IFERROR(__xludf.DUMMYFUNCTION("""COMPUTED_VALUE"""),"DESTY") -> DESTY | I6: =IFERROR(__xludf.DUMMYFUNCTION("""COMPUTED_VALUE"""),"NOPI") -> NOPI | M6: DESTY | N6: =COUNTIF($H$2:$H1184,M6) -> 37 | O6: =COUNTIFS($H$2:$H1184,M6,$G$2:$G1184,"*PAKET*") -> 9 | P6: =COUNTIFS($H$2:$H1184,M6,$G$2:$G1184,"*SESI*") -> 11 | Q6: =COUNTIFS($H$2:$H1184,M6,$G$2:$G1184,"*TIDAK*") -> 17 | R6: =SUM(O6:P6) -> 20 | U6: DESTY | V6: =IFERROR(O6/N6,0) -> 0.24324324 | W6: =IFERROR(P6/N6,0) -> 0.2972973 | X6: =IFERROR(Q6/N6,0) -> 0.45945946 | Y6: =IFERROR(R6/N6,0) -> 0.54054054
A7: =IFERROR(__xludf.DUMMYFUNCTION("""COMPUTED_VALUE"""),46025.0) -> 46025 | B7: =if(A7="","", text(A7,"mm")&text(A7,"mmm")) -> 01Jan | C7: =IFERROR(__xludf.DUMMYFUNCTION("""COMPUTED_VALUE"""),"K. E. ANANTA UTAMI") -> K. E. ANANTA UTAMI | D7: {=IFNA(XLOOKUP(C7,'👥 Daftar Nama Pasien'!$B$6:$B1181,'👥 Daftar Nama Pasien'!$D$6:$D1181),"")} -> 56 | E7: {=XLOOKUP(C7,'⬇️ PEMASUKAN'!$I$5:$I1181,'⬇️ PEMASUKAN'!$K$5:$K1181,,0,-1)} -> K.PT - PAKET SILVER | F7: =IF(E7="K.TA - TERAPI AWAL","TIDAK CLOSING",E7) -> K.PT - PAKET SILVER | G7: =IF(C7="","",IF(ISNUMBER(SEARCH("*K.PT*",F7)),"CLOSING PAKET",IF(ISNUMBER(SEARCH("*K.ST*",F7)),"CLOSING SESI","TIDAK CLOSING"))) -> CLOSING PAKET | H7: =IFERROR(__xludf.DUMMYFUNCTION("""COMPUTED_VALUE"""),"DESTY") -> DESTY | I7: =IFERROR(__xludf.DUMMYFUNCTION("""COMPUTED_VALUE"""),"NOPI") -> NOPI | M7: PRITY | N7: =COUNTIF($H$2:$H1185,M7) -> 29 | O7: =COUNTIFS($H$2:$H1185,M7,$G$2:$G1185,"*PAKET*") -> 7 | P7: =COUNTIFS($H$2:$H1185,M7,$G$2:$G1185,"*SESI*") -> 10 | Q7: =COUNTIFS($H$2:$H1185,M7,$G$2:$G1185,"*TIDAK*") -> 12 | R7: =SUM(O7:P7) -> 17 | U7: PRITY | V7: =IFERROR(O7/N7,0) -> 0.24137931 | W7: =IFERROR(P7/N7,0) -> 0.34482759 | X7: =IFERROR(Q7/N7,0) -> 0.4137931 | Y7: =IFERROR(R7/N7,0) -> 0.5862069
A8: =IFERROR(__xludf.DUMMYFUNCTION("""COMPUTED_VALUE"""),46025.0) -> 46025 | B8: =if(A8="","", text(A8,"mm")&text(A8,"mmm")) -> 01Jan | C8: =IFERROR(__xludf.DUMMYFUNCTION("""COMPUTED_VALUE"""),"KOLENIUS KOLAI") -> KOLENIUS KOLAI | D8: {=IFNA(XLOOKUP(C8,'👥 Daftar Nama Pasien'!$B$6:$B1181,'👥 Daftar Nama Pasien'!$D$6:$D1181),"")} -> 64 | E8: {=XLOOKUP(C8,'⬇️ PEMASUKAN'!$I$5:$I1181,'⬇️ PEMASUKAN'!$K$5:$K1181,,0,-1)} -> K.ST - SESI TERAPI | F8: =IF(E8="K.TA - TERAPI AWAL","TIDAK CLOSING",E8) -> K.ST - SESI TERAPI | G8: =IF(C8="","",IF(ISNUMBER(SEARCH("*K.PT*",F8)),"CLOSING PAKET",IF(ISNUMBER(SEARCH("*K.ST*",F8)),"CLOSING SESI","TIDAK CLOSING"))) -> CLOSING SESI | H8: =IFERROR(__xludf.DUMMYFUNCTION("""COMPUTED_VALUE"""),"DESTY") -> DESTY | I8: =IFERROR(__xludf.DUMMYFUNCTION("""COMPUTED_VALUE"""),"NOPI") -> NOPI | M8: WAHYU | N8: =COUNTIF($H$2:$H1186,M8) -> 32 | O8: =COUNTIFS($H$2:$H1186,M8,$G$2:$G1186,"*PAKET*") -> 7 | P8: =COUNTIFS($H$2:$H1186,M8,$G$2:$G1186,"*SESI*") -> 11 | Q8: =COUNTIFS($H$2:$H1186,M8,$G$2:$G1186,"*TIDAK*") -> 14 | R8: =SUM(O8:P8) -> 18 | U8: WAHYU | V8: =IFERROR(O8/N8,0) -> 0.21875 | W8: =IFERROR(P8/N8,0) -> 0.34375 | X8: =IFERROR(Q8/N8,0) -> 0.4375 | Y8: =IFERROR(R8/N8,0) -> 0.5625
A9: =IFERROR(__xludf.DUMMYFUNCTION("""COMPUTED_VALUE"""),46025.0) -> 46025 | B9: =if(A9="","", text(A9,"mm")&text(A9,"mmm")) -> 01Jan | C9: =IFERROR(__xludf.DUMMYFUNCTION("""COMPUTED_VALUE"""),"EMMA") -> EMMA | D9: {=IFNA(XLOOKUP(C9,'👥 Daftar Nama Pasien'!$B$6:$B1181,'👥 Daftar Nama Pasien'!$D$6:$D1181),"")} -> 60 | E9: {=XLOOKUP(C9,'⬇️ PEMASUKAN'!$I$5:$I1181,'⬇️ PEMASUKAN'!$K$5:$K1181,,0,-1)} -> K.ST - SESI TERAPI | F9: =IF(E9="K.TA - TERAPI AWAL","TIDAK CLOSING",E9) -> K.ST - SESI TERAPI | G9: =IF(C9="","",IF(ISNUMBER(SEARCH("*K.PT*",F9)),"CLOSING PAKET",IF(ISNUMBER(SEARCH("*K.ST*",F9)),"CLOSING SESI","TIDAK CLOSING"))) -> CLOSING SESI | H9: =IFERROR(__xludf.DUMMYFUNCTION("""COMPUTED_VALUE"""),"PRITY") -> PRITY | I9: =IFERROR(__xludf.DUMMYFUNCTION("""COMPUTED_VALUE"""),"NOPI") -> NOPI | M9: ORY | N9: =COUNTIF($H$2:$H1187,M9) -> 45 | O9: =COUNTIFS($H$2:$H1187,M9,$G$2:$G1187,"*PAKET*") -> 11 | P9: =COUNTIFS($H$2:$H1187,M9,$G$2:$G1187,"*SESI*") -> 7 | Q9: =COUNTIFS($H$2:$H1187,M9,$G$2:$G1187,"*TIDAK*") -> 27 | R9: =SUM(O9:P9) -> 18 | U9: ORY | V9: =IFERROR(O9/N9,0) -> 0.24444444 | W9: =IFERROR(P9/N9,0) -> 0.15555556 | X9: =IFERROR(Q9/N9,0) -> 0.6 | Y9: =IFERROR(R9/N9,0) -> 0.4
A10: =IFERROR(__xludf.DUMMYFUNCTION("""COMPUTED_VALUE"""),46025.0) -> 46025 | B10: =if(A10="","", text(A10,"mm")&text(A10,"mmm")) -> 01Jan | C10: =IFERROR(__xludf.DUMMYFUNCTION("""COMPUTED_VALUE"""),"YA MUHAMMAD IKHSANDI") -> YA MUHAMMAD IKHSANDI | D10: {=IFNA(XLOOKUP(C10,'👥 Daftar Nama Pasien'!$B$6:$B1181,'👥 Daftar Nama Pasien'!$D$6:$D1181),"")} -> 46 | E10: {=XLOOKUP(C10,'⬇️ PEMASUKAN'!$I$5:$I1181,'⬇️ PEMASUKAN'!$K$5:$K1181,,0,-1)} -> K.TA - TERAPI AWAL | F10: =IF(E10="K.TA - TERAPI AWAL","TIDAK CLOSING",E10) -> TIDAK CLOSING | G10: =IF(C10="","",IF(ISNUMBER(SEARCH("*K.PT*",F10)),"CLOSING PAKET",IF(ISNUMBER(SEARCH("*K.ST*",F10)),"CLOSING SESI","TIDAK CLOSING"))) -> TIDAK CLOSING | H10: =IFERROR(__xludf.DUMMYFUNCTION("""COMPUTED_VALUE"""),"DESTY") -> DESTY | I10: =IFERROR(__xludf.DUMMYFUNCTION("""COMPUTED_VALUE"""),"NOPI") -> NOPI | M10: HENA | N10: =COUNTIF($H$2:$H1188,M10) -> 27 | O10: =COUNTIFS($H$2:$H1188,M10,$G$2:$G1188,"*PAKET*") -> 6 | P10: =COUNTIFS($H$2:$H1188,M10,$G$2:$G1188,"*SESI*") -> 11 | Q10: =COUNTIFS($H$2:$H1188,M10,$G$2:$G1188,"*TIDAK*") -> 10 | R10: =SUM(O10:P10) -> 17 | U10: HENA | V10: =IFERROR(O10/N10,0) -> 0.22222222 | W10: =IFERROR(P10/N10,0) -> 0.40740741 | X10: =IFERROR(Q10/N10,0) -> 0.37037037 | Y10: =IFERROR(R10/N10,0) -> 0.62962963
A11: =IFERROR(__xludf.DUMMYFUNCTION("""COMPUTED_VALUE"""),46025.0) -> 46025 | B11: =if(A11="","", text(A11,"mm")&text(A11,"mmm")) -> 01Jan | C11: =IFERROR(__xludf.DUMMYFUNCTION("""COMPUTED_VALUE"""),"TAUFIK") -> TAUFIK | D11: {=IFNA(XLOOKUP(C11,'👥 Daftar Nama Pasien'!$B$6:$B1181,'👥 Daftar Nama Pasien'!$D$6:$D1181),"")} -> 30 | E11: {=XLOOKUP(C11,'⬇️ PEMASUKAN'!$I$5:$I1181,'⬇️ PEMASUKAN'!$K$5:$K1181,,0,-1)} -> K.ST - SESI TERAPI NEW | F11: =IF(E11="K.TA - TERAPI AWAL","TIDAK CLOSING",E11) -> K.ST - SESI TERAPI NEW | G11: =IF(C11="","",IF(ISNUMBER(SEARCH("*K.PT*",F11)),"CLOSING PAKET",IF(ISNUMBER(SEARCH("*K.ST*",F11)),"CLOSING SESI","TIDAK CLOSING"))) -> CLOSING SESI | H11: =IFERROR(__xludf.DUMMYFUNCTION("""COMPUTED_VALUE"""),"AUL") -> AUL | I11: =IFERROR(__xludf.DUMMYFUNCTION("""COMPUTED_VALUE"""),"NOPI") -> NOPI | M11: OKTA | N11: =COUNTIF($H$2:$H1189,M11) -> 42 | O11: =COUNTIFS($H$2:$H1189,M11,$G$2:$G1189,"*PAKET*") -> 12 | P11: =COUNTIFS($H$2:$H1189,M11,$G$2:$G1189,"*SESI*") -> 9 | Q11: =COUNTIFS($H$2:$H1189,M11,$G$2:$G1189,"*TIDAK*") -> 21 | R11: =SUM(O11:P11) -> 21 | U11: OKTA | V11: =IFERROR(O11/N11,0) -> 0.28571429 | W11: =IFERROR(P11/N11,0) -> 0.21428571 | X11: =IFERROR(Q11/N11,0) -> 0.5 | Y11: =IFERROR(R11/N11,0) -> 0.5
