Workbook
Name RentangBernama1: #REF!

Sheet 🙎‍♂️ Pasien
A1: . | B1: Timestamp | D1: Tanggal | E1: BULAN | F1: TAHUN | G1: Nama Pasien | H1: No. RM | I1: Usia | J1: Kategori Usia | K1: Tanggal Lahir | L1: Jenis Kelamin | M1: Alamat | N1: Kelurahan/Desa | O1: Kecamatan | P1: Kabupaten/Kota | Q1: Provinsi | R1: Agama | S1: Pekerjaan | T1: Keluhan | U1: Hobi/Aktivitas Sehari-hari | V1: No. HP/WhatsApp
A2: =IFERROR(__xludf.DUMMYFUNCTION("IMPORTRANGE(""https://docs.google.com/spreadsheets/d/1q5irXBuyRkQM_goHlRjPTSwHk1on6thK70p8lljqLrs/edit?gid=1342096879#gid=1342096879"",""🙎‍♂️ Pasien!A2:W"")"),"") | B2: =IFERROR(__xludf.DUMMYFUNCTION("""COMPUTED_VALUE"""),"Timestamp") -> Timestamp | D2: =IFERROR(__xludf.DUMMYFUNCTION("""COMPUTED_VALUE"""),"Tanggal") -> Tanggal | E2: =IFERROR(__xludf.DUMMYFUNCTION("""COMPUTED_VALUE"""),"Bulan") -> Bulan | F2: =IFERROR(__xludf.DUMMYFUNCTION("""COMPUTED_VALUE"""),"Tahun") -> Tahun | G2: =IFERROR(__xludf.DUMMYFUNCTION("""COMPUTED_VALUE"""),"Nama Pasien") -> Nama Pasien | H2: =IFERROR(__xludf.DUMMYFUNCTION("""COMPUTED_VALUE"""),"No. RM") -> No. RM | I2: =IFERROR(__xludf.DUMMYFUNCTION("""COMPUTED_VALUE"""),"Usia") -> Usia | J2: =IFERROR(__xludf.DUMMYFUNCTION("""COMPUTED_VALUE"""),"Kategori Usia") -> Kategori Usia | K2: =IFERROR(__xludf.DUMMYFUNCTION("""COMPUTED_VALUE"""),"Tanggal Lahir") -> Tanggal Lahir | L2: =IFERROR(__xludf.DUMMYFUNCTION("""COMPUTED_VALUE"""),"Jenis Kelamin") -> Jenis Kelamin | M2: =IFERROR(__xludf.DUMMYFUNCTION("""COMPUTED_VALUE"""),"Alamat") -> Alamat | N2: =IFERROR(__xludf.DUMMYFUNCTION("""COMPUTED_VALUE"""),"Kel./Desa") -> Kel./Desa | O2: =IFERROR(__xludf.DUMMYFUNCTION("""COMPUTED_VALUE"""),"Kecamatan") -> Kecamatan | P2: =IFERROR(__xludf.DUMMYFUNCTION("""COMPUTED_VALUE"""),"Kab./Kota") -> Kab./Kota | Q2: =IFERROR(__xludf.DUMMYFUNCTION("""COMPUTED_VALUE"""),"Provinsi") -> Provinsi | R2: =IFERROR(__xludf.DUMMYFUNCTION("""COMPUTED_VALUE"""),"Agama") -> Agama | S2: =IFERROR(__xludf.DUMMYFUNCTION("""COMPUTED_VALUE"""),"Pekerjaan") -> Pekerjaan | T2: =IFERROR(__xludf.DUMMYFUNCTION("""COMPUTED_VALUE"""),"Keluhan") -> Keluhan | U2: =IFERROR(__xludf.DUMMYFUNCTION("""COMPUTED_VALUE"""),"Hobi/Aktivitas Sehari-hari") -> Hobi/Aktivitas Sehari-hari | V2: =IFERROR(__xludf.DUMMYFUNCTION("""COMPUTED_VALUE"""),"No. WA") -> No. WA | W2: =IFERROR(__xludf.DUMMYFUNCTION("""COMPUTED_VALUE"""),"Column 1") -> Column 1
F3: =IFERROR(__xludf.DUMMYFUNCTION("""COMPUTED_VALUE"""),"1899") -> 1899 | G3: =IFERROR(__xludf.DUMMYFUNCTION("""COMPUTED_VALUE"""),"OFF") -> OFF | H3: =IFERROR(__xludf.DUMMYFUNCTION("""COMPUTED_VALUE"""),"OFF") -> OFF
F4: =IFERROR(__xludf.DUMMYFUNCTION("""COMPUTED_VALUE"""),"1899") -> 1899 | G4: =IFERROR(__xludf.DUMMYFUNCTION("""COMPUTED_VALUE"""),"LIBUR") -> LIBUR | H4: =IFERROR(__xludf.DUMMYFUNCTION("""COMPUTED_VALUE"""),"LIBUR") -> LIBUR
F5: =IFERROR(__xludf.DUMMYFUNCTION("""COMPUTED_VALUE"""),"1899") -> 1899 | G5: =IFERROR(__xludf.DUMMYFUNCTION("""COMPUTED_VALUE"""),"TA") -> TA
F6: =IFERROR(__xludf.DUMMYFUNCTION("""COMPUTED_VALUE"""),"1899") -> 1899 | G6: =IFERROR(__xludf.DUMMYFUNCTION("""COMPUTED_VALUE"""),"MANAJEMEN") -> MANAJEMEN | H6: =IFERROR(__xludf.DUMMYFUNCTION("""COMPUTED_VALUE"""),"MANAJEMEN") -> MANAJEMEN
F7: =IFERROR(__xludf.DUMMYFUNCTION("""COMPUTED_VALUE"""),"1899") -> 1899 | G7: =IFERROR(__xludf.DUMMYFUNCTION("""COMPUTED_VALUE"""),"KHUSUS") -> KHUSUS | H7: =IFERROR(__xludf.DUMMYFUNCTION("""COMPUTED_VALUE"""),"KHUSUS") -> KHUSUS
F8: =IFERROR(__xludf.DUMMYFUNCTION("""COMPUTED_VALUE"""),"1899") -> 1899 | G8: =IFERROR(__xludf.DUMMYFUNCTION("""COMPUTED_VALUE"""),"PIPO") -> PIPO | H8: =IFERROR(__xludf.DUMMYFUNCTION("""COMPUTED_VALUE"""),"PANGSUMA FC") -> PANGSUMA FC
E9: =IFERROR(__xludf.DUMMYFUNCTION("""COMPUTED_VALUE"""),"") | F9: =IFERROR(__xludf.DUMMYFUNCTION("""COMPUTED_VALUE"""),"1899") -> 1899 | H9: =IFERROR(__xludf.DUMMYFUNCTION("""COMPUTED_VALUE"""),"") | I9: =IFERROR(__xludf.DUMMYFUNCTION("""COMPUTED_VALUE"""),"") | J9: =IFERROR(__xludf.DUMMYFUNCTION("""COMPUTED_VALUE"""),"")
B10: =IFERROR(__xludf.DUMMYFUNCTION("""COMPUTED_VALUE"""),45006.90524418982) -> 45006.905 | D10: =IFERROR(__xludf.DUMMYFUNCTION("""COMPUTED_VALUE"""),44856.83403935185) -> 44856.834 | E10: =IFERROR(__xludf.DUMMYFUNCTION("""COMPUTED_VALUE"""),"10Okt") -> 10Okt | F10: =IFERROR(__xludf.DUMMYFUNCTION("""COMPUTED_VALUE"""),"2022") -> 2022 | G10: =IFERROR(__xludf.DUMMYFUNCTION("""COMPUTED_VALUE"""),"ZHOFRAN FARRAS ATAYA") -> ZHOFRAN FARRAS ATAYA | H10: =IFERROR(__xludf.DUMMYFUNCTION("""COMPUTED_VALUE"""),"Z0922105765") -> Z0922105765 | I10: =IFERROR(__xludf.DUMMYFUNCTION("""COMPUTED_VALUE"""),17.0) -> 17 | J10: =IFERROR(__xludf.DUMMYFUNCTION("""COMPUTED_VALUE"""),"< 18 tahun") -> < 18 tahun | K10: =IFERROR(__xludf.DUMMYFUNCTION("""COMPUTED_VALUE"""),39833.0) -> 39833 | L10: =IFERROR(__xludf.DUMMYFUNCTION("""COMPUTED_VALUE"""),"LAKI-LAKI") -> LAKI-LAKI | M10: =IFERROR(__xludf.DUMMYFUNCTION("""COMPUTED_VALUE"""),"JL. PARIT H. MUKSIN KOMP. PERMATA HIJAU") -> JL. PARIT H. MUKSIN KOMP. PERMATA HIJAU | N10: =IFERROR(__xludf.DUMMYFUNCTION("""COMPUTED_VALUE"""),"") | R10: =IFERROR(__xludf.DUMMYFUNCTION("""COMPUTED_VALUE"""),"ISLAM") -> ISLAM | S10: =IFERROR(__xludf.DUMMYFUNCTION("""COMPUTED_VALUE"""),"PELAJAR/MAHASISWA") -> PELAJAR/MAHASISWA | T10: =IFERROR(__xludf.DUMMYFUNCTION("""COMPUTED_VALUE"""),"SIKU - LENGAN BAWAH") -> SIKU - LENGAN BAWAH | U10: =IFERROR(__xludf.DUMMYFUNCTION("""COMPUTED_VALUE"""),"") | V10: =IFERROR(__xludf.DUMMYFUNCTION("""COMPUTED_VALUE"""),"082149675765") -> 082149675765
B11: =IFERROR(__xludf.DUMMYFUNCTION("""COMPUTED_VALUE"""),45006.90415178241) -> 45006.904 | D11: =IFERROR(__xludf.DUMMYFUNCTION("""COMPUTED_VALUE"""),44857.73925293981) -> 44857.739 | E11: =IFERROR(__xludf.DUMMYFUNCTION("""COMPUTED_VALUE"""),"10Okt") -> 10Okt | F11: =IFERROR(__xludf.DUMMYFUNCTION("""COMPUTED_VALUE"""),"2022") -> 2022 | G11: =IFERROR(__xludf.DUMMYFUNCTION("""COMPUTED_VALUE"""),"DIAH SUCI RINI") -> DIAH SUCI RINI | H11: =IFERROR(__xludf.DUMMYFUNCTION("""COMPUTED_VALUE"""),"D5722102445") -> D5722102445 | I11: =IFERROR(__xludf.DUMMYFUNCTION("""COMPUTED_VALUE"""),68.0) -> 68 | J11: =IFERROR(__xludf.DUMMYFUNCTION("""COMPUTED_VALUE"""),"> 44 tahun") -> > 44 tahun | K11: =IFERROR(__xludf.DUMMYFUNCTION("""COMPUTED_VALUE"""),21049.0) -> 21049 | L11: =IFERROR(__xludf.DUMMYFUNCTION("""COMPUTED_VALUE"""),"PEREMPUAN") -> PEREMPUAN | M11: =IFERROR(__xludf.DUMMYFUNCTION("""COMPUTED_VALUE"""),"JL. BERSAMA GG. BERSAMA") -> JL. BERSAMA GG. BERSAMA | R11: =IFERROR(__xludf.DUMMYFUNCTION("""COMPUTED_VALUE"""),"ISLAM") -> ISLAM | S11: =IFERROR(__xludf.DUMMYFUNCTION("""COMPUTED_VALUE"""),"PENSIUN") -> PENSIUN | T11: =IFERROR(__xludf.DUMMYFUNCTION("""COMPUTED_VALUE"""),"TULANG BELAKANG") -> TULANG BELAKANG | U11: =IFERROR(__xludf.DUMMYFUNCTION("""COMPUTED_VALUE"""),"") | V11: =IFERROR(__xludf.DUMMYFUNCTION("""COMPUTED_VALUE"""),"082158402445") -> 082158402445
B12: =IFERROR(__xludf.DUMMYFUNCTION("""COMPUTED_VALUE"""),45006.96855240741) -> 45006.969 | D12: =IFERROR(__xludf.DUMMYFUNCTION("""COMPUTED_VALUE"""),44921.725439814814) -> 44921.725 | E12: =IFERROR(__xludf.DUMMYFUNCTION("""COMPUTED_VALUE"""),"12Des") -> 12Des | F12: =IFERROR(__xludf.DUMMYFUNCTION("""COMPUTED_VALUE"""),"2022") -> 2022 | G12: =IFERROR(__xludf.DUMMYFUNCTION("""COMPUTED_VALUE"""),"MEIZARANI HELJA") -> MEIZARANI HELJA | H12: =IFERROR(__xludf.DUMMYFUNCTION("""COMPUTED_VALUE"""),"M9322128010") -> M9322128010 | I12: =IFERROR(__xludf.DUMMYFUNCTION("""COMPUTED_VALUE"""),33.0) -> 33 | J12: =IFERROR(__xludf.DUMMYFUNCTION("""COMPUTED_VALUE"""),"25-34 tahun") -> 25-34 tahun | K12: =IFERROR(__xludf.DUMMYFUNCTION("""COMPUTED_VALUE"""),34100.0) -> 34100 | L12: =IFERROR(__xludf.DUMMYFUNCTION("""COMPUTED_VALUE"""),"PEREMPUAN") -> PEREMPUAN | M12: =IFERROR(__xludf.DUMMYFUNCTION("""COMPUTED_VALUE"""),"JL. KOMYOS SOEDARSO GG, SAMBAS") -> JL. KOMYOS SOEDARSO GG, SAMBAS | R12: =IFERROR(__xludf.DUMMYFUNCTION("""COMPUTED_VALUE"""),"ISLAM") -> ISLAM | S12: =IFERROR(__xludf.DUMMYFUNCTION("""COMPUTED_VALUE"""),"BPD") -> BPD | T12: =IFERROR(__xludf.DUMMYFUNCTION("""COMPUTED_VALUE"""),"KEPALA - LEHER") -> KEPALA - LEHER | U12: =IFERROR(__xludf.DUMMYFUNCTION("""COMPUTED_VALUE"""),"") | V12: =IFERROR(__xludf.DUMMYFUNCTION("""COMPUTED_VALUE"""),"085245008010") -> 085245008010
B13: =IFERROR(__xludf.DUMMYFUNCTION("""COMPUTED_VALUE"""),45006.910388958335) -> 45006.91 | D13: =IFERROR(__xludf.DUMMYFUNCTION("""COMPUTED_VALUE"""),44928.0) -> 44928 | E13: =IFERROR(__xludf.DUMMYFUNCTION("""COMPUTED_VALUE"""),"01Jan") -> 01Jan | F13: =IFERROR(__xludf.DUMMYFUNCTION("""COMPUTED_VALUE"""),"2023") -> 2023 | G13: =IFERROR(__xludf.DUMMYFUNCTION("""COMPUTED_VALUE"""),"HUWAIDAH THIFAL NAURAH") -> HUWAIDAH THIFAL NAURAH | H13: =IFERROR(__xludf.DUMMYFUNCTION("""COMPUTED_VALUE"""),"H0123016085") -> H0123016085 | I13: =IFERROR(__xludf.DUMMYFUNCTION("""COMPUTED_VALUE"""),25.0) -> 25 | J13: =IFERROR(__xludf.DUMMYFUNCTION("""COMPUTED_VALUE"""),"25-34 tahun") -> 25-34 tahun | K13: =IFERROR(__xludf.DUMMYFUNCTION("""COMPUTED_VALUE"""),37038.0) -> 37038 | L13: =IFERROR(__xludf.DUMMYFUNCTION("""COMPUTED_VALUE"""),"PEREMPUAN") -> PEREMPUAN | M13: =IFERROR(__xludf.DUMMYFUNCTION("""COMPUTED_VALUE"""),"JL. KARET KOMP SEJAHTERA") -> JL. KARET KOMP SEJAHTERA | R13: =IFERROR(__xludf.DUMMYFUNCTION("""COMPUTED_VALUE"""),"ISLAM") -> ISLAM | S13: =IFERROR(__xludf.DUMMYFUNCTION("""COMPUTED_VALUE"""),"DOSEN/GURU") -> DOSEN/GURU | T13: =IFERROR(__xludf.DUMMYFUNCTION("""COMPUTED_VALUE"""),"PINGGANG") -> PINGGANG | U13: =IFERROR(__xludf.DUMMYFUNCTION("""COMPUTED_VALUE"""),"") | V13: =IFERROR(__xludf.DUMMYFUNCTION("""COMPUTED_VALUE"""),"085349896085") -> 085349896085
B14: =IFERROR(__xludf.DUMMYFUNCTION("""COMPUTED_VALUE"""),44941.5940162037) -> 44941.594 | D14: =IFERROR(__xludf.DUMMYFUNCTION("""COMPUTED_VALUE"""),44928.0) -> 44928 | E14: =IFERROR(__xludf.DUMMYFUNCTION("""COMPUTED_VALUE"""),"01Jan") -> 01Jan | F14: =IFERROR(__xludf.DUMMYFUNCTION("""COMPUTED_VALUE"""),"2023") -> 2023 | G14: =IFERROR(__xludf.DUMMYFUNCTION("""COMPUTED_VALUE"""),"SUFIRNA") -> SUFIRNA | H14: =IFERROR(__xludf.DUMMYFUNCTION("""COMPUTED_VALUE"""),"S7823018882") -> S7823018882 | I14: =IFERROR(__xludf.DUMMYFUNCTION("""COMPUTED_VALUE"""),48.0) -> 48 | J14: =IFERROR(__xludf.DUMMYFUNCTION("""COMPUTED_VALUE"""),"> 44 tahun") -> > 44 tahun | K14: =IFERROR(__xludf.DUMMYFUNCTION("""COMPUTED_VALUE"""),28629.0) -> 28629 | L14: =IFERROR(__xludf.DUMMYFUNCTION("""COMPUTED_VALUE"""),"PEREMPUAN") -> PEREMPUAN | M14: =IFERROR(__xludf.DUMMYFUNCTION("""COMPUTED_VALUE"""),"JL HIJAS NO 193") -> JL HIJAS NO 193 | R14: =IFERROR(__xludf.DUMMYFUNCTION("""COMPUTED_VALUE"""),"BUDDHA") -> BUDDHA | S14: =IFERROR(__xludf.DUMMYFUNCTION("""COMPUTED_VALUE"""),"SWASTA") -> SWASTA | T14: =IFERROR(__xludf.DUMMYFUNCTION("""COMPUTED_VALUE"""),"JARI TANGAN") -> JARI TANGAN | U14: =IFERROR(__xludf.DUMMYFUNCTION("""COMPUTED_VALUE"""),"-") -> - | V14: =IFERROR(__xludf.DUMMYFUNCTION("""COMPUTED_VALUE"""),"082148458882") -> 082148458882
B15: =IFERROR(__xludf.DUMMYFUNCTION("""COMPUTED_VALUE"""),44951.8272337963) -> 44951.827 | D15: =IFERROR(__xludf.DUMMYFUNCTION("""COMPUTED_VALUE"""),44929.0) -> 44929 | E15: =IFERROR(__xludf.DUMMYFUNCTION("""COMPUTED_VALUE"""),"01Jan") -> 01Jan | F15: =IFERROR(__xludf.DUMMYFUNCTION("""COMPUTED_VALUE"""),"2023") -> 2023 | G15: =IFERROR(__xludf.DUMMYFUNCTION("""COMPUTED_VALUE"""),"ALVIN DIYANDRA") -> ALVIN DIYANDRA | H15: =IFERROR(__xludf.DUMMYFUNCTION("""COMPUTED_VALUE"""),"A9723017817") -> A9723017817 | I15: =IFERROR(__xludf.DUMMYFUNCTION("""COMPUTED_VALUE"""),29.0) -> 29 | J15: =IFERROR(__xludf.DUMMYFUNCTION("""COMPUTED_VALUE"""),"25-34 tahun") -> 25-34 tahun | K15: =IFERROR(__xludf.DUMMYFUNCTION("""COMPUTED_VALUE"""),35517.0) -> 35517 | L15: =IFERROR(__xludf.DUMMYFUNCTION("""COMPUTED_VALUE"""),"LAKI-LAKI") -> LAKI-LAKI | M15: =IFERROR(__xludf.DUMMYFUNCTION("""COMPUTED_VALUE"""),"JL PARIS 2 KOMP BALIMAS 2 NO B8") -> JL PARIS 2 KOMP BALIMAS 2 NO B8 | R15: =IFERROR(__xludf.DUMMYFUNCTION("""COMPUTED_VALUE"""),"ISLAM") -> ISLAM | S15: =IFERROR(__xludf.DUMMYFUNCTION("""COMPUTED_VALUE"""),"SWASTA") -> SWASTA | T15: =IFERROR(__xludf.DUMMYFUNCTION("""COMPUTED_VALUE"""),"BAHU") -> BAHU | U15: =IFERROR(__xludf.DUMMYFUNCTION("""COMPUTED_VALUE"""),"-") -> - | V15: =IFERROR(__xludf.DUMMYFUNCTION("""COMPUTED_VALUE"""),"08988277817") -> 08988277817
B16: =IFERROR(__xludf.DUMMYFUNCTION("""COMPUTED_VALUE"""),44971.58675925926) -> 44971.587 | D16: =IFERROR(__xludf.DUMMYFUNCTION("""COMPUTED_VALUE"""),44929.0) -> 44929 | E16: =IFERROR(__xludf.DUMMYFUNCTION("""COMPUTED_VALUE"""),"01Jan") -> 01Jan | F16: =IFERROR(__xludf.DUMMYFUNCTION("""COMPUTED_VALUE"""),"2023") -> 2023 | G16: =IFERROR(__xludf.DUMMYFUNCTION("""COMPUTED_VALUE"""),"ANDI ICHWANUL AZWAR") -> ANDI ICHWANUL AZWAR | H16: =IFERROR(__xludf.DUMMYFUNCTION("""COMPUTED_VALUE"""),"A8823011011") -> A8823011011 | I16: =IFERROR(__xludf.DUMMYFUNCTION("""COMPUTED_VALUE"""),37.0) -> 37 | J16: =IFERROR(__xludf.DUMMYFUNCTION("""COMPUTED_VALUE"""),"35-44 tahun") -> 35-44 tahun | K16: =IFERROR(__xludf.DUMMYFUNCTION("""COMPUTED_VALUE"""),32379.0) -> 32379 | L16: =IFERROR(__xludf.DUMMYFUNCTION("""COMPUTED_VALUE"""),"LAKI-LAKI") -> LAKI-LAKI | M16: =IFERROR(__xludf.DUMMYFUNCTION("""COMPUTED_VALUE"""),"JL. H. R. A. RAHMAN GG. GUNUNG SAHARI") -> JL. H. R. A. RAHMAN GG. GUNUNG SAHARI | R16: =IFERROR(__xludf.DUMMYFUNCTION("""COMPUTED_VALUE"""),"ISLAM") -> ISLAM | S16: =IFERROR(__xludf.DUMMYFUNCTION("""COMPUTED_VALUE"""),"SWASTA") -> SWASTA | T16: =IFERROR(__xludf.DUMMYFUNCTION("""COMPUTED_VALUE"""),"- TUNGKAI BAWAH") -> - TUNGKAI BAWAH | U16: =IFERROR(__xludf.DUMMYFUNCTION("""COMPUTED_VALUE"""),"") | V16: =IFERROR(__xludf.DUMMYFUNCTION("""COMPUTED_VALUE"""),"08115691011") -> 08115691011
B17: =IFERROR(__xludf.DUMMYFUNCTION("""COMPUTED_VALUE"""),45006.87813922454) -> 45006.878 | D17: =IFERROR(__xludf.DUMMYFUNCTION("""COMPUTED_VALUE"""),44930.0) -> 44930 | E17: =IFERROR(__xludf.DUMMYFUNCTION("""COMPUTED_VALUE"""),"01Jan") -> 01Jan | F17: =IFERROR(__xludf.DUMMYFUNCTION("""COMPUTED_VALUE"""),"2023") -> 2023 | G17: =IFERROR(__xludf.DUMMYFUNCTION("""COMPUTED_VALUE"""),"AREEFAQEEL DIEN HAQQ") -> AREEFAQEEL DIEN HAQQ | H17: =IFERROR(__xludf.DUMMYFUNCTION("""COMPUTED_VALUE"""),"A1023015335") -> A1023015335 | I17: =IFERROR(__xludf.DUMMYFUNCTION("""COMPUTED_VALUE"""),15.0) -> 15 | J17: =IFERROR(__xludf.DUMMYFUNCTION("""COMPUTED_VALUE"""),"< 18 tahun") -> < 18 tahun | K17: =IFERROR(__xludf.DUMMYFUNCTION("""COMPUTED_VALUE"""),40440.0) -> 40440 | L17: =IFERROR(__xludf.DUMMYFUNCTION("""COMPUTED_VALUE"""),"LAKI-LAKI") -> LAKI-LAKI | M17: =IFERROR(__xludf.DUMMYFUNCTION("""COMPUTED_VALUE"""),"JL A R SALEH III NO 16") -> JL A R SALEH III NO 16 | R17: =IFERROR(__xludf.DUMMYFUNCTION("""COMPUTED_VALUE"""),"ISLAM") -> ISLAM | S17: =IFERROR(__xludf.DUMMYFUNCTION("""COMPUTED_VALUE"""),"PELAJAR/MAHASISWA") -> PELAJAR/MAHASISWA | U17: =IFERROR(__xludf.DUMMYFUNCTION("""COMPUTED_VALUE"""),"") | V17: =IFERROR(__xludf.DUMMYFUNCTION("""COMPUTED_VALUE"""),"081257035335") -> 081257035335
B18: =IFERROR(__xludf.DUMMYFUNCTION("""COMPUTED_VALUE"""),44985.451886574076) -> 44985.452 | D18: =IFERROR(__xludf.DUMMYFUNCTION("""COMPUTED_VALUE"""),44930.0) -> 44930 | E18: =IFERROR(__xludf.DUMMYFUNCTION("""COMPUTED_VALUE"""),"01Jan") -> 01Jan | F18: =IFERROR(__xludf.DUMMYFUNCTION("""COMPUTED_VALUE"""),"2023") -> 2023 | G18: =IFERROR(__xludf.DUMMYFUNCTION("""COMPUTED_VALUE"""),"NURLINA") -> NURLINA | H18: =IFERROR(__xludf.DUMMYFUNCTION("""COMPUTED_VALUE"""),"N8523017483") -> N8523017483 | I18: =IFERROR(__xludf.DUMMYFUNCTION("""COMPUTED_VALUE"""),40.0) -> 40 | J18: =IFERROR(__xludf.DUMMYFUNCTION("""COMPUTED_VALUE"""),"35-44 tahun") -> 35-44 tahun | K18: =IFERROR(__xludf.DUMMYFUNCTION("""COMPUTED_VALUE"""),31343.0) -> 31343 | L18: =IFERROR(__xludf.DUMMYFUNCTION("""COMPUTED_VALUE"""),"PEREMPUAN") -> PEREMPUAN | M18: =IFERROR(__xludf.DUMMYFUNCTION("""COMPUTED_VALUE"""),"JL. K. H. W. HASYIM GG. USAHA 1 NO. 17") -> JL. K. H. W. HASYIM GG. USAHA 1 NO. 17 | R18: =IFERROR(__xludf.DUMMYFUNCTION("""COMPUTED_VALUE"""),"ISLAM") -> ISLAM | S18: =IFERROR(__xludf.DUMMYFUNCTION("""COMPUTED_VALUE"""),"DOSEN/GURU") -> DOSEN/GURU | T18: =IFERROR(__xludf.DUMMYFUNCTION("""COMPUTED_VALUE"""),"TELAPAK KAKI") -> TELAPAK KAKI | U18: =IFERROR(__xludf.DUMMYFUNCTION("""COMPUTED_VALUE"""),"") | V18: =IFERROR(__xludf.DUMMYFUNCTION("""COMPUTED_VALUE"""),"08565007483") -> 08565007483
B19: =IFERROR(__xludf.DUMMYFUNCTION("""COMPUTED_VALUE"""),45011.63774479167) -> 45011.638 | D19: =IFERROR(__xludf.DUMMYFUNCTION("""COMPUTED_VALUE"""),44931.0) -> 44931 | E19: =IFERROR(__xludf.DUMMYFUNCTION("""COMPUTED_VALUE"""),"01Jan") -> 01Jan | F19: =IFERROR(__xludf.DUMMYFUNCTION("""COMPUTED_VALUE"""),"2023") -> 2023 | G19: =IFERROR(__xludf.DUMMYFUNCTION("""COMPUTED_VALUE"""),"A. THENU") -> A. THENU | H19: =IFERROR(__xludf.DUMMYFUNCTION("""COMPUTED_VALUE"""),"A7023018857") -> A7023018857 | I19: =IFERROR(__xludf.DUMMYFUNCTION("""COMPUTED_VALUE"""),55.0) -> 55 | J19: =IFERROR(__xludf.DUMMYFUNCTION("""COMPUTED_VALUE"""),"> 44 tahun") -> > 44 tahun | K19: =IFERROR(__xludf.DUMMYFUNCTION("""COMPUTED_VALUE"""),25875.0) -> 25875 | L19: =IFERROR(__xludf.DUMMYFUNCTION("""COMPUTED_VALUE"""),"LAKI-LAKI") -> LAKI-LAKI | M19: =IFERROR(__xludf.DUMMYFUNCTION("""COMPUTED_VALUE"""),"JL TABRANI AHMAD GG IKRAR NON70") -> JL TABRANI AHMAD GG IKRAR NON70 | R19: =IFERROR(__xludf.DUMMYFUNCTION("""COMPUTED_VALUE"""),"PROTESTAN") -> PROTESTAN | S19: =IFERROR(__xludf.DUMMYFUNCTION("""COMPUTED_VALUE"""),"SWASTA") -> SWASTA | T19: =IFERROR(__xludf.DUMMYFUNCTION("""COMPUTED_VALUE"""),"PINGGANG") -> PINGGANG | U19: =IFERROR(__xludf.DUMMYFUNCTION("""COMPUTED_VALUE"""),"-") -> - | V19: =IFERROR(__xludf.DUMMYFUNCTION("""COMPUTED_VALUE"""),"08125728857") -> 08125728857
B20: =IFERROR(__xludf.DUMMYFUNCTION("""COMPUTED_VALUE"""),45006.90633336805) -> 45006.906 | D20: =IFERROR(__xludf.DUMMYFUNCTION("""COMPUTED_VALUE"""),44931.0) -> 44931 | E20: =IFERROR(__xludf.DUMMYFUNCTION("""COMPUTED_VALUE"""),"01Jan") -> 01Jan | F20: =IFERROR(__xludf.DUMMYFUNCTION("""COMPUTED_VALUE"""),"2023") -> 2023 | G20: =IFERROR(__xludf.DUMMYFUNCTION("""COMPUTED_VALUE"""),"ATIKA ALIFIA F. TOBING") -> ATIKA ALIFIA F. TOBING | H20: =IFERROR(__xludf.DUMMYFUNCTION("""COMPUTED_VALUE"""),"A9023018425") -> A9023018425 | I20: =IFERROR(__xludf.DUMMYFUNCTION("""COMPUTED_VALUE"""),36.0) -> 36 | J20: =IFERROR(__xludf.DUMMYFUNCTION("""COMPUTED_VALUE"""),"35-44 tahun") -> 35-44 tahun | K20: =IFERROR(__xludf.DUMMYFUNCTION("""COMPUTED_VALUE"""),32990.0) -> 32990 | L20: =IFERROR(__xludf.DUMMYFUNCTION("""COMPUTED_VALUE"""),"PEREMPUAN") -> PEREMPUAN | M20: =IFERROR(__xludf.DUMMYFUNCTION("""COMPUTED_VALUE"""),"JL. PADAT KARYA GG. KARYA BARU NO. A1") -> JL. PADAT KARYA GG. KARYA BARU NO. A1 | R20: =IFERROR(__xludf.DUMMYFUNCTION("""COMPUTED_VALUE"""),"ISLAM") -> ISLAM | S20: =IFERROR(__xludf.DUMMYFUNCTION("""COMPUTED_VALUE"""),"ASN") -> ASN | T20: =IFERROR(__xludf.DUMMYFUNCTION("""COMPUTED_VALUE"""),"KAKI") -> KAKI | U20: =IFERROR(__xludf.DUMMYFUNCTION("""COMPUTED_VALUE"""),"DUDUK LAMA") -> DUDUK LAMA | V20: =IFERROR(__xludf.DUMMYFUNCTION("""COMPUTED_VALUE"""),"087789068425") -> 087789068425
B21: =IFERROR(__xludf.DUMMYFUNCTION("""COMPUTED_VALUE"""),45011.640681296296) -> 45011.641 | D21: =IFERROR(__xludf.DUMMYFUNCTION("""COMPUTED_VALUE"""),44931.0) -> 44931 | E21: =IFERROR(__xludf.DUMMYFUNCTION("""COMPUTED_VALUE"""),"01Jan") -> 01Jan | F21: =IFERROR(__xludf.DUMMYFUNCTION("""COMPUTED_VALUE"""),"2023") -> 2023 | G21: =IFERROR(__xludf.DUMMYFUNCTION("""COMPUTED_VALUE"""),"JAKA SEPTIADI") -> JAKA SEPTIADI | H21: =IFERROR(__xludf.DUMMYFUNCTION("""COMPUTED_VALUE"""),"J8823016633") -> J8823016633 | I21: =IFERROR(__xludf.DUMMYFUNCTION("""COMPUTED_VALUE"""),38.0) -> 38 | J21: =IFERROR(__xludf.DUMMYFUNCTION("""COMPUTED_VALUE"""),"35-44 tahun") -> 35-44 tahun | K21: =IFERROR(__xludf.DUMMYFUNCTION("""COMPUTED_VALUE"""),32239.0) -> 32239 | L21: =IFERROR(__xludf.DUMMYFUNCTION("""COMPUTED_VALUE"""),"LAKI-LAKI") -> LAKI-LAKI | M21: =IFERROR(__xludf.DUMMYFUNCTION("""COMPUTED_VALUE"""),"JL. PARIS 2 PONTIANAK") -> JL. PARIS 2 PONTIANAK | R21: =IFERROR(__xludf.DUMMYFUNCTION("""COMPUTED_VALUE"""),"ISLAM") -> ISLAM | S21: =IFERROR(__xludf.DUMMYFUNCTION("""COMPUTED_VALUE"""),"SWASTA") -> SWASTA | T21: =IFERROR(__xludf.DUMMYFUNCTION("""COMPUTED_VALUE"""),"PINGGANG") -> PINGGANG | U21: =IFERROR(__xludf.DUMMYFUNCTION("""COMPUTED_VALUE"""),"DUDUK LAMA") -> DUDUK LAMA | V21: =IFERROR(__xludf.DUMMYFUNCTION("""COMPUTED_VALUE"""),"081281616633") -> 081281616633
B22: =IFERROR(__xludf.DUMMYFUNCTION("""COMPUTED_VALUE"""),44888.56218804399) -> 44888.562 | D22: =IFERROR(__xludf.DUMMYFUNCTION("""COMPUTED_VALUE"""),44931.0) -> 44931 | E22: =IFERROR(__xludf.DUMMYFUNCTION("""COMPUTED_VALUE"""),"01Jan") -> 01Jan | F22: =IFERROR(__xludf.DUMMYFUNCTION("""COMPUTED_VALUE"""),"2023") -> 2023 | G22: =IFERROR(__xludf.DUMMYFUNCTION("""COMPUTED_VALUE"""),"MARIYO") -> MARIYO | H22: =IFERROR(__xludf.DUMMYFUNCTION("""COMPUTED_VALUE"""),"M6523010470") -> M6523010470 | I22: =IFERROR(__xludf.DUMMYFUNCTION("""COMPUTED_VALUE"""),60.0) -> 60 | J22: =IFERROR(__xludf.DUMMYFUNCTION("""COMPUTED_VALUE"""),"> 44 tahun") -> > 44 tahun | K22: =IFERROR(__xludf.DUMMYFUNCTION("""COMPUTED_VALUE"""),24088.0) -> 24088 | L22: =IFERROR(__xludf.DUMMYFUNCTION("""COMPUTED_VALUE"""),"LAKI-LAKI") -> LAKI-LAKI | M22: =IFERROR(__xludf.DUMMYFUNCTION("""COMPUTED_VALUE"""),"JL. PROF DR HAMKA GG NILAM 8") -> JL. PROF DR HAMKA GG NILAM 8 | R22: =IFERROR(__xludf.DUMMYFUNCTION("""COMPUTED_VALUE"""),"ISLAM") -> ISLAM | S22: =IFERROR(__xludf.DUMMYFUNCTION("""COMPUTED_VALUE"""),"SWASTA") -> SWASTA | T22: =IFERROR(__xludf.DUMMYFUNCTION("""COMPUTED_VALUE"""),"PINGGANG BOKONG") -> PINGGANG BOKONG | U22: =IFERROR(__xludf.DUMMYFUNCTION("""COMPUTED_VALUE"""),"") | V22: =IFERROR(__xludf.DUMMYFUNCTION("""COMPUTED_VALUE"""),"081933860470") -> 081933860470
B23: =IFERROR(__xludf.DUMMYFUNCTION("""COMPUTED_VALUE"""),44921.8215625) -> 44921.822 | D23: =IFERROR(__xludf.DUMMYFUNCTION("""COMPUTED_VALUE"""),44933.0) -> 44933 | E23: =IFERROR(__xludf.DUMMYFUNCTION("""COMPUTED_VALUE"""),"01Jan") -> 01Jan | F23: =IFERROR(__xludf.DUMMYFUNCTION("""COMPUTED_VALUE"""),"2023") -> 2023 | G23: =IFERROR(__xludf.DUMMYFUNCTION("""COMPUTED_VALUE"""),"ADIEL PRATAMA PUTRA K.") -> ADIEL PRATAMA PUTRA K. | H23: =IFERROR(__xludf.DUMMYFUNCTION("""COMPUTED_VALUE"""),"A0623015163") -> A0623015163 | I23: =IFERROR(__xludf.DUMMYFUNCTION("""COMPUTED_VALUE"""),20.0) -> 20 | J23: =IFERROR(__xludf.DUMMYFUNCTION("""COMPUTED_VALUE"""),"18-24 tahun") -> 18-24 tahun | K23: =IFERROR(__xludf.DUMMYFUNCTION("""COMPUTED_VALUE"""),38793.0) -> 38793 | L23: =IFERROR(__xludf.DUMMYFUNCTION("""COMPUTED_VALUE"""),"LAKI-LAKI") -> LAKI-LAKI | M23: =IFERROR(__xludf.DUMMYFUNCTION("""COMPUTED_VALUE"""),"JL DANAU SENTARUM GG PERSATUAN NO B4") -> JL DANAU SENTARUM GG PERSATUAN NO B4 | R23: =IFERROR(__xludf.DUMMYFUNCTION("""COMPUTED_VALUE"""),"ISLAM") -> ISLAM | S23: =IFERROR(__xludf.DUMMYFUNCTION("""COMPUTED_VALUE"""),"PELAJAR/MAHASISWA") -> PELAJAR/MAHASISWA | T23: =IFERROR(__xludf.DUMMYFUNCTION("""COMPUTED_VALUE"""),"SKOLIOSIS") -> SKOLIOSIS | U23: =IFERROR(__xludf.DUMMYFUNCTION("""COMPUTED_VALUE"""),"-") -> - | V23: =IFERROR(__xludf.DUMMYFUNCTION("""COMPUTED_VALUE"""),"085779775163") -> 085779775163
B24: =IFERROR(__xludf.DUMMYFUNCTION("""COMPUTED_VALUE"""),44973.39733796296) -> 44973.397 | D24: =IFERROR(__xludf.DUMMYFUNCTION("""COMPUTED_VALUE"""),44933.0) -> 44933 | E24: =IFERROR(__xludf.DUMMYFUNCTION("""COMPUTED_VALUE"""),"01Jan") -> 01Jan | F24: =IFERROR(__xludf.DUMMYFUNCTION("""COMPUTED_VALUE"""),"2023") -> 2023 | G24: =IFERROR(__xludf.DUMMYFUNCTION("""COMPUTED_VALUE"""),"DAVID BURUI") -> DAVID BURUI | H24: =IFERROR(__xludf.DUMMYFUNCTION("""COMPUTED_VALUE"""),"D6123013327") -> D6123013327 | I24: =IFERROR(__xludf.DUMMYFUNCTION("""COMPUTED_VALUE"""),64.0) -> 64 | J24: =IFERROR(__xludf.DUMMYFUNCTION("""COMPUTED_VALUE"""),"> 44 tahun") -> > 44 tahun | K24: =IFERROR(__xludf.DUMMYFUNCTION("""COMPUTED_VALUE"""),22626.0) -> 22626 | L24: =IFERROR(__xludf.DUMMYFUNCTION("""COMPUTED_VALUE"""),"LAKI-LAKI") -> LAKI-LAKI | M24: =IFERROR(__xludf.DUMMYFUNCTION("""COMPUTED_VALUE"""),"JL. PERUMNAS GG. MANTAN XI") -> JL. PERUMNAS GG. MANTAN XI | R24: =IFERROR(__xludf.DUMMYFUNCTION("""COMPUTED_VALUE"""),"ISLAM") -> ISLAM | S24: =IFERROR(__xludf.DUMMYFUNCTION("""COMPUTED_VALUE"""),"TIDAK ADA") -> TIDAK ADA | T24: =IFERROR(__xludf.DUMMYFUNCTION("""COMPUTED_VALUE"""),"DADA") -> DADA | U24: =IFERROR(__xludf.DUMMYFUNCTION("""COMPUTED_VALUE"""),"") | V24: =IFERROR(__xludf.DUMMYFUNCTION("""COMPUTED_VALUE"""),"081280423327") -> 081280423327
B25: =IFERROR(__xludf.DUMMYFUNCTION("""COMPUTED_VALUE"""),45006.87726905092) -> 45006.877 | D25: =IFERROR(__xludf.DUMMYFUNCTION("""COMPUTED_VALUE"""),44933.0) -> 44933 | E25: =IFERROR(__xludf.DUMMYFUNCTION("""COMPUTED_VALUE"""),"01Jan") -> 01Jan | F25: =IFERROR(__xludf.DUMMYFUNCTION("""COMPUTED_VALUE"""),"2023") -> 2023 | G25: =IFERROR(__xludf.DUMMYFUNCTION("""COMPUTED_VALUE"""),"DEDI SUNARDI") -> DEDI SUNARDI | H25: =IFERROR(__xludf.DUMMYFUNCTION("""COMPUTED_VALUE"""),"D8223017622") -> D8223017622 | I25: =IFERROR(__xludf.DUMMYFUNCTION("""COMPUTED_VALUE"""),43.0) -> 43 | J25: =IFERROR(__xludf.DUMMYFUNCTION("""COMPUTED_VALUE"""),"35-44 tahun") -> 35-44 tahun | K25: =IFERROR(__xludf.DUMMYFUNCTION("""COMPUTED_VALUE"""),30309.0) -> 30309 | L25: =IFERROR(__xludf.DUMMYFUNCTION("""COMPUTED_VALUE"""),"LAKI-LAKI") -> LAKI-LAKI | M25: =IFERROR(__xludf.DUMMYFUNCTION("""COMPUTED_VALUE"""),"SANGGAU") -> SANGGAU | R25: =IFERROR(__xludf.DUMMYFUNCTION("""COMPUTED_VALUE"""),"ISLAM") -> ISLAM | S25: =IFERROR(__xludf.DUMMYFUNCTION("""COMPUTED_VALUE"""),"SWASTA") -> SWASTA | T25: =IFERROR(__xludf.DUMMYFUNCTION("""COMPUTED_VALUE"""),"PINGGANG") -> PINGGANG | U25: =IFERROR(__xludf.DUMMYFUNCTION("""COMPUTED_VALUE"""),"") | V25: =IFERROR(__xludf.DUMMYFUNCTION("""COMPUTED_VALUE"""),"085822957622") -> 085822957622
B26: =IFERROR(__xludf.DUMMYFUNCTION("""COMPUTED_VALUE"""),44983.46637731481) -> 44983.466 | D26: =IFERROR(__xludf.DUMMYFUNCTION("""COMPUTED_VALUE"""),44933.0) -> 44933 | E26: =IFERROR(__xludf.DUMMYFUNCTION("""COMPUTED_VALUE"""),"01Jan") -> 01Jan | F26: =IFERROR(__xludf.DUMMYFUNCTION("""COMPUTED_VALUE"""),"2023") -> 2023 | G26: =IFERROR(__xludf.DUMMYFUNCTION("""COMPUTED_VALUE"""),"MIGUEL TJONDRO") -> MIGUEL TJONDRO | H26: =IFERROR(__xludf.DUMMYFUNCTION("""COMPUTED_VALUE"""),"M9823010741") -> M9823010741 | I26: =IFERROR(__xludf.DUMMYFUNCTION("""COMPUTED_VALUE"""),28.0) -> 28 | J26: =IFERROR(__xludf.DUMMYFUNCTION("""COMPUTED_VALUE"""),"25-34 tahun") -> 25-34 tahun | K26: =IFERROR(__xludf.DUMMYFUNCTION("""COMPUTED_VALUE"""),35871.0) -> 35871 | L26: =IFERROR(__xludf.DUMMYFUNCTION("""COMPUTED_VALUE"""),"LAKI-LAKI") -> LAKI-LAKI | M26: =IFERROR(__xludf.DUMMYFUNCTION("""COMPUTED_VALUE"""),"JL. P. H. HUSIN 1 GG. PERWIRA NO. 18A") -> JL. P. H. HUSIN 1 GG. PERWIRA NO. 18A | R26: =IFERROR(__xludf.DUMMYFUNCTION("""COMPUTED_VALUE"""),"KATOLIK") -> KATOLIK | S26: =IFERROR(__xludf.DUMMYFUNCTION("""COMPUTED_VALUE"""),"SWASTA") -> SWASTA | T26: =IFERROR(__xludf.DUMMYFUNCTION("""COMPUTED_VALUE"""),"KIRI") -> KIRI | U26: =IFERROR(__xludf.DUMMYFUNCTION("""COMPUTED_VALUE"""),"") | V26: =IFERROR(__xludf.DUMMYFUNCTION("""COMPUTED_VALUE"""),"08977200741") -> 08977200741
B27: =IFERROR(__xludf.DUMMYFUNCTION("""COMPUTED_VALUE"""),44941.44567129629) -> 44941.446 | D27: =IFERROR(__xludf.DUMMYFUNCTION("""COMPUTED_VALUE"""),44933.0) -> 44933 | E27: =IFERROR(__xludf.DUMMYFUNCTION("""COMPUTED_VALUE"""),"01Jan") -> 01Jan | F27: =IFERROR(__xludf.DUMMYFUNCTION("""COMPUTED_VALUE"""),"2023") -> 2023 | G27: =IFERROR(__xludf.DUMMYFUNCTION("""COMPUTED_VALUE"""),"TRI WAHYUNI") -> TRI WAHYUNI | H27: =IFERROR(__xludf.DUMMYFUNCTION("""COMPUTED_VALUE"""),"T7623010391") -> T7623010391 | I27: =IFERROR(__xludf.DUMMYFUNCTION("""COMPUTED_VALUE"""),50.0) -> 50 | J27: =IFERROR(__xludf.DUMMYFUNCTION("""COMPUTED_VALUE"""),"> 44 tahun") -> > 44 tahun | K27: =IFERROR(__xludf.DUMMYFUNCTION("""COMPUTED_VALUE"""),27825.0) -> 27825 | L27: =IFERROR(__xludf.DUMMYFUNCTION("""COMPUTED_VALUE"""),"PEREMPUAN") -> PEREMPUAN | M27: =IFERROR(__xludf.DUMMYFUNCTION("""COMPUTED_VALUE"""),"BENGKAYANG") -> BENGKAYANG | R27: =IFERROR(__xludf.DUMMYFUNCTION("""COMPUTED_VALUE"""),"ISLAM") -> ISLAM | S27: =IFERROR(__xludf.DUMMYFUNCTION("""COMPUTED_VALUE"""),"ASN") -> ASN | T27: =IFERROR(__xludf.DUMMYFUNCTION("""COMPUTED_VALUE"""),"PINGGANG") -> PINGGANG | U27: =IFERROR(__xludf.DUMMYFUNCTION("""COMPUTED_VALUE"""),"-") -> - | V27: =IFERROR(__xludf.DUMMYFUNCTION("""COMPUTED_VALUE"""),"081345790391") -> 081345790391
B28: =IFERROR(__xludf.DUMMYFUNCTION("""COMPUTED_VALUE"""),45006.8960915625) -> 45006.896 | D28: =IFERROR(__xludf.DUMMYFUNCTION("""COMPUTED_VALUE"""),44934.0) -> 44934 | E28: =IFERROR(__xludf.DUMMYFUNCTION("""COMPUTED_VALUE"""),"01Jan") -> 01Jan | F28: =IFERROR(__xludf.DUMMYFUNCTION("""COMPUTED_VALUE"""),"2023") -> 2023 | G28: =IFERROR(__xludf.DUMMYFUNCTION("""COMPUTED_VALUE"""),"ANANTA UTAMI") -> ANANTA UTAMI | H28: =IFERROR(__xludf.DUMMYFUNCTION("""COMPUTED_VALUE"""),"A9123011070") -> A9123011070 | I28: =IFERROR(__xludf.DUMMYFUNCTION("""COMPUTED_VALUE"""),34.0) -> 34 | J28: =IFERROR(__xludf.DUMMYFUNCTION("""COMPUTED_VALUE"""),"25-34 tahun") -> 25-34 tahun | K28: =IFERROR(__xludf.DUMMYFUNCTION("""COMPUTED_VALUE"""),33550.0) -> 33550 | L28: =IFERROR(__xludf.DUMMYFUNCTION("""COMPUTED_VALUE"""),"PEREMPUAN") -> PEREMPUAN | M28: =IFERROR(__xludf.DUMMYFUNCTION("""COMPUTED_VALUE"""),"JL. DR. SUTOMO GG. KARYA 1") -> JL. DR. SUTOMO GG. KARYA 1 | R28: =IFERROR(__xludf.DUMMYFUNCTION("""COMPUTED_VALUE"""),"KATOLIK") -> KATOLIK | S28: =IFERROR(__xludf.DUMMYFUNCTION("""COMPUTED_VALUE"""),"ASN") -> ASN | T28: =IFERROR(__xludf.DUMMYFUNCTION("""COMPUTED_VALUE"""),"KIRI") -> KIRI | U28: =IFERROR(__xludf.DUMMYFUNCTION("""COMPUTED_VALUE"""),"") | V28: =IFERROR(__xludf.DUMMYFUNCTION("""COMPUTED_VALUE"""),"081253051070") -> 081253051070
B29: =IFERROR(__xludf.DUMMYFUNCTION("""COMPUTED_VALUE"""),44973.42521990741) -> 44973.425 | D29: =IFERROR(__xludf.DUMMYFUNCTION("""COMPUTED_VALUE"""),44934.0) -> 44934 | E29: =IFERROR(__xludf.DUMMYFUNCTION("""COMPUTED_VALUE"""),"01Jan") -> 01Jan | F29: =IFERROR(__xludf.DUMMYFUNCTION("""COMPUTED_VALUE"""),"2023") -> 2023 | G29: =IFERROR(__xludf.DUMMYFUNCTION("""COMPUTED_VALUE"""),"EMMI") -> EMMI | H29: =IFERROR(__xludf.DUMMYFUNCTION("""COMPUTED_VALUE"""),"E6223013059") -> E6223013059 | I29: =IFERROR(__xludf.DUMMYFUNCTION("""COMPUTED_VALUE"""),63.0) -> 63 | J29: =IFERROR(__xludf.DUMMYFUNCTION("""COMPUTED_VALUE"""),"> 44 tahun") -> > 44 tahun | K29: =IFERROR(__xludf.DUMMYFUNCTION("""COMPUTED_VALUE"""),22971.0) -> 22971 | L29: =IFERROR(__xludf.DUMMYFUNCTION("""COMPUTED_VALUE"""),"PEREMPUAN") -> PEREMPUAN | M29: =IFERROR(__xludf.DUMMYFUNCTION("""COMPUTED_VALUE"""),"JL PURNAMA KOMP PURNAMA AGUNG 2 NO G1") -> JL PURNAMA KOMP PURNAMA AGUNG 2 NO G1 | R29: =IFERROR(__xludf.DUMMYFUNCTION("""COMPUTED_VALUE"""),"LAINNYA") -> LAINNYA | S29: =IFERROR(__xludf.DUMMYFUNCTION("""COMPUTED_VALUE"""),"TIDAK ADA") -> TIDAK ADA | T29: =IFERROR(__xludf.DUMMYFUNCTION("""COMPUTED_VALUE"""),"PINGGANG") -> PINGGANG | U29: =IFERROR(__xludf.DUMMYFUNCTION("""COMPUTED_VALUE"""),"-") -> - | V29: =IFERROR(__xludf.DUMMYFUNCTION("""COMPUTED_VALUE"""),"081345583059") -> 081345583059
B30: =IFERROR(__xludf.DUMMYFUNCTION("""COMPUTED_VALUE"""),44973.424212962964) -> 44973.424 | D30: =IFERROR(__xludf.DUMMYFUNCTION("""COMPUTED_VALUE"""),44934.0) -> 44934 | E30: =IFERROR(__xludf.DUMMYFUNCTION("""COMPUTED_VALUE"""),"01Jan") -> 01Jan | F30: =IFERROR(__xludf.DUMMYFUNCTION("""COMPUTED_VALUE"""),"2023") -> 2023 | G30: =IFERROR(__xludf.DUMMYFUNCTION("""COMPUTED_VALUE"""),"ZIQRIL HAKIM R") -> ZIQRIL HAKIM R | H30: =IFERROR(__xludf.DUMMYFUNCTION("""COMPUTED_VALUE"""),"Z0423010391") -> Z0423010391 | I30: =IFERROR(__xludf.DUMMYFUNCTION("""COMPUTED_VALUE"""),21.0) -> 21 | J30: =IFERROR(__xludf.DUMMYFUNCTION("""COMPUTED_VALUE"""),"18-24 tahun") -> 18-24 tahun | K30: =IFERROR(__xludf.DUMMYFUNCTION("""COMPUTED_VALUE"""),38279.0) -> 38279 | L30: =IFERROR(__xludf.DUMMYFUNCTION("""COMPUTED_VALUE"""),"LAKI-LAKI") -> LAKI-LAKI | M30: =IFERROR(__xludf.DUMMYFUNCTION("""COMPUTED_VALUE"""),"BENGKAYANG") -> BENGKAYANG | R30: =IFERROR(__xludf.DUMMYFUNCTION("""COMPUTED_VALUE"""),"ISLAM") -> ISLAM | S30: =IFERROR(__xludf.DUMMYFUNCTION("""COMPUTED_VALUE"""),"TNI/POLRI") -> TNI/POLRI | T30: =IFERROR(__xludf.DUMMYFUNCTION("""COMPUTED_VALUE"""),"RAHANG") -> RAHANG | U30: =IFERROR(__xludf.DUMMYFUNCTION("""COMPUTED_VALUE"""),"-") -> - | V30: =IFERROR(__xludf.DUMMYFUNCTION("""COMPUTED_VALUE"""),"081345790391") -> 081345790391
B31: =IFERROR(__xludf.DUMMYFUNCTION("""COMPUTED_VALUE"""),45006.89896464121) -> 45006.899 | D31: =IFERROR(__xludf.DUMMYFUNCTION("""COMPUTED_VALUE"""),44935.0) -> 44935 | E31: =IFERROR(__xludf.DUMMYFUNCTION("""COMPUTED_VALUE"""),"01Jan") -> 01Jan | F31: =IFERROR(__xludf.DUMMYFUNCTION("""COMPUTED_VALUE"""),"2023") -> 2023 | G31: =IFERROR(__xludf.DUMMYFUNCTION("""COMPUTED_VALUE"""),"ERNA SETIAWATY") -> ERNA SETIAWATY | H31: =IFERROR(__xludf.DUMMYFUNCTION("""COMPUTED_VALUE"""),"E5423019005") -> E5423019005 | I31: =IFERROR(__xludf.DUMMYFUNCTION("""COMPUTED_VALUE"""),71.0) -> 71 | J31: =IFERROR(__xludf.DUMMYFUNCTION("""COMPUTED_VALUE"""),"> 44 tahun") -> > 44 tahun | K31: =IFERROR(__xludf.DUMMYFUNCTION("""COMPUTED_VALUE"""),20084.0) -> 20084 | L31: =IFERROR(__xludf.DUMMYFUNCTION("""COMPUTED_VALUE"""),"PEREMPUAN") -> PEREMPUAN | M31: =IFERROR(__xludf.DUMMYFUNCTION("""COMPUTED_VALUE"""),"JL. KAPTEN P. TENDEAN NO. 17A") -> JL. KAPTEN P. TENDEAN NO. 17A | R31: =IFERROR(__xludf.DUMMYFUNCTION("""COMPUTED_VALUE"""),"BUDDHA") -> BUDDHA | S31: =IFERROR(__xludf.DUMMYFUNCTION("""COMPUTED_VALUE"""),"RUMAH TANGGA") -> RUMAH TANGGA | T31: =IFERROR(__xludf.DUMMYFUNCTION("""COMPUTED_VALUE"""),"PINGGANG") -> PINGGANG | U31: =IFERROR(__xludf.DUMMYFUNCTION("""COMPUTED_VALUE"""),"") | V31: =IFERROR(__xludf.DUMMYFUNCTION("""COMPUTED_VALUE"""),"087878219005") -> 087878219005
B32: =IFERROR(__xludf.DUMMYFUNCTION("""COMPUTED_VALUE"""),44908.589479166665) -> 44908.589 | D32: =IFERROR(__xludf.DUMMYFUNCTION("""COMPUTED_VALUE"""),44935.0) -> 44935 | E32: =IFERROR(__xludf.DUMMYFUNCTION("""COMPUTED_VALUE"""),"01Jan") -> 01Jan | F32: =IFERROR(__xludf.DUMMYFUNCTION("""COMPUTED_VALUE"""),"2023") -> 2023 | G32: =IFERROR(__xludf.DUMMYFUNCTION("""COMPUTED_VALUE"""),"EVA DOLOROSA") -> EVA DOLOROSA | H32: =IFERROR(__xludf.DUMMYFUNCTION("""COMPUTED_VALUE"""),"E6723010889") -> E6723010889 | I32: =IFERROR(__xludf.DUMMYFUNCTION("""COMPUTED_VALUE"""),58.0) -> 58 | J32: =IFERROR(__xludf.DUMMYFUNCTION("""COMPUTED_VALUE"""),"> 44 tahun") -> > 44 tahun | K32: =IFERROR(__xludf.DUMMYFUNCTION("""COMPUTED_VALUE"""),24668.0) -> 24668 | L32: =IFERROR(__xludf.DUMMYFUNCTION("""COMPUTED_VALUE"""),"PEREMPUAN") -> PEREMPUAN | M32: =IFERROR(__xludf.DUMMYFUNCTION("""COMPUTED_VALUE"""),"JL. PARIS II GG. DEMAK NO.10") -> JL. PARIS II GG. DEMAK NO.10 | R32: =IFERROR(__xludf.DUMMYFUNCTION("""COMPUTED_VALUE"""),"ISLAM") -> ISLAM | S32: =IFERROR(__xludf.DUMMYFUNCTION("""COMPUTED_VALUE"""),"DOSEN/GURU") -> DOSEN/GURU | U32: =IFERROR(__xludf.DUMMYFUNCTION("""COMPUTED_VALUE"""),"-") -> - | V32: =IFERROR(__xludf.DUMMYFUNCTION("""COMPUTED_VALUE"""),"08125700889") -> 08125700889
B33: =IFERROR(__xludf.DUMMYFUNCTION("""COMPUTED_VALUE"""),44964.8041087963) -> 44964.804 | D33: =IFERROR(__xludf.DUMMYFUNCTION("""COMPUTED_VALUE"""),44936.0) -> 44936 | E33: =IFERROR(__xludf.DUMMYFUNCTION("""COMPUTED_VALUE"""),"01Jan") -> 01Jan | F33: =IFERROR(__xludf.DUMMYFUNCTION("""COMPUTED_VALUE"""),"2023") -> 2023 | G33: =IFERROR(__xludf.DUMMYFUNCTION("""COMPUTED_VALUE"""),"ANTO PRAYUGO") -> ANTO PRAYUGO | H33: =IFERROR(__xludf.DUMMYFUNCTION("""COMPUTED_VALUE"""),"A9523012989") -> A9523012989 | I33: =IFERROR(__xludf.DUMMYFUNCTION("""COMPUTED_VALUE"""),31.0) -> 31 | J33: =IFERROR(__xludf.DUMMYFUNCTION("""COMPUTED_VALUE"""),"25-34 tahun") -> 25-34 tahun | K33: =IFERROR(__xludf.DUMMYFUNCTION("""COMPUTED_VALUE"""),34806.0) -> 34806 | L33: =IFERROR(__xludf.DUMMYFUNCTION("""COMPUTED_VALUE"""),"LAKI-LAKI") -> LAKI-LAKI | M33: =IFERROR(__xludf.DUMMYFUNCTION("""COMPUTED_VALUE"""),"JL PERDANA KOMP BALI AGUNG 2") -> JL PERDANA KOMP BALI AGUNG 2 | R33: =IFERROR(__xludf.DUMMYFUNCTION("""COMPUTED_VALUE"""),"ISLAM") -> ISLAM | S33: =IFERROR(__xludf.DUMMYFUNCTION("""COMPUTED_VALUE"""),"PERBANKAN") -> PERBANKAN | U33: =IFERROR(__xludf.DUMMYFUNCTION("""COMPUTED_VALUE"""),"FUTSAL") -> FUTSAL | V33: =IFERROR(__xludf.DUMMYFUNCTION("""COMPUTED_VALUE"""),"081350622989") -> 081350622989
B34: =IFERROR(__xludf.DUMMYFUNCTION("""COMPUTED_VALUE"""),45006.87447142361) -> 45006.874 | D34: =IFERROR(__xludf.DUMMYFUNCTION("""COMPUTED_VALUE"""),44936.0) -> 44936 | E34: =IFERROR(__xludf.DUMMYFUNCTION("""COMPUTED_VALUE"""),"01Jan") -> 01Jan | F34: =IFERROR(__xludf.DUMMYFUNCTION("""COMPUTED_VALUE"""),"2023") -> 2023 | G34: =IFERROR(__xludf.DUMMYFUNCTION("""COMPUTED_VALUE"""),"FAHMI") -> FAHMI | H34: =IFERROR(__xludf.DUMMYFUNCTION("""COMPUTED_VALUE"""),"F8623010888") -> F8623010888 | I34: =IFERROR(__xludf.DUMMYFUNCTION("""COMPUTED_VALUE"""),40.0) -> 40 | J34: =IFERROR(__xludf.DUMMYFUNCTION("""COMPUTED_VALUE"""),"35-44 tahun") -> 35-44 tahun | K34: =IFERROR(__xludf.DUMMYFUNCTION("""COMPUTED_VALUE"""),31523.0) -> 31523 | L34: =IFERROR(__xludf.DUMMYFUNCTION("""COMPUTED_VALUE"""),"LAKI-LAKI") -> LAKI-LAKI | M34: =IFERROR(__xludf.DUMMYFUNCTION("""COMPUTED_VALUE"""),"JL KARYA") -> JL KARYA | R34: =IFERROR(__xludf.DUMMYFUNCTION("""COMPUTED_VALUE"""),"ISLAM") -> ISLAM | S34: =IFERROR(__xludf.DUMMYFUNCTION("""COMPUTED_VALUE"""),"SWASTA") -> SWASTA | T34: =IFERROR(__xludf.DUMMYFUNCTION("""COMPUTED_VALUE"""),"PUNGGUNG ATAS") -> PUNGGUNG ATAS | U34: =IFERROR(__xludf.DUMMYFUNCTION("""COMPUTED_VALUE"""),"") | V34: =IFERROR(__xludf.DUMMYFUNCTION("""COMPUTED_VALUE"""),"087819990888") -> 087819990888
B35: =IFERROR(__xludf.DUMMYFUNCTION("""COMPUTED_VALUE"""),45006.90724241898) -> 45006.907 | D35: =IFERROR(__xludf.DUMMYFUNCTION("""COMPUTED_VALUE"""),44936.0) -> 44936 | E35: =IFERROR(__xludf.DUMMYFUNCTION("""COMPUTED_VALUE"""),"01Jan") -> 01Jan | F35: =IFERROR(__xludf.DUMMYFUNCTION("""COMPUTED_VALUE"""),"2023") -> 2023 | G35: =IFERROR(__xludf.DUMMYFUNCTION("""COMPUTED_VALUE"""),"RYANDI ARDIENDA P.") -> RYANDI ARDIENDA P. | H35: =IFERROR(__xludf.DUMMYFUNCTION("""COMPUTED_VALUE"""),"R9323012323") -> R9323012323 | I35: =IFERROR(__xludf.DUMMYFUNCTION("""COMPUTED_VALUE"""),32.0) -> 32 | J35: =IFERROR(__xludf.DUMMYFUNCTION("""COMPUTED_VALUE"""),"25-34 tahun") -> 25-34 tahun | K35: =IFERROR(__xludf.DUMMYFUNCTION("""COMPUTED_VALUE"""),34184.0) -> 34184 | L35: =IFERROR(__xludf.DUMMYFUNCTION("""COMPUTED_VALUE"""),"LAKI-LAKI") -> LAKI-LAKI | M35: =IFERROR(__xludf.DUMMYFUNCTION("""COMPUTED_VALUE"""),"JL. P. H. HUSIN 2") -> JL. P. H. HUSIN 2 | R35: =IFERROR(__xludf.DUMMYFUNCTION("""COMPUTED_VALUE"""),"ISLAM") -> ISLAM | S35: =IFERROR(__xludf.DUMMYFUNCTION("""COMPUTED_VALUE"""),"BUMN") -> BUMN | T35: =IFERROR(__xludf.DUMMYFUNCTION("""COMPUTED_VALUE"""),"BAHU KANAN") -> BAHU KANAN | U35: =IFERROR(__xludf.DUMMYFUNCTION("""COMPUTED_VALUE"""),"") | V35: =IFERROR(__xludf.DUMMYFUNCTION("""COMPUTED_VALUE"""),"081255802323") -> 081255802323
B36: =IFERROR(__xludf.DUMMYFUNCTION("""COMPUTED_VALUE"""),45006.890850497686) -> 45006.891 | D36: =IFERROR(__xludf.DUMMYFUNCTION("""COMPUTED_VALUE"""),44936.762511574074) -> 44936.763 | E36: =IFERROR(__xludf.DUMMYFUNCTION("""COMPUTED_VALUE"""),"01Jan") -> 01Jan | F36: =IFERROR(__xludf.DUMMYFUNCTION("""COMPUTED_VALUE"""),"2023") -> 2023 | G36: =IFERROR(__xludf.DUMMYFUNCTION("""COMPUTED_VALUE"""),"NURYANTO") -> NURYANTO | H36: =IFERROR(__xludf.DUMMYFUNCTION("""COMPUTED_VALUE"""),"N5423010002") -> N5423010002 | I36: =IFERROR(__xludf.DUMMYFUNCTION("""COMPUTED_VALUE"""),71.0) -> 71 | J36: =IFERROR(__xludf.DUMMYFUNCTION("""COMPUTED_VALUE"""),"> 44 tahun") -> > 44 tahun | K36: =IFERROR(__xludf.DUMMYFUNCTION("""COMPUTED_VALUE"""),19988.0) -> 19988 | L36: =IFERROR(__xludf.DUMMYFUNCTION("""COMPUTED_VALUE"""),"LAKI-LAKI") -> LAKI-LAKI | M36: =IFERROR(__xludf.DUMMYFUNCTION("""COMPUTED_VALUE"""),"JL. NIRBAYA NO. 3") -> JL. NIRBAYA NO. 3 | R36: =IFERROR(__xludf.DUMMYFUNCTION("""COMPUTED_VALUE"""),"ISLAM") -> ISLAM | S36: =IFERROR(__xludf.DUMMYFUNCTION("""COMPUTED_VALUE"""),"PENSIUN") -> PENSIUN | T36: =IFERROR(__xludf.DUMMYFUNCTION("""COMPUTED_VALUE"""),"KAKI KIRI") -> KAKI KIRI | U36: =IFERROR(__xludf.DUMMYFUNCTION("""COMPUTED_VALUE"""),"") | V36: =IFERROR(__xludf.DUMMYFUNCTION("""COMPUTED_VALUE"""),"081256340002") -> 081256340002
B37: =IFERROR(__xludf.DUMMYFUNCTION("""COMPUTED_VALUE"""),45010.53389464121) -> 45010.534 | D37: =IFERROR(__xludf.DUMMYFUNCTION("""COMPUTED_VALUE"""),44937.0) -> 44937 | E37: =IFERROR(__xludf.DUMMYFUNCTION("""COMPUTED_VALUE"""),"01Jan") -> 01Jan | F37: =IFERROR(__xludf.DUMMYFUNCTION("""COMPUTED_VALUE"""),"2023") -> 2023 | G37: =IFERROR(__xludf.DUMMYFUNCTION("""COMPUTED_VALUE"""),"DIMAS PANDU HIDAYATULLAH") -> DIMAS PANDU HIDAYATULLAH | H37: =IFERROR(__xludf.DUMMYFUNCTION("""COMPUTED_VALUE"""),"D0023011314") -> D0023011314 | I37: =IFERROR(__xludf.DUMMYFUNCTION("""COMPUTED_VALUE"""),26.0) -> 26 | J37: =IFERROR(__xludf.DUMMYFUNCTION("""COMPUTED_VALUE"""),"25-34 tahun") -> 25-34 tahun | K37: =IFERROR(__xludf.DUMMYFUNCTION("""COMPUTED_VALUE"""),36670.0) -> 36670 | L37: =IFERROR(__xludf.DUMMYFUNCTION("""COMPUTED_VALUE"""),"LAKI-LAKI") -> LAKI-LAKI | M37: =IFERROR(__xludf.DUMMYFUNCTION("""COMPUTED_VALUE"""),"JL. KOMYOS SOEDARSO GG. HIDAYAH") -> JL. KOMYOS SOEDARSO GG. HIDAYAH | R37: =IFERROR(__xludf.DUMMYFUNCTION("""COMPUTED_VALUE"""),"ISLAM") -> ISLAM | S37: =IFERROR(__xludf.DUMMYFUNCTION("""COMPUTED_VALUE"""),"PELAJAR/MAHASISWA") -> PELAJAR/MAHASISWA | T37: =IFERROR(__xludf.DUMMYFUNCTION("""COMPUTED_VALUE"""),"ANKLE") -> ANKLE | U37: =IFERROR(__xludf.DUMMYFUNCTION("""COMPUTED_VALUE"""),"") | V37: =IFERROR(__xludf.DUMMYFUNCTION("""COMPUTED_VALUE"""),"0895611361314") -> 0895611361314
B38: =IFERROR(__xludf.DUMMYFUNCTION("""COMPUTED_VALUE"""),45006.89271108796) -> 45006.893 | D38: =IFERROR(__xludf.DUMMYFUNCTION("""COMPUTED_VALUE"""),44937.0) -> 44937 | E38: =IFERROR(__xludf.DUMMYFUNCTION("""COMPUTED_VALUE"""),"01Jan") -> 01Jan | F38: =IFERROR(__xludf.DUMMYFUNCTION("""COMPUTED_VALUE"""),"2023") -> 2023 | G38: =IFERROR(__xludf.DUMMYFUNCTION("""COMPUTED_VALUE"""),"EIVA RADE SIHO") -> EIVA RADE SIHO | H38: =IFERROR(__xludf.DUMMYFUNCTION("""COMPUTED_VALUE"""),"E7623015810") -> E7623015810 | I38: =IFERROR(__xludf.DUMMYFUNCTION("""COMPUTED_VALUE"""),49.0) -> 49 | J38: =IFERROR(__xludf.DUMMYFUNCTION("""COMPUTED_VALUE"""),"> 44 tahun") -> > 44 tahun | K38: =IFERROR(__xludf.DUMMYFUNCTION("""COMPUTED_VALUE"""),28091.0) -> 28091 | L38: =IFERROR(__xludf.DUMMYFUNCTION("""COMPUTED_VALUE"""),"PEREMPUAN") -> PEREMPUAN | M38: =IFERROR(__xludf.DUMMYFUNCTION("""COMPUTED_VALUE"""),"JL PERINTIS GG MADRASAH BLOK E10") -> JL PERINTIS GG MADRASAH BLOK E10 | R38: =IFERROR(__xludf.DUMMYFUNCTION("""COMPUTED_VALUE"""),"PROTESTAN") -> PROTESTAN | S38: =IFERROR(__xludf.DUMMYFUNCTION("""COMPUTED_VALUE"""),"SWASTA") -> SWASTA | T38: =IFERROR(__xludf.DUMMYFUNCTION("""COMPUTED_VALUE"""),"TANGAN KANAN") -> TANGAN KANAN | U38: =IFERROR(__xludf.DUMMYFUNCTION("""COMPUTED_VALUE"""),"-") -> - | V38: =IFERROR(__xludf.DUMMYFUNCTION("""COMPUTED_VALUE"""),"08125705810") -> 08125705810
B39: =IFERROR(__xludf.DUMMYFUNCTION("""COMPUTED_VALUE"""),44931.62291666667) -> 44931.623 | D39: =IFERROR(__xludf.DUMMYFUNCTION("""COMPUTED_VALUE"""),44937.0) -> 44937 | E39: =IFERROR(__xludf.DUMMYFUNCTION("""COMPUTED_VALUE"""),"01Jan") -> 01Jan | F39: =IFERROR(__xludf.DUMMYFUNCTION("""COMPUTED_VALUE"""),"2023") -> 2023 | G39: =IFERROR(__xludf.DUMMYFUNCTION("""COMPUTED_VALUE"""),"ERICK TRIENARDO") -> ERICK TRIENARDO | H39: =IFERROR(__xludf.DUMMYFUNCTION("""COMPUTED_VALUE"""),"E9723014638") -> E9723014638 | I39: =IFERROR(__xludf.DUMMYFUNCTION("""COMPUTED_VALUE"""),29.0) -> 29 | J39: =IFERROR(__xludf.DUMMYFUNCTION("""COMPUTED_VALUE"""),"25-34 tahun") -> 25-34 tahun | K39: =IFERROR(__xludf.DUMMYFUNCTION("""COMPUTED_VALUE"""),35502.0) -> 35502 | L39: =IFERROR(__xludf.DUMMYFUNCTION("""COMPUTED_VALUE"""),"LAKI-LAKI") -> LAKI-LAKI | M39: =IFERROR(__xludf.DUMMYFUNCTION("""COMPUTED_VALUE"""),"DESA SEMUDUN") -> DESA SEMUDUN | R39: =IFERROR(__xludf.DUMMYFUNCTION("""COMPUTED_VALUE"""),"PROTESTAN") -> PROTESTAN | S39: =IFERROR(__xludf.DUMMYFUNCTION("""COMPUTED_VALUE"""),"SWASTA") -> SWASTA | T39: =IFERROR(__xludf.DUMMYFUNCTION("""COMPUTED_VALUE"""),"ANKLE") -> ANKLE | U39: =IFERROR(__xludf.DUMMYFUNCTION("""COMPUTED_VALUE"""),"") | V39: =IFERROR(__xludf.DUMMYFUNCTION("""COMPUTED_VALUE"""),"081348474638") -> 081348474638
B40: =IFERROR(__xludf.DUMMYFUNCTION("""COMPUTED_VALUE"""),44917.445069444446) -> 44917.445 | D40: =IFERROR(__xludf.DUMMYFUNCTION("""COMPUTED_VALUE"""),44937.0) -> 44937 | E40: =IFERROR(__xludf.DUMMYFUNCTION("""COMPUTED_VALUE"""),"01Jan") -> 01Jan | F40: =IFERROR(__xludf.DUMMYFUNCTION("""COMPUTED_VALUE"""),"2023") -> 2023 | G40: =IFERROR(__xludf.DUMMYFUNCTION("""COMPUTED_VALUE"""),"FLAVIUS PANGAREGO") -> FLAVIUS PANGAREGO | H40: =IFERROR(__xludf.DUMMYFUNCTION("""COMPUTED_VALUE"""),"F9623012859") -> F9623012859 | I40: =IFERROR(__xludf.DUMMYFUNCTION("""COMPUTED_VALUE"""),30.0) -> 30 | J40: =IFERROR(__xludf.DUMMYFUNCTION("""COMPUTED_VALUE"""),"25-34 tahun") -> 25-34 tahun | K40: =IFERROR(__xludf.DUMMYFUNCTION("""COMPUTED_VALUE"""),35203.0) -> 35203 | L40: =IFERROR(__xludf.DUMMYFUNCTION("""COMPUTED_VALUE"""),"LAKI-LAKI") -> LAKI-LAKI | M40: =IFERROR(__xludf.DUMMYFUNCTION("""COMPUTED_VALUE"""),"JL. AMPERA NO. B7") -> JL. AMPERA NO. B7 | R40: =IFERROR(__xludf.DUMMYFUNCTION("""COMPUTED_VALUE"""),"KATOLIK") -> KATOLIK | S40: =IFERROR(__xludf.DUMMYFUNCTION("""COMPUTED_VALUE"""),"ASN") -> ASN | U40: =IFERROR(__xludf.DUMMYFUNCTION("""COMPUTED_VALUE"""),"FUTSAL") -> FUTSAL | V40: =IFERROR(__xludf.DUMMYFUNCTION("""COMPUTED_VALUE"""),"082298792859") -> 082298792859
...

Sheet Pivot Table 176

Sheet 📝 Kunjungan
X1: ⏳ LIHAT DATA SEMESTER LALU
B2: SHIFT | C2: TIM | D2: ADMIN | E2: TANGGAL | F2: TAHUN | G2: BULAN | H2: HARI | I2: JAM | J2: FISIO | K2: LAYANAN | L2: NAMA PASIEN | M2: NO. RM | N2: USIA | O2: JENIS KELAMIN | P2: AGAMA | Q2: PEKERJAAN | R2: KELUHAN | S2: HOBI/AKTIVITAS SEHARI-HARI | T2: KEHADIRAN | U2: NO. SESI | V2: KETERANGAN | W2: ✅ | X2: CATATAN ADMIN
B3: PAGI | C3: {=IFNA(XLOOKUP(J3,'⚙️ Pengaturan'!$H$5:$H1508,'⚙️ Pengaturan'!$I$5:$I1508),"")} -> TIM Y | D3: SUCI | E3: 45931 | F3: =IF($E3="","",TEXT($E3,"YYYY")) -> 2025 | G3: =IF($E3="","",TEXT($E3,"MM")&TEXT($E3,"MMM")) -> 10Okt | H3: =IF($E3="","",TEXT($E3,"DDDD")) -> Rabu | I3: 09.00 | J3: WAHYU | K3: TERAPI AWAL | L3: AFNUR RIKI AMRULLAH | M3: =IFNA(VLOOKUP(L3,'🙎‍♂️ Pasien'!G:V,2,FALSE),"") -> A9025092121 | N3: =IFNA(VLOOKUP(L3,'🙎‍♂️ Pasien'!G:L,3,FALSE),"") -> 36 | O3: =IFNA(VLOOKUP(L3,'🙎‍♂️ Pasien'!G:V,6,FALSE),"") -> LAKI-LAKI | P3: =IFNA(VLOOKUP(L3,'🙎‍♂️ Pasien'!G:V,12,FALSE),"") -> ISLAM | Q3: =IFNA(VLOOKUP(L3:L1508,'🙎‍♂️ Pasien'!G:V,13,FALSE),"") -> WIRASWASTA | R3: {=ifna(xlookup(L3,'🙎‍♂️ Pasien'!$G$5:$G1508,'🙎‍♂️ Pasien'!$T$5:$T1508),"")} -> PINGGANG KECETIT | S3: {=ifna(xlookup(L3,'🙎‍♂️ Pasien'!$G$5:$G1508,'🙎‍♂️ Pasien'!$U$5:$U1508),"")} -> - | T3: HADIR | U3: - | V3: SUAMI DELILLA | W3: TRUE
B4: PAGI | C4: {=IFNA(XLOOKUP(J4,'⚙️ Pengaturan'!$H$5:$H1508,'⚙️ Pengaturan'!$I$5:$I1508),"")} -> TIM A | D4: SUCI | E4: 45931 | F4: =IF($E4="","",TEXT($E4,"YYYY")) -> 2025 | G4: =IF($E4="","",TEXT($E4,"MM")&TEXT($E4,"MMM")) -> 10Okt | H4: =IF($E4="","",TEXT($E4,"DDDD")) -> Rabu | I4: 09.00 | J4: HENA | K4: PAKET TERAPI | L4: RUDI HARTONO | M4: =IFNA(VLOOKUP(L4,'🙎‍♂️ Pasien'!G:V,2,FALSE),"") -> R2525091389 | N4: =IFNA(VLOOKUP(L4,'🙎‍♂️ Pasien'!G:L,3,FALSE),"") -> 1 | O4: =IFNA(VLOOKUP(L4,'🙎‍♂️ Pasien'!G:V,6,FALSE),"") -> LAKI-LAKI | P4: =IFNA(VLOOKUP(L4,'🙎‍♂️ Pasien'!G:V,12,FALSE),"") -> PROTESTAN | Q4: =IFNA(VLOOKUP(L4:L1508,'🙎‍♂️ Pasien'!G:V,13,FALSE),"") -> KARYAWAN | R4: {=ifna(xlookup(L4,'🙎‍♂️ Pasien'!$G$5:$G1508,'🙎‍♂️ Pasien'!$T$5:$T1508),"")} -> FROZEN SHOULDER | S4: {=ifna(xlookup(L4,'🙎‍♂️ Pasien'!$G$5:$G1508,'🙎‍♂️ Pasien'!$U$5:$U1508),"")} -> TIDAK BISA MAIN BADMINTON | T4: HADIR | U4: 1 | W4: TRUE
B5: PAGI | C5: {=IFNA(XLOOKUP(J5,'⚙️ Pengaturan'!$H$5:$H1508,'⚙️ Pengaturan'!$I$5:$I1508),"")} -> TIM A | D5: SUCI | E5: 45931 | F5: =IF($E5="","",TEXT($E5,"YYYY")) -> 2025 | G5: =IF($E5="","",TEXT($E5,"MM")&TEXT($E5,"MMM")) -> 10Okt | H5: =IF($E5="","",TEXT($E5,"DDDD")) -> Rabu | I5: 10.00 | J5: HENA | K5: PAKET TERAPI | L5: GRACIA IVANA GOUWYN | M5: =IFNA(VLOOKUP(L5,'🙎‍♂️ Pasien'!G:V,2,FALSE),"") -> G0425088990 | N5: =IFNA(VLOOKUP(L5,'🙎‍♂️ Pasien'!G:L,3,FALSE),"") -> 21 | O5: =IFNA(VLOOKUP(L5,'🙎‍♂️ Pasien'!G:V,6,FALSE),"") -> PEREMPUAN | P5: =IFNA(VLOOKUP(L5,'🙎‍♂️ Pasien'!G:V,12,FALSE),"") -> PROTESTAN | Q5: =IFNA(VLOOKUP(L5:L1508,'🙎‍♂️ Pasien'!G:V,13,FALSE),"") -> BUSINESS OWNER | R5: {=ifna(xlookup(L5,'🙎‍♂️ Pasien'!$G$5:$G1508,'🙎‍♂️ Pasien'!$T$5:$T1508),"")} -> TANGAN | S5: {=ifna(xlookup(L5,'🙎‍♂️ Pasien'!$G$5:$G1508,'🙎‍♂️ Pasien'!$U$5:$U1508),"")} -> BERMAIN TENNIS | T5: TIDAK HADIR | U5: - | V5: MAU PINDAH HARI ADA AGENDA DADAKAN | W5: TRUE
B6: PAGI | C6: {=IFNA(XLOOKUP(J6,'⚙️ Pengaturan'!$H$5:$H1508,'⚙️ Pengaturan'!$I$5:$I1508),"")} -> TIM A | D6: SUCI | E6: 45931 | F6: =IF($E6="","",TEXT($E6,"YYYY")) -> 2025 | G6: =IF($E6="","",TEXT($E6,"MM")&TEXT($E6,"MMM")) -> 10Okt | H6: =IF($E6="","",TEXT($E6,"DDDD")) -> Rabu | I6: 10.00 | J6: HENA | K6: SESI TERAPI | L6: LILI JARIAH | M6: =IFNA(VLOOKUP(L6,'🙎‍♂️ Pasien'!G:V,2,FALSE),"") -> L8125099600 | N6: =IFNA(VLOOKUP(L6,'🙎‍♂️ Pasien'!G:L,3,FALSE),"") -> 45 | O6: =IFNA(VLOOKUP(L6,'🙎‍♂️ Pasien'!G:V,6,FALSE),"") -> PEREMPUAN | P6: =IFNA(VLOOKUP(L6,'🙎‍♂️ Pasien'!G:V,12,FALSE),"") -> ISLAM | Q6: =IFNA(VLOOKUP(L6:L1508,'🙎‍♂️ Pasien'!G:V,13,FALSE),"") -> IRT | R6: {=ifna(xlookup(L6,'🙎‍♂️ Pasien'!$G$5:$G1508,'🙎‍♂️ Pasien'!$T$5:$T1508),"")} -> SAKIT PINGGANG KIRI | S6: {=ifna(xlookup(L6,'🙎‍♂️ Pasien'!$G$5:$G1508,'🙎‍♂️ Pasien'!$U$5:$U1508),"")} -> CATERING | T6: HADIR | U6: - | W6: TRUE
B7: PAGI | C7: {=IFNA(XLOOKUP(J7,'⚙️ Pengaturan'!$H$5:$H1508,'⚙️ Pengaturan'!$I$5:$I1508),"")} -> TIM Y | D7: SUCI | E7: 45931 | F7: =IF($E7="","",TEXT($E7,"YYYY")) -> 2025 | G7: =IF($E7="","",TEXT($E7,"MM")&TEXT($E7,"MMM")) -> 10Okt | H7: =IF($E7="","",TEXT($E7,"DDDD")) -> Rabu | I7: 10.00 | J7: WAHYU | K7: TERAPI AWAL | L7: LIM OI KHIUN ALS RIANA | M7: =IFNA(VLOOKUP(L7,'🙎‍♂️ Pasien'!G:V,2,FALSE),"") -> L5925109995 | N7: =IFNA(VLOOKUP(L7,'🙎‍♂️ Pasien'!G:L,3,FALSE),"") -> 67 | O7: =IFNA(VLOOKUP(L7,'🙎‍♂️ Pasien'!G:V,6,FALSE),"") -> PEREMPUAN | P7: =IFNA(VLOOKUP(L7,'🙎‍♂️ Pasien'!G:V,12,FALSE),"") -> KATOLIK | Q7: =IFNA(VLOOKUP(L7:L1508,'🙎‍♂️ Pasien'!G:V,13,FALSE),"") -> WIRASWASTA | R7: {=ifna(xlookup(L7,'🙎‍♂️ Pasien'!$G$5:$G1508,'🙎‍♂️ Pasien'!$T$5:$T1508),"")} -> LUTUT | S7: {=ifna(xlookup(L7,'🙎‍♂️ Pasien'!$G$5:$G1508,'🙎‍♂️ Pasien'!$U$5:$U1508),"")} -> IBU RUMAH TANGGA | T7: HADIR | U7: - | W7: TRUE
B8: PAGI | C8: {=IFNA(XLOOKUP(J8,'⚙️ Pengaturan'!$H$5:$H1508,'⚙️ Pengaturan'!$I$5:$I1508),"")} -> TIM A | D8: SUCI | E8: 45931 | F8: =IF($E8="","",TEXT($E8,"YYYY")) -> 2025 | G8: =IF($E8="","",TEXT($E8,"MM")&TEXT($E8,"MMM")) -> 10Okt | H8: =IF($E8="","",TEXT($E8,"DDDD")) -> Rabu | I8: 10.00 | J8: HESTI | K8: PAKET TERAPI | L8: LIM OI SIP ALS ERNY | M8: =IFNA(VLOOKUP(L8,'🙎‍♂️ Pasien'!G:V,2,FALSE),"") -> L5325099995 | N8: =IFNA(VLOOKUP(L8,'🙎‍♂️ Pasien'!G:L,3,FALSE),"") -> 73 | O8: =IFNA(VLOOKUP(L8,'🙎‍♂️ Pasien'!G:V,6,FALSE),"") -> PEREMPUAN | P8: =IFNA(VLOOKUP(L8,'🙎‍♂️ Pasien'!G:V,12,FALSE),"") -> KATOLIK | Q8: =IFNA(VLOOKUP(L8:L1508,'🙎‍♂️ Pasien'!G:V,13,FALSE),"") -> KARYAWAN SWASTA | R8: {=ifna(xlookup(L8,'🙎‍♂️ Pasien'!$G$5:$G1508,'🙎‍♂️ Pasien'!$T$5:$T1508),"")} -> OPERASI LUTUT | S8: {=ifna(xlookup(L8,'🙎‍♂️ Pasien'!$G$5:$G1508,'🙎‍♂️ Pasien'!$U$5:$U1508),"")} -> JALAN SEHAT | T8: HADIR | U8: 1 | W8: TRUE
B9: PAGI | C9: {=IFNA(XLOOKUP(J9,'⚙️ Pengaturan'!$H$5:$H1508,'⚙️ Pengaturan'!$I$5:$I1508),"")} -> TIM Y | D9: SUCI | E9: 45931 | F9: =IF($E9="","",TEXT($E9,"YYYY")) -> 2025 | G9: =IF($E9="","",TEXT($E9,"MM")&TEXT($E9,"MMM")) -> 10Okt | H9: =IF($E9="","",TEXT($E9,"DDDD")) -> Rabu | I9: 11.00 | J9: WAHYU | K9: PAKET TERAPI | L9: EDY HARTONO | M9: =IFNA(VLOOKUP(L9,'🙎‍♂️ Pasien'!G:V,2,FALSE),"") -> E7525090355 | N9: =IFNA(VLOOKUP(L9,'🙎‍♂️ Pasien'!G:L,3,FALSE),"") -> 51 | O9: =IFNA(VLOOKUP(L9,'🙎‍♂️ Pasien'!G:V,6,FALSE),"") -> LAKI-LAKI | P9: =IFNA(VLOOKUP(L9,'🙎‍♂️ Pasien'!G:V,12,FALSE),"") -> PROTESTAN | Q9: =IFNA(VLOOKUP(L9:L1508,'🙎‍♂️ Pasien'!G:V,13,FALSE),"") -> WIRAUSAHA | R9: {=ifna(xlookup(L9,'🙎‍♂️ Pasien'!$G$5:$G1508,'🙎‍♂️ Pasien'!$T$5:$T1508),"")} -> SAKIT DI BAHU | S9: {=ifna(xlookup(L9,'🙎‍♂️ Pasien'!$G$5:$G1508,'🙎‍♂️ Pasien'!$U$5:$U1508),"")} -> KARENA PUSH UP | T9: HADIR | U9: 4 | W9: TRUE
B10: PAGI | C10: {=IFNA(XLOOKUP(J10,'⚙️ Pengaturan'!$H$5:$H1508,'⚙️ Pengaturan'!$I$5:$I1508),"")} -> TIM A | D10: SUCI | E10: 45931 | F10: =IF($E10="","",TEXT($E10,"YYYY")) -> 2025 | G10: =IF($E10="","",TEXT($E10,"MM")&TEXT($E10,"MMM")) -> 10Okt | H10: =IF($E10="","",TEXT($E10,"DDDD")) -> Rabu | I10: 13.00 | J10: HESTI | K10: PAKET TERAPI | L10: AHMAD DANY NOVALDI | M10: =IFNA(VLOOKUP(L10,'🙎‍♂️ Pasien'!G:V,2,FALSE),"") -> A0625085349 | N10: =IFNA(VLOOKUP(L10,'🙎‍♂️ Pasien'!G:L,3,FALSE),"") -> 19 | O10: =IFNA(VLOOKUP(L10,'🙎‍♂️ Pasien'!G:V,6,FALSE),"") -> LAKI-LAKI | P10: =IFNA(VLOOKUP(L10,'🙎‍♂️ Pasien'!G:V,12,FALSE),"") -> ISLAM | Q10: =IFNA(VLOOKUP(L10:L1508,'🙎‍♂️ Pasien'!G:V,13,FALSE),"") -> PELAJAR/MAHASISWA | R10: {=ifna(xlookup(L10,'🙎‍♂️ Pasien'!$G$5:$G1508,'🙎‍♂️ Pasien'!$T$5:$T1508),"")} -> BAHU | S10: {=ifna(xlookup(L10,'🙎‍♂️ Pasien'!$G$5:$G1508,'🙎‍♂️ Pasien'!$U$5:$U1508),"")} -> SILAT | T10: TIDAK HADIR | U10: 5 | V10: ADA JADWAL UTS | W10: TRUE
B11: PAGI | C11: {=IFNA(XLOOKUP(J11,'⚙️ Pengaturan'!$H$5:$H1508,'⚙️ Pengaturan'!$I$5:$I1508),"")} -> TIM A | D11: SUCI | E11: 45931 | F11: =IF($E11="","",TEXT($E11,"YYYY")) -> 2025 | G11: =IF($E11="","",TEXT($E11,"MM")&TEXT($E11,"MMM")) -> 10Okt | H11: =IF($E11="","",TEXT($E11,"DDDD")) -> Rabu | I11: 13.00 | J11: OKTA | K11: PAKET TERAPI | L11: LENY SUMANTRI | M11: =IFNA(VLOOKUP(L11,'🙎‍♂️ Pasien'!G:V,2,FALSE),"") -> L8725094767 | N11: =IFNA(VLOOKUP(L11,'🙎‍♂️ Pasien'!G:L,3,FALSE),"") -> 38 | O11: =IFNA(VLOOKUP(L11,'🙎‍♂️ Pasien'!G:V,6,FALSE),"") -> PEREMPUAN | P11: =IFNA(VLOOKUP(L11,'🙎‍♂️ Pasien'!G:V,12,FALSE),"") -> KATOLIK | Q11: =IFNA(VLOOKUP(L11:L1508,'🙎‍♂️ Pasien'!G:V,13,FALSE),"") -> IBU RUMAH TANGGA | R11: {=ifna(xlookup(L11,'🙎‍♂️ Pasien'!$G$5:$G1508,'🙎‍♂️ Pasien'!$T$5:$T1508),"")} -> NYERI LEHER | S11: {=ifna(xlookup(L11,'🙎‍♂️ Pasien'!$G$5:$G1508,'🙎‍♂️ Pasien'!$U$5:$U1508),"")} -> KURANG GERAK | T11: HADIR | U11: 1 | W11: TRUE
B12: PAGI | C12: {=IFNA(XLOOKUP(J12,'⚙️ Pengaturan'!$H$5:$H1508,'⚙️ Pengaturan'!$I$5:$I1508),"")} -> MANAJEMEN | D12: SUCI | E12: 45931 | F12: =IF($E12="","",TEXT($E12,"YYYY")) -> 2025 | G12: =IF($E12="","",TEXT($E12,"MM")&TEXT($E12,"MMM")) -> 10Okt | H12: =IF($E12="","",TEXT($E12,"DDDD")) -> Rabu | I12: 13.00 | J12: EDO | K12: TERAPI AWAL | L12: SUHERDIYANTO, S.PD | M12: =IFNA(VLOOKUP(L12,'🙎‍♂️ Pasien'!G:V,2,FALSE),"") -> S8025102353 | N12: =IFNA(VLOOKUP(L12,'🙎‍♂️ Pasien'!G:L,3,FALSE),"") -> 46 | O12: =IFNA(VLOOKUP(L12,'🙎‍♂️ Pasien'!G:V,6,FALSE),"") -> LAKI-LAKI | P12: =IFNA(VLOOKUP(L12,'🙎‍♂️ Pasien'!G:V,12,FALSE),"") -> ISLAM | Q12: =IFNA(VLOOKUP(L12:L1508,'🙎‍♂️ Pasien'!G:V,13,FALSE),"") -> KARYAWAN HONORER | R12: {=ifna(xlookup(L12,'🙎‍♂️ Pasien'!$G$5:$G1508,'🙎‍♂️ Pasien'!$T$5:$T1508),"")} -> PINGGANG SAMPAI KAKI | S12: {=ifna(xlookup(L12,'🙎‍♂️ Pasien'!$G$5:$G1508,'🙎‍♂️ Pasien'!$U$5:$U1508),"")} -> SEPEDA DAN BULU TANGKIS | T12: HADIR | U12: - | W12: TRUE
B13: PAGI | C13: {=IFNA(XLOOKUP(J13,'⚙️ Pengaturan'!$H$5:$H1508,'⚙️ Pengaturan'!$I$5:$I1508),"")} -> TIM A | D13: SUCI | E13: 45931 | F13: =IF($E13="","",TEXT($E13,"YYYY")) -> 2025 | G13: =IF($E13="","",TEXT($E13,"MM")&TEXT($E13,"MMM")) -> 10Okt | H13: =IF($E13="","",TEXT($E13,"DDDD")) -> Rabu | I13: 14.00 | J13: HENA | K13: PAKET TERAPI | L13: MARIYAM | M13: =IFNA(VLOOKUP(L13,'🙎‍♂️ Pasien'!G:V,2,FALSE),"") -> M6825093469 | N13: =IFNA(VLOOKUP(L13,'🙎‍♂️ Pasien'!G:L,3,FALSE),"") -> 58 | O13: =IFNA(VLOOKUP(L13,'🙎‍♂️ Pasien'!G:V,6,FALSE),"") -> PEREMPUAN | P13: =IFNA(VLOOKUP(L13,'🙎‍♂️ Pasien'!G:V,12,FALSE),"") -> ISLAM | Q13: =IFNA(VLOOKUP(L13:L1508,'🙎‍♂️ Pasien'!G:V,13,FALSE),"") -> IBU RUMAH TANGGA | R13: {=ifna(xlookup(L13,'🙎‍♂️ Pasien'!$G$5:$G1508,'🙎‍♂️ Pasien'!$T$5:$T1508),"")} -> KAKI SAKIT SEKALI BERJALAN.. AWALNYA HANYA SATU KAKI YANG SAKIT PAS PULANG UMROH KAKI YANG TIDAK SAKIT JADI SAKIT SEKALI DAN SANGAT KESULITAN UNTUK BERJALAN DAN SAKITNYA SAMPE KE PINGGANG | S13: {=ifna(xlookup(L13,'🙎‍♂️ Pasien'!$G$5:$G1508,'🙎‍♂️ Pasien'!$U$5:$U1508),"")} -> ORANG YANG ULET, SUKA BEBERES, MASAK, NYIRAM TANAMAN, NYAPU, NGEPEL | T13: HADIR | U13: 3 | W13: TRUE
B14: SORE | C14: {=IFNA(XLOOKUP(J14,'⚙️ Pengaturan'!$H$5:$H1508,'⚙️ Pengaturan'!$I$5:$I1508),"")} -> TIM Y | D14: NOPI | E14: 45931 | F14: =IF($E14="","",TEXT($E14,"YYYY")) -> 2025 | G14: =IF($E14="","",TEXT($E14,"MM")&TEXT($E14,"MMM")) -> 10Okt | H14: =IF($E14="","",TEXT($E14,"DDDD")) -> Rabu | I14: 15.00 | J14: ORY | K14: SESI TERAPI | L14: FATI ARIFAH | M14: =IFNA(VLOOKUP(L14,'🙎‍♂️ Pasien'!G:V,2,FALSE),"") -> F1025103034 | N14: =IFNA(VLOOKUP(L14,'🙎‍♂️ Pasien'!G:L,3,FALSE),"") -> 16 | O14: =IFNA(VLOOKUP(L14,'🙎‍♂️ Pasien'!G:V,6,FALSE),"") -> PEREMPUAN | P14: =IFNA(VLOOKUP(L14,'🙎‍♂️ Pasien'!G:V,12,FALSE),"") -> ISLAM | Q14: =IFNA(VLOOKUP(L14:L1508,'🙎‍♂️ Pasien'!G:V,13,FALSE),"") -> MASIH SEKOLAH | R14: {=ifna(xlookup(L14,'🙎‍♂️ Pasien'!$G$5:$G1508,'🙎‍♂️ Pasien'!$T$5:$T1508),"")} -> PADA SAAT JALAN DEKAT MATA KAKI TERASA SAKIT | S14: {=ifna(xlookup(L14,'🙎‍♂️ Pasien'!$G$5:$G1508,'🙎‍♂️ Pasien'!$U$5:$U1508),"")} -> SILAT | T14: HADIR | U14: - | V14: BEASISWA BANG EDO | W14: TRUE
B15: SORE | C15: {=IFNA(XLOOKUP(J15,'⚙️ Pengaturan'!$H$5:$H1508,'⚙️ Pengaturan'!$I$5:$I1508),"")} -> TIM Y | D15: NOPI | E15: 45931 | F15: =IF($E15="","",TEXT($E15,"YYYY")) -> 2025 | G15: =IF($E15="","",TEXT($E15,"MM")&TEXT($E15,"MMM")) -> 10Okt | H15: =IF($E15="","",TEXT($E15,"DDDD")) -> Rabu | I15: 15.00 | J15: DESTY | K15: PAKET TERAPI | L15: HO HIAN KI | M15: =IFNA(VLOOKUP(L15,'🙎‍♂️ Pasien'!G:V,2,FALSE),"") -> H5024091565 | N15: =IFNA(VLOOKUP(L15,'🙎‍♂️ Pasien'!G:L,3,FALSE),"") -> 75 | O15: =IFNA(VLOOKUP(L15,'🙎‍♂️ Pasien'!G:V,6,FALSE),"") -> PEREMPUAN | P15: =IFNA(VLOOKUP(L15,'🙎‍♂️ Pasien'!G:V,12,FALSE),"") -> BUDDHA | Q15: =IFNA(VLOOKUP(L15:L1508,'🙎‍♂️ Pasien'!G:V,13,FALSE),"") -> RUMAH TANGGA | R15: {=ifna(xlookup(L15,'🙎‍♂️ Pasien'!$G$5:$G1508,'🙎‍♂️ Pasien'!$T$5:$T1508),"")} -> NYERI/KESEMUTAN DI PAHA KIRI | S15: {=ifna(xlookup(L15,'🙎‍♂️ Pasien'!$G$5:$G1508,'🙎‍♂️ Pasien'!$U$5:$U1508),"")} -> MENANAM BUNGA | T15: HADIR | U15: 6 | W15: TRUE
B16: SORE | C16: {=IFNA(XLOOKUP(J16,'⚙️ Pengaturan'!$H$5:$H1508,'⚙️ Pengaturan'!$I$5:$I1508),"")} -> TIM Y | D16: NOPI | E16: 45931 | F16: =IF($E16="","",TEXT($E16,"YYYY")) -> 2025 | G16: =IF($E16="","",TEXT($E16,"MM")&TEXT($E16,"MMM")) -> 10Okt | H16: =IF($E16="","",TEXT($E16,"DDDD")) -> Rabu | I16: 16.00 | J16: DESTY | K16: PAKET TERAPI | L16: AISHA NAJWA AQILA | M16: =IFNA(VLOOKUP(L16,'🙎‍♂️ Pasien'!G:V,2,FALSE),"") -> A0825098780 | N16: =IFNA(VLOOKUP(L16,'🙎‍♂️ Pasien'!G:L,3,FALSE),"") -> 18 | O16: =IFNA(VLOOKUP(L16,'🙎‍♂️ Pasien'!G:V,6,FALSE),"") -> PEREMPUAN | P16: =IFNA(VLOOKUP(L16,'🙎‍♂️ Pasien'!G:V,12,FALSE),"") -> ISLAM | Q16: =IFNA(VLOOKUP(L16:L1508,'🙎‍♂️ Pasien'!G:V,13,FALSE),"") -> PELAJAR | R16: {=ifna(xlookup(L16,'🙎‍♂️ Pasien'!$G$5:$G1508,'🙎‍♂️ Pasien'!$T$5:$T1508),"")} -> SAKIT DI LUTUT | S16: {=ifna(xlookup(L16,'🙎‍♂️ Pasien'!$G$5:$G1508,'🙎‍♂️ Pasien'!$U$5:$U1508),"")} -> MAIN BASKET | T16: HADIR | U16: 2 | W16: TRUE
