Workbook

Sheet READ ME
B2: Pencatatan Keuangan Klinik Kesehatan
B3: 45056
B6: >> Akses file preview ini hanya comment only. Pastikan untuk membuat duplikasi file terlebih dahulu dengan cara klik menu File > Make a copy. Abaikan pesan ini jika saat klik link dari KaryaKarsa pertama kali kamu sudah membuat duplikasi file.
B8: Tentang:
B9: Template Google sheet pencatatan keuangan untuk klinik kesehatan ini dapat membantu kamu mengelola keuangan usahamu menjadi lebih tertata. Template pengelola keuangan ini terdiri 7 sheet yang dapat digunakan langsung. Dirancang sesederhana mungkin agar dapat digunakan semua kalangan, dan juga sudah dilengkapi kolom untuk masing-masing bulan agar dapat digunakan sepanjang tahun.
B13: Panduan:
B14: 1. Saat pertama kali menggunakan template ini, pastikan kamu menyesuaikan beberapa pengaturan umum pada sheet ⚙️Pengaturan. Atur Nama Usaha, Jenis Pemeriksaan, Harga Paket, Jenis Pengeluaran, dan Nama Dokter.
B15: 2. Setiap kali terjadi transaksi pendapatan/pemasukan, silahkan catat trasaksinya pada sheet Pendapatan. Pilih tanggal terjadinya transaksi dengan cara klik 2x pada kolom D, sesuaikan nama produk, lalu nominal transaksi akan otomatis terisi.
B16: 3. Lakukan hal yg sama seperti panduan nomor 2 untuk setiap transaksi pengeluaran pada sheet Pengeluaran.
B17: 3. Jika data yg kamu masukan sudah sesuai, silahkan cek pada sheet Arus Kas untuk akumulasi transaksi yg sudah dicatat. Lihat pada bagian atas untuk kolom sesuai bulan berjalan.
B18: 4. Untuk rekap transaksi, silahkan cek pada sheet Laporan. Pada sheet ini kamu dapat melihat ringkasan transaksi secara bulanan maupun dalam periode waktu tertentu dengan mengganti tanggal mulai dan selesai laporan. [NEW!]
B20: Catatan:
B21: ⚡Fitur ceklis yang tersedia tidak memengaruhi formula maupun sheet lainnya. Ceklis ini hanya mempermudah untuk sortir transaksi.
B22: ⚡ Beberapa fitur pada spreadsheet ini kemungkinan belum support jika digunakan lewat aplikasi Excel. Untuk penggunaan maksimal, pastikan hanya melakukan editing lewat Google sheet.
... B29: Terima kasih karena sudah mendukung Template Google sheet ini lewat KaryaKarsa! :)
G31: by: @andreqve

Sheet Pemasukan
B2: Pencatatan Kunjungan Pasien
B4: Tanggal: | D4: =TODAY() -> 46314 | J4: ='⚙️Pengaturan'!B3 -> Fisioterapi Gang Sehat Singkawang
B6: ✓ | C6: No. | D6: Tanggal | E6: Nama Pasien | F6: Jenis Pemeriksaan | G6: Harga Paket | H6: Pembayaran | I6: Biaya Lainnya | J6: Total Biaya
B8: FALSE | C8: {=SEQUENCE(1000,"1")} -> 1 | D8: 45293 | E8: Ny. Wahdah Siti Aisyah | F8: Terapi Awal | G8: =SUMPRODUCT(('⚙️Pengaturan'!$C$3:$C$100=$F8)*('⚙️Pengaturan'!$D$3:$D$100)) -> 250000 | H8: TUNAI | J8: =G8-I8 -> 250000
B9: FALSE | C9: 2 | D9: 45293 | E9: Ny. Bong Lin Tju | F9: Terapi Awal | G9: =SUMPRODUCT(('⚙️Pengaturan'!$C$3:$C$100=$F9)*('⚙️Pengaturan'!$D$3:$D$100)) -> 250000 | H9: TUNAI | J9: =G9-I9 -> 250000
B10: FALSE | C10: 3 | D10: 45295 | E10: Ny. IRA MAYASITA, ST | F10: Terapi Awal | G10: =SUMPRODUCT(('⚙️Pengaturan'!$C$3:$C$100=$F10)*('⚙️Pengaturan'!$D$3:$D$100)) -> 250000 | H10: TUNAI | J10: =G10-I10 -> 250000
B11: FALSE | C11: 4 | D11: 45297 | E11: Ny. NOVITA SARI | F11: Sesi Terapi | G11: =SUMPRODUCT(('⚙️Pengaturan'!$C$3:$C$100=$F11)*('⚙️Pengaturan'!$D$3:$D$100)) -> 150000 | H11: TUNAI | J11: =G11-I11 -> 150000
B12: FALSE | C12: 5 | D12: 45297 | E12: Ny. Bong Lin Tju | F12: Sesi Terapi | G12: =SUMPRODUCT(('⚙️Pengaturan'!$C$3:$C$100=$F12)*('⚙️Pengaturan'!$D$3:$D$100)) -> 150000 | H12: TUNAI | J12: =G12-I12 -> 150000
B13: FALSE | C13: 6 | D13: 45298 | E13: Ny. Jaimah | F13: Terapi Awal | G13: =SUMPRODUCT(('⚙️Pengaturan'!$C$3:$C$100=$F13)*('⚙️Pengaturan'!$D$3:$D$100)) -> 250000 | H13: TUNAI | J13: =G13-I13 -> 250000
B14: FALSE | C14: 7 | D14: 45299 | E14: Tn. MUJIBURRAHMAN | F14: Terapi Awal | G14: =SUMPRODUCT(('⚙️Pengaturan'!$C$3:$C$100=$F14)*('⚙️Pengaturan'!$D$3:$D$100)) -> 250000 | H14: TUNAI | J14: =G14-I14 -> 250000
B15: FALSE | C15: 8 | D15: 45299 | E15: Tn. MUJIBURRAHMAN | F15: Paket Terapi 1 | G15: =SUMPRODUCT(('⚙️Pengaturan'!$C$3:$C$100=$F15)*('⚙️Pengaturan'!$D$3:$D$100)) -> 650000 | H15: TUNAI | I15: 450000 | J15: =G15-I15 -> 200000
B16: FALSE | C16: 9 | D16: 45299 | E16: Ny. Julia | F16: Sesi Terapi | G16: =SUMPRODUCT(('⚙️Pengaturan'!$C$3:$C$100=$F16)*('⚙️Pengaturan'!$D$3:$D$100)) -> 150000 | H16: TUNAI | J16: =G16-I16 -> 150000
B17: FALSE | C17: 10 | D17: 45299 | E17: Tn. Hengky chandra | F17: Terapi Awal | G17: =SUMPRODUCT(('⚙️Pengaturan'!$C$3:$C$100=$F17)*('⚙️Pengaturan'!$D$3:$D$100)) -> 250000 | H17: TUNAI | J17: =G17-I17 -> 250000
B18: FALSE | C18: 11 | D18: 45300 | E18: Ny. Sofiana mandawati | F18: Terapi Awal | G18: =SUMPRODUCT(('⚙️Pengaturan'!$C$3:$C$100=$F18)*('⚙️Pengaturan'!$D$3:$D$100)) -> 250000 | H18: TRF | J18: =G18-I18 -> 250000
B19: FALSE | C19: 12 | D19: 45301 | E19: Ny. Bong Lin Tju | F19: Sesi Terapi | G19: =SUMPRODUCT(('⚙️Pengaturan'!$C$3:$C$100=$F19)*('⚙️Pengaturan'!$D$3:$D$100)) -> 150000 | H19: TUNAI | J19: =G19-I19 -> 150000
B20: FALSE | C20: 13 | D20: 45301 | E20: Ny. SETIAWATI | F20: Terapi Awal | G20: =SUMPRODUCT(('⚙️Pengaturan'!$C$3:$C$100=$F20)*('⚙️Pengaturan'!$D$3:$D$100)) -> 250000 | H20: TRF | J20: =G20-I20 -> 250000
B21: FALSE | C21: 14 | D21: 45301 | E21: Ny. SETIAWATI | F21: Paket Terapi 2 | G21: =SUMPRODUCT(('⚙️Pengaturan'!$C$3:$C$100=$F21)*('⚙️Pengaturan'!$D$3:$D$100)) -> 1200000 | H21: TRF | J21: =G21-I21 -> 1200000
B22: FALSE | C22: 15 | D22: 45302 | E22: Nn. Mira | F22: Terapi Awal | G22: =SUMPRODUCT(('⚙️Pengaturan'!$C$3:$C$100=$F22)*('⚙️Pengaturan'!$D$3:$D$100)) -> 250000 | H22: TRF | J22: =G22-I22 -> 250000
B23: FALSE | C23: 16 | D23: 45304 | E23: Ny. JAIMAH | F23: Paket Terapi 1 | G23: =SUMPRODUCT(('⚙️Pengaturan'!$C$3:$C$100=$F23)*('⚙️Pengaturan'!$D$3:$D$100)) -> 650000 | H23: TUNAI | J23: =G23-I23 -> 650000
B24: FALSE | C24: 17 | D24: 45304 | E24: Tn. MUJIBURRAHMAN | F24: Paket Terapi 1 | G24: =SUMPRODUCT(('⚙️Pengaturan'!$C$3:$C$100=$F24)*('⚙️Pengaturan'!$D$3:$D$100)) -> 650000 | H24: TUNAI | I24: 200000 | J24: =G24-I24 -> 450000
B25: FALSE | C25: 18 | D25: 45305 | E25: Tn. Hengky chandra | F25: Sesi Terapi | G25: =SUMPRODUCT(('⚙️Pengaturan'!$C$3:$C$100=$F25)*('⚙️Pengaturan'!$D$3:$D$100)) -> 150000 | H25: TUNAI | J25: =G25-I25 -> 150000
B26: FALSE | C26: 19 | D26: 45306 | E26: Tn. Tjhang Fendi | F26: Terapi Awal | G26: =SUMPRODUCT(('⚙️Pengaturan'!$C$3:$C$100=$F26)*('⚙️Pengaturan'!$D$3:$D$100)) -> 250000 | H26: TUNAI | J26: =G26-I26 -> 250000
B27: FALSE | C27: 20 | D27: 45306 | E27: Tn. Tjhang Fendi | F27: Paket Terapi 1 | G27: =SUMPRODUCT(('⚙️Pengaturan'!$C$3:$C$100=$F27)*('⚙️Pengaturan'!$D$3:$D$100)) -> 650000 | H27: TUNAI | I27: 450000 | J27: =G27-I27 -> 200000
B28: FALSE | C28: 21 | D28: 45308 | E28: Tn. RASYID MUKHTABAR | F28: Paket Terapi 1 | G28: =SUMPRODUCT(('⚙️Pengaturan'!$C$3:$C$100=$F28)*('⚙️Pengaturan'!$D$3:$D$100)) -> 650000 | H28: TUNAI | J28: =G28-I28 -> 650000
B29: FALSE | C29: 22 | D29: 45308 | E29: Tn. Zulfahmi | F29: Terapi Awal | G29: =SUMPRODUCT(('⚙️Pengaturan'!$C$3:$C$100=$F29)*('⚙️Pengaturan'!$D$3:$D$100)) -> 250000 | H29: TUNAI | J29: =G29-I29 -> 250000
B30: FALSE | C30: 23 | D30: 45308 | E30: Tn. Albert Kadir | F30: Sesi Terapi | G30: =SUMPRODUCT(('⚙️Pengaturan'!$C$3:$C$100=$F30)*('⚙️Pengaturan'!$D$3:$D$100)) -> 150000 | H30: TUNAI | J30: =G30-I30 -> 150000
B31: FALSE | C31: 24 | D31: 45309 | E31: Ny. CATHARINA DJUNAIDI | F31: Paket Terapi 2 | G31: =SUMPRODUCT(('⚙️Pengaturan'!$C$3:$C$100=$F31)*('⚙️Pengaturan'!$D$3:$D$100)) -> 1200000 | H31: TUNAI | I31: 900000 | J31: =G31-I31 -> 300000
B32: FALSE | C32: 25 | D32: 45309 | E32: Tn. IRVAN YUSSIANDI | F32: Terapi Awal | G32: =SUMPRODUCT(('⚙️Pengaturan'!$C$3:$C$100=$F32)*('⚙️Pengaturan'!$D$3:$D$100)) -> 250000 | H32: TUNAI | J32: =G32-I32 -> 250000
B33: FALSE | C33: 26 | D33: 45309 | E33: Tn. Tjhang Fendi | F33: Paket Terapi 1 | G33: =SUMPRODUCT(('⚙️Pengaturan'!$C$3:$C$100=$F33)*('⚙️Pengaturan'!$D$3:$D$100)) -> 650000 | H33: TUNAI | I33: 200000 | J33: =G33-I33 -> 450000
B34: FALSE | C34: 27 | D34: 45309 | E34: Ny. IRA MAYASITA, ST | F34: Sesi Terapi | G34: =SUMPRODUCT(('⚙️Pengaturan'!$C$3:$C$100=$F34)*('⚙️Pengaturan'!$D$3:$D$100)) -> 150000 | H34: TUNAI | J34: =G34-I34 -> 150000
B35: FALSE | C35: 28 | D35: 45309 | E35: Tn. Ade Mariadi | F35: Paket Terapi 2 | G35: =SUMPRODUCT(('⚙️Pengaturan'!$C$3:$C$100=$F35)*('⚙️Pengaturan'!$D$3:$D$100)) -> 1200000 | H35: TUNAI | I35: 600000 | J35: =G35-I35 -> 600000
B36: FALSE | C36: 29 | D36: 45311 | E36: Tn. WASIMAN | F36: Terapi Awal | G36: =SUMPRODUCT(('⚙️Pengaturan'!$C$3:$C$100=$F36)*('⚙️Pengaturan'!$D$3:$D$100)) -> 250000 | H36: TUNAI | J36: =G36-I36 -> 250000
B37: FALSE | C37: 30 | D37: 45311 | E37: Tn. WASIMAN | F37: Paket Terapi 1 | G37: =SUMPRODUCT(('⚙️Pengaturan'!$C$3:$C$100=$F37)*('⚙️Pengaturan'!$D$3:$D$100)) -> 650000 | H37: TUNAI | I37: 450000 | J37: =G37-I37 -> 200000
B38: FALSE | C38: 31 | D38: 45311 | E38: Nn. Queenshya Theda Dilans | F38: Terapi Awal | G38: =SUMPRODUCT(('⚙️Pengaturan'!$C$3:$C$100=$F38)*('⚙️Pengaturan'!$D$3:$D$100)) -> 250000 | H38: TUNAI | J38: =G38-I38 -> 250000
B39: FALSE | C39: 32 | D39: 45312 | E39: Tn. DULHADI USMAN | F39: Terapi Awal Homevisit | G39: =SUMPRODUCT(('⚙️Pengaturan'!$C$3:$C$100=$F39)*('⚙️Pengaturan'!$D$3:$D$100)) -> 300000 | H39: TUNAI | J39: =G39-I39 -> 300000
B40: FALSE | C40: 33 | D40: 45313 | E40: Ny. NOVITA SARI | F40: Sesi Terapi | G40: =SUMPRODUCT(('⚙️Pengaturan'!$C$3:$C$100=$F40)*('⚙️Pengaturan'!$D$3:$D$100)) -> 150000 | H40: TUNAI | J40: =G40-I40 -> 150000
B41: FALSE | C41: 34 | D41: 45313 | E41: Tn. WASIMAN | F41: Paket Terapi 1 | G41: =SUMPRODUCT(('⚙️Pengaturan'!$C$3:$C$100=$F41)*('⚙️Pengaturan'!$D$3:$D$100)) -> 650000 | H41: TUNAI | I41: 200000 | J41: =G41-I41 -> 450000
B42: FALSE | C42: 35 | D42: 45313 | E42: Ny. Ani Roniah | F42: Terapi Awal | G42: =SUMPRODUCT(('⚙️Pengaturan'!$C$3:$C$100=$F42)*('⚙️Pengaturan'!$D$3:$D$100)) -> 250000 | H42: TUNAI | J42: =G42-I42 -> 250000
B43: FALSE | C43: 36 | D43: 45314 | E43: Tn. DULHADI USMAN | F43: Sesi terapi Homevisit | G43: =SUMPRODUCT(('⚙️Pengaturan'!$C$3:$C$100=$F43)*('⚙️Pengaturan'!$D$3:$D$100)) -> 200000 | H43: TUNAI | J43: =G43-I43 -> 200000
B44: FALSE | C44: 37 | D44: 45314 | E44: Ny. Queenshya Theda Dilans | F44: Paket Terapi 1 | G44: =SUMPRODUCT(('⚙️Pengaturan'!$C$3:$C$100=$F44)*('⚙️Pengaturan'!$D$3:$D$100)) -> 650000 | H44: TUNAI | J44: =G44-I44 -> 650000
...

Sheet Pengeluaran
B4: Tanggal: | D4: =TODAY() -> 46314 | G4: ='⚙️Pengaturan'!B3 -> Fisioterapi Gang Sehat Singkawang
B6: ✓ | C6: No. | D6: Tanggal | E6: Kategori | F6: Nominal | G6: Detail Pencatatan | H6: Instansi
B8: FALSE | C8: {=SEQUENCE(1000,"1")} -> 1 | D8: 45383 | E8: Beban Kebersihan | F8: 25500 | G8: Hit | H8: TUNAI
B9: FALSE | C9: 2 | D9: 45383 | E9: Beban Kebersihan | F9: 25500 | G9: Stella | H9: TUNAI
B10: FALSE | C10: 3 | D10: 45383 | E10: Beban Pelayanan | F10: 2000 | G10: Es Batu | H10: TUNAI
B11: FALSE | C11: 4 | D11: 45384 | E11: Beban Listrik | F11: 201901 | G11: Token Listrik | H11: TUNAI
B12: FALSE | C12: 5 | D12: 45384 | E12: Beban Pelayanan | F12: 4000 | G12: Es Batu | H12: TUNAI
B13: FALSE | C13: 6 | D13: 45385 | E13: Beban Pelayanan | F13: 4000 | G13: Es Batu | H13: TUNAI
B14: FALSE | C14: 7 | D14: 45385 | E14: Beban Kebersihan | F14: 1000 | G14: Molto | H14: TUNAI
B15: FALSE | C15: 8 | D15: 45386 | E15: Beban Pelayanan | F15: 4000 | G15: Es Batu | H15: TUNAI
B16: FALSE | C16: 9 | D16: 45388 | E16: Beban Pelayanan | F16: 2000 | G16: Es Batu | H16: TUNAI
B17: FALSE | C17: 10 | D17: 45388 | E17: Beban Pelayanan | F17: 16500 | G17: Laundry Handuk | H17: TUNAI
B18: FALSE | C18: 11 | D18: 45389 | E18: Beban Kebersihan | F18: 15000 | G18: Cetak Banner Pengumuman | H18: TUNAI
B19: FALSE | C19: 12 | D19: 45389 | E19: Beban Pelayanan | F19: 3500 | G19: Sikat Gigi | H19: TUNAI
B20: FALSE | C20: 13 | D20: 45397 | E20: Beban Pelayanan | F20: 2500 | G20: Es Batu | H20: TUNAI
... B261: FALSE | C261: 254 | D261: 45531 | E261: Beban Kebersihan | F261: 16500 | G261: Laundry Handuk | H261: TUNAI
B262: FALSE | C262: 255 | D262: 45531 | E262: Beban Gaji Pegawai | F262: 11767500 | H262: TUNAI
B263: FALSE | C263: 256 | D263: 45532 | E263: Beban Kebersihan | F263: 12000 | G263: Plastik Sampah | H263: TUNAI
B264: FALSE | C264: 257 | D264: 45532 | E264: Beban Pelayanan Dewasa | F264: 22000 | G264: Baby Oil | H264: TUNAI
B265: FALSE | C265: 258 | D265: 45533 | E265: Beban Pelayanan Dewasa | F265: 33000 | G265: Mineral 600ml/box | H265: TUNAI
B266: FALSE | C266: 259 | D266: 45533 | E266: Beban Pelayanan Dewasa | F266: 2500 | G266: es batu | H266: TUNAI
B267: FALSE | C267: 260 | D267: 45533 | E267: Beban Pelayanan Dewasa | F267: 13000 | G267: Galon | H267: TUNAI
B268: FALSE | C268: 261 | D268: 45533 | E268: Beban Pelayanan Dewasa | F268: 2000 | G268: Es Batu | H268: TUNAI
B269: FALSE | C269: 262 | D269: 45534 | E269: Beban Pelayanan Dewasa | F269: 33000 | G269: Tisu | H269: TUNAI
B270: FALSE | C270: 263 | D270: 45535 | E270: Beban ATK | F270: 12500 | G270: Clip Board | H270: TUNAI
B271: FALSE | C271: 264 | D271: 45535 | E271: Beban Promosi | F271: 10000 | G271: Hansapast Plester | H271: TUNAI
B272: FALSE | C272: 265 | D272: 45535 | E272: Beban Promosi | F272: 8000 | G272: Kasa | H272: TUNAI
B273: FALSE | C273: 266 | D273: 45535 | E273: Beban Promosi | F273: 29500 | G273: Plastik Warp | H273: TUNAI
B274: FALSE | C274: 267 | D274: 45535 | E274: Beban Pelayanan Dewasa | F274: 2500 | G274: Es Batu | H274: TUNAI
... B330: FALSE | C330: 323 | D330: 45561 | E330: Beban Pelayanan Dewasa | F330: 2500 | G330: Es Batu | H330: TUNAI
B331: FALSE | C331: 324 | D331: 45561 | E331: Beban Gaji Pegawai | F331: =8527000+1100+1750000 -> 10278100 | G331: Total gaji + partime | H331: TRF
B332: FALSE | C332: 325 | D332: 45563 | E332: Beban Pelayanan Dewasa | F332: 13000 | G332: Galon | H332: TUNAI
B333: FALSE | C333: 326 | D333: 45563 | E333: Beban Pelayanan Dewasa | F333: 2500 | G333: Es Batu | H333: TUNAI
B334: FALSE | C334: 327 | D334: 45563 | E334: Beban Gaji Pegawai | F334: 150000 | G334: Gaji Pengganti Admin | H334: TUNAI
B335: FALSE | C335: 328 | D335: 45564 | E335: Beban Pelayanan Dewasa | F335: Rp. 2.500 | G335: Es Batu | H335: TUNAI
B336: FALSE | C336: 329 | D336: 45565 | E336: Beban Pelayanan Dewasa | F336: 64500 | G336: Pad Tes | H336: TUNAI
B337: FALSE | C337: 330 | D337: 45565 | E337: Beban Pelayanan Dewasa | F337: 2500 | G337: Es Batu | H337: TUNAI
B338: FALSE | C338: 331 | D338: 45565 | E338: Beban pemeliharaan bangunan | F338: 50000 | G338: Las Kursi | H338: TUNAI
B339: FALSE | C339: 332 | D339: 45566 | E339: Beban Listrik | F339: 202351 | G339: Token Listrik | H339: TUNAI
B340: FALSE | C340: 333 | D340: 45566 | E340: Beban Pelayanan Dewasa | F340: 5000 | G340: Es Batu | H340: TUNAI
...

Sheet Laporan
B2: Dashboard Laporan Transaksi 📊 | J2: Tahun: | K2: =TEXT(TODAY(), "YYYY") -> 2026 | L2: =MONTH(DATEVALUE(K3&" 1")) -> 10
J3: Bulan: | K3: Oktober
E5: Ringkasan Bulanan 📊
B7: Total Pemeriksaan | E7: Nilai Transaksi | H7: Total Pengeluaran | K7: Laba Bersih
B8: =COUNTIFS(Pemasukan!D:D, ">="&DATE(YEAR(TODAY()), L2, 1), Pemasukan!D:D, "<="&EOMONTH(DATE(YEAR(TODAY()), L2, 1), 0), Pemasukan!D:D, "<>") -> 1 | E8: {=INDIRECT("Arus Kas!" & CHAR(66 + L2) & "25")} -> 0 | H8: {=INDIRECT("Arus Kas!" & CHAR(66 + L2) & "40")} -> 0 | K8: {=INDIRECT("Arus Kas!" & CHAR(66 + L2) & "45")} -> 254600
E29: Laporan Harian 📊 | K29: Start 🡓 | L29: 🡓 End
K30: 45292 | L30: 45322
B32: Rekap Jenis Pemeriksaan 💊 | H32: Rekap Transaksi Dokter 🩺
B33: Nama Paket/Obat | D33: Total | E33: Nominal | F33: Catatan | H33: Nama Dokter | J33: Total | K33: Nominal | L33: Catatan
B34: ='⚙️Pengaturan'!C3 -> New Paket Terapi 1 | D34: =COUNTIFS(Pemasukan!$D:$D, ">="&TEXT($K$30, "DD/MM/YYYY"), Pemasukan!$D:$D, "<="&TEXT($L$30, "DD/MM/YYYY"), Pemasukan!$F:$F, B34) -> 0 | E34: =SUMIFS(Pemasukan!$J:$J, Pemasukan!$D:$D, ">="&TEXT($K$30, "DD/MM/YYYY"), Pemasukan!$D:$D, "<="&TEXT($L$30, "DD/MM/YYYY"), Pemasukan!$F:$F, B34) -> 0 | H34: ='⚙️Pengaturan'!F3 -> TRF | J34: =COUNTIFS(Pemasukan!$D:$D, ">="&TEXT($K$30, "DD/MM/YYYY"), Pemasukan!$D:$D, "<="&TEXT($L$30, "DD/MM/YYYY"), Pemasukan!$H:$H, H34) -> 8 | K34: =SUMIFS(Pemasukan!$J:$J, Pemasukan!$D:$D, ">="&TEXT($K$30, "DD/MM/YYYY"), Pemasukan!$D:$D, "<="&TEXT($L$30, "DD/MM/YYYY"), Pemasukan!$H:$H, H34) -> 4950000
B35: =#REF! -> #REF! | D35: =COUNTIFS(Pemasukan!$D:$D, ">="&TEXT($K$30, "DD/MM/YYYY"), Pemasukan!$D:$D, "<="&TEXT($L$30, "DD/MM/YYYY"), Pemasukan!$F:$F, B35) -> 0 | E35: =SUMIFS(Pemasukan!$J:$J, Pemasukan!$D:$D, ">="&TEXT($K$30, "DD/MM/YYYY"), Pemasukan!$D:$D, "<="&TEXT($L$30, "DD/MM/YYYY"), Pemasukan!$F:$F, B35) -> 0 | H35: ='⚙️Pengaturan'!F4 -> TUNAI | J35: =COUNTIFS(Pemasukan!$D:$D, ">="&TEXT($K$30, "DD/MM/YYYY"), Pemasukan!$D:$D, "<="&TEXT($L$30, "DD/MM/YYYY"), Pemasukan!$H:$H, H35) -> 45 | K35: =SUMIFS(Pemasukan!$J:$J, Pemasukan!$D:$D, ">="&TEXT($K$30, "DD/MM/YYYY"), Pemasukan!$D:$D, "<="&TEXT($L$30, "DD/MM/YYYY"), Pemasukan!$H:$H, H35) -> 13850000
B36: =#REF! -> #REF! | D36: =COUNTIFS(Pemasukan!$D:$D, ">="&TEXT($K$30, "DD/MM/YYYY"), Pemasukan!$D:$D, "<="&TEXT($L$30, "DD/MM/YYYY"), Pemasukan!$F:$F, B36) -> 0 | E36: =SUMIFS(Pemasukan!$J:$J, Pemasukan!$D:$D, ">="&TEXT($K$30, "DD/MM/YYYY"), Pemasukan!$D:$D, "<="&TEXT($L$30, "DD/MM/YYYY"), Pemasukan!$F:$F, B36) -> 0 | H36: ='⚙️Pengaturan'!F5 | J36: =COUNTIFS(Pemasukan!$D:$D, ">="&TEXT($K$30, "DD/MM/YYYY"), Pemasukan!$D:$D, "<="&TEXT($L$30, "DD/MM/YYYY"), Pemasukan!$H:$H, H36) -> 0 | K36: =SUMIFS(Pemasukan!$J:$J, Pemasukan!$D:$D, ">="&TEXT($K$30, "DD/MM/YYYY"), Pemasukan!$D:$D, "<="&TEXT($L$30, "DD/MM/YYYY"), Pemasukan!$H:$H, H36) -> 0
B37: ='⚙️Pengaturan'!C4 -> New Paket Terapi 2 | D37: =COUNTIFS(Pemasukan!$D:$D, ">="&TEXT($K$30, "DD/MM/YYYY"), Pemasukan!$D:$D, "<="&TEXT($L$30, "DD/MM/YYYY"), Pemasukan!$F:$F, B37) -> 0 | E37: =SUMIFS(Pemasukan!$J:$J, Pemasukan!$D:$D, ">="&TEXT($K$30, "DD/MM/YYYY"), Pemasukan!$D:$D, "<="&TEXT($L$30, "DD/MM/YYYY"), Pemasukan!$F:$F, B37) -> 0 | H37: ='⚙️Pengaturan'!F6 | J37: =COUNTIFS(Pemasukan!$D:$D, ">="&TEXT($K$30, "DD/MM/YYYY"), Pemasukan!$D:$D, "<="&TEXT($L$30, "DD/MM/YYYY"), Pemasukan!$H:$H, H37) -> 0 | K37: =SUMIFS(Pemasukan!$J:$J, Pemasukan!$D:$D, ">="&TEXT($K$30, "DD/MM/YYYY"), Pemasukan!$D:$D, "<="&TEXT($L$30, "DD/MM/YYYY"), Pemasukan!$H:$H, H37) -> 0
B38: ='⚙️Pengaturan'!C5 -> New Paket Terapi 3 | D38: =COUNTIFS(Pemasukan!$D:$D, ">="&TEXT($K$30, "DD/MM/YYYY"), Pemasukan!$D:$D, "<="&TEXT($L$30, "DD/MM/YYYY"), Pemasukan!$F:$F, B38) -> 0 | E38: =SUMIFS(Pemasukan!$J:$J, Pemasukan!$D:$D, ">="&TEXT($K$30, "DD/MM/YYYY"), Pemasukan!$D:$D, "<="&TEXT($L$30, "DD/MM/YYYY"), Pemasukan!$F:$F, B38) -> 0 | H38: ='⚙️Pengaturan'!F7 | J38: =COUNTIFS(Pemasukan!$D:$D, ">="&TEXT($K$30, "DD/MM/YYYY"), Pemasukan!$D:$D, "<="&TEXT($L$30, "DD/MM/YYYY"), Pemasukan!$H:$H, H38) -> 0 | K38: =SUMIFS(Pemasukan!$J:$J, Pemasukan!$D:$D, ">="&TEXT($K$30, "DD/MM/YYYY"), Pemasukan!$D:$D, "<="&TEXT($L$30, "DD/MM/YYYY"), Pemasukan!$H:$H, H38) -> 0
B39: ='⚙️Pengaturan'!C6 -> New Sesi Terapi | D39: =COUNTIFS(Pemasukan!$D:$D, ">="&TEXT($K$30, "DD/MM/YYYY"), Pemasukan!$D:$D, "<="&TEXT($L$30, "DD/MM/YYYY"), Pemasukan!$F:$F, B39) -> 0 | E39: =SUMIFS(Pemasukan!$J:$J, Pemasukan!$D:$D, ">="&TEXT($K$30, "DD/MM/YYYY"), Pemasukan!$D:$D, "<="&TEXT($L$30, "DD/MM/YYYY"), Pemasukan!$F:$F, B39) -> 0 | H39: ='⚙️Pengaturan'!F8 | J39: =COUNTIFS(Pemasukan!$D:$D, ">="&TEXT($K$30, "DD/MM/YYYY"), Pemasukan!$D:$D, "<="&TEXT($L$30, "DD/MM/YYYY"), Pemasukan!$H:$H, H39) -> 0 | K39: =SUMIFS(Pemasukan!$J:$J, Pemasukan!$D:$D, ">="&TEXT($K$30, "DD/MM/YYYY"), Pemasukan!$D:$D, "<="&TEXT($L$30, "DD/MM/YYYY"), Pemasukan!$H:$H, H39) -> 0
B40: ='⚙️Pengaturan'!C7 -> New Sesi terapi Homevisit | D40: =COUNTIFS(Pemasukan!$D:$D, ">="&TEXT($K$30, "DD/MM/YYYY"), Pemasukan!$D:$D, "<="&TEXT($L$30, "DD/MM/YYYY"), Pemasukan!$F:$F, B40) -> 0 | E40: =SUMIFS(Pemasukan!$J:$J, Pemasukan!$D:$D, ">="&TEXT($K$30, "DD/MM/YYYY"), Pemasukan!$D:$D, "<="&TEXT($L$30, "DD/MM/YYYY"), Pemasukan!$F:$F, B40) -> 0 | H40: ='⚙️Pengaturan'!F9 | J40: =COUNTIFS(Pemasukan!$D:$D, ">="&TEXT($K$30, "DD/MM/YYYY"), Pemasukan!$D:$D, "<="&TEXT($L$30, "DD/MM/YYYY"), Pemasukan!$H:$H, H40) -> 0 | K40: =SUMIFS(Pemasukan!$J:$J, Pemasukan!$D:$D, ">="&TEXT($K$30, "DD/MM/YYYY"), Pemasukan!$D:$D, "<="&TEXT($L$30, "DD/MM/YYYY"), Pemasukan!$H:$H, H40) -> 0
B41: ='⚙️Pengaturan'!C8 -> New Sesi terapi Homevisit + Jarak | D41: =COUNTIFS(Pemasukan!$D:$D, ">="&TEXT($K$30, "DD/MM/YYYY"), Pemasukan!$D:$D, "<="&TEXT($L$30, "DD/MM/YYYY"), Pemasukan!$F:$F, B41) -> 0 | E41: =SUMIFS(Pemasukan!$J:$J, Pemasukan!$D:$D, ">="&TEXT($K$30, "DD/MM/YYYY"), Pemasukan!$D:$D, "<="&TEXT($L$30, "DD/MM/YYYY"), Pemasukan!$F:$F, B41) -> 0 | H41: ='⚙️Pengaturan'!F10 | J41: =COUNTIFS(Pemasukan!$D:$D, ">="&TEXT($K$30, "DD/MM/YYYY"), Pemasukan!$D:$D, "<="&TEXT($L$30, "DD/MM/YYYY"), Pemasukan!$H:$H, H41) -> 0 | K41: =SUMIFS(Pemasukan!$J:$J, Pemasukan!$D:$D, ">="&TEXT($K$30, "DD/MM/YYYY"), Pemasukan!$D:$D, "<="&TEXT($L$30, "DD/MM/YYYY"), Pemasukan!$H:$H, H41) -> 0
B42: ='⚙️Pengaturan'!C9 -> New Paket Terapi Homevisit | D42: =COUNTIFS(Pemasukan!$D:$D, ">="&TEXT($K$30, "DD/MM/YYYY"), Pemasukan!$D:$D, "<="&TEXT($L$30, "DD/MM/YYYY"), Pemasukan!$F:$F, B42) -> 0 | E42: =SUMIFS(Pemasukan!$J:$J, Pemasukan!$D:$D, ">="&TEXT($K$30, "DD/MM/YYYY"), Pemasukan!$D:$D, "<="&TEXT($L$30, "DD/MM/YYYY"), Pemasukan!$F:$F, B42) -> 0 | H42: ='⚙️Pengaturan'!F11 | J42: =COUNTIFS(Pemasukan!$D:$D, ">="&TEXT($K$30, "DD/MM/YYYY"), Pemasukan!$D:$D, "<="&TEXT($L$30, "DD/MM/YYYY"), Pemasukan!$H:$H, H42) -> 0 | K42: =SUMIFS(Pemasukan!$J:$J, Pemasukan!$D:$D, ">="&TEXT($K$30, "DD/MM/YYYY"), Pemasukan!$D:$D, "<="&TEXT($L$30, "DD/MM/YYYY"), Pemasukan!$H:$H, H42) -> 0
B43: ='⚙️Pengaturan'!C10 -> New Paket Terapi Homevisit+ Jarak | D43: =COUNTIFS(Pemasukan!$D:$D, ">="&TEXT($K$30, "DD/MM/YYYY"), Pemasukan!$D:$D, "<="&TEXT($L$30, "DD/MM/YYYY"), Pemasukan!$F:$F, B43) -> 0 | E43: =SUMIFS(Pemasukan!$J:$J, Pemasukan!$D:$D, ">="&TEXT($K$30, "DD/MM/YYYY"), Pemasukan!$D:$D, "<="&TEXT($L$30, "DD/MM/YYYY"), Pemasukan!$F:$F, B43) -> 0 | H43: ='⚙️Pengaturan'!F12 | J43: =COUNTIFS(Pemasukan!$D:$D, ">="&TEXT($K$30, "DD/MM/YYYY"), Pemasukan!$D:$D, "<="&TEXT($L$30, "DD/MM/YYYY"), Pemasukan!$H:$H, H43) -> 0 | K43: =SUMIFS(Pemasukan!$J:$J, Pemasukan!$D:$D, ">="&TEXT($K$30, "DD/MM/YYYY"), Pemasukan!$D:$D, "<="&TEXT($L$30, "DD/MM/YYYY"), Pemasukan!$H:$H, H43) -> 0
B44: ='⚙️Pengaturan'!C11 -> Terapi Awal | D44: =COUNTIFS(Pemasukan!$D:$D, ">="&TEXT($K$30, "DD/MM/YYYY"), Pemasukan!$D:$D, "<="&TEXT($L$30, "DD/MM/YYYY"), Pemasukan!$F:$F, B44) -> 21 | E44: =SUMIFS(Pemasukan!$J:$J, Pemasukan!$D:$D, ">="&TEXT($K$30, "DD/MM/YYYY"), Pemasukan!$D:$D, "<="&TEXT($L$30, "DD/MM/YYYY"), Pemasukan!$F:$F, B44) -> 5250000 | H44: ='⚙️Pengaturan'!F13 | J44: =COUNTIFS(Pemasukan!$D:$D, ">="&TEXT($K$30, "DD/MM/YYYY"), Pemasukan!$D:$D, "<="&TEXT($L$30, "DD/MM/YYYY"), Pemasukan!$H:$H, H44) -> 0 | K44: =SUMIFS(Pemasukan!$J:$J, Pemasukan!$D:$D, ">="&TEXT($K$30, "DD/MM/YYYY"), Pemasukan!$D:$D, "<="&TEXT($L$30, "DD/MM/YYYY"), Pemasukan!$H:$H, H44) -> 0
B45: ='⚙️Pengaturan'!C12 -> Paket Terapi 1 | D45: =COUNTIFS(Pemasukan!$D:$D, ">="&TEXT($K$30, "DD/MM/YYYY"), Pemasukan!$D:$D, "<="&TEXT($L$30, "DD/MM/YYYY"), Pemasukan!$F:$F, B45) -> 13 | E45: =SUMIFS(Pemasukan!$J:$J, Pemasukan!$D:$D, ">="&TEXT($K$30, "DD/MM/YYYY"), Pemasukan!$D:$D, "<="&TEXT($L$30, "DD/MM/YYYY"), Pemasukan!$F:$F, B45) -> 5850000 | H45: ='⚙️Pengaturan'!F14 | J45: =COUNTIFS(Pemasukan!$D:$D, ">="&TEXT($K$30, "DD/MM/YYYY"), Pemasukan!$D:$D, "<="&TEXT($L$30, "DD/MM/YYYY"), Pemasukan!$H:$H, H45) -> 0 | K45: =SUMIFS(Pemasukan!$J:$J, Pemasukan!$D:$D, ">="&TEXT($K$30, "DD/MM/YYYY"), Pemasukan!$D:$D, "<="&TEXT($L$30, "DD/MM/YYYY"), Pemasukan!$H:$H, H45) -> 0
B46: ='⚙️Pengaturan'!C13 -> Paket Terapi 2 | D46: =COUNTIFS(Pemasukan!$D:$D, ">="&TEXT($K$30, "DD/MM/YYYY"), Pemasukan!$D:$D, "<="&TEXT($L$30, "DD/MM/YYYY"), Pemasukan!$F:$F, B46) -> 5 | E46: =SUMIFS(Pemasukan!$J:$J, Pemasukan!$D:$D, ">="&TEXT($K$30, "DD/MM/YYYY"), Pemasukan!$D:$D, "<="&TEXT($L$30, "DD/MM/YYYY"), Pemasukan!$F:$F, B46) -> 3600000 | H46: ='⚙️Pengaturan'!F15 | J46: =COUNTIFS(Pemasukan!$D:$D, ">="&TEXT($K$30, "DD/MM/YYYY"), Pemasukan!$D:$D, "<="&TEXT($L$30, "DD/MM/YYYY"), Pemasukan!$H:$H, H46) -> 0 | K46: =SUMIFS(Pemasukan!$J:$J, Pemasukan!$D:$D, ">="&TEXT($K$30, "DD/MM/YYYY"), Pemasukan!$D:$D, "<="&TEXT($L$30, "DD/MM/YYYY"), Pemasukan!$H:$H, H46) -> 0
B47: ='⚙️Pengaturan'!C14 -> Sesi Terapi | D47: =COUNTIFS(Pemasukan!$D:$D, ">="&TEXT($K$30, "DD/MM/YYYY"), Pemasukan!$D:$D, "<="&TEXT($L$30, "DD/MM/YYYY"), Pemasukan!$F:$F, B47) -> 10 | E47: =SUMIFS(Pemasukan!$J:$J, Pemasukan!$D:$D, ">="&TEXT($K$30, "DD/MM/YYYY"), Pemasukan!$D:$D, "<="&TEXT($L$30, "DD/MM/YYYY"), Pemasukan!$F:$F, B47) -> 1500000 | H47: ='⚙️Pengaturan'!F16 | J47: =COUNTIFS(Pemasukan!$D:$D, ">="&TEXT($K$30, "DD/MM/YYYY"), Pemasukan!$D:$D, "<="&TEXT($L$30, "DD/MM/YYYY"), Pemasukan!$H:$H, H47) -> 0 | K47: =SUMIFS(Pemasukan!$J:$J, Pemasukan!$D:$D, ">="&TEXT($K$30, "DD/MM/YYYY"), Pemasukan!$D:$D, "<="&TEXT($L$30, "DD/MM/YYYY"), Pemasukan!$H:$H, H47) -> 0
B48: ='⚙️Pengaturan'!C15 -> Terapi Awal Homevisit | D48: =COUNTIFS(Pemasukan!$D:$D, ">="&TEXT($K$30, "DD/MM/YYYY"), Pemasukan!$D:$D, "<="&TEXT($L$30, "DD/MM/YYYY"), Pemasukan!$F:$F, B48) -> 2 | E48: =SUMIFS(Pemasukan!$J:$J, Pemasukan!$D:$D, ">="&TEXT($K$30, "DD/MM/YYYY"), Pemasukan!$D:$D, "<="&TEXT($L$30, "DD/MM/YYYY"), Pemasukan!$F:$F, B48) -> 600000 | H48: ='⚙️Pengaturan'!F17 | J48: =COUNTIFS(Pemasukan!$D:$D, ">="&TEXT($K$30, "DD/MM/YYYY"), Pemasukan!$D:$D, "<="&TEXT($L$30, "DD/MM/YYYY"), Pemasukan!$H:$H, H48) -> 0 | K48: =SUMIFS(Pemasukan!$J:$J, Pemasukan!$D:$D, ">="&TEXT($K$30, "DD/MM/YYYY"), Pemasukan!$D:$D, "<="&TEXT($L$30, "DD/MM/YYYY"), Pemasukan!$H:$H, H48) -> 0
B49: ='⚙️Pengaturan'!C20 -> Paket Terapi Homevisit+ Jarak | D49: =COUNTIFS(Pemasukan!$D:$D, ">="&TEXT($K$30, "DD/MM/YYYY"), Pemasukan!$D:$D, "<="&TEXT($L$30, "DD/MM/YYYY"), Pemasukan!$F:$F, B49) -> 0 | E49: =SUMIFS(Pemasukan!$J:$J, Pemasukan!$D:$D, ">="&TEXT($K$30, "DD/MM/YYYY"), Pemasukan!$D:$D, "<="&TEXT($L$30, "DD/MM/YYYY"), Pemasukan!$F:$F, B49) -> 0 | H49: ='⚙️Pengaturan'!F18 | J49: =COUNTIFS(Pemasukan!$D:$D, ">="&TEXT($K$30, "DD/MM/YYYY"), Pemasukan!$D:$D, "<="&TEXT($L$30, "DD/MM/YYYY"), Pemasukan!$H:$H, H49) -> 0 | K49: =SUMIFS(Pemasukan!$J:$J, Pemasukan!$D:$D, ">="&TEXT($K$30, "DD/MM/YYYY"), Pemasukan!$D:$D, "<="&TEXT($L$30, "DD/MM/YYYY"), Pemasukan!$H:$H, H49) -> 0
B50: ='⚙️Pengaturan'!C21 | D50: =COUNTIFS(Pemasukan!$D:$D, ">="&TEXT($K$30, "DD/MM/YYYY"), Pemasukan!$D:$D, "<="&TEXT($L$30, "DD/MM/YYYY"), Pemasukan!$F:$F, B50) -> 0 | E50: =SUMIFS(Pemasukan!$J:$J, Pemasukan!$D:$D, ">="&TEXT($K$30, "DD/MM/YYYY"), Pemasukan!$D:$D, "<="&TEXT($L$30, "DD/MM/YYYY"), Pemasukan!$F:$F, B50) -> 0 | H50: ='⚙️Pengaturan'!F19 | J50: =COUNTIFS(Pemasukan!$D:$D, ">="&TEXT($K$30, "DD/MM/YYYY"), Pemasukan!$D:$D, "<="&TEXT($L$30, "DD/MM/YYYY"), Pemasukan!$H:$H, H50) -> 0 | K50: =SUMIFS(Pemasukan!$J:$J, Pemasukan!$D:$D, ">="&TEXT($K$30, "DD/MM/YYYY"), Pemasukan!$D:$D, "<="&TEXT($L$30, "DD/MM/YYYY"), Pemasukan!$H:$H, H50) -> 0
B51: =#REF! -> #REF! | D51: =COUNTIFS(Pemasukan!$D:$D, ">="&TEXT($K$30, "DD/MM/YYYY"), Pemasukan!$D:$D, "<="&TEXT($L$30, "DD/MM/YYYY"), Pemasukan!$F:$F, B51) -> 0 | E51: =SUMIFS(Pemasukan!$J:$J, Pemasukan!$D:$D, ">="&TEXT($K$30, "DD/MM/YYYY"), Pemasukan!$D:$D, "<="&TEXT($L$30, "DD/MM/YYYY"), Pemasukan!$F:$F, B51) -> 0 | H51: ='⚙️Pengaturan'!F20 | J51: =COUNTIFS(Pemasukan!$D:$D, ">="&TEXT($K$30, "DD/MM/YYYY"), Pemasukan!$D:$D, "<="&TEXT($L$30, "DD/MM/YYYY"), Pemasukan!$H:$H, H51) -> 0 | K51: =SUMIFS(Pemasukan!$J:$J, Pemasukan!$D:$D, ">="&TEXT($K$30, "DD/MM/YYYY"), Pemasukan!$D:$D, "<="&TEXT($L$30, "DD/MM/YYYY"), Pemasukan!$H:$H, H51) -> 0
B53: ='⚙️Pengaturan'!C21

Sheet Arus Kas
B2: Bulan | C2: Januari | D2: Februari | E2: Maret | F2: April | G2: Mei | H2: Juni | I2: Juli | J2: Agustus | K2: September | L2: Oktober | M2: November | N2: Desember
B4: Saldo Awal
B5: Nominal | D5: =C55 -> 27445585 | E5: =D55 -> 14150000 | F5: =E55 -> 16200000 | G5: =F55 -> 11644099 | H5: =G55 -> 12609182 | I5: =H55 -> 9377598 | J5: =I55 -> 22056737 | K5: =J55 -> 21166975 | ... N5: =M55 -> 9252167
B7: Pemasukan
B8: ='⚙️Pengaturan'!C3 -> New Paket Terapi 1 | C8: =SUMPRODUCT(Pemasukan!$J:$J,Text(Pemasukan!$D:$D,"mmmm")=C$2,Pemasukan!$F:$F=$B8) -> 750000 | D8: =SUMPRODUCT(Pemasukan!$J:$J,Text(Pemasukan!$D:$D,"mmmm")=D$2,Pemasukan!$F:$F=$B8) -> 0 | E8: =SUMPRODUCT(Pemasukan!$J:$J,Text(Pemasukan!$D:$D,"mmmm")=E$2,Pemasukan!$F:$F=$B8) -> 0 | F8: =SUMPRODUCT(Pemasukan!$J:$J,Text(Pemasukan!$D:$D,"mmmm")=F$2,Pemasukan!$F:$F=$B8) -> 0 | G8: =SUMPRODUCT(Pemasukan!$J:$J,Text(Pemasukan!$D:$D,"mmmm")=G$2,Pemasukan!$F:$F=$B8) -> 0 | H8: =SUMPRODUCT(Pemasukan!$J:$J,Text(Pemasukan!$D:$D,"mmmm")=H$2,Pemasukan!$F:$F=$B8) -> 0 | I8: =SUMPRODUCT(Pemasukan!$J:$J,Text(Pemasukan!$D:$D,"mmmm")=I$2,Pemasukan!$F:$F=$B8) -> 2550000 | J8: =SUMPRODUCT(Pemasukan!$J:$J,Text(Pemasukan!$D:$D,"mmmm")=J$2,Pemasukan!$F:$F=$B8) -> 12450000 | ... N8: =SUMPRODUCT(Pemasukan!$J:$J,Text(Pemasukan!$D:$D,"mmmm")=N$2,Pemasukan!$F:$F=$B8) -> 8810000
B9: ='⚙️Pengaturan'!C4 -> New Paket Terapi 2 | C9: =SUMPRODUCT(Pemasukan!$J:$J,Text(Pemasukan!$D:$D,"mmmm")=C$2,Pemasukan!$F:$F=$B9) -> 2800000 | D9: =SUMPRODUCT(Pemasukan!$J:$J,Text(Pemasukan!$D:$D,"mmmm")=D$2,Pemasukan!$F:$F=$B9) -> 0 | E9: =SUMPRODUCT(Pemasukan!$J:$J,Text(Pemasukan!$D:$D,"mmmm")=E$2,Pemasukan!$F:$F=$B9) -> 0 | F9: =SUMPRODUCT(Pemasukan!$J:$J,Text(Pemasukan!$D:$D,"mmmm")=F$2,Pemasukan!$F:$F=$B9) -> 0 | G9: =SUMPRODUCT(Pemasukan!$J:$J,Text(Pemasukan!$D:$D,"mmmm")=G$2,Pemasukan!$F:$F=$B9) -> 0 | H9: =SUMPRODUCT(Pemasukan!$J:$J,Text(Pemasukan!$D:$D,"mmmm")=H$2,Pemasukan!$F:$F=$B9) -> 0 | I9: =SUMPRODUCT(Pemasukan!$J:$J,Text(Pemasukan!$D:$D,"mmmm")=I$2,Pemasukan!$F:$F=$B9) -> 0 | J9: =SUMPRODUCT(Pemasukan!$J:$J,Text(Pemasukan!$D:$D,"mmmm")=J$2,Pemasukan!$F:$F=$B9) -> 0 | ... N9: =SUMPRODUCT(Pemasukan!$J:$J,Text(Pemasukan!$D:$D,"mmmm")=N$2,Pemasukan!$F:$F=$B9) -> 2660000
B10: ='⚙️Pengaturan'!C5 -> New Paket Terapi 3 | C10: =SUMPRODUCT(Pemasukan!$J:$J,Text(Pemasukan!$D:$D,"mmmm")=C$2,Pemasukan!$F:$F=$B10) -> 1300000 | D10: =SUMPRODUCT(Pemasukan!$J:$J,Text(Pemasukan!$D:$D,"mmmm")=D$2,Pemasukan!$F:$F=$B10) -> 0 | E10: =SUMPRODUCT(Pemasukan!$J:$J,Text(Pemasukan!$D:$D,"mmmm")=E$2,Pemasukan!$F:$F=$B10) -> 0 | F10: =SUMPRODUCT(Pemasukan!$J:$J,Text(Pemasukan!$D:$D,"mmmm")=F$2,Pemasukan!$F:$F=$B10) -> 0 | G10: =SUMPRODUCT(Pemasukan!$J:$J,Text(Pemasukan!$D:$D,"mmmm")=G$2,Pemasukan!$F:$F=$B10) -> 0 | H10: =SUMPRODUCT(Pemasukan!$J:$J,Text(Pemasukan!$D:$D,"mmmm")=H$2,Pemasukan!$F:$F=$B10) -> 0 | I10: =SUMPRODUCT(Pemasukan!$J:$J,Text(Pemasukan!$D:$D,"mmmm")=I$2,Pemasukan!$F:$F=$B10) -> 300000 | J10: =SUMPRODUCT(Pemasukan!$J:$J,Text(Pemasukan!$D:$D,"mmmm")=J$2,Pemasukan!$F:$F=$B10) -> 4900000 | ... N10: =SUMPRODUCT(Pemasukan!$J:$J,Text(Pemasukan!$D:$D,"mmmm")=N$2,Pemasukan!$F:$F=$B10) -> 0
B11: ='⚙️Pengaturan'!C6 -> New Sesi Terapi | C11: =SUMPRODUCT(Pemasukan!$J:$J,Text(Pemasukan!$D:$D,"mmmm")=C$2,Pemasukan!$F:$F=$B11) -> 2905000 | D11: =SUMPRODUCT(Pemasukan!$J:$J,Text(Pemasukan!$D:$D,"mmmm")=D$2,Pemasukan!$F:$F=$B11) -> 0 | E11: =SUMPRODUCT(Pemasukan!$J:$J,Text(Pemasukan!$D:$D,"mmmm")=E$2,Pemasukan!$F:$F=$B11) -> 0 | F11: =SUMPRODUCT(Pemasukan!$J:$J,Text(Pemasukan!$D:$D,"mmmm")=F$2,Pemasukan!$F:$F=$B11) -> 0 | G11: =SUMPRODUCT(Pemasukan!$J:$J,Text(Pemasukan!$D:$D,"mmmm")=G$2,Pemasukan!$F:$F=$B11) -> 0 | H11: =SUMPRODUCT(Pemasukan!$J:$J,Text(Pemasukan!$D:$D,"mmmm")=H$2,Pemasukan!$F:$F=$B11) -> 0 | I11: =SUMPRODUCT(Pemasukan!$J:$J,Text(Pemasukan!$D:$D,"mmmm")=I$2,Pemasukan!$F:$F=$B11) -> 2940000 | J11: =SUMPRODUCT(Pemasukan!$J:$J,Text(Pemasukan!$D:$D,"mmmm")=J$2,Pemasukan!$F:$F=$B11) -> 7115000 | ... N11: =SUMPRODUCT(Pemasukan!$J:$J,Text(Pemasukan!$D:$D,"mmmm")=N$2,Pemasukan!$F:$F=$B11) -> 6230000
B12: ='⚙️Pengaturan'!C7 -> New Sesi terapi Homevisit | C12: =SUMPRODUCT(Pemasukan!$J:$J,Text(Pemasukan!$D:$D,"mmmm")=C$2,Pemasukan!$F:$F=$B12) -> 1350000 | D12: =SUMPRODUCT(Pemasukan!$J:$J,Text(Pemasukan!$D:$D,"mmmm")=D$2,Pemasukan!$F:$F=$B12) -> 0 | E12: =SUMPRODUCT(Pemasukan!$J:$J,Text(Pemasukan!$D:$D,"mmmm")=E$2,Pemasukan!$F:$F=$B12) -> 0 | F12: =SUMPRODUCT(Pemasukan!$J:$J,Text(Pemasukan!$D:$D,"mmmm")=F$2,Pemasukan!$F:$F=$B12) -> 0 | G12: =SUMPRODUCT(Pemasukan!$J:$J,Text(Pemasukan!$D:$D,"mmmm")=G$2,Pemasukan!$F:$F=$B12) -> 0 | H12: =SUMPRODUCT(Pemasukan!$J:$J,Text(Pemasukan!$D:$D,"mmmm")=H$2,Pemasukan!$F:$F=$B12) -> 0 | I12: =SUMPRODUCT(Pemasukan!$J:$J,Text(Pemasukan!$D:$D,"mmmm")=I$2,Pemasukan!$F:$F=$B12) -> 0 | J12: =SUMPRODUCT(Pemasukan!$J:$J,Text(Pemasukan!$D:$D,"mmmm")=J$2,Pemasukan!$F:$F=$B12) -> 900000 | ... N12: =SUMPRODUCT(Pemasukan!$J:$J,Text(Pemasukan!$D:$D,"mmmm")=N$2,Pemasukan!$F:$F=$B12) -> 1125000
B13: ='⚙️Pengaturan'!C8 -> New Sesi terapi Homevisit + Jarak | C13: =SUMPRODUCT(Pemasukan!$J:$J,Text(Pemasukan!$D:$D,"mmmm")=C$2,Pemasukan!$F:$F=$B13) -> 0 | D13: =SUMPRODUCT(Pemasukan!$J:$J,Text(Pemasukan!$D:$D,"mmmm")=D$2,Pemasukan!$F:$F=$B13) -> 0 | E13: =SUMPRODUCT(Pemasukan!$J:$J,Text(Pemasukan!$D:$D,"mmmm")=E$2,Pemasukan!$F:$F=$B13) -> 0 | F13: =SUMPRODUCT(Pemasukan!$J:$J,Text(Pemasukan!$D:$D,"mmmm")=F$2,Pemasukan!$F:$F=$B13) -> 0 | G13: =SUMPRODUCT(Pemasukan!$J:$J,Text(Pemasukan!$D:$D,"mmmm")=G$2,Pemasukan!$F:$F=$B13) -> 0 | H13: =SUMPRODUCT(Pemasukan!$J:$J,Text(Pemasukan!$D:$D,"mmmm")=H$2,Pemasukan!$F:$F=$B13) -> 0 | I13: =SUMPRODUCT(Pemasukan!$J:$J,Text(Pemasukan!$D:$D,"mmmm")=I$2,Pemasukan!$F:$F=$B13) -> 0 | J13: =SUMPRODUCT(Pemasukan!$J:$J,Text(Pemasukan!$D:$D,"mmmm")=J$2,Pemasukan!$F:$F=$B13) -> 0 | ... N13: =SUMPRODUCT(Pemasukan!$J:$J,Text(Pemasukan!$D:$D,"mmmm")=N$2,Pemasukan!$F:$F=$B13) -> 0
B14: ='⚙️Pengaturan'!C9 -> New Paket Terapi Homevisit | C14: =SUMPRODUCT(Pemasukan!$J:$J,Text(Pemasukan!$D:$D,"mmmm")=C$2,Pemasukan!$F:$F=$B14) -> 0 | D14: =SUMPRODUCT(Pemasukan!$J:$J,Text(Pemasukan!$D:$D,"mmmm")=D$2,Pemasukan!$F:$F=$B14) -> 0 | E14: =SUMPRODUCT(Pemasukan!$J:$J,Text(Pemasukan!$D:$D,"mmmm")=E$2,Pemasukan!$F:$F=$B14) -> 0 | F14: =SUMPRODUCT(Pemasukan!$J:$J,Text(Pemasukan!$D:$D,"mmmm")=F$2,Pemasukan!$F:$F=$B14) -> 0 | G14: =SUMPRODUCT(Pemasukan!$J:$J,Text(Pemasukan!$D:$D,"mmmm")=G$2,Pemasukan!$F:$F=$B14) -> 0 | H14: =SUMPRODUCT(Pemasukan!$J:$J,Text(Pemasukan!$D:$D,"mmmm")=H$2,Pemasukan!$F:$F=$B14) -> 0 | I14: =SUMPRODUCT(Pemasukan!$J:$J,Text(Pemasukan!$D:$D,"mmmm")=I$2,Pemasukan!$F:$F=$B14) -> 0 | J14: =SUMPRODUCT(Pemasukan!$J:$J,Text(Pemasukan!$D:$D,"mmmm")=J$2,Pemasukan!$F:$F=$B14) -> 2000000 | ... N14: =SUMPRODUCT(Pemasukan!$J:$J,Text(Pemasukan!$D:$D,"mmmm")=N$2,Pemasukan!$F:$F=$B14) -> 2000000
B15: ='⚙️Pengaturan'!C10 -> New Paket Terapi Homevisit+ Jarak | C15: =SUMPRODUCT(Pemasukan!$J:$J,Text(Pemasukan!$D:$D,"mmmm")=C$2,Pemasukan!$F:$F=$B15) -> 0 | D15: =SUMPRODUCT(Pemasukan!$J:$J,Text(Pemasukan!$D:$D,"mmmm")=D$2,Pemasukan!$F:$F=$B15) -> 0 | E15: =SUMPRODUCT(Pemasukan!$J:$J,Text(Pemasukan!$D:$D,"mmmm")=E$2,Pemasukan!$F:$F=$B15) -> 0 | F15: =SUMPRODUCT(Pemasukan!$J:$J,Text(Pemasukan!$D:$D,"mmmm")=F$2,Pemasukan!$F:$F=$B15) -> 0 | G15: =SUMPRODUCT(Pemasukan!$J:$J,Text(Pemasukan!$D:$D,"mmmm")=G$2,Pemasukan!$F:$F=$B15) -> 0 | H15: =SUMPRODUCT(Pemasukan!$J:$J,Text(Pemasukan!$D:$D,"mmmm")=H$2,Pemasukan!$F:$F=$B15) -> 0 | I15: =SUMPRODUCT(Pemasukan!$J:$J,Text(Pemasukan!$D:$D,"mmmm")=I$2,Pemasukan!$F:$F=$B15) -> 0 | J15: =SUMPRODUCT(Pemasukan!$J:$J,Text(Pemasukan!$D:$D,"mmmm")=J$2,Pemasukan!$F:$F=$B15) -> 0 | ... N15: =SUMPRODUCT(Pemasukan!$J:$J,Text(Pemasukan!$D:$D,"mmmm")=N$2,Pemasukan!$F:$F=$B15) -> 0
B16: ='⚙️Pengaturan'!C11 -> Terapi Awal | C16: =SUMPRODUCT(Pemasukan!$J:$J,Text(Pemasukan!$D:$D,"mmmm")=C$2,Pemasukan!$F:$F=$B16) -> 5250000 | D16: =SUMPRODUCT(Pemasukan!$J:$J,Text(Pemasukan!$D:$D,"mmmm")=D$2,Pemasukan!$F:$F=$B16) -> 4250000 | E16: =SUMPRODUCT(Pemasukan!$J:$J,Text(Pemasukan!$D:$D,"mmmm")=E$2,Pemasukan!$F:$F=$B16) -> 4800000 | F16: =SUMPRODUCT(Pemasukan!$J:$J,Text(Pemasukan!$D:$D,"mmmm")=F$2,Pemasukan!$F:$F=$B16) -> 2000000 | G16: =SUMPRODUCT(Pemasukan!$J:$J,Text(Pemasukan!$D:$D,"mmmm")=G$2,Pemasukan!$F:$F=$B16) -> 4250000 | H16: =SUMPRODUCT(Pemasukan!$J:$J,Text(Pemasukan!$D:$D,"mmmm")=H$2,Pemasukan!$F:$F=$B16) -> 2500000 | I16: =SUMPRODUCT(Pemasukan!$J:$J,Text(Pemasukan!$D:$D,"mmmm")=I$2,Pemasukan!$F:$F=$B16) -> 7750000 | J16: =SUMPRODUCT(Pemasukan!$J:$J,Text(Pemasukan!$D:$D,"mmmm")=J$2,Pemasukan!$F:$F=$B16) -> 175000 | ... N16: =SUMPRODUCT(Pemasukan!$J:$J,Text(Pemasukan!$D:$D,"mmmm")=N$2,Pemasukan!$F:$F=$B16) -> 0
B17: ='⚙️Pengaturan'!C12 -> Paket Terapi 1 | C17: =SUMPRODUCT(Pemasukan!$J:$J,Text(Pemasukan!$D:$D,"mmmm")=C$2,Pemasukan!$F:$F=$B17) -> 5850000 | D17: =SUMPRODUCT(Pemasukan!$J:$J,Text(Pemasukan!$D:$D,"mmmm")=D$2,Pemasukan!$F:$F=$B17) -> 4200000 | E17: =SUMPRODUCT(Pemasukan!$J:$J,Text(Pemasukan!$D:$D,"mmmm")=E$2,Pemasukan!$F:$F=$B17) -> 6150000 | F17: =SUMPRODUCT(Pemasukan!$J:$J,Text(Pemasukan!$D:$D,"mmmm")=F$2,Pemasukan!$F:$F=$B17) -> 1350000 | G17: =SUMPRODUCT(Pemasukan!$J:$J,Text(Pemasukan!$D:$D,"mmmm")=G$2,Pemasukan!$F:$F=$B17) -> 6500000 | H17: =SUMPRODUCT(Pemasukan!$J:$J,Text(Pemasukan!$D:$D,"mmmm")=H$2,Pemasukan!$F:$F=$B17) -> 1500000 | I17: =SUMPRODUCT(Pemasukan!$J:$J,Text(Pemasukan!$D:$D,"mmmm")=I$2,Pemasukan!$F:$F=$B17) -> 10100000 | J17: =SUMPRODUCT(Pemasukan!$J:$J,Text(Pemasukan!$D:$D,"mmmm")=J$2,Pemasukan!$F:$F=$B17) -> 4750000 | ... N17: =SUMPRODUCT(Pemasukan!$J:$J,Text(Pemasukan!$D:$D,"mmmm")=N$2,Pemasukan!$F:$F=$B17) -> 0
B18: ='⚙️Pengaturan'!C13 -> Paket Terapi 2 | C18: =SUMPRODUCT(Pemasukan!$J:$J,Text(Pemasukan!$D:$D,"mmmm")=C$2,Pemasukan!$F:$F=$B18) -> 3600000 | D18: =SUMPRODUCT(Pemasukan!$J:$J,Text(Pemasukan!$D:$D,"mmmm")=D$2,Pemasukan!$F:$F=$B18) -> 1200000 | E18: =SUMPRODUCT(Pemasukan!$J:$J,Text(Pemasukan!$D:$D,"mmmm")=E$2,Pemasukan!$F:$F=$B18) -> 3600000 | F18: =SUMPRODUCT(Pemasukan!$J:$J,Text(Pemasukan!$D:$D,"mmmm")=F$2,Pemasukan!$F:$F=$B18) -> 3600000 | G18: =SUMPRODUCT(Pemasukan!$J:$J,Text(Pemasukan!$D:$D,"mmmm")=G$2,Pemasukan!$F:$F=$B18) -> 250000 | H18: =SUMPRODUCT(Pemasukan!$J:$J,Text(Pemasukan!$D:$D,"mmmm")=H$2,Pemasukan!$F:$F=$B18) -> 3350000 | I18: =SUMPRODUCT(Pemasukan!$J:$J,Text(Pemasukan!$D:$D,"mmmm")=I$2,Pemasukan!$F:$F=$B18) -> 2400000 | J18: =SUMPRODUCT(Pemasukan!$J:$J,Text(Pemasukan!$D:$D,"mmmm")=J$2,Pemasukan!$F:$F=$B18) -> 2400000 | ... N18: =SUMPRODUCT(Pemasukan!$J:$J,Text(Pemasukan!$D:$D,"mmmm")=N$2,Pemasukan!$F:$F=$B18) -> 1200000
B19: ='⚙️Pengaturan'!C14 -> Sesi Terapi | C19: =SUMPRODUCT(Pemasukan!$J:$J,Text(Pemasukan!$D:$D,"mmmm")=C$2,Pemasukan!$F:$F=$B19) -> 1500000 | D19: =SUMPRODUCT(Pemasukan!$J:$J,Text(Pemasukan!$D:$D,"mmmm")=D$2,Pemasukan!$F:$F=$B19) -> 4500000 | E19: =SUMPRODUCT(Pemasukan!$J:$J,Text(Pemasukan!$D:$D,"mmmm")=E$2,Pemasukan!$F:$F=$B19) -> 1650000 | F19: =SUMPRODUCT(Pemasukan!$J:$J,Text(Pemasukan!$D:$D,"mmmm")=F$2,Pemasukan!$F:$F=$B19) -> 2500000 | G19: =SUMPRODUCT(Pemasukan!$J:$J,Text(Pemasukan!$D:$D,"mmmm")=G$2,Pemasukan!$F:$F=$B19) -> 2300000 | H19: =SUMPRODUCT(Pemasukan!$J:$J,Text(Pemasukan!$D:$D,"mmmm")=H$2,Pemasukan!$F:$F=$B19) -> 2100000 | I19: =SUMPRODUCT(Pemasukan!$J:$J,Text(Pemasukan!$D:$D,"mmmm")=I$2,Pemasukan!$F:$F=$B19) -> 4050000 | J19: =SUMPRODUCT(Pemasukan!$J:$J,Text(Pemasukan!$D:$D,"mmmm")=J$2,Pemasukan!$F:$F=$B19) -> 1050000 | ... N19: =SUMPRODUCT(Pemasukan!$J:$J,Text(Pemasukan!$D:$D,"mmmm")=N$2,Pemasukan!$F:$F=$B19) -> 450000
... B24: ='⚙️Pengaturan'!C19 -> Paket Terapi Homevisit | C24: =SUMPRODUCT(Pemasukan!$J:$J,Text(Pemasukan!$D:$D,"mmmm")=C$2,Pemasukan!$F:$F=$B24) -> 1800000 | D24: =SUMPRODUCT(Pemasukan!$J:$J,Text(Pemasukan!$D:$D,"mmmm")=D$2,Pemasukan!$F:$F=$B24) -> 0 | E24: =SUMPRODUCT(Pemasukan!$J:$J,Text(Pemasukan!$D:$D,"mmmm")=E$2,Pemasukan!$F:$F=$B24) -> 0 | F24: =SUMPRODUCT(Pemasukan!$J:$J,Text(Pemasukan!$D:$D,"mmmm")=F$2,Pemasukan!$F:$F=$B24) -> 1800000 | G24: =SUMPRODUCT(Pemasukan!$J:$J,Text(Pemasukan!$D:$D,"mmmm")=G$2,Pemasukan!$F:$F=$B24) -> 0 | H24: =SUMPRODUCT(Pemasukan!$J:$J,Text(Pemasukan!$D:$D,"mmmm")=H$2,Pemasukan!$F:$F=$B24) -> 0 | I24: =SUMPRODUCT(Pemasukan!$J:$J,Text(Pemasukan!$D:$D,"mmmm")=I$2,Pemasukan!$F:$F=$B24) -> 3600000 | J24: =SUMPRODUCT(Pemasukan!$J:$J,Text(Pemasukan!$D:$D,"mmmm")=J$2,Pemasukan!$F:$F=$B24) -> 0 | ... N24: =SUMPRODUCT(Pemasukan!$J:$J,Text(Pemasukan!$D:$D,"mmmm")=N$2,Pemasukan!$F:$F=$B24) -> 0
B25: ='⚙️Pengaturan'!C20 -> Paket Terapi Homevisit+ Jarak | I25: =SUMPRODUCT(Pemasukan!$J:$J,Text(Pemasukan!$D:$D,"mmmm")=I$2,Pemasukan!$F:$F=$B25) -> 0 | J25: =SUMPRODUCT(Pemasukan!$J:$J,Text(Pemasukan!$D:$D,"mmmm")=J$2,Pemasukan!$F:$F=$B25) -> 0 | K25: =SUMPRODUCT(Pemasukan!$J:$J,Text(Pemasukan!$D:$D,"mmmm")=K$2,Pemasukan!$F:$F=$B25) -> 0 | L25: =SUMPRODUCT(Pemasukan!$J:$J,Text(Pemasukan!$D:$D,"mmmm")=L$2,Pemasukan!$F:$F=$B25) -> 0 | M25: =SUMPRODUCT(Pemasukan!$J:$J,Text(Pemasukan!$D:$D,"mmmm")=M$2,Pemasukan!$F:$F=$B25) -> 0 | N25: =SUMPRODUCT(Pemasukan!$J:$J,Text(Pemasukan!$D:$D,"mmmm")=N$2,Pemasukan!$F:$F=$B25) -> 0
B26: Total | C26: =SUM(C8:C24) -> 27905000 | D26: =SUM(D8:D24) -> 14150000 | E26: =SUM(E8:E24) -> 16200000 | F26: =SUM(F8:F24) -> 11850000 | G26: =SUM(G8:G24) -> 13950000 | H26: =SUM(H8:H24) -> 10000000 | I26: =SUM(I8:I24) -> 33690000 | J26: =SUM(J8:J24) -> 35740000 | ... M26: =SUM(M8:M24) -> 22475000 | N26: =SUM(N8:N25) -> 22475000
B28: Pengeluaran
B29: ='⚙️Pengaturan'!E3 -> Beban Gaji Pegawai | C29: =SUMPRODUCT(Pengeluaran!$F:$F,Text(Pengeluaran!$D:$D,"mmmm")=C$2,Pengeluaran!$E:$E=$B29) -> 0 | D29: =SUMPRODUCT(Pengeluaran!$F:$F,Text(Pengeluaran!$D:$D,"mmmm")=D$2,Pengeluaran!$E:$E=$B29) -> 0 | E29: =SUMPRODUCT(Pengeluaran!$F:$F,Text(Pengeluaran!$D:$D,"mmmm")=E$2,Pengeluaran!$E:$E=$B29) -> 0 | F29: =SUMPRODUCT(Pengeluaran!$F:$F,Text(Pengeluaran!$D:$D,"mmmm")=F$2,Pengeluaran!$E:$E=$B29) -> 0 | G29: =SUMPRODUCT(Pengeluaran!$F:$F,Text(Pengeluaran!$D:$D,"mmmm")=G$2,Pengeluaran!$E:$E=$B29) -> 0 | H29: =SUMPRODUCT(Pengeluaran!$F:$F,Text(Pengeluaran!$D:$D,"mmmm")=H$2,Pengeluaran!$E:$E=$B29) -> 0 | I29: =SUMPRODUCT(Pengeluaran!$F:$F,Text(Pengeluaran!$D:$D,"mmmm")=I$2,Pengeluaran!$E:$E=$B29) -> 9779043 | J29: =SUMPRODUCT(Pengeluaran!$F:$F,Text(Pengeluaran!$D:$D,"mmmm")=J$2,Pengeluaran!$E:$E=$B29) -> 11767500 | ... N29: =SUMPRODUCT(Pengeluaran!$F:$F,Text(Pengeluaran!$D:$D,"mmmm")=N$2,Pengeluaran!$E:$E=$B29) -> 9122500
B30: ='⚙️Pengaturan'!E4 -> Beban Listrik | C30: =SUMPRODUCT(Pengeluaran!$F:$F,Text(Pengeluaran!$D:$D,"mmmm")=C$2,Pengeluaran!$E:$E=$B30) -> 402415 | D30: =SUMPRODUCT(Pengeluaran!$F:$F,Text(Pengeluaran!$D:$D,"mmmm")=D$2,Pengeluaran!$E:$E=$B30) -> 0 | E30: =SUMPRODUCT(Pengeluaran!$F:$F,Text(Pengeluaran!$D:$D,"mmmm")=E$2,Pengeluaran!$E:$E=$B30) -> 0 | F30: =SUMPRODUCT(Pengeluaran!$F:$F,Text(Pengeluaran!$D:$D,"mmmm")=F$2,Pengeluaran!$E:$E=$B30) -> 205901 | G30: =SUMPRODUCT(Pengeluaran!$F:$F,Text(Pengeluaran!$D:$D,"mmmm")=G$2,Pengeluaran!$E:$E=$B30) -> 403818 | H30: =SUMPRODUCT(Pengeluaran!$F:$F,Text(Pengeluaran!$D:$D,"mmmm")=H$2,Pengeluaran!$E:$E=$B30) -> 404402 | I30: =SUMPRODUCT(Pengeluaran!$F:$F,Text(Pengeluaran!$D:$D,"mmmm")=I$2,Pengeluaran!$E:$E=$B30) -> 807320 | J30: =SUMPRODUCT(Pengeluaran!$F:$F,Text(Pengeluaran!$D:$D,"mmmm")=J$2,Pengeluaran!$E:$E=$B30) -> 807025 | ... N30: =SUMPRODUCT(Pengeluaran!$F:$F,Text(Pengeluaran!$D:$D,"mmmm")=N$2,Pengeluaran!$E:$E=$B30) -> 709772
B31: ='⚙️Pengaturan'!E5 -> Beban PDAM | C31: =SUMPRODUCT(Pengeluaran!$F:$F,Text(Pengeluaran!$D:$D,"mmmm")=C$2,Pengeluaran!$E:$E=$B31) -> 0 | D31: =SUMPRODUCT(Pengeluaran!$F:$F,Text(Pengeluaran!$D:$D,"mmmm")=D$2,Pengeluaran!$E:$E=$B31) -> 0 | E31: =SUMPRODUCT(Pengeluaran!$F:$F,Text(Pengeluaran!$D:$D,"mmmm")=E$2,Pengeluaran!$E:$E=$B31) -> 0 | F31: =SUMPRODUCT(Pengeluaran!$F:$F,Text(Pengeluaran!$D:$D,"mmmm")=F$2,Pengeluaran!$E:$E=$B31) -> 0 | G31: =SUMPRODUCT(Pengeluaran!$F:$F,Text(Pengeluaran!$D:$D,"mmmm")=G$2,Pengeluaran!$E:$E=$B31) -> 0 | H31: =SUMPRODUCT(Pengeluaran!$F:$F,Text(Pengeluaran!$D:$D,"mmmm")=H$2,Pengeluaran!$E:$E=$B31) -> 0 | I31: =SUMPRODUCT(Pengeluaran!$F:$F,Text(Pengeluaran!$D:$D,"mmmm")=I$2,Pengeluaran!$E:$E=$B31) -> 0 | J31: =SUMPRODUCT(Pengeluaran!$F:$F,Text(Pengeluaran!$D:$D,"mmmm")=J$2,Pengeluaran!$E:$E=$B31) -> 0 | ... N31: =SUMPRODUCT(Pengeluaran!$F:$F,Text(Pengeluaran!$D:$D,"mmmm")=N$2,Pengeluaran!$E:$E=$B31) -> 0
B32: ='⚙️Pengaturan'!E6 -> Beban pemeliharaan bangunan | C32: =SUMPRODUCT(Pengeluaran!$F:$F,Text(Pengeluaran!$D:$D,"mmmm")=C$2,Pengeluaran!$E:$E=$B32) -> 0 | D32: =SUMPRODUCT(Pengeluaran!$F:$F,Text(Pengeluaran!$D:$D,"mmmm")=D$2,Pengeluaran!$E:$E=$B32) -> 0 | E32: =SUMPRODUCT(Pengeluaran!$F:$F,Text(Pengeluaran!$D:$D,"mmmm")=E$2,Pengeluaran!$E:$E=$B32) -> 0 | F32: =SUMPRODUCT(Pengeluaran!$F:$F,Text(Pengeluaran!$D:$D,"mmmm")=F$2,Pengeluaran!$E:$E=$B32) -> 0 | G32: =SUMPRODUCT(Pengeluaran!$F:$F,Text(Pengeluaran!$D:$D,"mmmm")=G$2,Pengeluaran!$E:$E=$B32) -> 35000 | H32: =SUMPRODUCT(Pengeluaran!$F:$F,Text(Pengeluaran!$D:$D,"mmmm")=H$2,Pengeluaran!$E:$E=$B32) -> 35000 | I32: =SUMPRODUCT(Pengeluaran!$F:$F,Text(Pengeluaran!$D:$D,"mmmm")=I$2,Pengeluaran!$E:$E=$B32) -> 50000 | J32: =SUMPRODUCT(Pengeluaran!$F:$F,Text(Pengeluaran!$D:$D,"mmmm")=J$2,Pengeluaran!$E:$E=$B32) -> 45000 | ... N32: =SUMPRODUCT(Pengeluaran!$F:$F,Text(Pengeluaran!$D:$D,"mmmm")=N$2,Pengeluaran!$E:$E=$B32) -> 0
B33: ='⚙️Pengaturan'!E7 -> Beban pemeliharaan peralatan | C33: =SUMPRODUCT(Pengeluaran!$F:$F,Text(Pengeluaran!$D:$D,"mmmm")=C$2,Pengeluaran!$E:$E=$B33) -> 0 | D33: =SUMPRODUCT(Pengeluaran!$F:$F,Text(Pengeluaran!$D:$D,"mmmm")=D$2,Pengeluaran!$E:$E=$B33) -> 0 | E33: =SUMPRODUCT(Pengeluaran!$F:$F,Text(Pengeluaran!$D:$D,"mmmm")=E$2,Pengeluaran!$E:$E=$B33) -> 0 | F33: =SUMPRODUCT(Pengeluaran!$F:$F,Text(Pengeluaran!$D:$D,"mmmm")=F$2,Pengeluaran!$E:$E=$B33) -> 0 | G33: =SUMPRODUCT(Pengeluaran!$F:$F,Text(Pengeluaran!$D:$D,"mmmm")=G$2,Pengeluaran!$E:$E=$B33) -> 660000 | H33: =SUMPRODUCT(Pengeluaran!$F:$F,Text(Pengeluaran!$D:$D,"mmmm")=H$2,Pengeluaran!$E:$E=$B33) -> 123000 | I33: =SUMPRODUCT(Pengeluaran!$F:$F,Text(Pengeluaran!$D:$D,"mmmm")=I$2,Pengeluaran!$E:$E=$B33) -> 0 | J33: =SUMPRODUCT(Pengeluaran!$F:$F,Text(Pengeluaran!$D:$D,"mmmm")=J$2,Pengeluaran!$E:$E=$B33) -> 280000 | ... N33: =SUMPRODUCT(Pengeluaran!$F:$F,Text(Pengeluaran!$D:$D,"mmmm")=N$2,Pengeluaran!$E:$E=$B33) -> 188000
B34: ='⚙️Pengaturan'!E8 -> Beban Konsumsi | C34: =SUMPRODUCT(Pengeluaran!$F:$F,Text(Pengeluaran!$D:$D,"mmmm")=C$2,Pengeluaran!$E:$E=$B34) -> 0 | D34: =SUMPRODUCT(Pengeluaran!$F:$F,Text(Pengeluaran!$D:$D,"mmmm")=D$2,Pengeluaran!$E:$E=$B34) -> 0 | E34: =SUMPRODUCT(Pengeluaran!$F:$F,Text(Pengeluaran!$D:$D,"mmmm")=E$2,Pengeluaran!$E:$E=$B34) -> 0 | F34: =SUMPRODUCT(Pengeluaran!$F:$F,Text(Pengeluaran!$D:$D,"mmmm")=F$2,Pengeluaran!$E:$E=$B34) -> 0 | G34: =SUMPRODUCT(Pengeluaran!$F:$F,Text(Pengeluaran!$D:$D,"mmmm")=G$2,Pengeluaran!$E:$E=$B34) -> 0 | H34: =SUMPRODUCT(Pengeluaran!$F:$F,Text(Pengeluaran!$D:$D,"mmmm")=H$2,Pengeluaran!$E:$E=$B34) -> 0 | I34: =SUMPRODUCT(Pengeluaran!$F:$F,Text(Pengeluaran!$D:$D,"mmmm")=I$2,Pengeluaran!$E:$E=$B34) -> 0 | J34: =SUMPRODUCT(Pengeluaran!$F:$F,Text(Pengeluaran!$D:$D,"mmmm")=J$2,Pengeluaran!$E:$E=$B34) -> 304000 | ... N34: =SUMPRODUCT(Pengeluaran!$F:$F,Text(Pengeluaran!$D:$D,"mmmm")=N$2,Pengeluaran!$E:$E=$B34) -> 0
B35: ='⚙️Pengaturan'!E9 -> Beban acara dan pertemuan | C35: =SUMPRODUCT(Pengeluaran!$F:$F,Text(Pengeluaran!$D:$D,"mmmm")=C$2,Pengeluaran!$E:$E=$B35) -> 0 | D35: =SUMPRODUCT(Pengeluaran!$F:$F,Text(Pengeluaran!$D:$D,"mmmm")=D$2,Pengeluaran!$E:$E=$B35) -> 0 | E35: =SUMPRODUCT(Pengeluaran!$F:$F,Text(Pengeluaran!$D:$D,"mmmm")=E$2,Pengeluaran!$E:$E=$B35) -> 0 | F35: =SUMPRODUCT(Pengeluaran!$F:$F,Text(Pengeluaran!$D:$D,"mmmm")=F$2,Pengeluaran!$E:$E=$B35) -> 0 | G35: =SUMPRODUCT(Pengeluaran!$F:$F,Text(Pengeluaran!$D:$D,"mmmm")=G$2,Pengeluaran!$E:$E=$B35) -> 0 | H35: =SUMPRODUCT(Pengeluaran!$F:$F,Text(Pengeluaran!$D:$D,"mmmm")=H$2,Pengeluaran!$E:$E=$B35) -> 0 | I35: =SUMPRODUCT(Pengeluaran!$F:$F,Text(Pengeluaran!$D:$D,"mmmm")=I$2,Pengeluaran!$E:$E=$B35) -> 0 | J35: =SUMPRODUCT(Pengeluaran!$F:$F,Text(Pengeluaran!$D:$D,"mmmm")=J$2,Pengeluaran!$E:$E=$B35) -> 0 | ... N35: =SUMPRODUCT(Pengeluaran!$F:$F,Text(Pengeluaran!$D:$D,"mmmm")=N$2,Pengeluaran!$E:$E=$B35) -> 0
B36: ='⚙️Pengaturan'!E10 -> Beban Rapat | C36: =SUMPRODUCT(Pengeluaran!$F:$F,Text(Pengeluaran!$D:$D,"mmmm")=C$2,Pengeluaran!$E:$E=$B36) -> 30000 | D36: =SUMPRODUCT(Pengeluaran!$F:$F,Text(Pengeluaran!$D:$D,"mmmm")=D$2,Pengeluaran!$E:$E=$B36) -> 0 | E36: =SUMPRODUCT(Pengeluaran!$F:$F,Text(Pengeluaran!$D:$D,"mmmm")=E$2,Pengeluaran!$E:$E=$B36) -> 0 | F36: =SUMPRODUCT(Pengeluaran!$F:$F,Text(Pengeluaran!$D:$D,"mmmm")=F$2,Pengeluaran!$E:$E=$B36) -> 0 | G36: =SUMPRODUCT(Pengeluaran!$F:$F,Text(Pengeluaran!$D:$D,"mmmm")=G$2,Pengeluaran!$E:$E=$B36) -> 0 | H36: =SUMPRODUCT(Pengeluaran!$F:$F,Text(Pengeluaran!$D:$D,"mmmm")=H$2,Pengeluaran!$E:$E=$B36) -> 60000 | I36: =SUMPRODUCT(Pengeluaran!$F:$F,Text(Pengeluaran!$D:$D,"mmmm")=I$2,Pengeluaran!$E:$E=$B36) -> 0 | J36: =SUMPRODUCT(Pengeluaran!$F:$F,Text(Pengeluaran!$D:$D,"mmmm")=J$2,Pengeluaran!$E:$E=$B36) -> 0 | ... N36: =SUMPRODUCT(Pengeluaran!$F:$F,Text(Pengeluaran!$D:$D,"mmmm")=N$2,Pengeluaran!$E:$E=$B36) -> 15000
B37: ='⚙️Pengaturan'!E11 -> Beban Telepon dan Internet | C37: =SUMPRODUCT(Pengeluaran!$F:$F,Text(Pengeluaran!$D:$D,"mmmm")=C$2,Pengeluaran!$E:$E=$B37) -> 27000 | D37: =SUMPRODUCT(Pengeluaran!$F:$F,Text(Pengeluaran!$D:$D,"mmmm")=D$2,Pengeluaran!$E:$E=$B37) -> 0 | E37: =SUMPRODUCT(Pengeluaran!$F:$F,Text(Pengeluaran!$D:$D,"mmmm")=E$2,Pengeluaran!$E:$E=$B37) -> 0 | F37: =SUMPRODUCT(Pengeluaran!$F:$F,Text(Pengeluaran!$D:$D,"mmmm")=F$2,Pengeluaran!$E:$E=$B37) -> 0 | G37: =SUMPRODUCT(Pengeluaran!$F:$F,Text(Pengeluaran!$D:$D,"mmmm")=G$2,Pengeluaran!$E:$E=$B37) -> 27000 | H37: =SUMPRODUCT(Pengeluaran!$F:$F,Text(Pengeluaran!$D:$D,"mmmm")=H$2,Pengeluaran!$E:$E=$B37) -> 0 | I37: =SUMPRODUCT(Pengeluaran!$F:$F,Text(Pengeluaran!$D:$D,"mmmm")=I$2,Pengeluaran!$E:$E=$B37) -> 27000 | J37: =SUMPRODUCT(Pengeluaran!$F:$F,Text(Pengeluaran!$D:$D,"mmmm")=J$2,Pengeluaran!$E:$E=$B37) -> 0 | ... N37: =SUMPRODUCT(Pengeluaran!$F:$F,Text(Pengeluaran!$D:$D,"mmmm")=N$2,Pengeluaran!$E:$E=$B37) -> 0
B38: ='⚙️Pengaturan'!E12 -> Beban Jasa | C38: =SUMPRODUCT(Pengeluaran!$F:$F,Text(Pengeluaran!$D:$D,"mmmm")=C$2,Pengeluaran!$E:$E=$B38) -> 0 | D38: =SUMPRODUCT(Pengeluaran!$F:$F,Text(Pengeluaran!$D:$D,"mmmm")=D$2,Pengeluaran!$E:$E=$B38) -> 0 | E38: =SUMPRODUCT(Pengeluaran!$F:$F,Text(Pengeluaran!$D:$D,"mmmm")=E$2,Pengeluaran!$E:$E=$B38) -> 0 | F38: =SUMPRODUCT(Pengeluaran!$F:$F,Text(Pengeluaran!$D:$D,"mmmm")=F$2,Pengeluaran!$E:$E=$B38) -> 0 | G38: =SUMPRODUCT(Pengeluaran!$F:$F,Text(Pengeluaran!$D:$D,"mmmm")=G$2,Pengeluaran!$E:$E=$B38) -> 0 | H38: =SUMPRODUCT(Pengeluaran!$F:$F,Text(Pengeluaran!$D:$D,"mmmm")=H$2,Pengeluaran!$E:$E=$B38) -> 0 | I38: =SUMPRODUCT(Pengeluaran!$F:$F,Text(Pengeluaran!$D:$D,"mmmm")=I$2,Pengeluaran!$E:$E=$B38) -> 0 | J38: =SUMPRODUCT(Pengeluaran!$F:$F,Text(Pengeluaran!$D:$D,"mmmm")=J$2,Pengeluaran!$E:$E=$B38) -> 0 | ... N38: =SUMPRODUCT(Pengeluaran!$F:$F,Text(Pengeluaran!$D:$D,"mmmm")=N$2,Pengeluaran!$E:$E=$B38) -> 0
B39: ='⚙️Pengaturan'!E13 -> Beban Promosi | C39: =SUMPRODUCT(Pengeluaran!$F:$F,Text(Pengeluaran!$D:$D,"mmmm")=C$2,Pengeluaran!$E:$E=$B39) -> 0 | D39: =SUMPRODUCT(Pengeluaran!$F:$F,Text(Pengeluaran!$D:$D,"mmmm")=D$2,Pengeluaran!$E:$E=$B39) -> 0 | E39: =SUMPRODUCT(Pengeluaran!$F:$F,Text(Pengeluaran!$D:$D,"mmmm")=E$2,Pengeluaran!$E:$E=$B39) -> 0 | F39: =SUMPRODUCT(Pengeluaran!$F:$F,Text(Pengeluaran!$D:$D,"mmmm")=F$2,Pengeluaran!$E:$E=$B39) -> 0 | G39: =SUMPRODUCT(Pengeluaran!$F:$F,Text(Pengeluaran!$D:$D,"mmmm")=G$2,Pengeluaran!$E:$E=$B39) -> 215000 | H39: =SUMPRODUCT(Pengeluaran!$F:$F,Text(Pengeluaran!$D:$D,"mmmm")=H$2,Pengeluaran!$E:$E=$B39) -> 0 | I39: =SUMPRODUCT(Pengeluaran!$F:$F,Text(Pengeluaran!$D:$D,"mmmm")=I$2,Pengeluaran!$E:$E=$B39) -> 134000 | J39: =SUMPRODUCT(Pengeluaran!$F:$F,Text(Pengeluaran!$D:$D,"mmmm")=J$2,Pengeluaran!$E:$E=$B39) -> 443500 | ... N39: =SUMPRODUCT(Pengeluaran!$F:$F,Text(Pengeluaran!$D:$D,"mmmm")=N$2,Pengeluaran!$E:$E=$B39) -> 95000
B40: ='⚙️Pengaturan'!E14 -> Beban Hutang Bank | C40: =SUMPRODUCT(Pengeluaran!$F:$F,Text(Pengeluaran!$D:$D,"mmmm")=C$2,Pengeluaran!$E:$E=$B40) -> 0 | D40: =SUMPRODUCT(Pengeluaran!$F:$F,Text(Pengeluaran!$D:$D,"mmmm")=D$2,Pengeluaran!$E:$E=$B40) -> 0 | E40: =SUMPRODUCT(Pengeluaran!$F:$F,Text(Pengeluaran!$D:$D,"mmmm")=E$2,Pengeluaran!$E:$E=$B40) -> 0 | F40: =SUMPRODUCT(Pengeluaran!$F:$F,Text(Pengeluaran!$D:$D,"mmmm")=F$2,Pengeluaran!$E:$E=$B40) -> 0 | G40: =SUMPRODUCT(Pengeluaran!$F:$F,Text(Pengeluaran!$D:$D,"mmmm")=G$2,Pengeluaran!$E:$E=$B40) -> 0 | H40: =SUMPRODUCT(Pengeluaran!$F:$F,Text(Pengeluaran!$D:$D,"mmmm")=H$2,Pengeluaran!$E:$E=$B40) -> 0 | I40: =SUMPRODUCT(Pengeluaran!$F:$F,Text(Pengeluaran!$D:$D,"mmmm")=I$2,Pengeluaran!$E:$E=$B40) -> 0 | J40: =SUMPRODUCT(Pengeluaran!$F:$F,Text(Pengeluaran!$D:$D,"mmmm")=J$2,Pengeluaran!$E:$E=$B40) -> 0 | ... N40: =SUMPRODUCT(Pengeluaran!$F:$F,Text(Pengeluaran!$D:$D,"mmmm")=N$2,Pengeluaran!$E:$E=$B40) -> 0
B41: ='⚙️Pengaturan'!E15 -> Beban Pelayanan Dewasa | F41: =SUMPRODUCT(Pengeluaran!$F:$F,Text(Pengeluaran!$D:$D,"mmmm")=F$2,Pengeluaran!$E:$E=$B41) -> 38000 | I41: =SUMPRODUCT(Pengeluaran!$F:$F,Text(Pengeluaran!$D:$D,"mmmm")=I$2,Pengeluaran!$E:$E=$B41) -> 561000 | J41: =SUMPRODUCT(Pengeluaran!$F:$F,Text(Pengeluaran!$D:$D,"mmmm")=J$2,Pengeluaran!$E:$E=$B41) -> 790500 | K41: =SUMPRODUCT(Pengeluaran!$F:$F,Text(Pengeluaran!$D:$D,"mmmm")=K$2,Pengeluaran!$E:$E=$B41) -> 1054351 | L41: =SUMPRODUCT(Pengeluaran!$F:$F,Text(Pengeluaran!$D:$D,"mmmm")=L$2,Pengeluaran!$E:$E=$B41) -> 692600 | M41: =SUMPRODUCT(Pengeluaran!$F:$F,Text(Pengeluaran!$D:$D,"mmmm")=M$2,Pengeluaran!$E:$E=$B41) -> 220000 | N41: =SUMPRODUCT(Pengeluaran!$F:$F,Text(Pengeluaran!$D:$D,"mmmm")=N$2,Pengeluaran!$E:$E=$B41) -> 637600
B42: ='⚙️Pengaturan'!E16 -> Beban Pelayanan Anak | F42: =SUMPRODUCT(Pengeluaran!$F:$F,Text(Pengeluaran!$D:$D,"mmmm")=F$2,Pengeluaran!$E:$E=$B42) -> 0 | I42: =SUMPRODUCT(Pengeluaran!$F:$F,Text(Pengeluaran!$D:$D,"mmmm")=I$2,Pengeluaran!$E:$E=$B42) -> 11500 | J42: =SUMPRODUCT(Pengeluaran!$F:$F,Text(Pengeluaran!$D:$D,"mmmm")=J$2,Pengeluaran!$E:$E=$B42) -> 0 | K42: =SUMPRODUCT(Pengeluaran!$F:$F,Text(Pengeluaran!$D:$D,"mmmm")=K$2,Pengeluaran!$E:$E=$B42) -> 0 | L42: =SUMPRODUCT(Pengeluaran!$F:$F,Text(Pengeluaran!$D:$D,"mmmm")=L$2,Pengeluaran!$E:$E=$B42) -> 0 | M42: =SUMPRODUCT(Pengeluaran!$F:$F,Text(Pengeluaran!$D:$D,"mmmm")=M$2,Pengeluaran!$E:$E=$B42) -> 0 | N42: =SUMPRODUCT(Pengeluaran!$F:$F,Text(Pengeluaran!$D:$D,"mmmm")=N$2,Pengeluaran!$E:$E=$B42) -> 0
B43: ='⚙️Pengaturan'!E17 -> Beban HPP Anak | F43: =SUMPRODUCT(Pengeluaran!$F:$F,Text(Pengeluaran!$D:$D,"mmmm")=F$2,Pengeluaran!$E:$E=$B43) -> 0 | I43: =SUMPRODUCT(Pengeluaran!$F:$F,Text(Pengeluaran!$D:$D,"mmmm")=I$2,Pengeluaran!$E:$E=$B43) -> 0 | J43: =SUMPRODUCT(Pengeluaran!$F:$F,Text(Pengeluaran!$D:$D,"mmmm")=J$2,Pengeluaran!$E:$E=$B43) -> 0 | K43: =SUMPRODUCT(Pengeluaran!$F:$F,Text(Pengeluaran!$D:$D,"mmmm")=K$2,Pengeluaran!$E:$E=$B43) -> 0 | L43: =SUMPRODUCT(Pengeluaran!$F:$F,Text(Pengeluaran!$D:$D,"mmmm")=L$2,Pengeluaran!$E:$E=$B43) -> 0 | M43: =SUMPRODUCT(Pengeluaran!$F:$F,Text(Pengeluaran!$D:$D,"mmmm")=M$2,Pengeluaran!$E:$E=$B43) -> 0 | N43: =SUMPRODUCT(Pengeluaran!$F:$F,Text(Pengeluaran!$D:$D,"mmmm")=N$2,Pengeluaran!$E:$E=$B43) -> 0
B44: ='⚙️Pengaturan'!E18 -> Beban HPP Dewasa | F44: =SUMPRODUCT(Pengeluaran!$F:$F,Text(Pengeluaran!$D:$D,"mmmm")=F$2,Pengeluaran!$E:$E=$B44) -> 0 | I44: =SUMPRODUCT(Pengeluaran!$F:$F,Text(Pengeluaran!$D:$D,"mmmm")=I$2,Pengeluaran!$E:$E=$B44) -> 0 | J44: =SUMPRODUCT(Pengeluaran!$F:$F,Text(Pengeluaran!$D:$D,"mmmm")=J$2,Pengeluaran!$E:$E=$B44) -> 0 | K44: =SUMPRODUCT(Pengeluaran!$F:$F,Text(Pengeluaran!$D:$D,"mmmm")=K$2,Pengeluaran!$E:$E=$B44) -> 0 | L44: =SUMPRODUCT(Pengeluaran!$F:$F,Text(Pengeluaran!$D:$D,"mmmm")=L$2,Pengeluaran!$E:$E=$B44) -> 0 | M44: =SUMPRODUCT(Pengeluaran!$F:$F,Text(Pengeluaran!$D:$D,"mmmm")=M$2,Pengeluaran!$E:$E=$B44) -> 0 | N44: =SUMPRODUCT(Pengeluaran!$F:$F,Text(Pengeluaran!$D:$D,"mmmm")=N$2,Pengeluaran!$E:$E=$B44) -> 0
B45: ='⚙️Pengaturan'!E19 -> Beban Kebersihan | F45: =SUMPRODUCT(Pengeluaran!$F:$F,Text(Pengeluaran!$D:$D,"mmmm")=F$2,Pengeluaran!$E:$E=$B45) -> 102000 | I45: =SUMPRODUCT(Pengeluaran!$F:$F,Text(Pengeluaran!$D:$D,"mmmm")=I$2,Pengeluaran!$E:$E=$B45) -> 131300 | J45: =SUMPRODUCT(Pengeluaran!$F:$F,Text(Pengeluaran!$D:$D,"mmmm")=J$2,Pengeluaran!$E:$E=$B45) -> 56000 | K45: =SUMPRODUCT(Pengeluaran!$F:$F,Text(Pengeluaran!$D:$D,"mmmm")=K$2,Pengeluaran!$E:$E=$B45) -> 49500 | L45: =SUMPRODUCT(Pengeluaran!$F:$F,Text(Pengeluaran!$D:$D,"mmmm")=L$2,Pengeluaran!$E:$E=$B45) -> 254600 | M45: =SUMPRODUCT(Pengeluaran!$F:$F,Text(Pengeluaran!$D:$D,"mmmm")=M$2,Pengeluaran!$E:$E=$B45) -> 120100 | N45: =SUMPRODUCT(Pengeluaran!$F:$F,Text(Pengeluaran!$D:$D,"mmmm")=N$2,Pengeluaran!$E:$E=$B45) -> 113500
B46: ='⚙️Pengaturan'!E20 -> Beban ATK | F46: =SUMPRODUCT(Pengeluaran!$F:$F,Text(Pengeluaran!$D:$D,"mmmm")=F$2,Pengeluaran!$E:$E=$B46) -> 201480 | I46: =SUMPRODUCT(Pengeluaran!$F:$F,Text(Pengeluaran!$D:$D,"mmmm")=I$2,Pengeluaran!$E:$E=$B46) -> 130100 | J46: =SUMPRODUCT(Pengeluaran!$F:$F,Text(Pengeluaran!$D:$D,"mmmm")=J$2,Pengeluaran!$E:$E=$B46) -> 79500 | K46: =SUMPRODUCT(Pengeluaran!$F:$F,Text(Pengeluaran!$D:$D,"mmmm")=K$2,Pengeluaran!$E:$E=$B46) -> 113000 | L46: =SUMPRODUCT(Pengeluaran!$F:$F,Text(Pengeluaran!$D:$D,"mmmm")=L$2,Pengeluaran!$E:$E=$B46) -> 27500 | M46: =SUMPRODUCT(Pengeluaran!$F:$F,Text(Pengeluaran!$D:$D,"mmmm")=M$2,Pengeluaran!$E:$E=$B46) -> 283000 | N46: =SUMPRODUCT(Pengeluaran!$F:$F,Text(Pengeluaran!$D:$D,"mmmm")=N$2,Pengeluaran!$E:$E=$B46) -> 5000
B47: ='⚙️Pengaturan'!E21 -> Beban Parkir | F47: =SUMPRODUCT(Pengeluaran!$F:$F,Text(Pengeluaran!$D:$D,"mmmm")=F$2,Pengeluaran!$E:$E=$B47) -> 18900 | I47: =SUMPRODUCT(Pengeluaran!$F:$F,Text(Pengeluaran!$D:$D,"mmmm")=I$2,Pengeluaran!$E:$E=$B47) -> 2000 | J47: =SUMPRODUCT(Pengeluaran!$F:$F,Text(Pengeluaran!$D:$D,"mmmm")=J$2,Pengeluaran!$E:$E=$B47) -> 0 | K47: =SUMPRODUCT(Pengeluaran!$F:$F,Text(Pengeluaran!$D:$D,"mmmm")=K$2,Pengeluaran!$E:$E=$B47) -> 0 | L47: =SUMPRODUCT(Pengeluaran!$F:$F,Text(Pengeluaran!$D:$D,"mmmm")=L$2,Pengeluaran!$E:$E=$B47) -> 0 | M47: =SUMPRODUCT(Pengeluaran!$F:$F,Text(Pengeluaran!$D:$D,"mmmm")=M$2,Pengeluaran!$E:$E=$B47) -> 2000 | N47: =SUMPRODUCT(Pengeluaran!$F:$F,Text(Pengeluaran!$D:$D,"mmmm")=N$2,Pengeluaran!$E:$E=$B47) -> 0
B48: ='⚙️Pengaturan'!E22 | F48: =SUMPRODUCT(Pengeluaran!$F:$F,Text(Pengeluaran!$D:$D,"mmmm")=F$2,Pengeluaran!$E:$E=$B48) -> 0 | I48: =SUMPRODUCT(Pengeluaran!$F:$F,Text(Pengeluaran!$D:$D,"mmmm")=I$2,Pengeluaran!$E:$E=$B48) -> 0 | J48: =SUMPRODUCT(Pengeluaran!$F:$F,Text(Pengeluaran!$D:$D,"mmmm")=J$2,Pengeluaran!$E:$E=$B48) -> 0 | K48: =SUMPRODUCT(Pengeluaran!$F:$F,Text(Pengeluaran!$D:$D,"mmmm")=K$2,Pengeluaran!$E:$E=$B48) -> 0 | L48: =SUMPRODUCT(Pengeluaran!$F:$F,Text(Pengeluaran!$D:$D,"mmmm")=L$2,Pengeluaran!$E:$E=$B48) -> 0 | M48: =SUMPRODUCT(Pengeluaran!$F:$F,Text(Pengeluaran!$D:$D,"mmmm")=M$2,Pengeluaran!$E:$E=$B48) -> 0 | N48: =SUMPRODUCT(Pengeluaran!$F:$F,Text(Pengeluaran!$D:$D,"mmmm")=N$2,Pengeluaran!$E:$E=$B48) -> 0
...

Sheet ⚙️Pengaturan
B2: Nama Usaha | C2: Jenis Pemeriksaan / Obat | D2: Harga Paket Pemeriksaan | E2: Jenis Pengeluaran | F2: Pembayaran
B3: Fisioterapi Gang Sehat Singkawang | C3: New Paket Terapi 1 | D3: 750000 | E3: Beban Gaji Pegawai | F3: TRF
C4: New Paket Terapi 2 | D4: 1400000 | E4: Beban Listrik | F4: TUNAI
C5: New Paket Terapi 3 | D5: 1300000 | E5: Beban PDAM
C6: New Sesi Terapi | D6: 175000 | E6: Beban pemeliharaan bangunan
C7: New Sesi terapi Homevisit | D7: 225000 | E7: Beban pemeliharaan peralatan
C8: New Sesi terapi Homevisit + Jarak | D8: 275000 | E8: Beban Konsumsi
C9: New Paket Terapi Homevisit | D9: 2000000 | E9: Beban acara dan pertemuan
C10: New Paket Terapi Homevisit+ Jarak | D10: 2050000 | E10: Beban Rapat
C11: Terapi Awal | D11: 250000 | E11: Beban Telepon dan Internet
C12: Paket Terapi 1 | D12: 650000 | E12: Beban Jasa
C13: Paket Terapi 2 | D13: 1200000 | E13: Beban Promosi
C14: Sesi Terapi | D14: 150000 | E14: Beban Hutang Bank
C15: Terapi Awal Homevisit | D15: 300000 | E15: Beban Pelayanan Dewasa
