Workbook
Name ANDI: 'JADWAL TERAPI'!$B$14:$H$17
Name NISA: #REF!
Name HESTI: #REF!
Name DANRU: #REF!
Name RIA: #REF!
Name RentangBernama1: #REF!
Name DANI: 'JADWAL TERAPI'!$B$4:$H$7
Name NADA: #REF!

Sheet LIST
A1: Suci | C1: ARDIAN KASPARI | D1: 09.00 | E1: CNS
A2: Susi | C2: DANIEL ALVES | D2: 10.00 | E2: PNS
A3: Mia | D3: 11.00
B4: ECY | C4: DIAS RIANSYAH | D4: 12.00 | E4: NECK
B5: EDO | C5: EKO JULIANTO | D5: 13.00 | E5: SHOULDER
B6: LULU | C6: FILIPPO INZAGHI | D6: 14.00 | E6: UPPER ARM
B7: RIA | C7: IQBAL ALIEFIAN | D7: 15.00 | E7: ELBOW
B8: IRMA | C8: JOKO PRASETIYO | D8: 16.00 | E8: LOWER ARM
B9: VIRA | C9: M. FAJRIYAN | D9: 17.00 | E9: WRIST
B10: TIA | C10: M. NIZAR | E10: HAND
B11: IIS | C11: MARCUS GAVA | E11: UPPER BACK
B12: NISA | C12: MARVIN ALEXA | E12: LOWER BACK
B13: FALLEN | C13: NASYUA RAVA | E13: PELVIC
B14: IRA | C14: RAMA REDONI | E14: HIP
C15: REFANI PUTRA | E15: THIGH
C16: ROMI HUMANDRI | E16: KNEE
C17: SANUSI | E17: CALF
C18: SYAHRIL RIYANTO | E18: ANKLE
C19: THIFAAL RAFIF | E19: FOOT
C20: WANDY KURNIAWAN | E20: SYSTEMIC
C21: YUDI PRIYATNA | E21: POSTURE

Sheet INPUTAN PASIEN
B1: Timestamp | C1: Tanggal | D1: Nama Anak | E1: Nama Panggilan | F1: No. RM | G1: Tanggal Lahir | H1: Usia | I1: Jenis Kelamin | J1: Keluhan | K1: Agama | L1: Nama Ibu | M1: Pekerjaan Ibu | N1: Nama Ayah | O1: Pekerjaan Ayah | P1: Alamat | Q1: Kel./Desa | R1: Kecamatan | S1: Kab./Kota | T1: Provinsi | U1: No. WA | V1: Sumber Pasien
B2: 45090.432 | D2: KHALID IBRAHIM AL KAHFI | G2: 44042 | I2: LAKI-LAKI | J2: FISIOTERAPI MOTORIK | K2: ISLAM | L2: DINDA FIRLIANSARI | M2: IBU RUMAH TANGGA | U2: 082231905665
B3: 45090.855 | D3: Muhammad Ammar | G3: 44128 | I3: LAKI-LAKI | J3: SENSORIK INTEGRASI & TERAPI WICARA | K3: ISLAM | L3: Nadya Ulfa | M3: Ibu Rumah Tangga | U3: 081328347009/0895702479833
B4: 45090.857 | D4: Rifqi Syafiq Syahputra | G4: 43060 | I4: LAKI-LAKI | J4: FISIOTERAPI | K4: ISLAM | L4: Desy Ariani Nasution | M4: ASN | U4: 08115706881
B5: 45090.857 | D5: Jordan Gabrian | G5: 43780 | I5: LAKI-LAKI | J5: SENSORIK INTEGRASI & TERAPI WICARA | K5: PROTESTAN | L5: Lia Andriani | M5: Ibu rumah tangga | U5: 089622447016
B6: 45090.857 | D6: Arsya khairul fatih | G6: 44172 | I6: LAKI-LAKI | J6: TERAPI WICARA | K6: ISLAM | L6: Deasy novita sari | M6: Ibu rumah tangga | U6: 085658366269
B7: 45090.857 | D7: Raisya Rahma Syahira | G7: 43853 | I7: PEREMPUAN | J7: FISIOTERAPI | K7: ISLAM | L7: Desy Ariani Nasution | M7: ASN | U7: 08115706881
B8: 45090.862 | D8: AHMAD LATIF SAFULLAH | G8: 39847 | I8: LAKI-LAKI | J8: FISIOTERAPI | K8: ISLAM | L8: DARWANTI | M8: IBU RUMAH TANGGA | U8: 082252116339
B9: 45090.862 | D9: Khalid ibrahim al kahfi | G9: 44042 | I9: LAKI-LAKI | J9: FISIOTERAPI | K9: ISLAM | L9: Dinda firliansari | M9: IRT | U9: 082231905665
B10: 45090.863 | D10: DAVID CHRISTIAN | G10: 43515 | I10: LAKI-LAKI | J10: SENSORIK INTEGRASI & TERAPI WICARA | K10: PROTESTAN | L10: DESSY | M10: WIRASWASTA | U10: 085248068221
B11: 45090.864 | D11: CELINE ZOEY HEARTILLY | G11: 43431 | I11: PEREMPUAN | J11: SENSORIK INTEGRASI & TERAPI WICARA | K11: BUDDHA | L11: SYLVIA VERONIKA | M11: IBU RUMAH TANGGA | U11: 085245070077
B12: 45090.868 | D12: Kenzo Alfa As-siddiq | G12: 44219 | I12: LAKI-LAKI | J12: TERAPI WICARA | K12: ISLAM | L12: Tara Chairunisa | M12: Guru | U12: 081362524442
B13: 45090.869 | D13: RAYYA FATIHAH RAZAANA | G13: 41379 | I13: PEREMPUAN | J13: FISIOTERAPI | K13: ISLAM | L13: EVA NOVIANTI HESTI VERA | M13: PNS | U13: 08152234183
... B58: 45160.417 | D58: Jasper Gabriel | G58: 43039 | I58: LAKI-LAKI | J58: SENSORIK INTEGRASI & TERAPI WICARA | K58: PROTESTAN | L58: Yenny | M58: Ibu rumah tangga | U58: 081917142519
B59: 45171.735 | D59: FAYK KAIVAN SERGUERO | G59: 44719 | I59: LAKI-LAKI | J59: BANYAK OMONG | K59: ISLAM | L59: ETRI YULIA ANDINI | M59: IRT | N59: DANI FAHRIZAL | O59: SWASTA | P59: JL. P. H. HUSIN 2 GG. WISUDA NO. 23A | U59: 082158963663
B60: 45171.744 | D60: AHMAD SYAKIR | G60: 44794 | I60: LAKI-LAKI | J60: PILEK BATUK | K60: ISLAM | L60: IRMA RISKIMA | M60: SWASTA | N60: SYEKH ARPI | O60: WIRAUSAHA | P60: JALAN ARTERI SUPADIO CABANG KIRI | U60: 08981380248
B61: 45172.594 | D61: RAINA AISYAH SUPRIADI | G61: 41412 | I61: PEREMPUAN | J61: CP | K61: ISLAM | L61: KARTINI APRILYANI | M61: IBU RUMAH TANGGA | N61: DENNY SUPRIADI | O61: PNS | P61: JL.PEMDA KOMP.GRIYA MAYOR A.26 | U61: 082353828426
B62: 45172.598 | D62: RAISSA FATIMAH SUPRIADI | G62: 41412 | I62: PEREMPUAN | J62: CP | K62: ISLAM | L62: KARTINI APRILYANI | M62: IBU RUMAH TANGGA | N62: DENNY SUPRIADI | O62: PNS | P62: JL.PEMDA.KOMP GRIYA MAYOR A.26 | U62: 082353828426
B63: 45172.598 | D63: RAINA AISYAH SUPRIADI | G63: 41412 | I63: PEREMPUAN | J63: CP | K63: ISLAM | L63: KARTINI APRILYANI | M63: IBU RUMAH TANGGA | N63: DENNY SUPRIADI | O63: PNS | P63: JL.PEMDA KOMP.GRIYA MAYOR A.26 | U63: 082353828426
B64: 45172.602 | D64: Syarif Muhammad Alfateh | G64: 44196 | I64: LAKI-LAKI | J64: Sering kaget, sesak saat malam hari karena lendir sehingga pola tidur berubah | K64: ISLAM | L64: Syarifah Fifi Mariani Alkadrie | M64: Honorer | N64: SY. Adhy | O64: Karyawan swasta | P64: Jalan Tritura No. 10 Kel. Dalam Bugis Kec. Pontianak timur | U64: 085754395905
B65: 45173.726 | D65: Muhammad Azzam Aco | G65: 42627 | I65: LAKI-LAKI | J65: Lambat bicara diagnosa dr ADHD | K65: ISLAM | L65: Ira nia | M65: Ibu rumah tangga | N65: Maman Aco | O65: Buruh harian lepas | P65: Jalan Kom Yos Sudarso gang alpokat indah, jalur 0 | U65: 081255816909
B66: 45173.727 | D66: Elzevarel Zerkha Azarya | G66: 44426 | I66: LAKI-LAKI | J66: SPEECH DELAY | K66: PROTESTAN | L66: Krisyesika | M66: Dosen | N66: Eben Heizer | O66: Wiraswasta | P66: Jln. Trans Kalimantan Gg. Budaya No. 1 | U66: 085346807788
B67: 45173.731 | D67: Amir Syakir | G67: 43364 | I67: LAKI-LAKI | J67: Tidak fokus | K67: ISLAM | L67: Wahyuli Astuti | M67: Ibu rumah tangga | N67: Suwardi | O67: Karyawan swasta | P67: Jl komyo sudarso gg srikaya 2 no 19 | U67: 082148665510
B68: 45173.733 | D68: Muhammad Zafran Maerad | G68: 44264 | I68: LAKI-LAKI | J68: speach delay | K68: ISLAM | L68: Dewi Sulistianingsih | M68: Karyawan Swasta | N68: Hafitdin | O68: Karyawan Swasta | P68: Jl M Sohor Gg Sederhana | U68: 08998092083
B69: 45173.739 | D69: Marcello | G69: 43931 | I69: LAKI-LAKI | J69: telat bicara | K69: BUDDHA | L69: Hie fui na | M69: ibu rumah tangga | N69: Pet ho | O69: wiraswasta | P69: jl nawawi hasan 3 no 342 | U69: 082158815530
B70: 45173.742 | D70: AZQEEYA ELNARA RACAISHA | G70: 44268 | I70: PEREMPUAN | J70: SPEECH DELAY | K70: ISLAM | L70: URAY YUCA ERGAIASHA | M70: IRT | N70: RAHMAT RAZULY HIDAYAT | O70: SWASTA | P70: JL. KARYA KOMP. FAJAR ASRI 3 A-28 | U70: 08982292556
... B169: 45288.409 | D169: Imran hanif pribadi | G169: 33762 | I169: LAKI-LAKI | J169: Add | K169: ISLAM | L169: Eni dian pertiwi | M169: Ibu rumah tangga | N169: Citra teguh iman pribadi | O169: Pegawai swasta | P169: Jalan wonobaru gg remaja 2 no 30 | U169: 082139121261
B170: 45293.501 | D170: FAYK KAIVAN SERGUERO | G170: 44719 | I170: LAKI-LAKI | J170: BANYAK OMONG | K170: ISLAM | L170: ETRI YULIA ANDINI | M170: IBU RUMAH TANGGA | N170: DANI FAHRIZAL | O170: TENAGA KESEHATAN | P170: JL. P. H. HUSIN 2 GG.WISUDA NO. 23A | Q170: BANGKA BELITUNG DARAT | R170: PONTIANAK TENGGARA | S170: PONTIANAK | T170: KALIMANTAN BARAT | U170: 081333668688
B171: 45293.508 | D171: AHMAD SYAKIR ARISTAMA | G171: 44794 | I171: LAKI-LAKI | J171: BANYAK OMONG | K171: ISLAM | L171: IRMA RISKIMA | M171: TENAGA KESEHATAN | N171: SYEKH ARPI | O171: PENGUSAHA | P171: CABANG KIRI GG. SEDERHANA | Q171: PARIT BARU | R171: SUNGAI RAYA | S171: KUBU RAYA | T171: KALIMANTAN BARAT | U171: 08981380248
B172: 45294.449 | D172: Muhammad akram zaydan | G172: 43166 | I172: LAKI-LAKI | J172: Kurang fokus | K172: ISLAM | L172: Mierandha edward lubis | M172: IBU RUMAH TANGGA | N172: Nofiandy surya | O172: WIRASWASTA | P172: Desa kapur, komplek Star bhayangkara residance block H no.5 | Q172: Mekar baru | R172: Sungai raya | S172: Kuburaya | T172: Kalimantan barat | U172: 0817202880
B173: 45294.531 | D173: Manuel ernando halim. | G173: 43354 | I173: LAKI-LAKI | J173: Speed delay | K173: KATOLIK | L173: Sari yohana | M173: IBU RUMAH TANGGA | N173: Frendy | O173: Karyawan | P173: Jl.wonodadi 3 | Q173: Kota baru | S173: Pontianak | T173: Kalbar | U173: 081288306888
B174: 45294.667 | D174: Labib Razan Al Barra | G174: 44813 | I174: LAKI-LAKI | J174: Masalah gangguan makan | K174: ISLAM | L174: Riski liana sari | M174: TENAGA KESEHATAN | N174: Muhammad iqbal farizqi | O174: PNS | P174: Komplek btn sekayam indah. Dusun balaikarangan 3 | Q174: Balai karangan | R174: Sekayam | S174: Sanggau | T174: Kalbar | U174: 085250805070
B175: 45295.478 | D175: Darev christian zega | G175: 44243 | I175: LAKI-LAKI | J175: Belum bisa lancar bicara & hiperaktif | K175: PROTESTAN | L175: Jeema Herrera Evelina Sinaga | M175: IBU RUMAH TANGGA | N175: Darmin Usman zega | O175: WIRASWASTA | P175: Jl madyosari 1 dalam no 51 | Q175: Akcaya | R175: Pontianak | S175: Pontianak selatan | T175: Kalbar | U175: 089603315528
B176: 45295.596 | D176: Arvan rayhan diandita | G176: 44427 | I176: LAKI-LAKI | J176: Terapi perilaku dan terapi wicara | K176: ISLAM | L176: Ressy serliandari | M176: IBU RUMAH TANGGA | N176: Bagus diandita | O176: PNS | P176: Sungai raya dalam komp. Srikandi 06 | Q176: Sungai raya | R176: Sungai raya | S176: Kubu raya | T176: Kalimantan barat | U176: 085654550060
B177: 45295.839 | D177: Jevano ang | G177: 44384 | I177: LAKI-LAKI | J177: Belum bisa ngomong, hanya bisa manggil papa mama koko dadah gak ya | K177: KATOLIK | L177: Silvia | M177: IBU RUMAH TANGGA | N177: Hendra | O177: WIRASWASTA | P177: Jl srikandi komp hosana fhileo blok bb22 | Q177: Sungai raya dalam | R177: Sungai raya | S177: Kubu raya | T177: Kalimantan barat | U177: 089625550586
B178: 45297.693 | D178: HAFIZH AL FARREL DAMARIO | G178: 43091 | I178: LAKI-LAKI | J178: BICARA KURANG JELAS | K178: ISLAM | L178: RAWAN TRI SULISTYA | M178: IBU RUMAH TANGGA | N178: LUSINANTO HARTADI | O178: SWASTA | P178: Jl. Karya Perumahan Graha Kirana 13 No.A4 | Q178: SUNGAI KAKAP | R178: KOTA BARU | S178: KOTA BARU | T178: PONTIANAK | U178: 081286995997
B179: 45298.725 | D179: Arkan Subhan Alfarizi | G179: 42390 | I179: LAKI-LAKI | J179: cerebral palsy, belum bisa berjalan | K179: ISLAM | L179: Eka Lestari | M179: PNS | N179: Dwi Rachmawan | O179: PNS | P179: Jl. Ujung pandang Gg. Bala arung No 17 | Q179: kelurahan Sungai Jawi | R179: Pontianak Kota | S179: Kota Pontianak | T179: Kalimantan Barat | U179: 085820410031
B180: 45298.734 | D180: TALINO CASSIUS SILSLAHI | G180: 44200 | I180: LAKI-LAKI | J180: Speech Delay | K180: KATOLIK | L180: FLORENSIA INDAN STEPANI | M180: KARYAWAN SWASTA | N180: BENNY PERNANDO SILALAHI | O180: KARYAWAN SWASTA | P180: JALAN DANAU SENTARUM GG. KALI BENING (Rumah ke-10) | Q180: SUNGAI BANGKONG | R180: PONTIANAK KOTA | S180: PONTIANAK | T180: KALIMANTAN BARAT | U180: 081286234546
B181: 45298.8 | D181: MACK KIO JUANSON | G181: 44462 | I181: LAKI-LAKI | J181: UMUR 2 TAHUN 4 BULAN MALAS BICARA | K181: KATOLIK | L181: JULIANA | M181: IBU RUMAH TANGGA | N181: ANDY | O181: KARYAWAN | P181: JL. MERDEKA NO.506 | Q181: MARIANA | R181: PONTIANAK KOTA | S181: KOTA PONTIANAK | T181: KALIMANTAN BARAT | U181: 085247179223
B182: 45299.669 | D182: Dharsata Indira | G182: 45001 | I182: PEREMPUAN | J182: Leher belum tegak dan badan sering dikakukan | K182: ISLAM | L182: Dita Octavia | M182: IBU RUMAH TANGGA | N182: Jarno | O182: Buruh | P182: Dusun sumber Rejo rt 003 rw 002 | Q182: Pinang Dalam | R182: Kubu | S182: Kubu Raya/Pontianak | T182: Kalimantan Barat | U182: 085787680674
...

Sheet 🙎‍♂️ Pasien
C1: DATA PASIEN GRIYA ANAK GANG SEHAT
B3: Timestamp | C3: Tanggal | D3: Nama Anak | E3: Nama Panggilan | F3: No. RM | G3: Tanggal Lahir | H3: Usia | I3: Jenis Kelamin | J3: Keluhan | K3: Agama | L3: Nama Ibu | M3: Pekerjaan Ibu | N3: Nama Ayah | O3: Pekerjaan Ayah | P3: Alamat | Q3: Kel./Desa | R3: Kecamatan | S3: Kab./Kota | T3: Provinsi | U3: No. WA | V3: Sumber Pasien
F4: {=if(C4:C633="","",left(D4:D633,"1")&text(C4:C633,"yy")&text(C4:C633,"mm"&text(G4:G633,"yy"))&right(U4:U633,"2"))} | H4: {=if(C4:C633="","",(floor((today()-G4:G633)/365,1)&" th "&FLOOR((today()-G4:G633)/(365/12),1)-(floor((today()-G4:G633)/365,1)*12)&" bl"))}
D5: OFF
D6: TA
D7: SYS
D8: MANAJEMEN
B9: 13/06/2023 10:21:22 | C9: 45090.432 | D9: KHALID IBRAHIM AL KAHFI | F9: K23062065 | G9: 30/07/2020 | H9: 6 th 1 bl | I9: LAKI-LAKI | J9: FISIOTERAPI MOTORIK | K9: ISLAM | L9: DINDA FIRLIANSARI | M9: IBU RUMAH TANGGA | U9: 082231905665
B10: 13/06/2023 20:30:32 | C10: 45090.855 | D10: MUHAMMAD AMMAR | F10: M23062033 | G10: 24/10/2020 | H10: 5 th 10 bl | I10: LAKI-LAKI | J10: SENSORIK INTEGRASI & TERAPI WICARA | K10: ISLAM | L10: NADYA ULFA | M10: IBU RUMAH TANGGA | U10: 081328347009/0895702479833
B11: 13/06/2023 20:33:25 | C11: 45090.857 | D11: RIFQI SYAFIQ SYAHPUTRA | F11: R23061781 | G11: 21/11/2017 | H11: 8 th 9 bl | I11: LAKI-LAKI | J11: FISIOTERAPI | K11: ISLAM | L11: DESY ARIANI NASUTION | M11: ASN | U11: 08115706881
B12: 13/06/2023 20:33:28 | C12: 45090.857 | D12: JORDAN GABRIAN | F12: J23061916 | G12: 11/11/2019 | H12: 6 th 9 bl | I12: LAKI-LAKI | J12: SENSORIK INTEGRASI & TERAPI WICARA | K12: PROTESTAN | L12: LIA ANDRIANI | M12: IBU RUMAH TANGGA | U12: 089622447016
B13: 13/06/2023 20:34:10 | C13: 45090.857 | D13: ARSYA KHAIRUL FATIH | F13: A23062069 | G13: 07/12/2020 | H13: 5 th 8 bl | I13: LAKI-LAKI | J13: TERAPI WICARA | K13: ISLAM | L13: DEASY NOVITA SARI | M13: IBU RUMAH TANGGA | U13: 085658366269
B14: 13/06/2023 20:34:28 | C14: 45090.857 | D14: RAISYA RAHMA SYAHIRA | F14: R23062081 | G14: 23/01/2020 | H14: 6 th 7 bl | I14: PEREMPUAN | J14: FISIOTERAPI | K14: ISLAM | L14: DESY ARIANI NASUTION | M14: ASN | U14: 08115706881
B15: 13/06/2023 20:40:42 | C15: 45090.862 | D15: AHMAD LATIF SAFULLAH | F15: A23060939 | G15: 03/02/2009 | H15: 17 th 6 bl | I15: LAKI-LAKI | J15: FISIOTERAPI | K15: ISLAM | L15: DARWANTI | M15: IBU RUMAH TANGGA | U15: 082252116339
B16: 13/06/2023 20:40:53 | C16: 45090.862 | D16: KHALID IBRAHIM AL KAHFI | F16: K23062065 | G16: 30/07/2020 | H16: 6 th 1 bl | I16: LAKI-LAKI | J16: FISIOTERAPI | K16: ISLAM | L16: DINDA FIRLIANSARI | M16: IRT | U16: 082231905665
B17: 13/06/2023 20:42:52 | C17: 45090.863 | D17: DAVID CHRISTIAN | F17: D23061921 | G17: 19/02/2019 | H17: 7 th 6 bl | I17: LAKI-LAKI | J17: SENSORIK INTEGRASI & TERAPI WICARA | K17: PROTESTAN | L17: DESSY | M17: WIRASWASTA | U17: 085248068221
B18: 13/06/2023 20:44:35 | C18: 45090.864 | D18: CELINE ZOEY HEARTILLY | F18: C23061877 | G18: 27/11/2018 | H18: 7 th 9 bl | I18: PEREMPUAN | J18: SENSORIK INTEGRASI & TERAPI WICARA | K18: BUDDHA | L18: SYLVIA VERONIKA | M18: IBU RUMAH TANGGA | U18: 085245070077
B19: 13/06/2023 20:49:30 | C19: 45090.868 | D19: KENZO ALFA AS-SIDDIQ | F19: K23062142 | G19: 23/01/2021 | H19: 5 th 7 bl | I19: LAKI-LAKI | J19: TERAPI WICARA | K19: ISLAM | L19: TARA CHAIRUNISA | M19: GURU | U19: 081362524442
B20: 13/06/2023 20:51:33 | C20: 45090.869 | D20: RAYYA FATIHAH RAZAANA | F20: R23061383 | G20: 15/04/2013 | H20: 13 th 4 bl | I20: PEREMPUAN | J20: FISIOTERAPI | K20: ISLAM | L20: EVA NOVIANTI HESTI VERA | M20: PNS | U20: 08152234183
... B65: 22/08/2023 10:00:51 | C65: 45160.417 | D65: JASPER GABRIEL | F65: J23081719 | G65: 31/10/2017 | H65: 8 th 10 bl | I65: LAKI-LAKI | J65: SENSORIK INTEGRASI & TERAPI WICARA | K65: PROTESTAN | L65: YENNY | M65: IBU RUMAH TANGGA | U65: 081917142519
B66: 02/09/2023 17:37:54 | C66: 45171.735 | D66: FAYK KAIVAN SERGUERO | F66: F23092263 | G66: 07/06/2022 | H66: 4 th 2 bl | I66: LAKI-LAKI | J66: BANYAK OMONG | K66: ISLAM | L66: ETRI YULIA ANDINI | M66: IRT | N66: DANI FAHRIZAL | O66: SWASTA | P66: JL. P. H. HUSIN 2 GG. WISUDA NO. 23A | U66: 082158963663
B67: 02/09/2023 17:52:01 | C67: 45171.744 | D67: AHMAD SYAKIR | F67: A23092248 | G67: 21/08/2022 | H67: 4 th 0 bl | I67: LAKI-LAKI | J67: PILEK BATUK | K67: ISLAM | L67: IRMA RISKIMA | M67: SWASTA | N67: SYEKH ARPI | O67: WIRAUSAHA | P67: JALAN ARTERI SUPADIO CABANG KIRI | U67: 08981380248
B68: 03/09/2023 14:15:18 | C68: 45172.594 | D68: RAINA AISYAH SUPRIADI | F68: R23091326 | G68: 18/05/2013 | H68: 13 th 3 bl | I68: PEREMPUAN | J68: CP | K68: ISLAM | L68: KARTINI APRILYANI | M68: IBU RUMAH TANGGA | N68: DENNY SUPRIADI | O68: PNS | P68: JL.PEMDA KOMP.GRIYA MAYOR A.26 | U68: 082353828426
B69: 03/09/2023 14:20:58 | C69: 45172.598 | D69: RAISSA FATIMAH SUPRIADI | F69: R23091326 | G69: 18/05/2013 | H69: 13 th 3 bl | I69: PEREMPUAN | J69: CP | K69: ISLAM | L69: KARTINI APRILYANI | M69: IBU RUMAH TANGGA | N69: DENNY SUPRIADI | O69: PNS | P69: JL.PEMDA.KOMP GRIYA MAYOR A.26 | U69: 082353828426
B70: 03/09/2023 14:21:12 | C70: 45172.598 | D70: RAINA AISYAH SUPRIADI | F70: R23091326 | G70: 18/05/2013 | H70: 13 th 3 bl | I70: PEREMPUAN | J70: CP | K70: ISLAM | L70: KARTINI APRILYANI | M70: IBU RUMAH TANGGA | N70: DENNY SUPRIADI | O70: PNS | P70: JL.PEMDA KOMP.GRIYA MAYOR A.26 | U70: 082353828426
B71: 03/09/2023 14:26:24 | C71: 45172.602 | D71: SYARIF MUHAMMAD ALFATEH | F71: S23092005 | G71: 31/12/2020 | H71: 5 th 7 bl | I71: LAKI-LAKI | J71: SERING KAGET, SESAK SAAT MALAM HARI KARENA LENDIR SEHINGGA POLA TIDUR BERUBAH | K71: ISLAM | L71: SYARIFAH FIFI MARIANI ALKADRIE | M71: HONORER | N71: SY. ADHY | O71: KARYAWAN SWASTA | P71: JALAN TRITURA NO. 10 KEL. DALAM BUGIS KEC. PONTIANAK TIMUR | U71: 085754395905
B72: 04/09/2023 17:26:00 | C72: 45173.726 | D72: MUHAMMAD AZZAM ACO | F72: M23091609 | G72: 14/09/2016 | H72: 9 th 11 bl | I72: LAKI-LAKI | J72: LAMBAT BICARA DIAGNOSA DR ADHD | K72: ISLAM | L72: IRA NIA | M72: IBU RUMAH TANGGA | N72: MAMAN ACO | O72: BURUH HARIAN LEPAS | P72: JALAN KOM YOS SUDARSO GANG ALPOKAT INDAH, JALUR 0 | U72: 081255816909
B73: 04/09/2023 17:27:17 | C73: 45173.727 | D73: ELZEVAREL ZERKHA AZARYA | F73: E23092188 | G73: 18/08/2021 | H73: 5 th 0 bl | I73: LAKI-LAKI | J73: SPEECH DELAY | K73: PROTESTAN | L73: KRISYESIKA | M73: DOSEN | N73: EBEN HEIZER | O73: WIRASWASTA | P73: JLN. TRANS KALIMANTAN GG. BUDAYA NO. 1 | U73: 085346807788
B74: 04/09/2023 17:32:45 | C74: 45173.731 | D74: AMIR SYAKIR | F74: A23091810 | G74: 21/09/2018 | H74: 7 th 11 bl | I74: LAKI-LAKI | J74: TIDAK FOKUS | K74: ISLAM | L74: WAHYULI ASTUTI | M74: IBU RUMAH TANGGA | N74: SUWARDI | O74: KARYAWAN SWASTA | P74: JL KOMYO SUDARSO GG SRIKAYA 2 NO 19 | U74: 082148665510
B75: 04/09/2023 17:34:53 | C75: 45173.733 | D75: MUHAMMAD ZAFRAN MAERAD | F75: M23092183 | G75: 09/03/2021 | H75: 5 th 5 bl | I75: LAKI-LAKI | J75: SPEACH DELAY | K75: ISLAM | L75: DEWI SULISTIANINGSIH | M75: KARYAWAN SWASTA | N75: HAFITDIN | O75: KARYAWAN SWASTA | P75: JL M SOHOR GG SEDERHANA | U75: 08998092083
B76: 04/09/2023 17:44:10 | C76: 45173.739 | D76: MARCELLO | F76: M23092030 | G76: 10/04/2020 | H76: 6 th 4 bl | I76: LAKI-LAKI | J76: TELAT BICARA | K76: BUDDHA | L76: HIE FUI NA | M76: IBU RUMAH TANGGA | N76: PET HO | O76: WIRASWASTA | P76: JL NAWAWI HASAN 3 NO 342 | U76: 082158815530
B77: 04/09/2023 17:48:15 | C77: 45173.742 | D77: AZQEEYA ELNARA RACAISHA | F77: A23092156 | G77: 13/03/2021 | H77: 5 th 5 bl | I77: PEREMPUAN | J77: SPEECH DELAY | K77: ISLAM | L77: URAY YUCA ERGAIASHA | M77: IRT | N77: RAHMAT RAZULY HIDAYAT | O77: SWASTA | P77: JL. KARYA KOMP. FAJAR ASRI 3 A-28 | U77: 08982292556
... B176: 28/12/2023 9:48:15 | C176: 45288.409 | D176: IMRAN HANIF PRIBADI | F176: I23129261 | G176: 07/06/1992 | H176: 34 th 3 bl | I176: LAKI-LAKI | J176: ADD | K176: ISLAM | L176: ENI DIAN PERTIWI | M176: IBU RUMAH TANGGA | N176: CITRA TEGUH IMAN PRIBADI | O176: PEGAWAI SWASTA | P176: JALAN WONOBARU GG REMAJA 2 NO 30 | U176: 082139121261
B177: 02/01/2024 12:00:48 | C177: 45293.501 | D177: FAYK KAIVAN SERGUERO | F177: F24012288 | G177: 07/06/2022 | H177: 4 th 2 bl | I177: LAKI-LAKI | J177: BANYAK OMONG | K177: ISLAM | L177: ETRI YULIA ANDINI | M177: IBU RUMAH TANGGA | N177: DANI FAHRIZAL | O177: TENAGA KESEHATAN | P177: JL. P. H. HUSIN 2 GG.WISUDA NO. 23A | Q177: BANGKA BELITUNG DARAT | R177: PONTIANAK TENGGARA | S177: PONTIANAK | T177: KALIMANTAN BARAT | U177: 081333668688
B178: 02/01/2024 12:11:02 | C178: 45293.508 | D178: AHMAD SYAKIR ARISTAMA | F178: A24012248 | G178: 21/08/2022 | H178: 4 th 0 bl | I178: LAKI-LAKI | J178: BANYAK OMONG | K178: ISLAM | L178: IRMA RISKIMA | M178: TENAGA KESEHATAN | N178: SYEKH ARPI | O178: PENGUSAHA | P178: CABANG KIRI GG. SEDERHANA | Q178: PARIT BARU | R178: SUNGAI RAYA | S178: KUBU RAYA | T178: KALIMANTAN BARAT | U178: 08981380248
B179: 03/01/2024 10:46:11 | C179: 45294.449 | D179: MUHAMMAD AKRAM ZAYDAN | F179: M24011880 | G179: 07/03/2018 | H179: 8 th 5 bl | I179: LAKI-LAKI | J179: KURANG FOKUS | K179: ISLAM | L179: MIERANDHA EDWARD LUBIS | M179: IBU RUMAH TANGGA | N179: NOFIANDY SURYA | O179: WIRASWASTA | P179: DESA KAPUR, KOMPLEK STAR BHAYANGKARA RESIDANCE BLOCK H NO.5 | Q179: MEKAR BARU | R179: SUNGAI RAYA | S179: KUBURAYA | T179: KALIMANTAN BARAT | U179: 0817202880
B180: 03/01/2024 12:45:15 | C180: 45294.531 | D180: MANUEL ERNANDO HALIM. | F180: M24011888 | G180: 11/09/2018 | H180: 7 th 11 bl | I180: LAKI-LAKI | J180: SPEED DELAY | K180: KATOLIK | L180: SARI YOHANA | M180: IBU RUMAH TANGGA | N180: FRENDY | O180: KARYAWAN | P180: JL.WONODADI 3 | Q180: KOTA BARU | S180: PONTIANAK | T180: KALBAR | U180: 081288306888
B181: 03/01/2024 16:00:59 | C181: 45294.667 | D181: LABIB RAZAN AL BARRA | F181: L24012270 | G181: 09/09/2022 | H181: 3 th 11 bl | I181: LAKI-LAKI | J181: MASALAH GANGGUAN MAKAN | K181: ISLAM | L181: RISKI LIANA SARI | M181: TENAGA KESEHATAN | N181: MUHAMMAD IQBAL FARIZQI | O181: PNS | P181: KOMPLEK BTN SEKAYAM INDAH. DUSUN BALAIKARANGAN 3 | Q181: BALAI KARANGAN | R181: SEKAYAM | S181: SANGGAU | T181: KALBAR | U181: 085250805070
B182: 04/01/2024 11:28:32 | C182: 45295.478 | D182: DAREV CHRISTIAN ZEGA | F182: D24012128 | G182: 16/02/2021 | H182: 5 th 6 bl | I182: LAKI-LAKI | J182: BELUM BISA LANCAR BICARA & HIPERAKTIF | K182: PROTESTAN | L182: JEEMA HERRERA EVELINA SINAGA | M182: IBU RUMAH TANGGA | N182: DARMIN USMAN ZEGA | O182: WIRASWASTA | P182: JL MADYOSARI 1 DALAM NO 51 | Q182: AKCAYA | R182: PONTIANAK | S182: PONTIANAK SELATAN | T182: KALBAR | U182: 089603315528
B183: 04/01/2024 14:18:15 | C183: 45295.596 | D183: ARVAN RAYHAN DIANDITA | F183: A24012160 | G183: 19/08/2021 | H183: 5 th 0 bl | I183: LAKI-LAKI | J183: TERAPI PERILAKU DAN TERAPI WICARA | K183: ISLAM | L183: RESSY SERLIANDARI | M183: IBU RUMAH TANGGA | N183: BAGUS DIANDITA | O183: PNS | P183: SUNGAI RAYA DALAM KOMP. SRIKANDI 06 | Q183: SUNGAI RAYA | R183: SUNGAI RAYA | S183: KUBU RAYA | T183: KALIMANTAN BARAT | U183: 085654550060
...

Sheet AMBIL DATA PENGGAJIAN

Sheet JADWAL RAMADHAN 2026
B1: JADWAL GRIYA ANAK GANG SEHAT
D3: FT | J3: TW | O3: BT | R3: PSI
E4: MISWI | F4: EDO | G4: IRMA | H4: LULU | I4: TIA | K4: ADEL | L4: CHITA | P4: IRA | Q4: STEFY | S4: ISTI
B5: 46097 | D5: =$B$5 -> 46097
B6: =$B$5 -> 46097 | C6: 08.00 | D6: SYS | E6: DINDA ANGELICA DOMINIQUE | F6: OFF | G6: OFF | H6: OFF | I6: OFF | J6: SYS | K6: ALEENA MARIZA | L6: OFF | M6: OFF | N6: OFF | O6: SYS | P6: OFF | Q6: ALICE GLIONA DARCHELLE | R6: SYS | S6: OFF
C7: 09.00 | D7: SYS | E7: ATTHAR ADAM PRASETYA | F7: OFF | G7: OFF | H7: OFF | I7: OFF | J7: SYS | K7: ALEXANDER OTTO | L7: OFF | M7: OFF | N7: OFF | O7: SYS | P7: OFF | Q7: MUHAMMAD ALFATIH | R7: SYS | S7: off
B8: =$B$5 -> 46097 | C8: 10.00 | D8: SYS | E8: KAIRO GANENDRA CATRA | F8: OFF | G8: OFF | H8: off | I8: OFF | J8: SYS | K8: SHAQUEENA ALESHA MECCAYLA | L8: OFF | M8: OFF | N8: OFF | O8: SYS | P8: OFF | Q8: GEORGHINO GABRIELLO BRIO | R8: SYS | S8: OFF
B9: =$B$5 -> 46097 | C9: 11.00 | D9: SYS | E9: OFF | F9: MUHAMMAD DZAKY ALMAIR | G9: OFF | H9: KEENAN PRADIPA CHANDRA | I9: off | J9: SYS | K9: ISTIRAHAT | L9: ARSYA SHAKA SANJAYA | M9: OFF | N9: OFF | O9: SYS | P9: FATHIYA SYAFFIRA CRISTANDI | Q9: OFF | R9: SYS | S9: OFF
B10: =$B$5 -> 46097 | C10: 12.00 | D10: SYS | F10: OFF | G10: OFF | I10: OFF | J10: SYS | L10: ARETHA ZAIBA ALMIRA | M10: OFF | N10: off | O10: SYS | P10: MIKAIL LARRY | Q10: ZAYN KHALIFA ABBASY | R10: SYS | S10: OFF
B11: =$B$5 -> 46097 | C11: 13.00 | D11: SYS | E11: FIRDAUS AL QAADIRI | F11: OFF | G11: OFF | H11: MUHAMMAD AL FATIH (SUI ASAM) | I11: OFF | J11: SYS | K11: MUHAMMAD ALMEER IZHAR | L11: MIKAEL SEPTIAN ADAM MAHENDRA | M11: OFF | N11: off | O11: SYS | P11: MUHAMMAD ALFAHREZY RAHMAN | R11: SYS | S11: OFF
B12: =$B$5 -> 46097 | C12: 14.00 | D12: SYS | E12: OFF | F12: OFF | G12: OFF | H12: OFF | I12: OFF | J12: SYS | K12: OFF | L12: OFF | M12: OFF | N12: off | O12: SYS | P12: OFF | Q12: OFF | R12: SYS | S12: OFF
B13: =$B$5 -> 46097 | C13: 15.00 | D13: SYS | E13: OFF | F13: OFF | G13: OFF | H13: JESLYN YOVELA | I13: OFF | J13: SYS | K13: OFF | M13: OFF | N13: OFF | O13: SYS | Q13: OFF | R13: SYS | S13: OFF
B14: =$B$5 -> 46097 | C14: 16.00 | D14: SYS | E14: OFF | F14: OFF | G14: OFF | H14: JENNAIRA SHAHIA | I14: OFF | J14: SYS | K14: OFF | L14: JOSH GEVARIEL WIJAYA | M14: OFF | N14: off | O14: SYS | P14: HADZIQ ABRAR RAMLI | Q14: OFF | R14: SYS | S14: OFF
B15: =$B$5 -> 46097 | C15: 17.00 | D15: SYS | E15: OFF | F15: OFF | G15: OFF | H15: OFF | I15: OFF | J15: SYS | K15: OFF | L15: OFF | M15: OFF | N15: off | O15: SYS | P15: OFF | Q15: OFF | R15: SYS | S15: OFF
B16: 46098 | D16: =$B$16 -> 46098
B17: =$B$16 -> 46098 | C17: 08.00 | D17: SYS | E17: ARCHIO GREYSEN BOWMAN | F17: OFF | G17: OFF | H17: OFF | I17: OFF | J17: SYS | K17: ABIZARD BILAL WARDANY | L17: OFF | M17: OFF | N17: OFF | O17: SYS | P17: OFF | Q17: DARREN CLAY EVANO | R17: SYS | S17: OFF
B18: =$B$16 -> 46098 | C18: 09.00 | D18: SYS | E18: RIFQI SYAFIQ SYAHPUTRA | F18: OFF | G18: off | H18: OFF | I18: OFF | J18: SYS | K18: AHMAD ASHIF BARKHIYA | L18: OFF | M18: OFF | N18: OFF | O18: SYS | P18: off | Q18: ALEXANDER OTTO | R18: SYS
B19: =$B$16 -> 46098 | C19: 10.00 | D19: SYS | E19: GEORGHINO GABRIELLO BRIO | F19: off | G19: MUHAMMAD FARHAN FAJRIN | H19: OFF | I19: OFF | J19: SYS | K19: KAIRO GANENDRA CATRA | L19: OFF | M19: OFF | N19: OFF | O19: SYS | P19: OFF | Q19: Crisiant Fredrich Liu | R19: SYS | S19: OFF
B20: =$B$16 -> 46098 | C20: 11.00 | D20: SYS | E20: OFF | F20: off | G20: SHANUM ALMAHYRA ADHISTY | H20: Amira Zahra Anvini | I20: OFF | J20: SYS | K20: OFF | M20: OFF | N20: OFF | O20: SYS | P20: FATHIYA SYAFFIRA CRISTANDI | Q20: OFF | R20: SYS | S20: OFF
B21: =$B$16 -> 46098 | C21: 12.00 | D21: SYS | F21: OFF | G21: OFF | I21: OFF | J21: SYS | K21: Amira Zahra Anvini | L21: M. UWAIS KHAIRUNNAFIS ARIFIN | M21: OFF | N21: OFF | O21: SYS | P21: MIKAEL SEPTIAN ADAM MAHENDRA | R21: SYS | S21: OFF
B22: =$B$16 -> 46098 | C22: 13.00 | D22: SYS | E22: M. UWAIS KHAIRUNNAFIS ARIFIN | F22: OFF | G22: OFF | H22: MUHAMMAD AL FATIH (SUI ASAM) | I22: OFF | J22: SYS | M22: OFF | N22: OFF | O22: SYS | P22: RIVALDI RUDIANTO | Q22: EDWIN HOWARD | R22: SYS | S22: OFF
B23: =$B$16 -> 46098 | C23: 14.00 | D23: SYS | E23: OFF | F23: OFF | G23: ASSYIFA LAVANYA AZZAHRA | H23: OFF | I23: OFF | J23: SYS | K23: OFF | L23: OFF | M23: OFF | N23: OFF | O23: SYS | P23: OFF | Q23: OFF | R23: SYS | S23: OFF
B24: =$B$16 -> 46098 | C24: 15.00 | D24: SYS | E24: OFF | F24: OFF | G24: OFF | H24: REMIEL STEPHANO TAN | I24: OFF | J24: SYS | K24: OFF | M24: OFF | N24: OFF | O24: SYS | P24: JENNAIRA SHAHIA | Q24: OFF | R24: SYS | S24: OFF
B25: =$B$16 -> 46098 | C25: 16.00 | D25: SYS | E25: OFF | F25: OFF | G25: OFF | H25: RAISYA RAHMA SYAHIRA | I25: OFF | J25: SYS | K25: OFF | M25: OFF | N25: OFF | O25: SYS | P25: shafwan Abdillah | Q25: OFF | R25: SYS | S25: OFF
B26: =$B$16 -> 46098 | C26: 17.00 | D26: SYS | E26: OFF | F26: OFF | G26: OFF | H26: OFF | I26: OFF | J26: SYS | K26: OFF | L26: OFF | M26: OFF | N26: OFF | O26: SYS | P26: OFF | Q26: OFF | R26: SYS | S26: OFF
B27: 46099 | D27: =$B$27 -> 46099
B28: =$B$27 -> 46099 | C28: 08.00 | D28: SYS | E28: DINDA ANGELICA DOMINIQUE | F28: OFF | G28: OFF | H28: OFF | I28: OFF | J28: SYS | K28: MIKAEL SEPTIAN ADAM MAHENDRA | L28: OFF | M28: OFF | N28: OFF | O28: SYS | Q28: OFF | R28: SYS | S28: OFF
B29: =$B$27 -> 46099 | C29: 09.00 | D29: SYS | E29: MUHAMMAD NABIL NUGRAHA | F29: MUHAMMAD FARHAN FAJRIN | G29: OFF | H29: OFF | I29: ELDIPTHO GALEN SIPAYUNG | J29: SYS | K29: ALICE GLIONA DARCHELLE | L29: OFF | M29: OFF | N29: OFF | O29: SYS | P29: MUHAMMAD ALFATIH | Q29: OFF | R29: SYS | S29: OFF
B30: =$B$27 -> 46099 | C30: 10.00 | D30: SYS | E30: GEORGHINO GABRIELLO BRIO | F30: OFF | G30: SHANUM ALMAHYRA ADHISTY | H30: OFF | I30: OFF | J30: SYS | K30: NAUFAL MELVIANO | L30: OFF | M30: OFF | N30: OFF | O30: SYS | P30: MUHAMMAD DANISH AL FAHREZI KOSASIH | Q30: OFF | R30: SYS | S30: OFF
B31: =$B$27 -> 46099 | C31: 11.00 | D31: SYS | E31: OFF | F31: MUHAMMAD DZAKY ALMAIR | G31: OFF | H31: FATHIYA SYAFFIRA CRISTANDI | I31: OFF | J31: SYS | K31: OFF | M31: off | N31: OFF | O31: SYS | P31: OFF | Q31: KEENAN PRADIPA CHANDRA | R31: SYS | S31: OFF
B32: =$B$27 -> 46099 | C32: 12.00 | D32: SYS | F32: OFF | G32: OFF | I32: OFF | J32: SYS | M32: OFF | N32: off | O32: SYS | P32: MUHAMMAD SHAQUILLE RASENDRIA AKHZA | R32: SYS | S32: OFF
B33: =$B$27 -> 46099 | C33: 13.00 | D33: SYS | E33: HELMIZAR RIZKI DETARA | F33: OFF | G33: OFF | H33: AFIZA GAMILA SUGIYONO | I33: OFF | J33: SYS | M33: OFF | N33: off | O33: SYS | P33: MUHAMMAD AL FATIH (SUI ASAM) | Q33: DEVAN FELICIO KURNIAWAN | R33: SYS | S33: OFF
B34: =$B$27 -> 46099 | C34: 14.00 | D34: SYS | E34: OFF | F34: OFF | G34: OFF | H34: OFF | I34: OFF | J34: SYS | K34: OFF | L34: OFF | M34: OFF | N34: OFF | O34: SYS | P34: OFF | Q34: OFF | R34: SYS | S34: OFF
B35: =$B$27 -> 46099 | C35: 15.00 | D35: SYS | E35: OFF | F35: OFF | G35: OFF | H35: JESLYN YOVELA | I35: OFF | J35: SYS | K35: OFF | L35: JENNAIRA SHAHIA | M35: OFF | N35: OFF | O35: SYS | P35: OFF | Q35: RAISYA RAHMA SYAHIRA | R35: SYS | S35: OFF
B36: =$B$27 -> 46099 | C36: 16.00 | D36: SYS | E36: OFF | F36: OFF | G36: OFF | H36: HADZIQ ABRAR RAMLI | I36: OFF | J36: SYS | K36: OFF | L36: MUHAMMAD ALMEER IZHAR | M36: OFF | N36: off | O36: SYS | P36: HADZIQ ABRAR RAMLI | Q36: AMEERA SHOFIYAH IRAWAN | R36: SYS | S36: OFF
B37: =$B$27 -> 46099 | C37: 17.00 | D37: SYS | E37: OFF | F37: OFF | G37: OFF | H37: OFF | I37: OFF | J37: SYS | K37: OFF | L37: OFF | M37: OFF | N37: off | O37: SYS | P37: OFF | Q37: OFF | R37: SYS | S37: OFF
B38: 46100 | D38: =$B$38 -> 46100
B39: =$B$38 -> 46100 | C39: 08.00 | D39: SYS | E39: MARYAM AZKIA AZMA MAIZA | F39: OFF | G39: OFF | H39: OFF | I39: OFF | J39: SYS | K39: MIKAEL SEPTIAN ADAM MAHENDRA | L39: OFF | M39: OFF | N39: OFF | O39: SYS | P39: GEORGHINO GABRIELLO BRIO | Q39: OFF | R39: SYS | S39: OFF
B40: =$B$38 -> 46100 | C40: 09.00 | D40: SYS | E40: RIFQI SYAFIQ SYAHPUTRA | F40: OFF | G40: OFF | H40: OFF | I40: ELDIPTHO GALEN SIPAYUNG | J40: SYS | K40: AZQEEYA ELNARA RACAISHA | L40: OFF | M40: OFF | N40: OFF | O40: SYS | P40: AHMAD ASHIF BARKHIYA | Q40: OFF | R40: SYS | S40: OFF
B41: =$B$38 -> 46100 | C41: 10.00 | D41: SYS | E41: MUHAMMAD RAFFASYA ALFARIZQI | F41: OFF | G41: SHANUM ALMAHYRA ADHISTY | H41: OFF | I41: KHALID DIBILAL | J41: SYS | K41: Azka Zlatan | L41: OFF | M41: OFF | N41: OFF | O41: SYS | P41: MIKAEL SEPTIAN ADAM MAHENDRA | Q41: OFF | R41: SYS | S41: OFF
...

Sheet JADWAL TERAPI BARU
B1: JADWAL GRIYA ANAK GANG SEHAT
D3: FT | J3: TW | O3: BT | R3: PSI
E4: MISWI | F4: EDO | G4: IRMA | H4: LULU | I4: TIA | K4: ADEL | L4: CHITA | P4: IRA | Q4: STEFY | S4: ISTI
B5: 46118 | D5: =$B$5 -> 46118
B6: =$B$5 -> 46118 | C6: 08.00 | D6: SYS | E6: DINDA ANGELICA DOMINIQUE | F6: OFF | G6: OFF | H6: OFF | I6: OFF | J6: SYS | K6: off | L6: ARSYA SHAKA SANJAYA | M6: OFF | N6: OFF | O6: SYS | P6: OFF | Q6: MUHAMMAD RAYA ALSAKI | R6: SYS | S6: OFF
C7: 09.00 | D7: SYS | E7: ATTHAR ADAM PRASETYA | F7: OFF | G7: off | H7: OFF | I7: GEORGHINO GABRIELLO BRIO | J7: SYS | K7: off | L7: MUHAMMAD RAYA ALSAKI | M7: OFF | N7: OFF | O7: SYS | P7: OFF | Q7: MUHAMMAD ALFATIH | R7: SYS | S7: OFF
B8: =$B$5 -> 46118 | C8: 10.00 | D8: SYS | E8: KEENAN PRADIPA CHANDRA | F8: OFF | G8: OFF | H8: OFF | I8: SHAQUEENA ALESHA MECCAYLA | J8: SYS | K8: OFF | L8: RAYYA AZZAHRA SULISTIONO | M8: OFF | N8: OFF | O8: SYS | P8: OFF | Q8: arsakha kanchana | R8: SYS | S8: KAIRO GANENDRA CATRA
B9: =$B$5 -> 46118 | C9: 11.00 | D9: SYS | E9: OFF | F9: MUHAMMAD DZAKY ALMAIR | G9: off | H9: OFF | I9: OFF | J9: SYS | K9: off | L9: OFF | M9: OFF | N9: OFF | O9: SYS | P9: OFF | Q9: OFF | R9: SYS | S9: OFF
B10: =$B$5 -> 46118 | C10: 12.00 | D10: SYS | F10: OFF | G10: OFF | H10: ZAYN KHALIFA ABBASY | I10: OFF | J10: SYS | K10: thoriq | L10: MUHAMMAD ARTANABIL MAUZA | M10: ARETHA ZAIBA ALMIRA | N10: OFF | O10: SYS | P10: FATHIYA SYAFFIRA CRISTANDI | Q10: GLORY | R10: SYS | S10: MIKAIL LARRY
B11: =$B$5 -> 46118 | C11: 13.00 | D11: SYS | E11: FIRDAUS AL QAADIRI | F11: OFF | G11: OFF | H11: MUHAMMAD AL FATIH (SUI ASAM) | I11: OFF | J11: SYS | K11: OFF | L11: LATIFA JAWHARA | M11: MUHAMMAD ALMEER IZHAR | N11: off | O11: SYS | P11: ELRIC LEONARD THE | Q11: MUHAMMAD ALFAHREZY RAHMAN | R11: SYS | S11: FARHAT OZKAN ATTHALLAH
B12: =$B$5 -> 46118 | C12: 14.00 | D12: SYS | E12: off | F12: OFF | G12: OFF | H12: JESLYN YOVELA | I12: OFF | J12: SYS | K12: OFF | L12: OFF | M12: IGNATIUS HANSEL TANDILINO | N12: off | O12: SYS | P12: mariana rumi | Q12: OFF | R12: SYS | S12: M.AL HANAN SYAH
B13: =$B$5 -> 46118 | C13: 15.00 | D13: SYS | E13: OFF | F13: OFF | G13: OFF | H13: OFF | I13: OFF | J13: SYS | K13: OFF | L13: OFF | M13: OFF | N13: OFF | O13: SYS | P13: OFF | Q13: OFF | R13: SYS
B14: =$B$5 -> 46118 | C14: 16.00 | D14: SYS | E14: OFF | F14: OFF | G14: OFF | H14: NELSEN ALVERO PRATAMA | I14: OFF | J14: SYS | K14: OFF | L14: OFF | M14: JOSH | N14: off | O14: SYS | P14: ALEENA | Q14: off | R14: SYS | S14: OFF
B15: =$B$5 -> 46118 | C15: 17.00 | D15: SYS | E15: OFF | F15: OFF | G15: OFF | H15: MAIZA | I15: OFF | J15: SYS | K15: OFF | L15: OFF | M15: Azka Zlatan | N15: off | O15: SYS | P15: ALEXANDER OTTO | Q15: OFF | R15: SYS | S15: OFF
B16: 46119 | D16: =$B$16 -> 46119
B17: =$B$16 -> 46119 | C17: 08.00 | D17: SYS | E17: OFF | F17: OFF | G17: OFF | H17: MIKAEL SEPTIAN ADAM MAHENDRA | I17: OFF | J17: SYS | K17: OFF | L17: ABIZARD BILAL WARDANY | M17: OFF | N17: OFF | O17: SYS | P17: MAUZAN ARFIZ ALFARIZKY | Q17: OFF | R17: SYS | S17: OFF
B18: =$B$16 -> 46119 | C18: 09.00 | D18: SYS | E18: off | F18: OFF | G18: SHANUM ALMAHYRA ADHISTY | H18: AHMAD LATIF SAFULLAH | I18: OFF | J18: SYS | K18: off | L18: AHMAD ASHIF BARKHIYA | M18: OFF | N18: OFF | O18: SYS | P18: RIFQI SYAFIQ SYAHPUTRA | Q18: OFF | R18: SYS | S18: OFF
B19: =$B$16 -> 46119 | C19: 10.00 | D19: SYS | E19: OFF | F19: OFF | G19: MUHAMMAD FARHAN FAJRIN | H19: GEORGHINO GABRIELLO BRIO | I19: OFF | J19: SYS | K19: off | L19: KAIRO GANENDRA CATRA | M19: OFF | N19: OFF | O19: SYS | P19: Crisiant Fredrich Liu | Q19: OFF | R19: SYS | S19: MATTEW BRAYENALBERGA LIE
B20: =$B$16 -> 46119 | C20: 11.00 | D20: SYS | E20: OFF | F20: OFF | G20: OFF | H20: OFF | I20: OFF | J20: SYS | K20: off | L20: OFF | M20: OFF | N20: OFF | O20: SYS | P20: OFF | Q20: OFF | R20: SYS | S20: OFF
B21: =$B$16 -> 46119 | C21: 12.00 | D21: SYS | E21: Amira Zahra Anvini | F21: OFF | G21: OFF | I21: OFF | J21: SYS | K21: off | L21: AHMAD ZAYN | M21: MUHAMMAD RAYA ALSAKI | N21: off | O21: SYS | P21: LATIFA JAWHARA | Q21: DARREN CLAY | R21: SYS
B22: =$B$16 -> 46119 | C22: 13.00 | D22: SYS | E22: LATIFA JAWHARA | F22: OFF | G22: OFF | H22: MUHAMMAD AL FATIH (SUI ASAM) | I22: OFF | J22: SYS | K22: off | L22: Amira Zahra Anvini | M22: KENIZIO ALLUCA XAVIELLE | N22: OFF | O22: SYS | P22: ELRIC LEONARD THE | Q22: MUHAMMAD RAYA ALSAKI | R22: SYS
B23: =$B$16 -> 46119 | C23: 14.00 | D23: SYS | E23: M. UWAIS KHAIRUNNAFIS ARIFIN | F23: OFF | G23: ASSYIFA LAVANYA AZZAHRA | H23: OFF | I23: off | J23: SYS | K23: OFF | L23: OFF | M23: SALIANA RALINE MARYAM | N23: OFF | O23: SYS | P23: OFF | Q23: RIVALDI RUDIANTO | R23: SYS | S23: EDWIN HOWARD
B24: =$B$16 -> 46119 | C24: 15.00 | D24: SYS | E24: OFF | F24: OFF | G24: OFF | H24: OFF | I24: OFF | J24: SYS | K24: OFF | L24: OFF | M24: OFF | N24: OFF | O24: SYS | P24: OFF | Q24: OFF | R24: SYS
B25: =$B$16 -> 46119 | C25: 16.00 | D25: SYS | E25: RAISYA RAHMA SYAHIRA | F25: OFF | G25: off | H25: OFF | I25: OFF | J25: SYS | K25: OFF | L25: OFF | M25: M.AL HANAN SYAH | N25: off | O25: SYS | P25: OFF | Q25: SHAFWAN | R25: SYS | S25: OFF
B26: =$B$16 -> 46119 | C26: 17.00 | D26: SYS | E26: REMIEL STEPHANO TAN | F26: OFF | G26: OFF | H26: off | I26: OFF | J26: SYS | K26: OFF | L26: OFF | M26: ALEXANDER OTTO | N26: off | O26: SYS | P26: AZQEEYA ELNARA RACAISHA | Q26: BENNETT HANZEL CLARENCE | R26: SYS | S26: OFF
B27: 46120 | D27: =$B$27 -> 46120
B28: =$B$27 -> 46120 | C28: 08.00 | D28: SYS | E28: OFF | F28: OFF | G28: OFF | H28: DINDA ANGELICA DOMINIQUE | I28: OFF | J28: SYS | K28: OFF | L28: EMERSON | M28: OFF | N28: OFF | O28: SYS | P28: OFF | Q28: MIKAEL SEPTIAN ADAM MAHENDRA | R28: SYS | S28: OFF
B29: =$B$27 -> 46120 | C29: 09.00 | D29: SYS | E29: OFF | F29: MUHAMMAD FARHAN FAJRIN | G29: OFF | H29: KEENAN PRADIPA | I29: ALICE | J29: SYS | K29: OFF | L29: MUHAMMAD ALFATIH | M29: off | N29: OFF | O29: SYS | P29: OFF | Q29: MAUZAN | R29: SYS | S29: OFF
B30: =$B$27 -> 46120 | C30: 10.00 | D30: SYS | E30: OFF | F30: OFF | G30: SHANUM ALMAHYRA ADHISTY | H30: GEORGHINO GABRIELLO BRIO | I30: OFF | J30: SYS | K30: off | L30: JENNAIRA SHAHIA | M30: OFF | N30: OFF | O30: SYS | P30: OFF | Q30: MUHAMMAD DANISH AL FAHREZI KOSASIH | R30: SYS | S30: ALEENA MARIZA
B31: =$B$27 -> 46120 | C31: 11.00 | D31: SYS | E31: OFF | F31: MUHAMMAD DZAKY ALMAIR | G31: OFF | H31: OFF | I31: OFF | J31: SYS | K31: OFF | L31: OFF | M31: off | N31: OFF | O31: SYS | P31: OFF | Q31: OFF | R31: SYS | S31: OFF
B32: =$B$27 -> 46120 | C32: 12.00 | D32: SYS | F32: OFF | G32: GAVRIEL FRITZ LIU | I32: OFF | J32: SYS | K32: MUHAMMAD SHAQUILLE RASENDRIA AKHZA | L32: FATHIYAH SYAFFIRA | M32: OFF | N32: off | O32: SYS | P32: GHIBRAN UMAIR ALFATIH | Q32: MUHAMMAD SHAQUILLE RASENDRIA AKHZA | R32: SYS
B33: =$B$27 -> 46120 | C33: 13.00 | D33: SYS | E33: MUHAMMAD AL FATIH (SUI ASAM) | F33: OFF | G33: OFF | H33: HELMIZAR RIZKI DETARA | I33: OFF | J33: SYS | K33: DAFFI ETWAN PRAYOGO | L33: MUHAMMAD RAYA ALSAKI | M33: off | N33: off | O33: SYS | P33: DEVAN FELICIO KURNIAWAN | Q33: ELRIC LEONARD THE | R33: SYS
B34: =$B$27 -> 46120 | C34: 14.00 | D34: SYS | E34: JESLYN YOVELA | F34: OFF | G34: OFF | H34: OFF | I34: OFF | J34: SYS | K34: MUHAMMAD ADAM | L34: OFF | M34: OFF | N34: OFF | O34: SYS | P34: MUHAMMAD RAYA ALSAKI | Q34: OFF | R34: SYS
B35: =$B$27 -> 46120 | C35: 15.00 | D35: SYS | E35: OFF | F35: OFF | G35: OFF | H35: OFF | I35: OFF | J35: SYS | K35: OFF | L35: OFF | M35: OFF | N35: OFF | O35: SYS | P35: OFF | Q35: OFF | R35: SYS | S35: AMEERA SHOFIYAH IRAWAN
B36: =$B$27 -> 46120 | C36: 16.00 | D36: SYS | E36: CASVAL YAHYA NAWASENA | F36: OFF | G36: OFF | H36: OFF | I36: OFF | J36: SYS | K36: ALETTA AMEERA SYAZANI | L36: NELSEN ALVERO PRATAMA | M36: off | N36: off | O36: SYS | P36: RAISYA RAHMA SYAHIRA | Q36: OFF | R36: SYS | S36: OFF
B37: =$B$27 -> 46120 | C37: 17.00 | D37: SYS | F37: OFF | G37: OFF | H37: OFF | I37: OFF | J37: SYS | K37: MUHAMMAD ALMEER IZHAR | L37: off | M37: OFF | N37: off | O37: SYS | P37: HADZIQ ABRAR RAMLI | Q37: OFF | R37: SYS | S37: OFF
B38: 46121 | D38: =$B$38 -> 46121
B39: =$B$38 -> 46121 | C39: 08.00 | D39: SYS | E39: OFF | F39: OFF | G39: OFF | I39: OFF | J39: SYS | K39: off | L39: GHAMIDI AYDIN PUTRA HARIBOWO | M39: OFF | N39: OFF | O39: SYS | P39: OFF | Q39: GEORGHINO GABRIELLO BRIO | R39: SYS | S39: OFF
B40: =$B$38 -> 46121 | C40: 09.00 | D40: SYS | E40: OFF | F40: OFF | G40: OFF | H40: RIFQI SYAFIQ SYAHPUTRA | I40: AZQEEYA | J40: SYS | K40: off | L40: ALICE GLIONA DARCHELLE | M40: OFF | N40: OFF | O40: SYS | P40: OFF | Q40: AHMAD ASHIF BARKHIYA | R40: SYS | S40: OFF
B41: =$B$38 -> 46121 | C41: 10.00 | D41: SYS | E41: OFF | F41: OFF | G41: SHANUM ALMAHYRA ADHISTY | H41: MUHAMMAD RAFFASYA ALFARIZQI | I41: KHALID DIBILAL | J41: SYS | K41: OFF | L41: NAUFAL MELVIANO | M41: off | N41: OFF | O41: SYS | P41: OFF | Q41: ARSAKHA KANCHANA FAHRIZAL | R41: SYS | S41: ATTHAR ADAM PRASETYA
...

Sheet 📑 Pendaftaran
A1: f | B1: Timestamp | C1: Tanggal | D1: Nama Anak | E1: Nama Panggilan | F1: No. RM | G1: Tanggal Lahir | H1: Usia | I1: Jenis Kelamin | J1: Keluhan | K1: Agama | L1: Nama Ibu | M1: Pekerjaan Ibu | N1: Nama Ayah | O1: Pekerjaan Ayah | P1: Alamat | Q1: Kel./Desa | R1: Kecamatan | S1: Kab./Kota | T1: Provinsi | U1: No. WA | V1: Sumber Pasien
B2: {=UPPER('INPUTAN PASIEN'!B2:B1226)} -> 13/06/2023 10:21:22 | C2: {=UPPER('INPUTAN PASIEN'!C2:C1226)} | D2: {=UPPER('INPUTAN PASIEN'!D2:D1226)} -> KHALID IBRAHIM AL KAHFI | E2: {=UPPER('INPUTAN PASIEN'!E2:E1226)} | G2: {=UPPER('INPUTAN PASIEN'!G2:G1226)} -> 30/07/2020 | I2: {=UPPER('INPUTAN PASIEN'!I2:I1226)} -> LAKI-LAKI | J2: {=UPPER('INPUTAN PASIEN'!J2:J1226)} -> FISIOTERAPI MOTORIK | K2: {=UPPER('INPUTAN PASIEN'!K2:K1226)} -> ISLAM | L2: {=UPPER('INPUTAN PASIEN'!L2:L1226)} -> DINDA FIRLIANSARI | M2: {=UPPER('INPUTAN PASIEN'!M2:M1226)} -> IBU RUMAH TANGGA | N2: {=UPPER('INPUTAN PASIEN'!N2:N1226)} | O2: {=UPPER('INPUTAN PASIEN'!O2:O1226)} | P2: {=UPPER('INPUTAN PASIEN'!P2:P1226)} | ... V2: {=UPPER('INPUTAN PASIEN'!V2:V1226)}
B3: 13/06/2023 20:30:32 | D3: MUHAMMAD AMMAR | G3: 24/10/2020 | I3: LAKI-LAKI | J3: SENSORIK INTEGRASI & TERAPI WICARA | K3: ISLAM | L3: NADYA ULFA | M3: IBU RUMAH TANGGA | U3: 081328347009/0895702479833
B4: 13/06/2023 20:33:25 | D4: RIFQI SYAFIQ SYAHPUTRA | G4: 21/11/2017 | I4: LAKI-LAKI | J4: FISIOTERAPI | K4: ISLAM | L4: DESY ARIANI NASUTION | M4: ASN | U4: 08115706881
B5: 13/06/2023 20:33:28 | D5: JORDAN GABRIAN | G5: 11/11/2019 | I5: LAKI-LAKI | J5: SENSORIK INTEGRASI & TERAPI WICARA | K5: PROTESTAN | L5: LIA ANDRIANI | M5: IBU RUMAH TANGGA | U5: 089622447016
B6: 13/06/2023 20:34:10 | D6: ARSYA KHAIRUL FATIH | G6: 07/12/2020 | I6: LAKI-LAKI | J6: TERAPI WICARA | K6: ISLAM | L6: DEASY NOVITA SARI | M6: IBU RUMAH TANGGA | U6: 085658366269
B7: 13/06/2023 20:34:28 | D7: RAISYA RAHMA SYAHIRA | G7: 23/01/2020 | I7: PEREMPUAN | J7: FISIOTERAPI | K7: ISLAM | L7: DESY ARIANI NASUTION | M7: ASN | U7: 08115706881
B8: 13/06/2023 20:40:42 | D8: AHMAD LATIF SAFULLAH | G8: 03/02/2009 | I8: LAKI-LAKI | J8: FISIOTERAPI | K8: ISLAM | L8: DARWANTI | M8: IBU RUMAH TANGGA | U8: 082252116339
B9: 13/06/2023 20:40:53 | D9: KHALID IBRAHIM AL KAHFI | G9: 30/07/2020 | I9: LAKI-LAKI | J9: FISIOTERAPI | K9: ISLAM | L9: DINDA FIRLIANSARI | M9: IRT | U9: 082231905665
B10: 13/06/2023 20:42:52 | D10: DAVID CHRISTIAN | G10: 19/02/2019 | I10: LAKI-LAKI | J10: SENSORIK INTEGRASI & TERAPI WICARA | K10: PROTESTAN | L10: DESSY | M10: WIRASWASTA | U10: 085248068221
B11: 13/06/2023 20:44:35 | D11: CELINE ZOEY HEARTILLY | G11: 27/11/2018 | I11: PEREMPUAN | J11: SENSORIK INTEGRASI & TERAPI WICARA | K11: BUDDHA | L11: SYLVIA VERONIKA | M11: IBU RUMAH TANGGA | U11: 085245070077
B12: 13/06/2023 20:49:30 | D12: KENZO ALFA AS-SIDDIQ | G12: 23/01/2021 | I12: LAKI-LAKI | J12: TERAPI WICARA | K12: ISLAM | L12: TARA CHAIRUNISA | M12: GURU | U12: 081362524442
B13: 13/06/2023 20:51:33 | D13: RAYYA FATIHAH RAZAANA | G13: 15/04/2013 | I13: PEREMPUAN | J13: FISIOTERAPI | K13: ISLAM | L13: EVA NOVIANTI HESTI VERA | M13: PNS | U13: 08152234183
B14: 13/06/2023 20:52:20 | D14: RAINA AISYAH SUPRIADI | G14: 18/05/2013 | I14: PEREMPUAN | J14: FISIOTERAPI | K14: ISLAM | L14: KARTINI APRILYANI | M14: IBU RUMAH TQNGGA | U14: 082353828426
... B58: 22/08/2023 10:00:51 | D58: JASPER GABRIEL | G58: 31/10/2017 | I58: LAKI-LAKI | J58: SENSORIK INTEGRASI & TERAPI WICARA | K58: PROTESTAN | L58: YENNY | M58: IBU RUMAH TANGGA | U58: 081917142519
B59: 02/09/2023 17:37:54 | D59: FAYK KAIVAN SERGUERO | G59: 07/06/2022 | I59: LAKI-LAKI | J59: BANYAK OMONG | K59: ISLAM | L59: ETRI YULIA ANDINI | M59: IRT | N59: DANI FAHRIZAL | O59: SWASTA | P59: JL. P. H. HUSIN 2 GG. WISUDA NO. 23A | U59: 082158963663
B60: 02/09/2023 17:52:01 | D60: AHMAD SYAKIR | G60: 21/08/2022 | I60: LAKI-LAKI | J60: PILEK BATUK | K60: ISLAM | L60: IRMA RISKIMA | M60: SWASTA | N60: SYEKH ARPI | O60: WIRAUSAHA | P60: JALAN ARTERI SUPADIO CABANG KIRI | U60: 08981380248
B61: 03/09/2023 14:15:18 | D61: RAINA AISYAH SUPRIADI | G61: 18/05/2013 | I61: PEREMPUAN | J61: CP | K61: ISLAM | L61: KARTINI APRILYANI | M61: IBU RUMAH TANGGA | N61: DENNY SUPRIADI | O61: PNS | P61: JL.PEMDA KOMP.GRIYA MAYOR A.26 | U61: 082353828426
B62: 03/09/2023 14:20:58 | D62: RAISSA FATIMAH SUPRIADI | G62: 18/05/2013 | I62: PEREMPUAN | J62: CP | K62: ISLAM | L62: KARTINI APRILYANI | M62: IBU RUMAH TANGGA | N62: DENNY SUPRIADI | O62: PNS | P62: JL.PEMDA.KOMP GRIYA MAYOR A.26 | U62: 082353828426
B63: 03/09/2023 14:21:12 | D63: RAINA AISYAH SUPRIADI | G63: 18/05/2013 | I63: PEREMPUAN | J63: CP | K63: ISLAM | L63: KARTINI APRILYANI | M63: IBU RUMAH TANGGA | N63: DENNY SUPRIADI | O63: PNS | P63: JL.PEMDA KOMP.GRIYA MAYOR A.26 | U63: 082353828426
B64: 03/09/2023 14:26:24 | D64: SYARIF MUHAMMAD ALFATEH | G64: 31/12/2020 | I64: LAKI-LAKI | J64: SERING KAGET, SESAK SAAT MALAM HARI KARENA LENDIR SEHINGGA POLA TIDUR BERUBAH | K64: ISLAM | L64: SYARIFAH FIFI MARIANI ALKADRIE | M64: HONORER | N64: SY. ADHY | O64: KARYAWAN SWASTA | P64: JALAN TRITURA NO. 10 KEL. DALAM BUGIS KEC. PONTIANAK TIMUR | U64: 085754395905
B65: 04/09/2023 17:26:00 | D65: MUHAMMAD AZZAM ACO | G65: 14/09/2016 | I65: LAKI-LAKI | J65: LAMBAT BICARA DIAGNOSA DR ADHD | K65: ISLAM | L65: IRA NIA | M65: IBU RUMAH TANGGA | N65: MAMAN ACO | O65: BURUH HARIAN LEPAS | P65: JALAN KOM YOS SUDARSO GANG ALPOKAT INDAH, JALUR 0 | U65: 081255816909
B66: 04/09/2023 17:27:17 | D66: ELZEVAREL ZERKHA AZARYA | G66: 18/08/2021 | I66: LAKI-LAKI | J66: SPEECH DELAY | K66: PROTESTAN | L66: KRISYESIKA | M66: DOSEN | N66: EBEN HEIZER | O66: WIRASWASTA | P66: JLN. TRANS KALIMANTAN GG. BUDAYA NO. 1 | U66: 085346807788
B67: 04/09/2023 17:32:45 | D67: AMIR SYAKIR | G67: 21/09/2018 | I67: LAKI-LAKI | J67: TIDAK FOKUS | K67: ISLAM | L67: WAHYULI ASTUTI | M67: IBU RUMAH TANGGA | N67: SUWARDI | O67: KARYAWAN SWASTA | P67: JL KOMYO SUDARSO GG SRIKAYA 2 NO 19 | U67: 082148665510
B68: 04/09/2023 17:34:53 | D68: MUHAMMAD ZAFRAN MAERAD | G68: 09/03/2021 | I68: LAKI-LAKI | J68: SPEACH DELAY | K68: ISLAM | L68: DEWI SULISTIANINGSIH | M68: KARYAWAN SWASTA | N68: HAFITDIN | O68: KARYAWAN SWASTA | P68: JL M SOHOR GG SEDERHANA | U68: 08998092083
B69: 04/09/2023 17:44:10 | D69: MARCELLO | G69: 10/04/2020 | I69: LAKI-LAKI | J69: TELAT BICARA | K69: BUDDHA | L69: HIE FUI NA | M69: IBU RUMAH TANGGA | N69: PET HO | O69: WIRASWASTA | P69: JL NAWAWI HASAN 3 NO 342 | U69: 082158815530
B70: 04/09/2023 17:48:15 | D70: AZQEEYA ELNARA RACAISHA | G70: 13/03/2021 | I70: PEREMPUAN | J70: SPEECH DELAY | K70: ISLAM | L70: URAY YUCA ERGAIASHA | M70: IRT | N70: RAHMAT RAZULY HIDAYAT | O70: SWASTA | P70: JL. KARYA KOMP. FAJAR ASRI 3 A-28 | U70: 08982292556
... B169: 28/12/2023 9:48:15 | D169: IMRAN HANIF PRIBADI | G169: 07/06/1992 | I169: LAKI-LAKI | J169: ADD | K169: ISLAM | L169: ENI DIAN PERTIWI | M169: IBU RUMAH TANGGA | N169: CITRA TEGUH IMAN PRIBADI | O169: PEGAWAI SWASTA | P169: JALAN WONOBARU GG REMAJA 2 NO 30 | U169: 082139121261
B170: 02/01/2024 12:00:48 | D170: FAYK KAIVAN SERGUERO | G170: 07/06/2022 | I170: LAKI-LAKI | J170: BANYAK OMONG | K170: ISLAM | L170: ETRI YULIA ANDINI | M170: IBU RUMAH TANGGA | N170: DANI FAHRIZAL | O170: TENAGA KESEHATAN | P170: JL. P. H. HUSIN 2 GG.WISUDA NO. 23A | Q170: BANGKA BELITUNG DARAT | R170: PONTIANAK TENGGARA | S170: PONTIANAK | T170: KALIMANTAN BARAT | U170: 081333668688
B171: 02/01/2024 12:11:02 | D171: AHMAD SYAKIR ARISTAMA | G171: 21/08/2022 | I171: LAKI-LAKI | J171: BANYAK OMONG | K171: ISLAM | L171: IRMA RISKIMA | M171: TENAGA KESEHATAN | N171: SYEKH ARPI | O171: PENGUSAHA | P171: CABANG KIRI GG. SEDERHANA | Q171: PARIT BARU | R171: SUNGAI RAYA | S171: KUBU RAYA | T171: KALIMANTAN BARAT | U171: 08981380248
B172: 03/01/2024 10:46:11 | D172: MUHAMMAD AKRAM ZAYDAN | G172: 07/03/2018 | I172: LAKI-LAKI | J172: KURANG FOKUS | K172: ISLAM | L172: MIERANDHA EDWARD LUBIS | M172: IBU RUMAH TANGGA | N172: NOFIANDY SURYA | O172: WIRASWASTA | P172: DESA KAPUR, KOMPLEK STAR BHAYANGKARA RESIDANCE BLOCK H NO.5 | Q172: MEKAR BARU | R172: SUNGAI RAYA | S172: KUBURAYA | T172: KALIMANTAN BARAT | U172: 0817202880
B173: 03/01/2024 12:45:15 | D173: MANUEL ERNANDO HALIM. | G173: 11/09/2018 | I173: LAKI-LAKI | J173: SPEED DELAY | K173: KATOLIK | L173: SARI YOHANA | M173: IBU RUMAH TANGGA | N173: FRENDY | O173: KARYAWAN | P173: JL.WONODADI 3 | Q173: KOTA BARU | S173: PONTIANAK | T173: KALBAR | U173: 081288306888
B174: 03/01/2024 16:00:59 | D174: LABIB RAZAN AL BARRA | G174: 09/09/2022 | I174: LAKI-LAKI | J174: MASALAH GANGGUAN MAKAN | K174: ISLAM | L174: RISKI LIANA SARI | M174: TENAGA KESEHATAN | N174: MUHAMMAD IQBAL FARIZQI | O174: PNS | P174: KOMPLEK BTN SEKAYAM INDAH. DUSUN BALAIKARANGAN 3 | Q174: BALAI KARANGAN | R174: SEKAYAM | S174: SANGGAU | T174: KALBAR | U174: 085250805070
B175: 04/01/2024 11:28:32 | D175: DAREV CHRISTIAN ZEGA | G175: 16/02/2021 | I175: LAKI-LAKI | J175: BELUM BISA LANCAR BICARA & HIPERAKTIF | K175: PROTESTAN | L175: JEEMA HERRERA EVELINA SINAGA | M175: IBU RUMAH TANGGA | N175: DARMIN USMAN ZEGA | O175: WIRASWASTA | P175: JL MADYOSARI 1 DALAM NO 51 | Q175: AKCAYA | R175: PONTIANAK | S175: PONTIANAK SELATAN | T175: KALBAR | U175: 089603315528
B176: 04/01/2024 14:18:15 | D176: ARVAN RAYHAN DIANDITA | G176: 19/08/2021 | I176: LAKI-LAKI | J176: TERAPI PERILAKU DAN TERAPI WICARA | K176: ISLAM | L176: RESSY SERLIANDARI | M176: IBU RUMAH TANGGA | N176: BAGUS DIANDITA | O176: PNS | P176: SUNGAI RAYA DALAM KOMP. SRIKANDI 06 | Q176: SUNGAI RAYA | R176: SUNGAI RAYA | S176: KUBU RAYA | T176: KALIMANTAN BARAT | U176: 085654550060
B177: 04/01/2024 20:07:59 | D177: JEVANO ANG | G177: 07/07/2021 | I177: LAKI-LAKI | J177: BELUM BISA NGOMONG, HANYA BISA MANGGIL PAPA MAMA KOKO DADAH GAK YA | K177: KATOLIK | L177: SILVIA | M177: IBU RUMAH TANGGA | N177: HENDRA | O177: WIRASWASTA | P177: JL SRIKANDI KOMP HOSANA FHILEO BLOK BB22 | Q177: SUNGAI RAYA DALAM | R177: SUNGAI RAYA | S177: KUBU RAYA | T177: KALIMANTAN BARAT | U177: 089625550586
B178: 06/01/2024 16:37:43 | D178: HAFIZH AL FARREL DAMARIO | G178: 22/12/2017 | I178: LAKI-LAKI | J178: BICARA KURANG JELAS | K178: ISLAM | L178: RAWAN TRI SULISTYA | M178: IBU RUMAH TANGGA | N178: LUSINANTO HARTADI | O178: SWASTA | P178: JL. KARYA PERUMAHAN GRAHA KIRANA 13 NO.A4 | Q178: SUNGAI KAKAP | R178: KOTA BARU | S178: KOTA BARU | T178: PONTIANAK | U178: 081286995997
B179: 07/01/2024 17:23:41 | D179: ARKAN SUBHAN ALFARIZI | G179: 21/01/2016 | I179: LAKI-LAKI | J179: CEREBRAL PALSY, BELUM BISA BERJALAN | K179: ISLAM | L179: EKA LESTARI | M179: PNS | N179: DWI RACHMAWAN | O179: PNS | P179: JL. UJUNG PANDANG GG. BALA ARUNG NO 17 | Q179: KELURAHAN SUNGAI JAWI | R179: PONTIANAK KOTA | S179: KOTA PONTIANAK | T179: KALIMANTAN BARAT | U179: 085820410031
B180: 07/01/2024 17:37:36 | D180: TALINO CASSIUS SILSLAHI | G180: 04/01/2021 | I180: LAKI-LAKI | J180: SPEECH DELAY | K180: KATOLIK | L180: FLORENSIA INDAN STEPANI | M180: KARYAWAN SWASTA | N180: BENNY PERNANDO SILALAHI | O180: KARYAWAN SWASTA | P180: JALAN DANAU SENTARUM GG. KALI BENING (RUMAH KE-10) | Q180: SUNGAI BANGKONG | R180: PONTIANAK KOTA | S180: PONTIANAK | T180: KALIMANTAN BARAT | U180: 081286234546
B181: 07/01/2024 19:11:28 | D181: MACK KIO JUANSON | G181: 23/09/2021 | I181: LAKI-LAKI | J181: UMUR 2 TAHUN 4 BULAN MALAS BICARA | K181: KATOLIK | L181: JULIANA | M181: IBU RUMAH TANGGA | N181: ANDY | O181: KARYAWAN | P181: JL. MERDEKA NO.506 | Q181: MARIANA | R181: PONTIANAK KOTA | S181: KOTA PONTIANAK | T181: KALIMANTAN BARAT | U181: 085247179223
...

Sheet PASIEN
B1: Timestamp | C1: f | D1: Nama Anak | E1: Column 21 | F1: No. RM | G1: Tgl. Lahir | H1: Usia (Thn.) | I1: Jens Kelamin | J1: Keluhan | K1: Agama | L1: Nama Ibu | M1: Pekerjaan Ibu | N1: Nama Ayah | O1: Pekerjaan Ayah | P1: Alamat | Q1: Kelurahan/Desa | R1: Kecamatan | S1: Kabupaten/Kota | T1: Provinsi | U1: No. HP/WA | V1: Sumber | W1: Column 20 | X1: Column 1 | Y1: Column 2 | Z1: Column 3
D2: OFF
D3: TA
D4: ISTIRAHAT
D5: SYS
F6: {=if(D6:D1110="","",left(D6:D1110,"1")&text(B6:B1110,"yy")&text(B6:B1110,"mm")&text(G6:G1110,"yy")&right(U6:U1110,2))} -> #REF! | H6: {=if(G6:G1110="","",rounddown((today()-G6:G1110)/365,0))} -> #REF!
B7: 45090.432 | D7: KHALID IBRAHIM AL KAHFI | G7: 44042 | I7: LAKI-LAKI | J7: FISIOTERAPI MOTORIK | K7: ISLAM | L7: DINDA FIRLIANSARI | M7: IBU RUMAH TANGGA | U7: 082231905665
B8: 45090.855 | D8: MUHAMMAD AMMAR | G8: 44128 | I8: LAKI-LAKI | J8: SENSORIK INTEGRASI & TERAPI WICARA | K8: ISLAM | L8: NADYA ULFA | M8: IBU RUMAH TANGGA | U8: 081328347009/0895702479833
B9: 45090.857 | D9: RIFQI SYAFIQ SYAHPUTRA | G9: 43060 | I9: LAKI-LAKI | J9: FISIOTERAPI | K9: ISLAM | L9: DESY ARIANI NASUTION | M9: ASN | U9: 08115706881
B10: 45090.857 | D10: JORDAN GABRIAN | G10: 43780 | I10: LAKI-LAKI | J10: SENSORIK INTEGRASI & TERAPI WICARA | K10: PROTESTAN | L10: LIA ANDRIANI | M10: IBU RUMAH TANGGA | U10: 089622447016
B11: 45090.857 | D11: ARSYA KHAIRUL FATIH | G11: 44172 | I11: LAKI-LAKI | J11: TERAPI WICARA | K11: ISLAM | L11: DEASY NOVITA SARI | M11: IBU RUMAH TANGGA | U11: 085658366269
B12: 45090.857 | D12: RAISYA RAHMA SYAHIRA | G12: 43853 | I12: PEREMPUAN | J12: FISIOTERAPI | K12: ISLAM | L12: DESY ARIANI NASUTION | M12: ASN | U12: 08115706881
B13: 45090.862 | D13: AHMAD LATIF SAFULLAH | G13: 39847 | I13: LAKI-LAKI | J13: FISIOTERAPI | K13: ISLAM | L13: DARWANTI | M13: IBU RUMAH TANGGA | U13: 082252116339
B14: 45090.862 | D14: KHALID IBRAHIM AL KAHFI | G14: 44042 | I14: LAKI-LAKI | J14: FISIOTERAPI | K14: ISLAM | L14: DINDA FIRLIANSARI | M14: IRT | U14: 082231905665
B15: 45090.863 | D15: DAVID CHRISTIAN | G15: 43515 | I15: LAKI-LAKI | J15: SENSORIK INTEGRASI & TERAPI WICARAA | K15: PROTESTAN | L15: DESSY | M15: WIRASWASTA | U15: 085248068221
B16: 45090.864 | D16: CELINE ZOEY HEARTILLY | G16: 43431 | I16: PEREMPUAN | J16: SENSORIK INTEGRASI & TERAPI WICARA | K16: BUDDHA | L16: SYLVIA VERONIKA | M16: IBU RUMAH TANGGA | U16: 085245070077
B17: 45090.868 | D17: KENZO ALFA AS-SIDDIQ | G17: 44219 | I17: LAKI-LAKI | J17: TERAPI WICARA | K17: ISLAM | L17: TARA CHAIRUNISA | M17: GURU | U17: 081362524442
B18: 45090.869 | D18: RAYYA FATIHAH RAZAANA | G18: 41379 | I18: PEREMPUAN | J18: FISIOTERAPI | K18: ISLAM | L18: EVA NOVIANTI HESTI VERA | M18: PNS | U18: 08152234183
... B63: 45160.417 | D63: JASPER GABRIEL | G63: 43039 | I63: LAKI-LAKI | J63: SENSORIK INTEGRASI & TERAPI WICARA | K63: PROTESTAN | L63: YENNY | M63: IBU RUMAH TANGGA | U63: 081917142519
B64: 45171.735 | D64: FAYK KAIVAN SERGUERO | G64: 44719 | I64: LAKI-LAKI | J64: BANYAK OMONG | K64: ISLAM | L64: ETRI YULIA ANDINI | M64: IRT | N64: DANI FAHRIZAL | O64: SWASTA | P64: JL. P. H. HUSIN 2 GG. WISUDA NO. 23A | U64: 082158963663
B65: 45171.744 | D65: AHMAD SYAKIR | G65: 44794 | I65: LAKI-LAKI | J65: PILEK BATUK | K65: ISLAM | L65: IRMA RISKIMA | M65: SWASTA | N65: SYEKH ARPI | O65: WIRAUSAHA | P65: JALAN ARTERI SUPADIO CABANG KIRI | U65: 08981380248
B66: 45172.594 | D66: RAINA AISYAH SUPRIADI | G66: 41412 | I66: PEREMPUAN | J66: CP | K66: ISLAM | L66: KARTINI APRILYANI | M66: IBU RUMAH TANGGA | N66: DENNY SUPRIADI | O66: PNS | P66: JL.PEMDA KOMP.GRIYA MAYOR A.26 | U66: 082353828426
B67: 45172.598 | D67: RAISSA FATIMAH SUPRIADI | G67: 41412 | I67: PEREMPUAN | J67: CP | K67: ISLAM | L67: KARTINI APRILYANI | M67: IBU RUMAH TANGGA | N67: DENNY SUPRIADI | O67: PNS | P67: JL.PEMDA.KOMP GRIYA MAYOR A.26 | U67: 082353828426
B68: 45172.598 | D68: RAINA AISYAH SUPRIADI | G68: 41412 | I68: PEREMPUAN | J68: CP | K68: ISLAM | L68: KARTINI APRILYANI | M68: IBU RUMAH TANGGA | N68: DENNY SUPRIADI | O68: PNS | P68: JL.PEMDA KOMP.GRIYA MAYOR A.26 | U68: 082353828426
B69: 45172.602 | D69: SYARIF MUHAMMAD ALFATEH | G69: 44196 | I69: LAKI-LAKI | J69: Sering kaget, sesak saat malam hari karena lendir sehingga pola tidur berubah | K69: ISLAM | L69: SYARIFAH FIFI MARIANI ALKADRIE | M69: HONORER | N69: SY. ADHY | O69: KARYAWAN SWASTA | P69: JALAN TRITURA NO. 10 KEL. DALAM BUGIS KEC. PONTIANAK TIMUR | U69: 085754395905
B70: 45173.726 | D70: MUHAMMAD AZZAM ACO | G70: 42627 | I70: LAKI-LAKI | J70: Lambat bicara diagnosa dr ADHD | K70: ISLAM | L70: IRA NIA | M70: IBU RUMAH TANGGA | N70: MAMAN ACO | O70: BURUH HARIAN LEPAS | P70: JALAN KOM YOS SUDARSO GANG ALPOKAT INDAH, JALUR 0 | U70: 081255816909
B71: 45173.727 | D71: ELZEVAREL ZERKHA AZARYA | G71: 44426 | I71: LAKI-LAKI | J71: SPEECH DELAY | K71: PROTESTAN | L71: KRISYESIKA | M71: DOSEN | N71: EBEN HEIZER | O71: WIRASWASTA | P71: JLN. TRANS KALIMANTAN GG. BUDAYA NO. 1 | U71: 085346807788
B72: 45173.731 | D72: AMIR SYAKIR | G72: 43364 | I72: LAKI-LAKI | J72: Tidak fokus | K72: ISLAM | L72: WAHYULI ASTUTI | M72: IBU RUMAH TANGGA | N72: SUWARDI | O72: KARYAWAN SWASTA | P72: JL KOMYO SUDARSO GG SRIKAYA 2 NO 19 | U72: 082148665510
B73: 45173.733 | D73: MUHAMMAD ZAFRAN MAERAD | G73: 44264 | I73: LAKI-LAKI | J73: speach delay | K73: ISLAM | L73: DEWI SULISTIANINGSIH | M73: KARYAWAN SWASTA | N73: HAFITDIN | O73: KARYAWAN SWASTA | P73: JL M SOHOR GG SEDERHANA | U73: 08998092083
B74: 45173.739 | D74: MARCELLO | G74: 43931 | I74: LAKI-LAKI | J74: telat bicara | K74: BUDDHA | L74: HIE FUI NA | M74: IBU RUMAH TANGGA | N74: PET HO | O74: WIRASWASTA | P74: JL NAWAWI HASAN 3 NO 342 | U74: 082158815530
B75: 45173.742 | D75: AZQEEYA ELNARA RACAISHA | G75: 44268 | I75: PEREMPUAN | J75: SPEECH DELAY | K75: ISLAM | L75: URAY YUCA ERGAIASHA | M75: IRT | N75: RAHMAT RAZULY HIDAYAT | O75: SWASTA | P75: JL. KARYA KOMP. FAJAR ASRI 3 A-28 | U75: 08982292556
... B174: 45288.409 | D174: IMRAN HANIF PRIBADI | G174: 33762 | I174: LAKI-LAKI | J174: Add | K174: ISLAM | L174: ENI DIAN PERTIWI | M174: IBU RUMAH TANGGA | N174: CITRA TEGUH IMAN PRIBADI | O174: PEGAWAI SWASTA | P174: JALAN WONOBARU GG REMAJA 2 NO 30 | U174: 082139121261
B175: 45293.501 | D175: FAYK KAIVAN SERGUERO | G175: 44719 | I175: LAKI-LAKI | J175: BANYAK OMONG | K175: ISLAM | L175: ETRI YULIA ANDINI | M175: IBU RUMAH TANGGA | N175: DANI FAHRIZAL | O175: TENAGA KESEHATAN | P175: JL. P. H. HUSIN 2 GG.WISUDA NO. 23A | Q175: BANGKA BELITUNG DARAT | R175: PONTIANAK TENGGARA | S175: PONTIANAK | T175: KALIMANTAN BARAT | U175: 081333668688
B176: 45293.508 | D176: AHMAD SYAKIR ARISTAMA | G176: 44794 | I176: LAKI-LAKI | J176: BANYAK OMONG | K176: ISLAM | L176: IRMA RISKIMA | M176: TENAGA KESEHATAN | N176: SYEKH ARPI | O176: PENGUSAHA | P176: CABANG KIRI GG. SEDERHANA | Q176: PARIT BARU | R176: SUNGAI RAYA | S176: KUBU RAYA | T176: KALIMANTAN BARAT | U176: 08981380248
B177: 45294.449 | D177: MUHAMMAD AKRAM ZAYDAN | G177: 43166 | I177: LAKI-LAKI | J177: Kurang fokus | K177: ISLAM | L177: MIERANDHA EDWARD LUBIS | M177: IBU RUMAH TANGGA | N177: NOFIANDY SURYA | O177: WIRASWASTA | P177: DESA KAPUR, KOMPLEK STAR BHAYANGKARA RESIDANCE BLOCK H NO.5 | Q177: MEKAR BARU | R177: SUNGAI RAYA | S177: KUBURAYA | T177: KALIMANTAN BARAT | U177: 0817202880
B178: 45294.531 | D178: MANUEL ERNANDO HALIM. | G178: 43354 | I178: LAKI-LAKI | J178: Speed delay | K178: KATOLIK | L178: SARI YOHANA | M178: IBU RUMAH TANGGA | N178: FRENDY | O178: KARYAWAN | P178: JL.WONODADI 3 | Q178: KOTA BARU | S178: PONTIANAK | T178: KALIMANTAN BARAT | U178: 081288306888
B179: 45294.667 | D179: LABIB RAZAN AL BARRA | G179: 44813 | I179: LAKI-LAKI | J179: Masalah gangguan makan | K179: ISLAM | L179: RISKI LIANA SARI | M179: TENAGA KESEHATAN | N179: MUHAMMAD IQBAL FARIZQI | O179: PNS | P179: KOMPLEK BTN SEKAYAM INDAH. DUSUN BALAIKARANGAN 3 | Q179: BALAI KARANGAN | R179: SEKAYAM | S179: SANGGAU | T179: KALIMANTAN BARAT | U179: 085250805070
