Workbook

Sheet Kunjungan
A1: =IFERROR(__xludf.DUMMYFUNCTION("IMPORTRANGE(""https://docs.google.com/spreadsheets/d/1aW3sXnkheKBRbfzWyPuTKDGfpreWLadXapsXPiXVWTI/edit?gid=32028930#gid=32028930"",""PFOTM!A:M"")"),"#REF!") -> #REF!

Sheet Rujukan SM
A1: =IFERROR(__xludf.DUMMYFUNCTION("importrange(""https://docs.google.com/spreadsheets/d/1gkriwcnFY3HBXnqeB5yAIfGRV5a_RuK9kR3zI8kzsZU/edit?gid=716905355#gid=716905355"",""PFOTM!$A:$B"")"),"#REF!") -> #REF!

Sheet Keuangan
A1: =IFERROR(__xludf.DUMMYFUNCTION("IMPORTRANGE(""https://docs.google.com/spreadsheets/d/1rGngrFis1E2Z1PSo8Tv63LG8vgc5otTCsxhuf5coKXw/edit?gid=1286117242#gid=1286117242"",""PFOTM!A:F"")"),"#REF!") -> #REF!

Sheet Rank
A14: Ranking

Sheet Live View

Sheet Data
A1: Data PFOTM 2026
A4: Nama | B4: Hadir | C4: Terlambat | D4: Alfa | E4: Jumlah. Kunjungan | F4: Paket 1 | G4: Paket 2 | H4: Paket 3 | I4: TA/Sesi Visit | J4: Paket Visit | K4: Rujukan SM | L4: Kegiatan External
A5: HESTI | B5: 23 | C5: 2 | D5: 0 | E5: {=IFNA(INDEX(Kunjungan!$B$3:$Z31,MATCH(A5,Kunjungan!$A$3:$A31,0),MATCH("Grand Total",Kunjungan!$B$2:$Z$2,0)),0)} -> 0 | F5: {=_xlfn.XLOOKUP(A5,Keuangan!$A$2:$A31,Keuangan!$B$2:$B31,0)} -> 0 | G5: {=_xlfn.XLOOKUP(A5,Keuangan!$A$2:$A31,Keuangan!$C$2:$C31,0)} -> 0 | H5: {=_xlfn.XLOOKUP(A5,Keuangan!$A$2:$A31,Keuangan!$D$2:$D31,0)} -> 0 | I5: {=_xlfn.XLOOKUP(A5,Keuangan!$A$2:$A31,Keuangan!$E$2:$E31,0)} -> 0 | J5: {=_xlfn.XLOOKUP(A5,Keuangan!$A$2:$A31,Keuangan!$F$2:$F31,0)} -> 0 | K5: {=_xlfn.XLOOKUP(A5,'Rujukan SM'!$A$2:$A31,'Rujukan SM'!$B$2:$B31,0,0,1)} -> 0 | L5: 0
A6: NADA | B6: 23 | C6: 0 | D6: 0 | E6: {=IFNA(INDEX(Kunjungan!$B$3:$Z31,MATCH(A6,Kunjungan!$A$3:$A31,0),MATCH("Grand Total",Kunjungan!$B$2:$Z$2,0)),0)} -> 0 | F6: {=_xlfn.XLOOKUP(A6,Keuangan!$A$2:$A31,Keuangan!$B$2:$B31,0)} -> 0 | G6: {=_xlfn.XLOOKUP(A6,Keuangan!$A$2:$A31,Keuangan!$C$2:$C31,0)} -> 0 | H6: {=_xlfn.XLOOKUP(A6,Keuangan!$A$2:$A31,Keuangan!$D$2:$D31,0)} -> 0 | I6: {=_xlfn.XLOOKUP(A6,Keuangan!$A$2:$A31,Keuangan!$E$2:$E31,0)} -> 0 | J6: {=_xlfn.XLOOKUP(A6,Keuangan!$A$2:$A31,Keuangan!$F$2:$F31,0)} -> 0 | K6: {=_xlfn.XLOOKUP(A6,'Rujukan SM'!$A$2:$A31,'Rujukan SM'!$B$2:$B31,0,0,1)} -> 0 | L6: 0
A7: DESTY | B7: 21 | C7: 0 | D7: 0 | E7: {=IFNA(INDEX(Kunjungan!$B$3:$Z31,MATCH(A7,Kunjungan!$A$3:$A31,0),MATCH("Grand Total",Kunjungan!$B$2:$Z$2,0)),0)} -> 0 | F7: {=_xlfn.XLOOKUP(A7,Keuangan!$A$2:$A31,Keuangan!$B$2:$B31,0)} -> 0 | G7: {=_xlfn.XLOOKUP(A7,Keuangan!$A$2:$A31,Keuangan!$C$2:$C31,0)} -> 0 | H7: {=_xlfn.XLOOKUP(A7,Keuangan!$A$2:$A31,Keuangan!$D$2:$D31,0)} -> 0 | I7: {=_xlfn.XLOOKUP(A7,Keuangan!$A$2:$A31,Keuangan!$E$2:$E31,0)} -> 0 | J7: {=_xlfn.XLOOKUP(A7,Keuangan!$A$2:$A31,Keuangan!$F$2:$F31,0)} -> 0 | K7: {=_xlfn.XLOOKUP(A7,'Rujukan SM'!$A$2:$A31,'Rujukan SM'!$B$2:$B31,0,0,1)} -> 0 | L7: 0
A8: PRITY | B8: 20 | C8: 1 | D8: 0 | E8: {=IFNA(INDEX(Kunjungan!$B$3:$Z31,MATCH(A8,Kunjungan!$A$3:$A31,0),MATCH("Grand Total",Kunjungan!$B$2:$Z$2,0)),0)} -> 0 | F8: {=_xlfn.XLOOKUP(A8,Keuangan!$A$2:$A31,Keuangan!$B$2:$B31,0)} -> 0 | G8: {=_xlfn.XLOOKUP(A8,Keuangan!$A$2:$A31,Keuangan!$C$2:$C31,0)} -> 0 | H8: {=_xlfn.XLOOKUP(A8,Keuangan!$A$2:$A31,Keuangan!$D$2:$D31,0)} -> 0 | I8: {=_xlfn.XLOOKUP(A8,Keuangan!$A$2:$A31,Keuangan!$E$2:$E31,0)} -> 0 | J8: {=_xlfn.XLOOKUP(A8,Keuangan!$A$2:$A31,Keuangan!$F$2:$F31,0)} -> 0 | K8: {=_xlfn.XLOOKUP(A8,'Rujukan SM'!$A$2:$A31,'Rujukan SM'!$B$2:$B31,0,0,1)} -> 0 | L8: 0
A9: WAHYU | B9: 23 | C9: 0 | D9: 0 | E9: {=IFNA(INDEX(Kunjungan!$B$3:$Z31,MATCH(A9,Kunjungan!$A$3:$A31,0),MATCH("Grand Total",Kunjungan!$B$2:$Z$2,0)),0)} -> 0 | F9: {=_xlfn.XLOOKUP(A9,Keuangan!$A$2:$A31,Keuangan!$B$2:$B31,0)} -> 0 | G9: {=_xlfn.XLOOKUP(A9,Keuangan!$A$2:$A31,Keuangan!$C$2:$C31,0)} -> 0 | H9: {=_xlfn.XLOOKUP(A9,Keuangan!$A$2:$A31,Keuangan!$D$2:$D31,0)} -> 0 | I9: {=_xlfn.XLOOKUP(A9,Keuangan!$A$2:$A31,Keuangan!$E$2:$E31,0)} -> 0 | J9: {=_xlfn.XLOOKUP(A9,Keuangan!$A$2:$A31,Keuangan!$F$2:$F31,0)} -> 0 | K9: {=_xlfn.XLOOKUP(A9,'Rujukan SM'!$A$2:$A31,'Rujukan SM'!$B$2:$B31,0,0,1)} -> 0 | L9: 0
A10: ORY | B10: 23 | C10: 0 | D10: 0 | E10: {=IFNA(INDEX(Kunjungan!$B$3:$Z31,MATCH(A10,Kunjungan!$A$3:$A31,0),MATCH("Grand Total",Kunjungan!$B$2:$Z$2,0)),0)} -> 0 | F10: {=_xlfn.XLOOKUP(A10,Keuangan!$A$2:$A31,Keuangan!$B$2:$B31,0)} -> 0 | G10: {=_xlfn.XLOOKUP(A10,Keuangan!$A$2:$A31,Keuangan!$C$2:$C31,0)} -> 0 | H10: {=_xlfn.XLOOKUP(A10,Keuangan!$A$2:$A31,Keuangan!$D$2:$D31,0)} -> 0 | I10: {=_xlfn.XLOOKUP(A10,Keuangan!$A$2:$A31,Keuangan!$E$2:$E31,0)} -> 0 | J10: {=_xlfn.XLOOKUP(A10,Keuangan!$A$2:$A31,Keuangan!$F$2:$F31,0)} -> 0 | K10: {=_xlfn.XLOOKUP(A10,'Rujukan SM'!$A$2:$A31,'Rujukan SM'!$B$2:$B31,0,0,1)} -> 0 | L10: 0
A11: HENA | B11: 20 | C11: 0 | D11: 0 | E11: {=IFNA(INDEX(Kunjungan!$B$3:$Z31,MATCH(A11,Kunjungan!$A$3:$A31,0),MATCH("Grand Total",Kunjungan!$B$2:$Z$2,0)),0)} -> 0 | F11: {=_xlfn.XLOOKUP(A11,Keuangan!$A$2:$A31,Keuangan!$B$2:$B31,0)} -> 0 | G11: {=_xlfn.XLOOKUP(A11,Keuangan!$A$2:$A31,Keuangan!$C$2:$C31,0)} -> 0 | H11: {=_xlfn.XLOOKUP(A11,Keuangan!$A$2:$A31,Keuangan!$D$2:$D31,0)} -> 0 | I11: {=_xlfn.XLOOKUP(A11,Keuangan!$A$2:$A31,Keuangan!$E$2:$E31,0)} -> 0 | J11: {=_xlfn.XLOOKUP(A11,Keuangan!$A$2:$A31,Keuangan!$F$2:$F31,0)} -> 0 | K11: {=_xlfn.XLOOKUP(A11,'Rujukan SM'!$A$2:$A31,'Rujukan SM'!$B$2:$B31,0,0,1)} -> 0 | L11: 0
A12: OKTA | B12: 19 | C12: 2 | D12: 1 | E12: {=IFNA(INDEX(Kunjungan!$B$3:$Z31,MATCH(A12,Kunjungan!$A$3:$A31,0),MATCH("Grand Total",Kunjungan!$B$2:$Z$2,0)),0)} -> 0 | F12: {=_xlfn.XLOOKUP(A12,Keuangan!$A$2:$A31,Keuangan!$B$2:$B31,0)} -> 0 | G12: {=_xlfn.XLOOKUP(A12,Keuangan!$A$2:$A31,Keuangan!$C$2:$C31,0)} -> 0 | H12: {=_xlfn.XLOOKUP(A12,Keuangan!$A$2:$A31,Keuangan!$D$2:$D31,0)} -> 0 | I12: {=_xlfn.XLOOKUP(A12,Keuangan!$A$2:$A31,Keuangan!$E$2:$E31,0)} -> 0 | J12: {=_xlfn.XLOOKUP(A12,Keuangan!$A$2:$A31,Keuangan!$F$2:$F31,0)} -> 0 | K12: {=_xlfn.XLOOKUP(A12,'Rujukan SM'!$A$2:$A31,'Rujukan SM'!$B$2:$B31,0,0,1)} -> 0 | L12: 0
A13: AUL | B13: 21 | C13: 0 | D13: 0 | E13: {=IFNA(INDEX(Kunjungan!$B$3:$Z31,MATCH(A13,Kunjungan!$A$3:$A31,0),MATCH("Grand Total",Kunjungan!$B$2:$Z$2,0)),0)} -> 0 | F13: {=_xlfn.XLOOKUP(A13,Keuangan!$A$2:$A31,Keuangan!$B$2:$B31,0)} -> 0 | G13: {=_xlfn.XLOOKUP(A13,Keuangan!$A$2:$A31,Keuangan!$C$2:$C31,0)} -> 0 | H13: {=_xlfn.XLOOKUP(A13,Keuangan!$A$2:$A31,Keuangan!$D$2:$D31,0)} -> 0 | I13: {=_xlfn.XLOOKUP(A13,Keuangan!$A$2:$A31,Keuangan!$E$2:$E31,0)} -> 0 | J13: {=_xlfn.XLOOKUP(A13,Keuangan!$A$2:$A31,Keuangan!$F$2:$F31,0)} -> 0 | K13: {=_xlfn.XLOOKUP(A13,'Rujukan SM'!$A$2:$A31,'Rujukan SM'!$B$2:$B31,0,0,1)} -> 0 | L13: 0
A14: PUTRI | B14: 21 | C14: 0 | D14: 0 | E14: {=IFNA(INDEX(Kunjungan!$B$3:$Z31,MATCH(A14,Kunjungan!$A$3:$A31,0),MATCH("Grand Total",Kunjungan!$B$2:$Z$2,0)),0)} -> 0 | F14: {=_xlfn.XLOOKUP(A14,Keuangan!$A$2:$A31,Keuangan!$B$2:$B31,0)} -> 0 | G14: {=_xlfn.XLOOKUP(A14,Keuangan!$A$2:$A31,Keuangan!$C$2:$C31,0)} -> 0 | H14: {=_xlfn.XLOOKUP(A14,Keuangan!$A$2:$A31,Keuangan!$D$2:$D31,0)} -> 0 | I14: {=_xlfn.XLOOKUP(A14,Keuangan!$A$2:$A31,Keuangan!$E$2:$E31,0)} -> 0 | J14: {=_xlfn.XLOOKUP(A14,Keuangan!$A$2:$A31,Keuangan!$F$2:$F31,0)} -> 0 | K14: {=_xlfn.XLOOKUP(A14,'Rujukan SM'!$A$2:$A31,'Rujukan SM'!$B$2:$B31,0,0,1)} -> 0 | L14: 0
A15: Data
A18: Nama | B18: Hadir | C18: Terlambat | D18: Alfa | E18: Jumlah Kunjungan | F18: Paket 1 | G18: Paket 2 | H18: Paket 3 | I18: TA/Sesi Visit | J18: Paket Visit | K18: Rujukan SM | L18: Kegiatan External | M18: Total Poin
A19: HESTI | B19: =B5*1 -> 23 | C19: =C5*-1 -> -2 | D19: =D5*2 -> 0 | E19: =E5*1 -> 0 | F19: =F5*3 -> 0 | G19: =G5*6 -> 0 | H19: =H5*12 -> 0 | I19: =I5*2 -> 0 | J19: =J5*10 -> 0 | K19: =K5*2 -> 0 | L19: =L5*2 -> 0 | M19: =sum(B19:L19) -> 21
A20: NADA | B20: =B6*1 -> 23 | C20: =C6*-1 -> 0 | D20: =D6*2 -> 0 | E20: =E6*1 -> 0 | F20: =F6*3 -> 0 | G20: =G6*6 -> 0 | H20: =H6*12 -> 0 | I20: =I6*2 -> 0 | J20: =J6*10 -> 0 | K20: =K6*2 -> 0 | L20: =L6*2 -> 0 | M20: =sum(B20:L20) -> 23
A21: DESTY | B21: =B7*1 -> 21 | C21: =C7*-1 -> 0 | D21: =D7*2 -> 0 | E21: =E7*1 -> 0 | F21: =F7*3 -> 0 | G21: =G7*6 -> 0 | H21: =H7*12 -> 0 | I21: =I7*2 -> 0 | J21: =J7*10 -> 0 | K21: =K7*2 -> 0 | L21: =L7*2 -> 0 | M21: =sum(B21:L21) -> 21
A22: PRITY | B22: =B8*1 -> 20 | C22: =C8*-1 -> -1 | D22: =D8*2 -> 0 | E22: =E8*1 -> 0 | F22: =F8*3 -> 0 | G22: =G8*6 -> 0 | H22: =H8*12 -> 0 | I22: =I8*2 -> 0 | J22: =J8*10 -> 0 | K22: =K8*2 -> 0 | L22: =L8*2 -> 0 | M22: =sum(B22:L22) -> 19
A23: WAHYU | B23: =B9*1 -> 23 | C23: =C9*-1 -> 0 | D23: =D9*2 -> 0 | E23: =E9*1 -> 0 | F23: =F9*3 -> 0 | G23: =G9*6 -> 0 | H23: =H9*12 -> 0 | I23: =I9*2 -> 0 | J23: =J9*10 -> 0 | K23: =K9*2 -> 0 | L23: =L9*2 -> 0 | M23: =sum(B23:L23) -> 23
A24: ORY | B24: =B10*1 -> 23 | C24: =C10*-1 -> 0 | D24: =D10*2 -> 0 | E24: =E10*1 -> 0 | F24: =F10*3 -> 0 | G24: =G10*6 -> 0 | H24: =H10*12 -> 0 | I24: =I10*2 -> 0 | J24: =J10*10 -> 0 | K24: =K10*2 -> 0 | L24: =L10*2 -> 0 | M24: =sum(B24:L24) -> 23
A25: HENA | B25: =B11*1 -> 20 | C25: =C11*-1 -> 0 | D25: =D11*2 -> 0 | E25: =E11*1 -> 0 | F25: =F11*3 -> 0 | G25: =G11*6 -> 0 | H25: =H11*12 -> 0 | I25: =I11*2 -> 0 | J25: =J11*10 -> 0 | K25: =K11*2 -> 0 | L25: =L11*2 -> 0 | M25: =sum(B25:L25) -> 20
A26: OKTA | B26: =B12*1 -> 19 | C26: =C12*-1 -> -2 | D26: =D12*2 -> 2 | E26: =E12*1 -> 0 | F26: =F12*3 -> 0 | G26: =G12*6 -> 0 | H26: =H12*12 -> 0 | I26: =I12*2 -> 0 | J26: =J12*10 -> 0 | K26: =K12*2 -> 0 | L26: =L12*2 -> 0 | M26: =sum(B26:L26) -> 19
A27: AUL | B27: =B13*1 -> 21 | C27: =C13*-1 -> 0 | D27: =D13*2 -> 0 | E27: =E13*1 -> 0 | F27: =F13*3 -> 0 | G27: =G13*6 -> 0 | H27: =H13*12 -> 0 | I27: =I13*2 -> 0 | J27: =J13*10 -> 0 | K27: =K13*2 -> 0 | L27: =L13*2 -> 0 | M27: =sum(B27:L27) -> 21
A28: PUTRI | B28: =B14*1 -> 21 | C28: =C14*-1 -> 0 | D28: =D14*2 -> 0 | E28: =E14*1 -> 0 | F28: =F14*3 -> 0 | G28: =G14*6 -> 0 | H28: =H14*12 -> 0 | I28: =I14*2 -> 0 | J28: =J14*10 -> 0 | K28: =K14*2 -> 0 | L28: =L14*2 -> 0 | M28: =sum(B28:L28) -> 21
A29: Poin

Sheet Rekap Data
A1: Rekap Data PFOTM 2026
A4: Periode | B4: Nama | C4: Hadir | D4: Terlambat | E4: Alfa | F4: Jumlah. Kunjungan | G4: Paket 1 | H4: Paket 2 | I4: Paket 3 | J4: TA/Sesi Visit | K4: Paket Visit | L4: Rujukan SM | M4: Kegiatan External | N4: Hari Kerja | O4: % Kehadiran | P4: % Disiplin | Q4: Kunj. per Hadir | R4: Paket per Hadir | S4: Jumlah Paket
A5: 01Jan | B5: HESTI | C5: 25 | D5: 1 | E5: 0 | F5: 91 | G5: 8 | H5: 2 | I5: 0 | J5: 0 | K5: 1 | M5: 0 | N5: 25 | O5: =C5/N5 -> 1 | P5: =(N5-D5)/N5 -> 0.96 | Q5: =F5/C5 -> 3.64 | R5: =sum(G5:I5)/C5 -> 0.4 | S5: =sum(G5:I5) -> 10
A6: 01Jan | B6: DANRU | C6: 25 | D6: 0 | E6: 0 | F6: 0 | G6: 0 | H6: 0 | I6: 0 | J6: 0 | K6: 0 | M6: 0 | N6: 25 | O6: =C6/N6 -> 1 | P6: =(N6-D6)/N6 -> 1 | Q6: =F6/C6 -> 0 | R6: =sum(G6:I6)/C6 -> 0 | S6: =sum(G6:I6) -> 0
A7: 01Jan | B7: NADA | C7: 25 | D7: 0 | E7: 0 | F7: 0 | G7: 0 | H7: 0 | I7: 0 | J7: 0 | K7: 0 | M7: 0 | N7: 25 | O7: =C7/N7 -> 1 | P7: =(N7-D7)/N7 -> 1 | Q7: =F7/C7 -> 0 | R7: =sum(G7:I7)/C7 -> 0 | S7: =sum(G7:I7) -> 0
A8: 01Jan | B8: DESTY | C8: 24 | D8: 0 | E8: 0 | F8: 69 | G8: 8 | H8: 3 | I8: 0 | J8: 6 | K8: 1 | M8: 0 | N8: 25 | O8: =C8/N8 -> 0.96 | P8: =(N8-D8)/N8 -> 1 | Q8: =F8/C8 -> 2.875 | R8: =sum(G8:I8)/C8 -> 0.45833333 | S8: =sum(G8:I8) -> 11
A9: 01Jan | B9: PRITY | C9: 25 | D9: 0 | E9: 0 | F9: 79 | G9: 3 | H9: 5 | I9: 0 | J9: 0 | K9: 0 | M9: 0 | N9: 25 | O9: =C9/N9 -> 1 | P9: =(N9-D9)/N9 -> 1 | Q9: =F9/C9 -> 3.16 | R9: =sum(G9:I9)/C9 -> 0.32 | S9: =sum(G9:I9) -> 8
A10: 01Jan | B10: WAHYU | C10: 25 | D10: 0 | E10: 0 | F10: 100 | G10: 7 | H10: 4 | I10: 0 | J10: 1 | K10: 0 | M10: 1 | N10: 25 | O10: =C10/N10 -> 1 | P10: =(N10-D10)/N10 -> 1 | Q10: =F10/C10 -> 4 | R10: =sum(G10:I10)/C10 -> 0.44 | S10: =sum(G10:I10) -> 11
A11: 01Jan | B11: ORY | C11: 24 | D11: 1 | E11: 0 | F11: 92 | G11: 8 | H11: 5 | I11: 0 | J11: 0 | K11: 0 | M11: 0 | N11: 25 | O11: =C11/N11 -> 0.96 | P11: =(N11-D11)/N11 -> 0.96 | Q11: =F11/C11 -> 3.8333333 | R11: =sum(G11:I11)/C11 -> 0.54166667 | S11: =sum(G11:I11) -> 13
A12: 01Jan | B12: HENA | C12: 25 | D12: 0 | E12: 0 | F12: 77 | G12: 8 | H12: 0 | I12: 0 | J12: 1 | K12: 2 | M12: 0 | N12: 25 | O12: =C12/N12 -> 1 | P12: =(N12-D12)/N12 -> 1 | Q12: =F12/C12 -> 3.08 | R12: =sum(G12:I12)/C12 -> 0.32 | S12: =sum(G12:I12) -> 8
A13: 01Jan | B13: OKTA | C13: 25 | D13: 0 | E13: 0 | F13: 81 | G13: 9 | H13: 1 | I13: 0 | J13: 0 | K13: 0 | M13: 0 | N13: 25 | O13: =C13/N13 -> 1 | P13: =(N13-D13)/N13 -> 1 | Q13: =F13/C13 -> 3.24 | R13: =sum(G13:I13)/C13 -> 0.4 | S13: =sum(G13:I13) -> 10
A14: 01Jan | B14: AUL | C14: 23 | D14: 0 | E14: 0 | F14: 73 | G14: 7 | H14: 1 | I14: 0 | J14: 0 | K14: 2 | M14: 0 | N14: 25 | O14: =C14/N14 -> 0.92 | P14: =(N14-D14)/N14 -> 1 | Q14: =F14/C14 -> 3.173913 | R14: =sum(G14:I14)/C14 -> 0.34782609 | S14: =sum(G14:I14) -> 8
A15: 01Jan | B15: PUTRI | C15: 25 | D15: 0 | E15: 0 | F15: 0 | G15: 0 | H15: 0 | I15: 0 | J15: 0 | K15: 0 | M15: 0 | N15: 25 | O15: =C15/N15 -> 1 | P15: =(N15-D15)/N15 -> 1 | Q15: =F15/C15 -> 0 | R15: =sum(G15:I15)/C15 -> 0 | S15: =sum(G15:I15) -> 0
A16: 02Feb | B16: HESTI | C16: 25 | D16: 1 | E16: 0 | F16: 72 | G16: 6 | H16: 2 | I16: 1 | J16: 0 | K16: 1 | M16: 3 | N16: 25 | O16: =C16/N16 -> 1 | P16: =(N16-D16)/N16 -> 0.96 | Q16: =F16/C16 -> 2.88 | R16: =sum(G16:I16)/C16 -> 0.36 | S16: =sum(G16:I16) -> 9
... A59: 05Mei | B59: PUTRI | C59: 24 | D59: 0 | E59: 0 | F59: 68 | G59: 6 | H59: 0 | I59: 0 | J59: 3 | K59: 3 | M59: 0 | N59: 24 | O59: =C59/N59 -> 1 | P59: =(N59-D59)/N59 -> 1 | Q59: =F59/C59 -> 2.8333333 | R59: =sum(G59:I59)/C59 -> 0.25 | S59: =sum(G59:I59) -> 6
A60: 06Jun | B60: HESTI | C60: 20 | D60: 1 | E60: 0 | F60: 79 | G60: 6 | H60: 2 | I60: 0 | J60: 1 | K60: 2 | L60: 0 | M60: 0 | N60: 23 | O60: =C60/N60 -> 0.86956522 | P60: =(N60-D60)/N60 -> 0.95652174 | Q60: =F60/C60 -> 3.95 | R60: =sum(G60:I60)/C60 -> 0.4 | S60: =sum(G60:I60) -> 8
A61: 06Jun | B61: DANRU | C61: 23 | D61: 0 | E61: 0 | F61: 0 | G61: 0 | H61: 0 | I61: 0 | J61: 0 | K61: 0 | L61: 0 | M61: 0 | N61: 23 | O61: =C61/N61 -> 1 | P61: =(N61-D61)/N61 -> 1 | Q61: =F61/C61 -> 0 | R61: =sum(G61:I61)/C61 -> 0 | S61: =sum(G61:I61) -> 0
A62: 06Jun | B62: NADA | C62: 23 | D62: 0 | E62: 0 | F62: 0 | G62: 0 | H62: 0 | I62: 0 | J62: 0 | K62: 0 | L62: 0 | M62: 0 | N62: 23 | O62: =C62/N62 -> 1 | P62: =(N62-D62)/N62 -> 1 | Q62: =F62/C62 -> 0 | R62: =sum(G62:I62)/C62 -> 0 | S62: =sum(G62:I62) -> 0
A63: 06Jun | B63: DESTY | C63: 23 | D63: 0 | E63: 0 | F63: 79 | G63: 9 | H63: 0 | I63: 0 | J63: 2 | K63: 0 | L63: 0 | M63: 0 | N63: 23 | O63: =C63/N63 -> 1 | P63: =(N63-D63)/N63 -> 1 | Q63: =F63/C63 -> 3.4347826 | R63: =sum(G63:I63)/C63 -> 0.39130435 | S63: =sum(G63:I63) -> 9
A64: 06Jun | B64: PRITY | C64: 20 | D64: 0 | E64: 0 | F64: 74 | G64: 7 | H64: 1 | I64: 0 | J64: 3 | K64: 0 | L64: 0 | M64: 0 | N64: 23 | O64: =C64/N64 -> 0.86956522 | P64: =(N64-D64)/N64 -> 1 | Q64: =F64/C64 -> 3.7 | R64: =sum(G64:I64)/C64 -> 0.4 | S64: =sum(G64:I64) -> 8
A65: 06Jun | B65: WAHYU | C65: 23 | D65: 0 | E65: 0 | F65: 98 | G65: 3 | H65: 2 | I65: 1 | J65: 0 | K65: 0 | L65: 0 | M65: 0 | N65: 23 | O65: =C65/N65 -> 1 | P65: =(N65-D65)/N65 -> 1 | Q65: =F65/C65 -> 4.2608696 | R65: =sum(G65:I65)/C65 -> 0.26086957 | S65: =sum(G65:I65) -> 6
A66: 06Jun | B66: ORY | C66: 23 | D66: 0 | E66: 0 | F66: 76 | G66: 8 | H66: 4 | I66: 0 | J66: 3 | K66: 0 | L66: 1 | M66: 0 | N66: 23 | O66: =C66/N66 -> 1 | P66: =(N66-D66)/N66 -> 1 | Q66: =F66/C66 -> 3.3043478 | R66: =sum(G66:I66)/C66 -> 0.52173913 | S66: =sum(G66:I66) -> 12
A67: 06Jun | B67: HENA | C67: 21 | D67: 0 | E67: 0 | F67: 74 | G67: 5 | H67: 3 | I67: 0 | J67: 2 | K67: 3 | L67: 0 | M67: 0 | N67: 23 | O67: =C67/N67 -> 0.91304348 | P67: =(N67-D67)/N67 -> 1 | Q67: =F67/C67 -> 3.5238095 | R67: =sum(G67:I67)/C67 -> 0.38095238 | S67: =sum(G67:I67) -> 8
A68: 06Jun | B68: OKTA | C68: 23 | D68: 0 | E68: 0 | F68: 79 | G68: 5 | H68: 4 | I68: 0 | J68: 4 | K68: 1 | L68: 0 | M68: 0 | N68: 23 | O68: =C68/N68 -> 1 | P68: =(N68-D68)/N68 -> 1 | Q68: =F68/C68 -> 3.4347826 | R68: =sum(G68:I68)/C68 -> 0.39130435 | S68: =sum(G68:I68) -> 9
A69: 06Jun | B69: AUL | C69: 23 | D69: 2 | E69: 0 | F69: 78 | G69: 5 | H69: 6 | I69: 0 | J69: 2 | K69: 3 | L69: 0 | M69: 0 | N69: 23 | O69: =C69/N69 -> 1 | P69: =(N69-D69)/N69 -> 0.91304348 | Q69: =F69/C69 -> 3.3913043 | R69: =sum(G69:I69)/C69 -> 0.47826087 | S69: =sum(G69:I69) -> 11
A70: 06Jun | B70: PUTRI | C70: 23 | D70: 0 | E70: 0 | F70: 78 | G70: 5 | H70: 4 | I70: 0 | J70: 2 | K70: 1 | L70: 0 | M70: 0 | N70: 23 | O70: =C70/N70 -> 1 | P70: =(N70-D70)/N70 -> 1 | Q70: =F70/C70 -> 3.3913043 | R70: =sum(G70:I70)/C70 -> 0.39130435 | S70: =sum(G70:I70) -> 9
A71: 07Jul | B71: HESTI | C71: 26 | D71: 1 | E71: 0 | F71: 90 | G71: 7 | H71: 3 | I71: 0 | J71: 4 | K71: 2 | L71: 3 | M71: 0 | N71: 26 | O71: =C71/N71 -> 1 | P71: =(N71-D71)/N71 -> 0.96153846 | Q71: =F71/C71 -> 3.4615385 | R71: =sum(G71:I71)/C71 -> 0.38461538 | S71: =sum(G71:I71) -> 10
... A100: 09Sep | B100: PUTRI | C100: 21 | D100: 0 | E100: 0 | F100: 62 | G100: 6 | H100: 2 | I100: 0 | J100: 0 | K100: 0 | L100: 1 | M100: 0 | N100: 23 | O100: =C100/N100 -> 0.91304348 | P100: =(N100-D100)/N100 -> 1 | Q100: =F100/C100 -> 2.952381 | R100: =sum(G100:I100)/C100 -> 0.38095238 | S100: =sum(G100:I100) -> 8

Sheet Rekap Poin
A1: Rekap Poin PFOTM 2026
A4: Periode | B4: Nama | C4: Hadir | D4: Terlambat | E4: Alfa | F4: Jumlah Kunjungan | G4: Paket 1 | H4: Paket 2 | I4: Paket 3 | J4: TA/Sesi Visit | K4: Paket Visit | L4: Rujukan SM | M4: Kegiatan External | N4: Total Poin | O4: Rank
A5: 01Jan | B5: HESTI | C5: 25 | D5: -1 | E5: 0 | F5: 91 | G5: 24 | H5: 12 | I5: 0 | J5: 0 | K5: 10 | M5: 0 | N5: 161 | O5: =RANK(N$5,N$5:N$15) -> 3
A6: 01Jan | B6: DANRU | C6: 25 | D6: 0 | E6: 0 | F6: 0 | G6: 0 | H6: 0 | I6: 0 | J6: 0 | K6: 0 | M6: 0 | N6: 25 | O6: =RANK(N$6,N$5:N$15) -> 9
A7: 01Jan | B7: NADA | C7: 25 | D7: 0 | E7: 0 | F7: 0 | G7: 0 | H7: 0 | I7: 0 | J7: 0 | K7: 0 | M7: 0 | N7: 25 | O7: =RANK(N$7,N$5:N$15) -> 9
A8: 01Jan | B8: DESTY | C8: 24 | D8: 0 | E8: 0 | F8: 69 | G8: 24 | H8: 18 | I8: 0 | J8: 12 | K8: 10 | M8: 0 | N8: 157 | O8: =RANK(N$8,N$5:N$15) -> 4
A9: 01Jan | B9: PRITY | C9: 25 | D9: 0 | E9: 0 | F9: 79 | G9: 9 | H9: 30 | I9: 0 | J9: 0 | K9: 0 | M9: 0 | N9: 143 | O9: =RANK(N$9,N$5:N$15) -> 6
A10: 01Jan | B10: WAHYU | C10: 25 | D10: 0 | E10: 0 | F10: 100 | G10: 21 | H10: 24 | I10: 0 | J10: 2 | K10: 0 | M10: 2 | N10: 174 | O10: =RANK(N$10,N$5:N$15) -> 1
A11: 01Jan | B11: ORY | C11: 24 | D11: -1 | E11: 0 | F11: 92 | G11: 24 | H11: 30 | I11: 0 | J11: 0 | K11: 0 | M11: 0 | N11: 169 | O11: =RANK(N$11,N$5:N$15) -> 2
A12: 01Jan | B12: HENA | C12: 25 | D12: 0 | E12: 0 | F12: 77 | G12: 24 | H12: 0 | I12: 0 | J12: 2 | K12: 20 | M12: 0 | N12: 148 | O12: =RANK(N$12,N$5:N$15) -> 5
A13: 01Jan | B13: OKTA | C13: 25 | D13: 0 | E13: 0 | F13: 81 | G13: 27 | H13: 6 | I13: 0 | J13: 0 | K13: 0 | M13: 0 | N13: 139 | O13: =RANK(N$13,N$5:N$15) -> 8
A14: 01Jan | B14: AUL | C14: 23 | D14: 0 | E14: 0 | F14: 73 | G14: 21 | H14: 6 | I14: 0 | J14: 0 | K14: 20 | M14: 0 | N14: 143 | O14: =RANK(N$14,N$5:N$15) -> 6
A15: 01Jan | B15: PUTRI | C15: 25 | D15: 0 | E15: 0 | F15: 0 | G15: 0 | H15: 0 | I15: 0 | J15: 0 | K15: 0 | M15: 0 | N15: 25 | O15: =RANK(N$15,N$5:N$15) -> 9
A16: 02Feb | B16: HESTI | C16: 25 | D16: -1 | E16: 0 | F16: 72 | G16: 18 | H16: 12 | I16: 12 | J16: 0 | K16: 10 | M16: 6 | N16: 154 | O16: =RANK(N$16,N$16:N$26) -> 6
A17: 02Feb | B17: DANRU | C17: 25 | D17: 0 | E17: 0 | F17: 0 | G17: 0 | H17: 0 | I17: 0 | J17: 0 | K17: 0 | M17: 0 | N17: 25 | O17: =RANK(N$17,N$16:N$26) -> 10
A18: 02Feb | B18: NADA | C18: 25 | D18: 0 | E18: 0 | F18: 0 | G18: 0 | H18: 0 | I18: 0 | J18: 0 | K18: 0 | M18: 0 | N18: 25 | O18: =RANK(N$18,N$16:N$26) -> 10
A19: 02Feb | B19: DESTY | C19: 25 | D19: -1 | E19: 0 | F19: 82 | G19: 33 | H19: 0 | I19: 0 | J19: 4 | K19: 10 | M19: 6 | N19: 159 | O19: =RANK(N$19,N$16:N$26) -> 5
A20: 02Feb | B20: PRITY | C20: 22 | D20: -5 | E20: 0 | F20: 65 | G20: 9 | H20: 18 | I20: 0 | J20: 16 | K20: 0 | M20: 6 | N20: 131 | O20: =RANK(N$20,N$16:N$26) -> 8
A21: 02Feb | B21: WAHYU | C21: 25 | D21: 0 | E21: 0 | F21: 98 | G21: 27 | H21: 36 | I21: 0 | J21: 2 | K21: 20 | M21: 6 | N21: 214 | O21: =RANK(N$21,N$16:N$26) -> 1
A22: 02Feb | B22: ORY | C22: 25 | D22: -1 | E22: 0 | F22: 81 | G22: 12 | H22: 0 | I22: 0 | J22: 4 | K22: 0 | M22: 6 | N22: 127 | O22: =RANK(N$22,N$16:N$26) -> 9
A23: 02Feb | B23: HENA | C23: 25 | D23: -1 | E23: 0 | F23: 75 | G23: 24 | H23: 12 | I23: 0 | J23: 6 | K23: 20 | M23: 6 | N23: 167 | O23: =RANK(N$23,N$16:N$26) -> 4
A24: 02Feb | B24: OKTA | C24: 25 | D24: 0 | E24: 0 | F24: 80 | G24: 21 | H24: 24 | I24: 0 | J24: 2 | K24: 10 | M24: 6 | N24: 168 | O24: =RANK(N$24,N$16:N$26) -> 3
A25: 02Feb | B25: AUL | C25: 25 | D25: -2 | E25: 0 | F25: 90 | G25: 15 | H25: 24 | I25: 0 | J25: 0 | K25: 20 | M25: 8 | N25: 180 | O25: =RANK(N$25,N$16:N$26) -> 2
A26: 02Feb | B26: PUTRI | C26: 23 | D26: 0 | E26: 0 | F26: 62 | G26: 12 | H26: 12 | I26: 0 | J26: 8 | K26: 10 | M26: 14 | N26: 141 | O26: =RANK(N$26,N$16:N$26) -> 7
A27: 03Mar | B27: HESTI | C27: 17 | D27: -1 | E27: 0 | F27: 45 | G27: 12 | H27: 6 | I27: 0 | J27: 0 | K27: 0 | M27: 0 | N27: 79 | O27: =RANK(N$27,N$27:N$37) -> 7
A28: 03Mar | B28: DANRU | C28: 17 | D28: 0 | E28: 0 | F28: 0 | G28: 0 | H28: 0 | I28: 0 | J28: 0 | K28: 0 | M28: 0 | N28: 17 | O28: =RANK(N$28,N$27:N$37) -> 10
A29: 03Mar | B29: NADA | C29: 17 | D29: 0 | E29: 0 | F29: 0 | G29: 0 | H29: 0 | I29: 0 | J29: 0 | K29: 0 | M29: 0 | N29: 17 | O29: =RANK(N$29,N$27:N$37) -> 10
A30: 03Mar | B30: DESTY | C30: 17 | D30: -1 | E30: 0 | F30: 44 | G30: 15 | H30: 0 | I30: 0 | J30: 4 | K30: 0 | M30: 0 | N30: 79 | O30: =RANK(N$30,N$27:N$37) -> 7
A31: 03Mar | B31: PRITY | C31: 17 | D31: -3 | E31: 0 | F31: 51 | G31: 12 | H31: 0 | I31: 0 | J31: 4 | K31: 0 | M31: 0 | N31: 81 | O31: =RANK(N$31,N$27:N$37) -> 6
A32: 03Mar | B32: WAHYU | C32: 16 | D32: 0 | E32: 0 | F32: 69 | G32: 6 | H32: 12 | I32: 0 | J32: 2 | K32: 10 | M32: 0 | N32: 115 | O32: =RANK(N$32,N$27:N$37) -> 2
A33: 03Mar | B33: ORY | C33: 17 | D33: -3 | E33: 0 | F33: 51 | G33: 9 | H33: 12 | I33: 0 | J33: 0 | K33: 0 | M33: 0 | N33: 86 | O33: =RANK(N$33,N$27:N$37) -> 4
A34: 03Mar | B34: HENA | C34: 16 | D34: 0 | E34: 0 | F34: 46 | G34: 15 | H34: 6 | I34: 0 | J34: 0 | K34: 0 | M34: 0 | N34: 83 | O34: =RANK(N$34,N$27:N$37) -> 5
A35: 03Mar | B35: OKTA | C35: 17 | D35: 0 | E35: 0 | F35: 46 | G35: 9 | H35: 6 | I35: 0 | J35: 0 | K35: 0 | M35: 0 | N35: 78 | O35: =RANK(N$35,N$27:N$37) -> 9
A36: 03Mar | B36: AUL | C36: 17 | D36: -1 | E36: 0 | F36: 56 | G36: 9 | H36: 12 | I36: 12 | J36: 4 | K36: 10 | M36: 0 | N36: 119 | O36: =RANK(N$36,N$27:N$37) -> 1
A37: 03Mar | B37: PUTRI | C37: 17 | D37: 0 | E37: 0 | F37: 52 | G37: 18 | H37: 0 | I37: 0 | J37: 2 | K37: 0 | M37: 0 | N37: 89 | O37: =RANK(N$37,N$27:N$37) -> 3
A38: 04Apr | B38: HESTI | C38: 24 | D38: -1 | E38: 0 | F38: 78 | G38: 18 | H38: 6 | I38: 12 | J38: 0 | K38: 10 | M38: 0 | N38: 147 | O38: =RANK(N$38,N$38:N$48) -> 7
A39: 04Apr | B39: DANRU | C39: 27 | D39: 0 | E39: 0 | F39: 0 | G39: 0 | H39: 0 | I39: 0 | J39: 0 | K39: 0 | M39: 0 | N39: 27 | O39: =RANK(N$39,N$38:N$48) -> 10
A40: 04Apr | B40: NADA | C40: 27 | D40: 0 | E40: 0 | F40: 0 | G40: 0 | H40: 0 | I40: 0 | J40: 0 | K40: 0 | M40: 0 | N40: 27 | O40: =RANK(N$40,N$38:N$48) -> 10
A41: 04Apr | B41: DESTY | C41: 23 | D41: 0 | E41: 0 | F41: 62 | G41: 24 | H41: 6 | I41: 0 | J41: 6 | K41: 10 | M41: 0 | N41: 131 | O41: =RANK(N$41,N$38:N$48) -> 9
A42: 04Apr | B42: PRITY | C42: 26 | D42: -1 | E42: 0 | F42: 82 | G42: 24 | H42: 24 | I42: 0 | J42: 2 | K42: 10 | M42: 4 | N42: 171 | O42: =RANK(N$42,N$38:N$48) -> 1
...

Sheet Daftar Pemenang
A1: Daftar Pemenang PFOTM 2026
A4: Bulan | B4: Champ | D4: Nama | E4: Total
A5: Jan | B5: WAHYU | D5: WAHYU | E5: =COUNTIF(win_by_month[Champ],D5) -> 5
A6: Feb | B6: WAHYU | D6: AUL | E6: =COUNTIF(win_by_month[Champ],D6) -> 2
A7: Mar | B7: AUL | D7: HESTI | E7: =COUNTIF(win_by_month[Champ],D7) -> 1
A8: Apr | B8: PRITY | D8: PRITY | E8: =COUNTIF(win_by_month[Champ],D8) -> 1
A9: Mei | B9: WAHYU | D9: DANRU | E9: =COUNTIF(win_by_month[Champ],D9) -> 0
A10: Jun | B10: AUL | D10: DESTY | E10: =COUNTIF(win_by_month[Champ],D10) -> 0
A11: Jul | B11: HESTI | D11: HENA | E11: =COUNTIF(win_by_month[Champ],D11) -> 0
A12: Agu | B12: WAHYU | D12: NADA | E12: =COUNTIF(win_by_month[Champ],D12) -> 0
A13: Sep | B13: WAHYU | D13: OKTA | E13: =COUNTIF(win_by_month[Champ],D13) -> 0
A14: Okt | D14: ORY | E14: =COUNTIF(win_by_month[Champ],D14) -> 0
A15: Nov | D15: PUTRI | E15: =COUNTIF(win_by_month[Champ],D15) -> 0
A16: Des
