Workbook

Sheet Revise Page Tarif Layanan
B1: Tarif Layanan
B2: Fisioterapi Gang Sehat Pontianak
B4: DATA LAMA | F4: DATA PERUBAHAN
B5: NAMA | C5: KATEGORI | D5: SESI | E5: HARGA (RP) | F5: NAMA 2 | G5: KATEGORI 2 | H5: PERTEMUAN | I5: HARGA (RP) 2 | J5: DURASI PER PERTEMUAN (MENIT) | K5: KETERANGAN
B6: TUKAR TUNAI | C6: LAINNYA | D6: - | E6: - | F6: - | G6: - | H6: - | I6: - | J6: - | K6: Tukar Tunai adalah pengeluaran. Halaman ini hanya daftar pemasukan sesuai pricelist.
B7: Paket Khusus | C7: PAKET KLINIK | D7: 10 | E7: 500000 | F7: - | G7: - | H7: - | I7: - | J7: - | K7: Tidak ada Paket Khusus dalam pricelist. Jika diskon khusus dapat diinput ke tab diskon.
B8: PAKET SM SEGMENTAL | C8: PAKET SPORT MASSAGE | D8: - | E8: 440000 | F8: - | G8: - | H8: - | I8: - | J8: - | K8: Duplikat. Nama sudah ada (identik) tapi kategori beda.
B9: Sport Massage | C9: SESI KLINIK | D9: 1 | E9: 150000 | F9: - | G9: - | H9: - | I9: - | J9: - | K9: Harga lama. Layanan sudah tidak berlaku.
B10: Paket Penyesuaian | C10: SESI KLINIK | D10: 3 | E10: - | F10: - | G10: - | H10: - | I10: - | J10: - | K10: Tidak ada paket penyesuaian dalam pricelist.
B11: Paket 1 | C11: PAKET KLINIK | D11: 5 | E11: 650000 | F11: PAKET 1 FISIOTERAPI | G11: KLINIK - FT PAKET | H11: 5 | I11: 650000 | J11: 60 | K11: -
B12: Paket 2 | C12: PAKET KLINIK | D12: 10 | E12: 1200000 | F12: PAKET 2 FISIOTERAPI | G12: KLINIK - FT PAKET | H12: 10 | I12: 1200000 | J12: 60 | K12: -
B13: Paket Gold | C13: PAKET KLINIK | D13: 10 | E13: 1300000 | F13: PAKET GOLD FISIOTERAPI | G13: KLINIK - FT PAKET | H13: 10 | I13: 1300000 | J13: 60 | K13: -
B14: Paket Platinum | C14: PAKET KLINIK | D14: 20 | E14: 2400000 | F14: PAKET PLATINUM FISIOTERAPI | G14: KLINIK - FT PAKET | H14: 20 | I14: 2400000 | J14: 60 | K14: -
B15: Paket Silver | C15: PAKET KLINIK | D15: 5 | E15: 750000 | F15: PAKET SILVER FISIOTERAPI | G15: KLINIK - FT PAKET | H15: 5 | I15: 750000 | J15: 60 | K15: -
B16: Sesi Terapi | C16: SESI KLINIK | D16: 1 | E16: 180000 | F16: SESI FISIOTERAPI | G16: KLINIK - FT SESI | H16: 1 | I16: 180000 | J16: 60 | K16: -
B17: Sesi | C17: SESI KLINIK | D17: 1 | E17: 150000 | F17: SESI FISIOTERAPI LAMA | G17: KLINIK - FT SESI | H17: 1 | I17: 150000 | J17: 60 | K17: -
B18: Terapi Awal | C18: TA KLINIK | D18: - | E18: 250000 | F18: TERAPI AWAL FISIOTERAPI | G18: KLINIK - FT TERAPI AWAL | H18: 1 | I18: 250000 | J18: 60 | K18: -
B19: - | C19: - | D19: - | E19: - | F19: PAKET 1 KELAS LANSIA | G19: KLINIK - KL PAKET | H19: 4 | I19: 160000 | J19: 60 | K19: Layanan ini tidak ada di data lama karena belum pernah diinput sebelumnya.
B20: - | C20: - | D20: - | E20: - | F20: PAKET 1 PRIVAT COUPLE LANSIA | G20: KLINIK - KL PAKET | H20: 4 | I20: 760000 | J20: 60 | K20: Layanan ini tidak ada di data lama karena belum pernah diinput sebelumnya.
B21: - | C21: - | D21: - | E21: - | F21: PAKET 1 PRIVAT LANSIA | G21: KLINIK - KL PAKET | H21: 4 | I21: 400000 | J21: 60 | K21: Layanan ini tidak ada di data lama karena belum pernah diinput sebelumnya.
B22: - | C22: - | D22: - | E22: - | F22: PAKET 2 KELAS LANSIA | G22: KLINIK - KL PAKET | H22: 8 | I22: 240000 | J22: 60 | K22: Layanan ini tidak ada di data lama karena belum pernah diinput sebelumnya.
B23: - | C23: - | D23: - | E23: - | F23: PAKET 2 PRIVAT COUPLE LANSIA | G23: KLINIK - KL PAKET | H23: 8 | I23: 1440000 | J23: 60 | K23: Layanan ini tidak ada di data lama karena belum pernah diinput sebelumnya.
B24: - | C24: - | D24: - | E24: - | F24: PAKET 2 PRIVAT LANSIA | G24: KLINIK - KL PAKET | H24: 8 | I24: 720000 | J24: 60 | K24: Layanan ini tidak ada di data lama karena belum pernah diinput sebelumnya.
B25: - | C25: - | D25: - | E25: - | F25: PAKET 3 PRIVAT COUPLE LANSIA | G25: KLINIK - KL PAKET | H25: 12 | I25: 2040000 | J25: 60 | K25: Layanan ini tidak ada di data lama karena belum pernah diinput sebelumnya.
B26: - | C26: - | D26: - | E26: - | F26: PAKET 3 PRIVAT LANSIA | G26: KLINIK - KL PAKET | H26: 12 | I26: 960000 | J26: 60 | K26: Layanan ini tidak ada di data lama karena belum pernah diinput sebelumnya.
B27: - | C27: - | D27: - | E27: - | F27: SESI KELAS LANSIA | G27: KLINIK - KL SESI | H27: 1 | I27: 50000 | J27: 60 | K27: Layanan ini tidak ada di data lama karena belum pernah diinput sebelumnya.
B28: - | C28: - | D28: - | E28: - | F28: SESI PRIVAT COUPLE LANSIA | G28: KLINIK - KL SESI | H28: 1 | I28: 200000 | J28: 60 | K28: Layanan ini tidak ada di data lama karena belum pernah diinput sebelumnya.
B29: - | C29: - | D29: - | E29: - | F29: SESI PRIVAT LANSIA | G29: KLINIK - KL SESI | H29: 1 | I29: 110000 | J29: 60 | K29: Layanan ini tidak ada di data lama karena belum pernah diinput sebelumnya.
B30: - | C30: - | D30: - | E30: - | F30: PAKET GOLD KELAS SKOLIOSIS | G30: KLINIK - KS PAKET | H30: 8 | I30: 800000 | J30: 60 | K30: Layanan ini tidak ada di data lama karena belum pernah diinput sebelumnya.
... B33: - | C33: - | D33: - | E33: - | F33: SESI KELAS SKOLIOSIS | G33: KLINIK - KS SESI | H33: 1 | I33: 110000 | J33: 60 | K33: Layanan ini tidak ada di data lama karena belum pernah diinput sebelumnya.
B34: PAKET SM COMBO | C34: SPORT MASSAGE | D34: 3 | E34: 460000 | F34: PAKET COMBO 1 SPORTS MASSAGE | G34: KLINIK - SM PAKET | H34: 3 | I34: 460000 | J34: - | K34: Paket ini adalah kombinasi 2 layanan: 2x SESI FULL BODY SPORTS MASSAGE dan 1x SESI SEGMENTAL SPORTS MASSAGE
B35: PAKET SM COMBO 2 | C35: SPORT MASSAGE | D35: 4 | E35: 500000 | F35: PAKET COMBO 2 SPORTS MASSAGE | G35: KLINIK - SM PAKET | H35: 4 | I35: 500000 | J35: - | K35: Paket ini adalah kombinasi 2 layanan: 1x SESI FULL BODY SPORTS MASSAGE dan 3x SESI SEGMENTAL SPORTS MASSAGE
B36: Paket Combo SM Full | C36: SPORT MASSAGE | D36: 3 | E36: 525000 | F36: PAKET FULL BODY SPORTS MASSAGE | G36: KLINIK - SM PAKET | H36: 3 | I36: 525000 | J36: 90 | K36: -
B37: PAKET SM SEGMENTAL | C37: SPORT MASSAGE | D37: 4 | E37: 440000 | F37: PAKET SEGMENTAL SPORTS MASSAGE | G37: KLINIK - SM PAKET | H37: 4 | I37: 440000 | J37: 60 | K37: -
B38: Full body SM | C38: SPORT MASSAGE | D38: 2 | E38: 195000 | F38: SESI FULL BODY SPORTS MASSAGE | G38: KLINIK - SM SESI | H38: 1 | I38: 195000 | J38: 90 | K38: -
B39: Segmental SM | C39: SPORT MASSAGE | D39: 1 | E39: 125000 | F39: SESI SEGMENTAL SPORTS MASSAGE | G39: KLINIK - SM SESI | H39: 1 | I39: 125000 | J39: 60 | K39: -
B40: Pakt Home Visit | C40: PAKET VISIT | D40: 10 | E40: 1800000 | F40: PAKET FISIOTERAPI HOME VISIT | G40: VISIT - FT PAKET | H40: 10 | I40: 1800000 | J40: 60 | K40: -
B41: - | C41: - | D41: - | E41: - | F41: PAKET FISIOTERAPI HOME VISIT + JARAK | G41: VISIT - FT PAKET | H41: 10 | I41: 1800000 | J41: 60 | K41: Layanan ini tidak ada di data lama karena belum pernah diinput sebelumnya.
B42: - | C42: - | D42: - | E42: - | F42: SESI FISIOTERAPI HOME VISIT | G42: VISIT - FT SESI | H42: 1 | I42: 200000 | J42: 60 | K42: Layanan ini tidak ada di data lama karena belum pernah diinput sebelumnya.
B43: - | C43: - | D43: - | E43: - | F43: SESI FISIOTERAPI HOME VISIT + JARAK | G43: VISIT - FT SESI | H43: 1 | I43: 250000 | J43: 60 | K43: Layanan ini tidak ada di data lama karena belum pernah diinput sebelumnya.
...

Sheet Revise Supabase
B1: Tarif Layanan
B2: Fisioterapi Gang Sehat Pontianak
B4: False Description | C4: True Description | D4: True Category | E4: True Price (Rp) | F4: Notes
B5: AIR MINERAL ×1 | C5: - | D5: - | E5: {=_xlfn.XLOOKUP(C5,'Revise Page Tarif Layanan'!$F$6:$F927,'Revise Page Tarif Layanan'!$I$6:$I927)} -> - | F5: PENGELUARAN
B6: AIR MINERAL ×2 | C6: - | D6: - | E6: {=_xlfn.XLOOKUP(C6,'Revise Page Tarif Layanan'!$F$6:$F927,'Revise Page Tarif Layanan'!$I$6:$I927)} -> - | F6: PENGELUARAN
B7: AN SUMIATI 172 | C7: - | D7: - | E7: {=_xlfn.XLOOKUP(C7,'Revise Page Tarif Layanan'!$F$6:$F927,'Revise Page Tarif Layanan'!$I$6:$I927)} -> - | F7: NAMA PASIEN (?)
B8: AN. ARRON | C8: - | D8: - | E8: {=_xlfn.XLOOKUP(C8,'Revise Page Tarif Layanan'!$F$6:$F927,'Revise Page Tarif Layanan'!$I$6:$I927)} -> - | F8: NAMA PASIEN (?)
B9: AN. AZMAN | C9: - | D9: - | E9: {=_xlfn.XLOOKUP(C9,'Revise Page Tarif Layanan'!$F$6:$F927,'Revise Page Tarif Layanan'!$I$6:$I927)} -> - | F9: NAMA PASIEN (?)
B10: an. Muhammad Athallah Raisyauqi | C10: - | D10: - | E10: {=_xlfn.XLOOKUP(C10,'Revise Page Tarif Layanan'!$F$6:$F927,'Revise Page Tarif Layanan'!$I$6:$I927)} -> - | F10: NAMA PASIEN (?)
B11: AN. YOVINKA SUTIONO | C11: - | D11: - | E11: {=_xlfn.XLOOKUP(C11,'Revise Page Tarif Layanan'!$F$6:$F927,'Revise Page Tarif Layanan'!$I$6:$I927)} -> - | F11: NAMA PASIEN (?)
B12: ANDIKA | C12: - | D12: - | E12: {=_xlfn.XLOOKUP(C12,'Revise Page Tarif Layanan'!$F$6:$F927,'Revise Page Tarif Layanan'!$I$6:$I927)} -> - | F12: NAMA PASIEN (?)
B13: BALANCE TUKAR TUNAI | C13: - | D13: - | E13: {=_xlfn.XLOOKUP(C13,'Revise Page Tarif Layanan'!$F$6:$F927,'Revise Page Tarif Layanan'!$I$6:$I927)} -> - | F13: PENGELUARAN
B14: BEASISWA BG ED0 | C14: - | D14: - | E14: {=_xlfn.XLOOKUP(C14,'Revise Page Tarif Layanan'!$F$6:$F927,'Revise Page Tarif Layanan'!$I$6:$I927)} -> - | F14: DISKON
B15: BELI ICE BAG | C15: - | D15: - | E15: {=_xlfn.XLOOKUP(C15,'Revise Page Tarif Layanan'!$F$6:$F927,'Revise Page Tarif Layanan'!$I$6:$I927)} -> - | F15: TOKO
B16: DEDDY TANJAYA | C16: - | D16: - | E16: {=_xlfn.XLOOKUP(C16,'Revise Page Tarif Layanan'!$F$6:$F927,'Revise Page Tarif Layanan'!$I$6:$I927)} -> - | F16: NAMA PASIEN (?)
B17: DISKON BG EDO | C17: - | D17: - | E17: {=_xlfn.XLOOKUP(C17,'Revise Page Tarif Layanan'!$F$6:$F927,'Revise Page Tarif Layanan'!$I$6:$I927)} -> - | F17: DISKON
B18: DOKU GS261009CA47NVDY · QRIS · ref 602c0643-7605-44d6-a264-0464b5091cc3 | C18: - | D18: - | E18: {=_xlfn.XLOOKUP(C18,'Revise Page Tarif Layanan'!$F$6:$F927,'Revise Page Tarif Layanan'!$I$6:$I927)} -> - | F18: (?)
B19: ENDANG MULYANI | C19: - | D19: - | E19: {=_xlfn.XLOOKUP(C19,'Revise Page Tarif Layanan'!$F$6:$F927,'Revise Page Tarif Layanan'!$I$6:$I927)} -> - | F19: NAMA PASIEN (?)
B20: FITRA ISWANDI | C20: - | D20: - | E20: {=_xlfn.XLOOKUP(C20,'Revise Page Tarif Layanan'!$F$6:$F927,'Revise Page Tarif Layanan'!$I$6:$I927)} -> - | F20: NAMA PASIEN (?)
B21: Full body SM | C21: SESI FULL BODY SPORTS MASSAGE | D21: KLINIK - SM SESI | E21: {=_xlfn.XLOOKUP(C21,'Revise Page Tarif Layanan'!$F$6:$F927,'Revise Page Tarif Layanan'!$I$6:$I927)} -> 195000 | F21: -
B22: Home Visit | C22: TERAPI AWAL FISIOTERAPI HOME VISIT | D22: VISIT - FT TERAPI AWAL | E22: {=_xlfn.XLOOKUP(C22,'Revise Page Tarif Layanan'!$F$6:$F927,'Revise Page Tarif Layanan'!$I$6:$I927)} -> 300000 | F22: -
B23: Impor data historis (KODE: TRX/2025/09/0002) · tanggal dari sistem order (tidak ditemukan di buku kas) | C23: - | D23: - | E23: {=_xlfn.XLOOKUP(C23,'Revise Page Tarif Layanan'!$F$6:$F927,'Revise Page Tarif Layanan'!$I$6:$I927)} -> - | F23: DATA IMPOR (?)
B24: Impor data historis (KODE: TRX/2025/09/0007) · tanggal dari sistem order (tidak ditemukan di buku kas) | C24: - | D24: - | E24: {=_xlfn.XLOOKUP(C24,'Revise Page Tarif Layanan'!$F$6:$F927,'Revise Page Tarif Layanan'!$I$6:$I927)} -> - | F24: DATA IMPOR (?)
B25: Impor data historis (KODE: TRX/2025/09/0012) · tanggal dari sistem order (tidak ditemukan di buku kas) | C25: - | D25: - | E25: {=_xlfn.XLOOKUP(C25,'Revise Page Tarif Layanan'!$F$6:$F927,'Revise Page Tarif Layanan'!$I$6:$I927)} -> - | F25: DATA IMPOR (?)
B26: Impor data historis (KODE: TRX/2025/09/0013) · tanggal dari sistem order (tidak ditemukan di buku kas) | C26: - | D26: - | E26: {=_xlfn.XLOOKUP(C26,'Revise Page Tarif Layanan'!$F$6:$F927,'Revise Page Tarif Layanan'!$I$6:$I927)} -> - | F26: DATA IMPOR (?)
B27: Impor data historis (KODE: TRX/2025/09/0014) · tanggal dari sistem order (tidak ditemukan di buku kas) | C27: - | D27: - | E27: {=_xlfn.XLOOKUP(C27,'Revise Page Tarif Layanan'!$F$6:$F927,'Revise Page Tarif Layanan'!$I$6:$I927)} -> - | F27: DATA IMPOR (?)
B28: Impor data historis (KODE: TRX/2025/09/0017) | C28: - | D28: - | E28: {=_xlfn.XLOOKUP(C28,'Revise Page Tarif Layanan'!$F$6:$F927,'Revise Page Tarif Layanan'!$I$6:$I927)} -> - | F28: DATA IMPOR (?)
B29: Impor data historis (KODE: TRX/2025/09/0018) · tanggal dari sistem order (tidak ditemukan di buku kas) | C29: - | D29: - | E29: {=_xlfn.XLOOKUP(C29,'Revise Page Tarif Layanan'!$F$6:$F927,'Revise Page Tarif Layanan'!$I$6:$I927)} -> - | F29: DATA IMPOR (?)
B30: Impor data historis (KODE: TRX/2025/09/0022) · tanggal dari sistem order (tidak ditemukan di buku kas) | C30: - | D30: - | E30: {=_xlfn.XLOOKUP(C30,'Revise Page Tarif Layanan'!$F$6:$F927,'Revise Page Tarif Layanan'!$I$6:$I927)} -> - | F30: DATA IMPOR (?)
B31: Impor data historis (KODE: TRX/2025/09/0023) · tanggal dari sistem order (tidak ditemukan di buku kas) | C31: - | D31: - | E31: {=_xlfn.XLOOKUP(C31,'Revise Page Tarif Layanan'!$F$6:$F927,'Revise Page Tarif Layanan'!$I$6:$I927)} -> - | F31: DATA IMPOR (?)
B32: Impor data historis (KODE: TRX/2025/10/0001) · tanggal dari sistem order (tidak ditemukan di buku kas) | C32: - | D32: - | E32: {=_xlfn.XLOOKUP(C32,'Revise Page Tarif Layanan'!$F$6:$F927,'Revise Page Tarif Layanan'!$I$6:$I927)} -> - | F32: DATA IMPOR (?)
B33: Impor data historis (KODE: TRX/2025/10/0004) | C33: - | D33: - | E33: {=_xlfn.XLOOKUP(C33,'Revise Page Tarif Layanan'!$F$6:$F927,'Revise Page Tarif Layanan'!$I$6:$I927)} -> - | F33: DATA IMPOR (?)
B34: Impor data historis (KODE: TRX/2025/10/0005) · tanggal dari sistem order (tidak ditemukan di buku kas) | C34: - | D34: - | E34: {=_xlfn.XLOOKUP(C34,'Revise Page Tarif Layanan'!$F$6:$F927,'Revise Page Tarif Layanan'!$I$6:$I927)} -> - | F34: DATA IMPOR (?)
B35: Impor data historis (KODE: TRX/2025/10/0006) · tanggal dari sistem order (tidak ditemukan di buku kas) | C35: - | D35: - | E35: {=_xlfn.XLOOKUP(C35,'Revise Page Tarif Layanan'!$F$6:$F927,'Revise Page Tarif Layanan'!$I$6:$I927)} -> - | F35: DATA IMPOR (?)
B36: Impor data historis (KODE: TRX/2025/10/0007) · tanggal dari sistem order (tidak ditemukan di buku kas) | C36: - | D36: - | E36: {=_xlfn.XLOOKUP(C36,'Revise Page Tarif Layanan'!$F$6:$F927,'Revise Page Tarif Layanan'!$I$6:$I927)} -> - | F36: DATA IMPOR (?)
B37: Impor data historis (KODE: TRX/2025/10/0008) · tanggal dari sistem order (tidak ditemukan di buku kas) | C37: - | D37: - | E37: {=_xlfn.XLOOKUP(C37,'Revise Page Tarif Layanan'!$F$6:$F927,'Revise Page Tarif Layanan'!$I$6:$I927)} -> - | F37: DATA IMPOR (?)
B38: Impor data historis (KODE: TRX/2025/10/0011) · tanggal dari sistem order (tidak ditemukan di buku kas) | C38: - | D38: - | E38: {=_xlfn.XLOOKUP(C38,'Revise Page Tarif Layanan'!$F$6:$F927,'Revise Page Tarif Layanan'!$I$6:$I927)} -> - | F38: DATA IMPOR (?)
B39: Impor data historis (KODE: TRX/2025/10/0012) · tanggal dari sistem order (tidak ditemukan di buku kas) | C39: - | D39: - | E39: {=_xlfn.XLOOKUP(C39,'Revise Page Tarif Layanan'!$F$6:$F927,'Revise Page Tarif Layanan'!$I$6:$I927)} -> - | F39: DATA IMPOR (?)
B40: Impor data historis (KODE: TRX/2025/10/0018) | C40: - | D40: - | E40: {=_xlfn.XLOOKUP(C40,'Revise Page Tarif Layanan'!$F$6:$F927,'Revise Page Tarif Layanan'!$I$6:$I927)} -> - | F40: DATA IMPOR (?)
B41: Impor data historis (KODE: TRX/2025/10/0019) · tanggal dari sistem order (tidak ditemukan di buku kas) | C41: - | D41: - | E41: {=_xlfn.XLOOKUP(C41,'Revise Page Tarif Layanan'!$F$6:$F927,'Revise Page Tarif Layanan'!$I$6:$I927)} -> - | F41: DATA IMPOR (?)
...
